Author: Bo3 BulkEdit
Description: Converted Schematic - Modified by Bo3BulkEdit
Version: 3
SettingsMode: WriteDisable
Frequency: 0
SpawnHeight: randomY
MinHeight: 0
MaxHeight: 256
CanOverride: true
MaxPercentageOutsideSourceBlock: 100
OutsideSourceBlock: placeAnyway
B(0,750,0,AIR)
B(15,750,15,AIR)
B(15,-3,15,betternether:quartz_stained_glass:15)
B(15,-2,13,betternether:quartz_stained_glass:15)
B(13,-2,14,betternether:quartz_stained_glass:15)
B(14,-2,14,betternether:quartz_stained_glass:15)
B(15,-2,14,betternether:quartz_stained_glass:15)
B(13,-2,15,betternether:quartz_stained_glass:15)
B(14,-2,15,betternether:quartz_stained_glass:15)
B(15,-2,15,betternether:quartz_stained_glass:15)
B(14,-1,11,betternether:quartz_stained_glass:15)
B(13,-1,12,betternether:quartz_stained_glass:15)
B(14,-1,12,betternether:quartz_stained_glass:15)
B(15,-1,12,betternether:quartz_stained_glass:15)
B(11,-1,13,betternether:quartz_stained_glass:15)
B(12,-1,13,betternether:quartz_stained_glass:15)
B(13,-1,13,betternether:quartz_stained_glass:15)
B(14,-1,13,betternether:quartz_stained_glass:15)
B(15,-1,13,betternether:quartz_stained_glass:15)
B(11,-1,14,betternether:quartz_stained_glass:15)
B(12,-1,14,betternether:quartz_stained_glass:15)
B(13,-1,14,betternether:quartz_stained_glass:15)
B(14,-1,14,betternether:quartz_stained_glass:15)
B(12,-1,15,betternether:quartz_stained_glass:15)
B(13,-1,15,betternether:quartz_stained_glass:15)
B(13,0,10,betternether:quartz_stained_glass:15)
B(14,0,10,betternether:quartz_stained_glass:15)
B(13,0,11,betternether:quartz_stained_glass:15)
B(14,0,11,betternether:quartz_stained_glass:15)
B(15,0,11,betternether:quartz_stained_glass:15)
B(10,0,12,betternether:quartz_stained_glass:15)
B(11,0,12,betternether:quartz_stained_glass:15)
B(12,0,12,betternether:quartz_stained_glass:15)
B(15,0,12,betternether:quartz_stained_glass:15)
B(10,0,13,betternether:quartz_stained_glass:15)
B(11,0,13,betternether:quartz_stained_glass:15)
B(12,0,13,betternether:quartz_stained_glass:15)
RB(13,0,13,srparasites:parasitestain:1,80,quark:crystal:1,30,srparasites:parasiterubbledense:1,100)
RB(14,0,13,srparasites:parasitestain:1,80,quark:crystal:1,30,srparasites:parasiterubbledense:1,100)
B(10,0,14,betternether:quartz_stained_glass:15)
B(11,0,14,betternether:quartz_stained_glass:15)
RB(13,0,14,srparasites:parasitestain:1,80,quark:crystal:1,30,srparasites:parasiterubbledense:1,100)
B(11,0,15,betternether:quartz_stained_glass:15)
B(12,0,15,betternether:quartz_stained_glass:15)
B(13,0,15,srparasites:parasiterubbledense:1)
B(14,0,15,betternether:quartz_stained_glass:15)
B(15,0,15,betternether:quartz_stained_glass:15)
B(12,1,9,betternether:quartz_stained_glass:15)
B(13,1,9,betternether:quartz_stained_glass:15)
B(11,1,10,betternether:quartz_stained_glass:15)
B(12,1,10,betternether:quartz_stained_glass:15)
B(13,1,10,betternether:quartz_stained_glass:15)
B(14,1,10,betternether:quartz_stained_glass:15)
B(15,1,10,betternether:quartz_stained_glass:15)
B(10,1,11,betternether:quartz_stained_glass:15)
B(11,1,11,betternether:quartz_stained_glass:15)
B(12,1,11,betternether:quartz_stained_glass:15)
B(13,1,11,betternether:quartz_stained_glass:15)
B(14,1,11,betternether:quartz_stained_glass:15)
B(15,1,11,betternether:quartz_stained_glass:15)
B(9,1,12,betternether:quartz_stained_glass:15)
B(10,1,12,betternether:quartz_stained_glass:15)
B(11,1,12,betternether:quartz_stained_glass:15)
RB(12,1,12,srparasites:parasitestain:1,80,quark:crystal:1,30,srparasites:parasiterubbledense:1,100)
RB(13,1,12,srparasites:parasitestain:1,80,quark:crystal:1,30,srparasites:parasiterubbledense:1,100)
B(14,1,12,betternether:quartz_stained_glass:15)
B(15,1,12,betternether:quartz_stained_glass:15)
B(9,1,13,betternether:quartz_stained_glass:15)
B(10,1,13,betternether:quartz_stained_glass:15)
B(11,1,13,betternether:quartz_stained_glass:15)
RB(12,1,13,srparasites:parasitestain:1,80,quark:crystal:1,30,srparasites:parasiterubbledense:1,100)
RB(13,1,13,srparasites:parasitestain:1,80,quark:crystal:1,30,srparasites:parasiterubbledense:1,100)
B(14,1,13,betternether:quartz_stained_glass:15)
B(15,1,13,betternether:quartz_stained_glass:15)
B(10,1,14,betternether:quartz_stained_glass:15)
B(11,1,14,betternether:quartz_stained_glass:15)
B(12,1,14,betternether:quartz_stained_glass:15)
B(13,1,14,srparasites:parasiterubbledense:1)
B(14,1,14,betternether:quartz_stained_glass:15)
B(15,1,14,betternether:quartz_stained_glass:15)
B(10,1,15,betternether:quartz_stained_glass:15)
B(11,1,15,betternether:quartz_stained_glass:15)
B(12,1,15,betternether:quartz_stained_glass:15)
B(13,1,15,betternether:quartz_stained_glass:15)
B(14,1,15,betternether:quartz_stained_glass:15)
B(15,1,15,betternether:quartz_stained_glass:15)
B(12,2,8,betternether:quartz_stained_glass:15)
B(11,2,9,betternether:quartz_stained_glass:15)
B(12,2,9,betternether:quartz_stained_glass:15)
B(13,2,9,betternether:quartz_stained_glass:15)
B(10,2,10,betternether:quartz_stained_glass:15)
B(11,2,10,betternether:quartz_stained_glass:15)
B(12,2,10,betternether:quartz_stained_glass:15)
B(13,2,10,betternether:quartz_stained_glass:15)
B(14,2,10,betternether:quartz_stained_glass:15)
B(15,2,10,betternether:quartz_stained_glass:15)
B(9,2,11,betternether:quartz_stained_glass:15)
B(10,2,11,betternether:quartz_stained_glass:15)
B(11,2,11,betternether:quartz_stained_glass:15)
RB(12,2,11,srparasites:parasitestain:1,80,quark:crystal:1,30,srparasites:parasiterubbledense:1,100)
B(13,2,11,betternether:quartz_stained_glass:15)
B(14,2,11,betternether:quartz_stained_glass:15)
B(15,2,11,betternether:quartz_stained_glass:15)
B(8,2,12,betternether:quartz_stained_glass:15)
B(9,2,12,betternether:quartz_stained_glass:15)
B(10,2,12,betternether:quartz_stained_glass:15)
RB(11,2,12,srparasites:parasitestain:1,80,quark:crystal:1,30,srparasites:parasiterubbledense:1,100)
RB(12,2,12,srparasites:parasitestain:1,80,quark:crystal:1,30,srparasites:parasiterubbledense:1,100)
RB(13,2,12,srparasites:parasitestain:1,80,quark:crystal:1,30,srparasites:parasiterubbledense:1,100)
B(14,2,12,betternether:quartz_stained_glass:15)
B(15,2,12,betternether:quartz_stained_glass:15)
B(9,2,13,betternether:quartz_stained_glass:15)
B(10,2,13,betternether:quartz_stained_glass:15)
B(11,2,13,betternether:quartz_stained_glass:15)
RB(12,2,13,srparasites:parasitestain:1,80,quark:crystal:1,30,srparasites:parasiterubbledense:1,100)
B(13,2,13,srparasites:parasiterubbledense:1)
B(14,2,13,srparasites:parasiterubbledense:1)
B(15,2,13,betternether:quartz_stained_glass:15)
B(10,2,14,betternether:quartz_stained_glass:15)
B(11,2,14,betternether:quartz_stained_glass:15)
B(12,2,14,srparasites:parasiterubbledense:1)
B(13,2,14,srparasites:parasiterubbledense:1)
B(14,2,14,betternether:quartz_stained_glass:15)
B(15,2,14,betternether:quartz_stained_glass:15)
B(10,2,15,betternether:quartz_stained_glass:15)
B(11,2,15,betternether:quartz_stained_glass:15)
B(12,2,15,srparasites:parasiterubbledense:1)
B(13,2,15,betternether:quartz_stained_glass:15)
B(14,2,15,betternether:quartz_stained_glass:15)
B(11,3,8,betternether:quartz_stained_glass:15)
B(12,3,8,betternether:quartz_stained_glass:15)
B(10,3,9,betternether:quartz_stained_glass:15)
B(11,3,9,betternether:quartz_stained_glass:15)
B(12,3,9,betternether:quartz_stained_glass:15)
B(13,3,9,betternether:quartz_stained_glass:15)
B(14,3,9,betternether:quartz_stained_glass:15)
B(9,3,10,betternether:quartz_stained_glass:15)
B(10,3,10,betternether:quartz_stained_glass:15)
B(11,3,10,betternether:quartz_stained_glass:15)
B(12,3,10,betternether:quartz_stained_glass:15)
B(13,3,10,betternether:quartz_stained_glass:15)
B(14,3,10,betternether:quartz_stained_glass:15)
B(15,3,10,betternether:quartz_stained_glass:15)
B(8,3,11,betternether:quartz_stained_glass:15)
B(9,3,11,betternether:quartz_stained_glass:15)
B(10,3,11,betternether:quartz_stained_glass:15)
RB(11,3,11,srparasites:parasitestain:1,80,quark:crystal:1,30,srparasites:parasiterubbledense:1,100)
RB(12,3,11,srparasites:parasitestain:1,80,quark:crystal:1,30,srparasites:parasiterubbledense:1,100)
B(13,3,11,betternether:quartz_stained_glass:15)
B(14,3,11,betternether:quartz_stained_glass:15)
B(15,3,11,betternether:quartz_stained_glass:15)
B(8,3,12,betternether:quartz_stained_glass:15)
B(9,3,12,betternether:quartz_stained_glass:15)
B(10,3,12,betternether:quartz_stained_glass:15)
RB(11,3,12,srparasites:parasitestain:1,80,quark:crystal:1,30,srparasites:parasiterubbledense:1,100)
RB(12,3,12,srparasites:parasitestain:1,80,quark:crystal:1,30,srparasites:parasiterubbledense:1,100)
B(13,3,12,srparasites:parasiterubbledense:1)
B(14,3,12,betternether:quartz_stained_glass:15)
B(15,3,12,betternether:quartz_stained_glass:15)
B(9,3,13,betternether:quartz_stained_glass:15)
B(10,3,13,betternether:quartz_stained_glass:15)
B(11,3,13,betternether:quartz_stained_glass:15)
B(12,3,13,srparasites:parasiterubbledense:1)
B(13,3,13,srparasites:parasiterubbledense:1)
B(14,3,13,betternether:quartz_stained_glass:15)
B(9,3,14,betternether:quartz_stained_glass:15)
B(10,3,14,betternether:quartz_stained_glass:15)
B(11,3,14,srparasites:parasiterubbledense:1)
B(12,3,14,srparasites:parasiterubbledense:1)
B(13,3,14,betternether:quartz_stained_glass:15)
B(14,3,14,betternether:quartz_stained_glass:15)
B(10,3,15,betternether:quartz_stained_glass:15)
B(11,3,15,betternether:quartz_stained_glass:15)
B(12,3,15,betternether:quartz_stained_glass:15)
B(11,4,7,betternether:quartz_stained_glass:15)
B(10,4,8,betternether:quartz_stained_glass:15)
B(11,4,8,betternether:quartz_stained_glass:15)
B(12,4,8,betternether:quartz_stained_glass:15)
B(9,4,9,betternether:quartz_stained_glass:15)
B(10,4,9,betternether:quartz_stained_glass:15)
B(11,4,9,betternether:quartz_stained_glass:15)
B(12,4,9,betternether:quartz_stained_glass:15)
B(13,4,9,betternether:quartz_stained_glass:15)
B(14,4,9,betternether:quartz_stained_glass:15)
B(8,4,10,betternether:quartz_stained_glass:15)
B(9,4,10,betternether:quartz_stained_glass:15)
B(10,4,10,betternether:quartz_stained_glass:15)
RB(11,4,10,srparasites:parasitestain:1,80,quark:crystal:1,30,srparasites:parasiterubbledense:1,100)
B(12,4,10,betternether:quartz_stained_glass:15)
B(13,4,10,betternether:quartz_stained_glass:15)
B(14,4,10,betternether:quartz_stained_glass:15)
B(7,4,11,betternether:quartz_stained_glass:15)
B(8,4,11,betternether:quartz_stained_glass:15)
B(9,4,11,betternether:quartz_stained_glass:15)
RB(10,4,11,srparasites:parasitestain:1,80,quark:crystal:1,30,srparasites:parasiterubbledense:1,100)
RB(11,4,11,srparasites:parasitestain:1,80,quark:crystal:1,30,srparasites:parasiterubbledense:1,100)
RB(12,4,11,srparasites:parasitestain:1,80,quark:crystal:1,30,srparasites:parasiterubbledense:1,100)
B(13,4,11,betternether:quartz_stained_glass:15)
B(14,4,11,betternether:quartz_stained_glass:15)
B(15,4,11,betternether:quartz_stained_glass:15)
B(8,4,12,betternether:quartz_stained_glass:15)
B(9,4,12,betternether:quartz_stained_glass:15)
B(10,4,12,betternether:quartz_stained_glass:15)
RB(11,4,12,srparasites:parasitestain:1,80,quark:crystal:1,30,srparasites:parasiterubbledense:1,100)
B(12,4,12,betternether:quartz_stained_glass:15)
B(13,4,12,betternether:quartz_stained_glass:15)
B(14,4,12,betternether:quartz_stained_glass:15)
B(9,4,13,betternether:quartz_stained_glass:15)
B(10,4,13,betternether:quartz_stained_glass:15)
B(11,4,13,betternether:quartz_stained_glass:15)
B(12,4,13,srparasites:parasiterubbledense:1)
B(13,4,13,betternether:quartz_stained_glass:15)
B(14,4,13,betternether:quartz_stained_glass:15)
B(9,4,14,betternether:quartz_stained_glass:15)
B(10,4,14,betternether:quartz_stained_glass:15)
B(11,4,14,betternether:quartz_stained_glass:15)
B(12,4,14,betternether:quartz_stained_glass:15)
B(13,4,14,betternether:quartz_stained_glass:15)
B(11,4,15,betternether:quartz_stained_glass:15)
B(10,5,7,betternether:quartz_stained_glass:15)
B(11,5,7,betternether:quartz_stained_glass:15)
B(9,5,8,betternether:quartz_stained_glass:15)
B(10,5,8,betternether:quartz_stained_glass:15)
B(11,5,8,betternether:quartz_stained_glass:15)
B(12,5,8,betternether:quartz_stained_glass:15)
B(13,5,8,betternether:quartz_stained_glass:15)
B(8,5,9,betternether:quartz_stained_glass:15)
B(9,5,9,betternether:quartz_stained_glass:15)
B(10,5,9,betternether:quartz_stained_glass:15)
B(11,5,9,betternether:quartz_stained_glass:15)
B(12,5,9,betternether:quartz_stained_glass:15)
B(13,5,9,betternether:quartz_stained_glass:15)
B(14,5,9,betternether:quartz_stained_glass:15)
B(7,5,10,betternether:quartz_stained_glass:15)
B(8,5,10,betternether:quartz_stained_glass:15)
B(9,5,10,betternether:quartz_stained_glass:15)
RB(10,5,10,srparasites:parasitestain:1,80,quark:crystal:1,30,srparasites:parasiterubbledense:1,100)
RB(11,5,10,srparasites:parasitestain:1,80,quark:crystal:1,30,srparasites:parasiterubbledense:1,100)
B(12,5,10,betternether:quartz_stained_glass:15)
B(13,5,10,betternether:quartz_stained_glass:15)
B(14,5,10,betternether:quartz_stained_glass:15)
B(7,5,11,betternether:quartz_stained_glass:15)
B(8,5,11,betternether:quartz_stained_glass:15)
B(9,5,11,betternether:quartz_stained_glass:15)
RB(10,5,11,srparasites:parasitestain:1,80,quark:crystal:1,30,srparasites:parasiterubbledense:1,100)
RB(11,5,11,srparasites:parasitestain:1,80,quark:crystal:1,30,srparasites:parasiterubbledense:1,100)
B(12,5,11,betternether:quartz_stained_glass:15)
B(13,5,11,betternether:quartz_stained_glass:15)
B(14,5,11,betternether:quartz_stained_glass:15)
B(8,5,12,betternether:quartz_stained_glass:15)
B(9,5,12,betternether:quartz_stained_glass:15)
B(10,5,12,betternether:quartz_stained_glass:15)
B(11,5,12,srparasites:parasiterubbledense:1)
B(12,5,12,srparasites:parasiterubbledense:1)
B(13,5,12,betternether:quartz_stained_glass:15)
B(8,5,13,betternether:quartz_stained_glass:15)
B(9,5,13,betternether:quartz_stained_glass:15)
B(10,5,13,betternether:quartz_stained_glass:15)
B(11,5,13,srparasites:parasiterubbledense:1)
B(12,5,13,betternether:quartz_stained_glass:15)
B(13,5,13,betternether:quartz_stained_glass:15)
B(9,5,14,betternether:quartz_stained_glass:15)
B(10,5,14,betternether:quartz_stained_glass:15)
B(11,5,14,betternether:quartz_stained_glass:15)
B(10,6,6,betternether:quartz_stained_glass:15)
B(9,6,7,betternether:quartz_stained_glass:15)
B(10,6,7,betternether:quartz_stained_glass:15)
B(11,6,7,betternether:quartz_stained_glass:15)
B(8,6,8,betternether:quartz_stained_glass:15)
B(9,6,8,betternether:quartz_stained_glass:15)
B(10,6,8,betternether:quartz_stained_glass:15)
B(11,6,8,betternether:quartz_stained_glass:15)
B(12,6,8,betternether:quartz_stained_glass:15)
B(13,6,8,betternether:quartz_stained_glass:15)
B(7,6,9,betternether:quartz_stained_glass:15)
B(8,6,9,betternether:quartz_stained_glass:15)
B(9,6,9,betternether:quartz_stained_glass:15)
RB(10,6,9,srparasites:parasitestain:1,80,quark:crystal:1,30,srparasites:parasiterubbledense:1,100)
B(11,6,9,betternether:quartz_stained_glass:15)
B(12,6,9,betternether:quartz_stained_glass:15)
B(13,6,9,betternether:quartz_stained_glass:15)
B(6,6,10,betternether:quartz_stained_glass:15)
B(7,6,10,betternether:quartz_stained_glass:15)
B(8,6,10,betternether:quartz_stained_glass:15)
RB(9,6,10,srparasites:parasitestain:1,80,quark:crystal:1,30,srparasites:parasiterubbledense:1,100)
RB(10,6,10,srparasites:parasitestain:1,80,quark:crystal:1,30,srparasites:parasiterubbledense:1,100)
RB(11,6,10,srparasites:parasitestain:1,80,quark:crystal:1,30,srparasites:parasiterubbledense:1,100)
B(12,6,10,betternether:quartz_stained_glass:15)
B(13,6,10,betternether:quartz_stained_glass:15)
B(14,6,10,betternether:quartz_stained_glass:15)
B(7,6,11,betternether:quartz_stained_glass:15)
B(8,6,11,betternether:quartz_stained_glass:15)
B(9,6,11,betternether:quartz_stained_glass:15)
RB(10,6,11,srparasites:parasitestain:1,80,quark:crystal:1,30,srparasites:parasiterubbledense:1,100)
B(11,6,11,betternether:quartz_stained_glass:15)
B(12,6,11,srparasites:parasiterubbledense:1)
B(13,6,11,betternether:quartz_stained_glass:15)
B(8,6,12,betternether:quartz_stained_glass:15)
B(9,6,12,betternether:quartz_stained_glass:15)
B(10,6,12,betternether:quartz_stained_glass:15)
B(11,6,12,srparasites:parasiterubbledense:1)
B(12,6,12,betternether:quartz_stained_glass:15)
B(13,6,12,betternether:quartz_stained_glass:15)
B(8,6,13,betternether:quartz_stained_glass:15)
B(9,6,13,betternether:quartz_stained_glass:15)
B(10,6,13,srparasites:parasiterubbledense:1)
B(11,6,13,betternether:quartz_stained_glass:15)
B(12,6,13,betternether:quartz_stained_glass:15)
B(10,6,14,betternether:quartz_stained_glass:15)
B(9,7,6,betternether:quartz_stained_glass:15)
B(10,7,6,betternether:quartz_stained_glass:15)
B(8,7,7,betternether:quartz_stained_glass:15)
B(9,7,7,betternether:quartz_stained_glass:15)
B(10,7,7,betternether:quartz_stained_glass:15)
B(11,7,7,betternether:quartz_stained_glass:15)
B(12,7,7,betternether:quartz_stained_glass:15)
B(7,7,8,betternether:quartz_stained_glass:15)
B(8,7,8,betternether:quartz_stained_glass:15)
B(9,7,8,betternether:quartz_stained_glass:15)
B(10,7,8,betternether:quartz_stained_glass:15)
B(11,7,8,betternether:quartz_stained_glass:15)
B(12,7,8,betternether:quartz_stained_glass:15)
B(13,7,8,betternether:quartz_stained_glass:15)
B(6,7,9,betternether:quartz_stained_glass:15)
B(7,7,9,betternether:quartz_stained_glass:15)
B(8,7,9,betternether:quartz_stained_glass:15)
RB(9,7,9,srparasites:parasitestain:1,80,quark:crystal:1,30,srparasites:parasiterubbledense:1,100)
RB(10,7,9,srparasites:parasitestain:1,80,quark:crystal:1,30,srparasites:parasiterubbledense:1,100)
B(11,7,9,betternether:quartz_stained_glass:15)
B(12,7,9,betternether:quartz_stained_glass:15)
B(13,7,9,betternether:quartz_stained_glass:15)
B(6,7,10,betternether:quartz_stained_glass:15)
B(7,7,10,betternether:quartz_stained_glass:15)
B(8,7,10,betternether:quartz_stained_glass:15)
RB(9,7,10,srparasites:parasitestain:1,80,quark:crystal:1,30,srparasites:parasiterubbledense:1,100)
RB(10,7,10,srparasites:parasitestain:1,80,quark:crystal:1,30,srparasites:parasiterubbledense:1,100)
B(11,7,10,srparasites:parasiterubbledense:1)
B(12,7,10,srparasites:parasiterubbledense:1)
B(13,7,10,betternether:quartz_stained_glass:15)
B(7,7,11,betternether:quartz_stained_glass:15)
B(8,7,11,betternether:quartz_stained_glass:15)
B(9,7,11,betternether:quartz_stained_glass:15)
B(10,7,11,betternether:quartz_stained_glass:15)
B(11,7,11,srparasites:parasiterubbledense:1)
B(12,7,11,betternether:quartz_stained_glass:15)
B(7,7,12,betternether:quartz_stained_glass:15)
B(8,7,12,betternether:quartz_stained_glass:15)
B(9,7,12,betternether:quartz_stained_glass:15)
B(10,7,12,betternether:quartz_stained_glass:15)
B(11,7,12,betternether:quartz_stained_glass:15)
B(12,7,12,betternether:quartz_stained_glass:15)
B(8,7,13,betternether:quartz_stained_glass:15)
B(9,7,13,betternether:quartz_stained_glass:15)
B(10,7,13,betternether:quartz_stained_glass:15)
B(9,8,5,betternether:quartz_stained_glass:15)
B(8,8,6,betternether:quartz_stained_glass:15)
B(9,8,6,betternether:quartz_stained_glass:15)
B(10,8,6,betternether:quartz_stained_glass:15)
B(7,8,7,betternether:quartz_stained_glass:15)
B(8,8,7,betternether:quartz_stained_glass:15)
B(9,8,7,betternether:quartz_stained_glass:15)
B(10,8,7,betternether:quartz_stained_glass:15)
B(11,8,7,betternether:quartz_stained_glass:15)
B(12,8,7,betternether:quartz_stained_glass:15)
B(6,8,8,betternether:quartz_stained_glass:15)
B(7,8,8,betternether:quartz_stained_glass:15)
B(8,8,8,betternether:quartz_stained_glass:15)
RB(9,8,8,srparasites:parasitestain:1,80,quark:crystal:1,30,srparasites:parasiterubbledense:1,100)
B(10,8,8,betternether:quartz_stained_glass:15)
B(11,8,8,betternether:quartz_stained_glass:15)
B(12,8,8,betternether:quartz_stained_glass:15)
B(5,8,9,betternether:quartz_stained_glass:15)
B(6,8,9,betternether:quartz_stained_glass:15)
B(7,8,9,betternether:quartz_stained_glass:15)
RB(8,8,9,srparasites:parasitestain:1,80,quark:crystal:1,30,srparasites:parasiterubbledense:1,100)
RB(9,8,9,srparasites:parasitestain:1,80,quark:crystal:1,30,srparasites:parasiterubbledense:1,100)
RB(10,8,9,srparasites:parasitestain:1,80,quark:crystal:1,30,srparasites:parasiterubbledense:1,100)
B(11,8,9,betternether:quartz_stained_glass:15)
B(12,8,9,srparasites:parasiterubbledense:1)
B(13,8,9,betternether:quartz_stained_glass:15)
B(6,8,10,betternether:quartz_stained_glass:15)
B(7,8,10,betternether:quartz_stained_glass:15)
B(8,8,10,betternether:quartz_stained_glass:15)
RB(9,8,10,srparasites:parasitestain:1,80,quark:crystal:1,30,srparasites:parasiterubbledense:1,100)
B(10,8,10,betternether:quartz_stained_glass:15)
B(11,8,10,srparasites:parasiterubbledense:1)
B(12,8,10,betternether:quartz_stained_glass:15)
B(7,8,11,betternether:quartz_stained_glass:15)
B(8,8,11,betternether:quartz_stained_glass:15)
B(9,8,11,betternether:quartz_stained_glass:15)
B(10,8,11,srparasites:parasiterubbledense:1)
B(11,8,11,betternether:quartz_stained_glass:15)
B(12,8,11,betternether:quartz_stained_glass:15)
B(7,8,12,betternether:quartz_stained_glass:15)
B(8,8,12,betternether:quartz_stained_glass:15)
B(9,8,12,betternether:quartz_stained_glass:15)
B(10,8,12,betternether:quartz_stained_glass:15)
B(11,8,12,betternether:quartz_stained_glass:15)
B(9,8,13,betternether:quartz_stained_glass:15)
B(8,9,5,betternether:quartz_stained_glass:15)
B(9,9,5,betternether:quartz_stained_glass:15)
B(7,9,6,betternether:quartz_stained_glass:15)
B(8,9,6,betternether:quartz_stained_glass:15)
B(9,9,6,betternether:quartz_stained_glass:15)
B(10,9,6,betternether:quartz_stained_glass:15)
B(11,9,6,betternether:quartz_stained_glass:15)
B(6,9,7,betternether:quartz_stained_glass:15)
B(7,9,7,betternether:quartz_stained_glass:15)
B(8,9,7,betternether:quartz_stained_glass:15)
B(9,9,7,betternether:quartz_stained_glass:15)
B(10,9,7,betternether:quartz_stained_glass:15)
B(11,9,7,betternether:quartz_stained_glass:15)
B(12,9,7,betternether:quartz_stained_glass:15)
B(5,9,8,betternether:quartz_stained_glass:15)
B(6,9,8,betternether:quartz_stained_glass:15)
B(7,9,8,betternether:quartz_stained_glass:15)
RB(8,9,8,srparasites:parasitestain:1,80,quark:crystal:1,30,srparasites:parasiterubbledense:1,100)
RB(9,9,8,srparasites:parasitestain:1,80,quark:crystal:1,30,srparasites:parasiterubbledense:1,100)
B(10,9,8,betternether:quartz_stained_glass:15)
B(11,9,8,betternether:quartz_stained_glass:15)
B(12,9,8,betternether:quartz_stained_glass:15)
B(5,9,9,betternether:quartz_stained_glass:15)
B(6,9,9,betternether:quartz_stained_glass:15)
B(7,9,9,betternether:quartz_stained_glass:15)
RB(8,9,9,srparasites:parasitestain:1,80,quark:crystal:1,30,srparasites:parasiterubbledense:1,100)
RB(9,9,9,srparasites:parasitestain:1,80,quark:crystal:1,30,srparasites:parasiterubbledense:1,100)
B(10,9,9,betternether:quartz_stained_glass:15)
B(11,9,9,betternether:quartz_stained_glass:15)
B(12,9,9,betternether:quartz_stained_glass:15)
B(6,9,10,betternether:quartz_stained_glass:15)
B(7,9,10,betternether:quartz_stained_glass:15)
B(8,9,10,betternether:quartz_stained_glass:15)
B(9,9,10,betternether:quartz_stained_glass:15)
B(10,9,10,betternether:quartz_stained_glass:15)
B(11,9,10,betternether:quartz_stained_glass:15)
B(6,9,11,betternether:quartz_stained_glass:15)
B(7,9,11,betternether:quartz_stained_glass:15)
B(8,9,11,betternether:quartz_stained_glass:15)
B(9,9,11,betternether:quartz_stained_glass:15)
B(10,9,11,betternether:quartz_stained_glass:15)
B(11,9,11,betternether:quartz_stained_glass:15)
B(7,9,12,betternether:quartz_stained_glass:15)
B(8,9,12,betternether:quartz_stained_glass:15)
B(9,9,12,betternether:quartz_stained_glass:15)
B(8,10,4,betternether:quartz_stained_glass:15)
B(7,10,5,betternether:quartz_stained_glass:15)
B(8,10,5,betternether:quartz_stained_glass:15)
B(9,10,5,betternether:quartz_stained_glass:15)
B(6,10,6,betternether:quartz_stained_glass:15)
B(7,10,6,betternether:quartz_stained_glass:15)
B(8,10,6,betternether:quartz_stained_glass:15)
B(9,10,6,betternether:quartz_stained_glass:15)
B(10,10,6,betternether:quartz_stained_glass:15)
B(11,10,6,betternether:quartz_stained_glass:15)
B(5,10,7,betternether:quartz_stained_glass:15)
B(6,10,7,betternether:quartz_stained_glass:15)
B(7,10,7,betternether:quartz_stained_glass:15)
RB(8,10,7,srparasites:parasitestain:1,80,quark:crystal:1,30,srparasites:parasiterubbledense:1,100)
B(9,10,7,betternether:quartz_stained_glass:15)
B(10,10,7,betternether:quartz_stained_glass:15)
B(11,10,7,betternether:quartz_stained_glass:15)
B(4,10,8,betternether:quartz_stained_glass:15)
B(5,10,8,betternether:quartz_stained_glass:15)
B(6,10,8,betternether:quartz_stained_glass:15)
RB(7,10,8,srparasites:parasitestain:1,80,quark:crystal:1,30,srparasites:parasiterubbledense:1,100)
RB(8,10,8,srparasites:parasitestain:1,80,quark:crystal:1,30,srparasites:parasiterubbledense:1,100)
RB(9,10,8,srparasites:parasitestain:1,80,quark:crystal:1,30,srparasites:parasiterubbledense:1,100)
B(10,10,8,betternether:quartz_stained_glass:15)
B(11,10,8,betternether:quartz_stained_glass:15)
B(12,10,8,betternether:quartz_stained_glass:15)
B(5,10,9,betternether:quartz_stained_glass:15)
B(6,10,9,betternether:quartz_stained_glass:15)
B(7,10,9,betternether:quartz_stained_glass:15)
RB(8,10,9,srparasites:parasitestain:1,80,quark:crystal:1,30,srparasites:parasiterubbledense:1,100)
B(9,10,9,betternether:quartz_stained_glass:15)
B(10,10,9,betternether:quartz_stained_glass:15)
B(11,10,9,betternether:quartz_stained_glass:15)
B(6,10,10,betternether:quartz_stained_glass:15)
B(7,10,10,betternether:quartz_stained_glass:15)
B(8,10,10,betternether:quartz_stained_glass:15)
B(9,10,10,betternether:quartz_stained_glass:15)
B(10,10,10,betternether:quartz_stained_glass:15)
B(11,10,10,betternether:quartz_stained_glass:15)
B(6,10,11,betternether:quartz_stained_glass:15)
B(7,10,11,betternether:quartz_stained_glass:15)
B(8,10,11,betternether:quartz_stained_glass:15)
B(9,10,11,betternether:quartz_stained_glass:15)
B(10,10,11,betternether:quartz_stained_glass:15)
B(8,10,12,betternether:quartz_stained_glass:15)
B(7,11,4,betternether:quartz_stained_glass:15)
B(8,11,4,betternether:quartz_stained_glass:15)
B(6,11,5,betternether:quartz_stained_glass:15)
B(7,11,5,betternether:quartz_stained_glass:15)
B(8,11,5,betternether:quartz_stained_glass:15)
B(9,11,5,betternether:quartz_stained_glass:15)
B(10,11,5,betternether:quartz_stained_glass:15)
B(5,11,6,betternether:quartz_stained_glass:15)
B(6,11,6,betternether:quartz_stained_glass:15)
B(7,11,6,betternether:quartz_stained_glass:15)
B(8,11,6,betternether:quartz_stained_glass:15)
B(9,11,6,betternether:quartz_stained_glass:15)
B(10,11,6,betternether:quartz_stained_glass:15)
B(11,11,6,betternether:quartz_stained_glass:15)
B(4,11,7,betternether:quartz_stained_glass:15)
B(5,11,7,betternether:quartz_stained_glass:15)
B(6,11,7,betternether:quartz_stained_glass:15)
RB(7,11,7,srparasites:parasitestain:1,80,quark:crystal:1,30,srparasites:parasiterubbledense:1,100)
RB(8,11,7,srparasites:parasitestain:1,80,quark:crystal:1,30,srparasites:parasiterubbledense:1,100)
B(9,11,7,betternether:quartz_stained_glass:15)
B(10,11,7,betternether:quartz_stained_glass:15)
B(11,11,7,betternether:quartz_stained_glass:15)
B(4,11,8,betternether:quartz_stained_glass:15)
B(5,11,8,betternether:quartz_stained_glass:15)
B(6,11,8,betternether:quartz_stained_glass:15)
RB(7,11,8,srparasites:parasitestain:1,80,quark:crystal:1,30,srparasites:parasiterubbledense:1,100)
RB(8,11,8,srparasites:parasitestain:1,80,quark:crystal:1,30,srparasites:parasiterubbledense:1,100)
B(9,11,8,betternether:quartz_stained_glass:15)
B(10,11,8,betternether:quartz_stained_glass:15)
B(11,11,8,betternether:quartz_stained_glass:15)
B(5,11,9,betternether:quartz_stained_glass:15)
B(6,11,9,betternether:quartz_stained_glass:15)
B(7,11,9,betternether:quartz_stained_glass:15)
B(8,11,9,betternether:quartz_stained_glass:15)
B(9,11,9,betternether:quartz_stained_glass:15)
B(10,11,9,betternether:quartz_stained_glass:15)
B(5,11,10,betternether:quartz_stained_glass:15)
B(6,11,10,betternether:quartz_stained_glass:15)
B(7,11,10,betternether:quartz_stained_glass:15)
B(8,11,10,betternether:quartz_stained_glass:15)
B(9,11,10,betternether:quartz_stained_glass:15)
B(10,11,10,betternether:quartz_stained_glass:15)
B(6,11,11,betternether:quartz_stained_glass:15)
B(7,11,11,betternether:quartz_stained_glass:15)
B(8,11,11,betternether:quartz_stained_glass:15)
B(7,12,3,betternether:quartz_stained_glass:15)
B(6,12,4,betternether:quartz_stained_glass:15)
B(7,12,4,betternether:quartz_stained_glass:15)
B(8,12,4,betternether:quartz_stained_glass:15)
B(5,12,5,betternether:quartz_stained_glass:15)
B(6,12,5,betternether:quartz_stained_glass:15)
B(7,12,5,betternether:quartz_stained_glass:15)
B(8,12,5,betternether:quartz_stained_glass:15)
B(9,12,5,betternether:quartz_stained_glass:15)
B(10,12,5,betternether:quartz_stained_glass:15)
B(4,12,6,betternether:quartz_stained_glass:15)
B(5,12,6,betternether:quartz_stained_glass:15)
B(6,12,6,betternether:quartz_stained_glass:15)
RB(7,12,6,srparasites:parasitestain:1,80,quark:crystal:1,30,srparasites:parasiterubbledense:1,100)
B(8,12,6,betternether:quartz_stained_glass:15)
B(9,12,6,betternether:quartz_stained_glass:15)
B(10,12,6,betternether:quartz_stained_glass:15)
B(3,12,7,betternether:quartz_stained_glass:15)
B(4,12,7,betternether:quartz_stained_glass:15)
B(5,12,7,betternether:quartz_stained_glass:15)
RB(6,12,7,srparasites:parasitestain:1,80,quark:crystal:1,30,srparasites:parasiterubbledense:1,100)
RB(7,12,7,srparasites:parasitestain:1,80,quark:crystal:1,30,srparasites:parasiterubbledense:1,100)
RB(8,12,7,srparasites:parasitestain:1,80,quark:crystal:1,30,srparasites:parasiterubbledense:1,100)
B(9,12,7,betternether:quartz_stained_glass:15)
B(10,12,7,betternether:quartz_stained_glass:15)
B(11,12,7,betternether:quartz_stained_glass:15)
B(4,12,8,betternether:quartz_stained_glass:15)
B(5,12,8,betternether:quartz_stained_glass:15)
B(6,12,8,betternether:quartz_stained_glass:15)
RB(7,12,8,srparasites:parasitestain:1,80,quark:crystal:1,30,srparasites:parasiterubbledense:1,100)
B(8,12,8,betternether:quartz_stained_glass:15)
B(9,12,8,betternether:quartz_stained_glass:15)
B(10,12,8,betternether:quartz_stained_glass:15)
B(5,12,9,betternether:quartz_stained_glass:15)
B(6,12,9,betternether:quartz_stained_glass:15)
B(7,12,9,betternether:quartz_stained_glass:15)
B(8,12,9,betternether:quartz_stained_glass:15)
B(9,12,9,betternether:quartz_stained_glass:15)
B(10,12,9,betternether:quartz_stained_glass:15)
B(5,12,10,betternether:quartz_stained_glass:15)
B(6,12,10,betternether:quartz_stained_glass:15)
B(7,12,10,betternether:quartz_stained_glass:15)
B(8,12,10,betternether:quartz_stained_glass:15)
B(9,12,10,betternether:quartz_stained_glass:15)
B(7,12,11,betternether:quartz_stained_glass:15)
B(6,13,3,betternether:quartz_stained_glass:15)
B(7,13,3,betternether:quartz_stained_glass:15)
B(5,13,4,betternether:quartz_stained_glass:15)
B(6,13,4,betternether:quartz_stained_glass:15)
B(7,13,4,betternether:quartz_stained_glass:15)
B(8,13,4,betternether:quartz_stained_glass:15)
B(9,13,4,betternether:quartz_stained_glass:15)
B(4,13,5,betternether:quartz_stained_glass:15)
B(5,13,5,betternether:quartz_stained_glass:15)
B(6,13,5,betternether:quartz_stained_glass:15)
B(7,13,5,betternether:quartz_stained_glass:15)
B(8,13,5,betternether:quartz_stained_glass:15)
B(9,13,5,betternether:quartz_stained_glass:15)
B(10,13,5,betternether:quartz_stained_glass:15)
B(3,13,6,betternether:quartz_stained_glass:15)
B(4,13,6,betternether:quartz_stained_glass:15)
B(5,13,6,betternether:quartz_stained_glass:15)
RB(6,13,6,srparasites:parasitestain:1,80,quark:crystal:1,30,srparasites:parasiterubbledense:1,100)
RB(7,13,6,srparasites:parasitestain:1,80,quark:crystal:1,30,srparasites:parasiterubbledense:1,100)
B(8,13,6,betternether:quartz_stained_glass:15)
B(9,13,6,betternether:quartz_stained_glass:15)
B(10,13,6,betternether:quartz_stained_glass:15)
B(3,13,7,betternether:quartz_stained_glass:15)
B(4,13,7,betternether:quartz_stained_glass:15)
B(5,13,7,betternether:quartz_stained_glass:15)
RB(6,13,7,srparasites:parasitestain:1,80,quark:crystal:1,30,srparasites:parasiterubbledense:1,100)
RB(7,13,7,srparasites:parasitestain:1,80,quark:crystal:1,30,srparasites:parasiterubbledense:1,100)
B(8,13,7,srparasites:parasiterubbledense:1)
B(9,13,7,betternether:quartz_stained_glass:15)
B(10,13,7,betternether:quartz_stained_glass:15)
B(4,13,8,betternether:quartz_stained_glass:15)
B(5,13,8,betternether:quartz_stained_glass:15)
B(6,13,8,betternether:quartz_stained_glass:15)
B(7,13,8,betternether:quartz_stained_glass:15)
B(8,13,8,betternether:quartz_stained_glass:15)
B(9,13,8,betternether:quartz_stained_glass:15)
B(4,13,9,betternether:quartz_stained_glass:15)
B(5,13,9,betternether:quartz_stained_glass:15)
B(6,13,9,betternether:quartz_stained_glass:15)
B(7,13,9,betternether:quartz_stained_glass:15)
B(8,13,9,betternether:quartz_stained_glass:15)
B(9,13,9,betternether:quartz_stained_glass:15)
B(5,13,10,betternether:quartz_stained_glass:15)
B(6,13,10,betternether:quartz_stained_glass:15)
B(7,13,10,betternether:quartz_stained_glass:15)
B(6,14,2,betternether:quartz_stained_glass:15)
B(5,14,3,betternether:quartz_stained_glass:15)
B(6,14,3,betternether:quartz_stained_glass:15)
B(7,14,3,betternether:quartz_stained_glass:15)
B(4,14,4,betternether:quartz_stained_glass:15)
B(5,14,4,betternether:quartz_stained_glass:15)
B(6,14,4,betternether:quartz_stained_glass:15)
B(7,14,4,betternether:quartz_stained_glass:15)
B(8,14,4,betternether:quartz_stained_glass:15)
B(9,14,4,betternether:quartz_stained_glass:15)
B(3,14,5,betternether:quartz_stained_glass:15)
B(4,14,5,betternether:quartz_stained_glass:15)
B(5,14,5,betternether:quartz_stained_glass:15)
RB(6,14,5,srparasites:parasitestain:1,80,quark:crystal:1,30,srparasites:parasiterubbledense:1,100)
B(7,14,5,betternether:quartz_stained_glass:15)
B(8,14,5,betternether:quartz_stained_glass:15)
B(9,14,5,betternether:quartz_stained_glass:15)
B(2,14,6,betternether:quartz_stained_glass:15)
B(3,14,6,betternether:quartz_stained_glass:15)
B(4,14,6,betternether:quartz_stained_glass:15)
RB(5,14,6,srparasites:parasitestain:1,80,quark:crystal:1,30,srparasites:parasiterubbledense:1,100)
RB(6,14,6,srparasites:parasitestain:1,80,quark:crystal:1,30,srparasites:parasiterubbledense:1,100)
RB(7,14,6,srparasites:parasitestain:1,80,quark:crystal:1,30,srparasites:parasiterubbledense:1,100)
B(8,14,6,srparasites:parasiterubbledense:1)
B(9,14,6,srparasites:parasiterubbledense:1)
B(10,14,6,betternether:quartz_stained_glass:15)
B(3,14,7,betternether:quartz_stained_glass:15)
B(4,14,7,betternether:quartz_stained_glass:15)
B(5,14,7,betternether:quartz_stained_glass:15)
RB(6,14,7,srparasites:parasitestain:1,80,quark:crystal:1,30,srparasites:parasiterubbledense:1,100)
B(7,14,7,srparasites:parasiterubbledense:1)
B(8,14,7,srparasites:parasiterubbledense:1)
B(9,14,7,betternether:quartz_stained_glass:15)
B(4,14,8,betternether:quartz_stained_glass:15)
B(5,14,8,betternether:quartz_stained_glass:15)
B(6,14,8,betternether:quartz_stained_glass:15)
B(7,14,8,srparasites:parasiterubbledense:1)
B(8,14,8,betternether:quartz_stained_glass:15)
B(9,14,8,betternether:quartz_stained_glass:15)
B(4,14,9,betternether:quartz_stained_glass:15)
B(5,14,9,betternether:quartz_stained_glass:15)
B(6,14,9,betternether:quartz_stained_glass:15)
B(7,14,9,betternether:quartz_stained_glass:15)
B(8,14,9,betternether:quartz_stained_glass:15)
B(6,14,10,betternether:quartz_stained_glass:15)
B(5,15,2,betternether:quartz_stained_glass:15)
B(6,15,2,betternether:quartz_stained_glass:15)
B(4,15,3,betternether:quartz_stained_glass:15)
B(5,15,3,betternether:quartz_stained_glass:15)
B(6,15,3,betternether:quartz_stained_glass:15)
B(7,15,3,betternether:quartz_stained_glass:15)
B(8,15,3,betternether:quartz_stained_glass:15)
B(3,15,4,betternether:quartz_stained_glass:15)
B(4,15,4,betternether:quartz_stained_glass:15)
B(5,15,4,betternether:quartz_stained_glass:15)
B(6,15,4,betternether:quartz_stained_glass:15)
B(7,15,4,betternether:quartz_stained_glass:15)
B(8,15,4,betternether:quartz_stained_glass:15)
B(9,15,4,betternether:quartz_stained_glass:15)
B(2,15,5,betternether:quartz_stained_glass:15)
B(3,15,5,betternether:quartz_stained_glass:15)
B(4,15,5,betternether:quartz_stained_glass:15)
RB(5,15,5,srparasites:parasitestain:1,80,quark:crystal:1,30,srparasites:parasiterubbledense:1,100)
RB(6,15,5,srparasites:parasitestain:1,80,quark:crystal:1,30,srparasites:parasiterubbledense:1,100)
B(7,15,5,betternether:quartz_stained_glass:15)
B(8,15,5,srparasites:parasiterubbledense:1)
B(9,15,5,betternether:quartz_stained_glass:15)
B(2,15,6,betternether:quartz_stained_glass:15)
B(3,15,6,betternether:quartz_stained_glass:15)
B(4,15,6,betternether:quartz_stained_glass:15)
RB(5,15,6,srparasites:parasitestain:1,80,quark:crystal:1,30,srparasites:parasiterubbledense:1,100)
RB(6,15,6,srparasites:parasitestain:1,80,quark:crystal:1,30,srparasites:parasiterubbledense:1,100)
B(7,15,6,srparasites:parasiterubbledense:1)
B(8,15,6,srparasites:parasiterubbledense:1)
B(9,15,6,betternether:quartz_stained_glass:15)
B(3,15,7,betternether:quartz_stained_glass:15)
B(4,15,7,betternether:quartz_stained_glass:15)
B(5,15,7,betternether:quartz_stained_glass:15)
B(6,15,7,srparasites:parasiterubbledense:1)
B(7,15,7,srparasites:parasiterubbledense:1)
B(8,15,7,betternether:quartz_stained_glass:15)
B(3,15,8,betternether:quartz_stained_glass:15)
B(4,15,8,betternether:quartz_stained_glass:15)
B(5,15,8,betternether:quartz_stained_glass:15)
B(6,15,8,betternether:quartz_stained_glass:15)
B(7,15,8,betternether:quartz_stained_glass:15)
B(8,15,8,betternether:quartz_stained_glass:15)
B(4,15,9,betternether:quartz_stained_glass:15)
B(5,15,9,betternether:quartz_stained_glass:15)
B(6,15,9,betternether:quartz_stained_glass:15)
B(5,16,1,betternether:quartz_stained_glass:15)
B(4,16,2,betternether:quartz_stained_glass:15)
B(5,16,2,betternether:quartz_stained_glass:15)
B(6,16,2,betternether:quartz_stained_glass:15)
B(3,16,3,betternether:quartz_stained_glass:15)
B(4,16,3,betternether:quartz_stained_glass:15)
B(5,16,3,betternether:quartz_stained_glass:15)
B(6,16,3,betternether:quartz_stained_glass:15)
B(7,16,3,betternether:quartz_stained_glass:15)
B(8,16,3,betternether:quartz_stained_glass:15)
B(2,16,4,betternether:quartz_stained_glass:15)
B(3,16,4,betternether:quartz_stained_glass:15)
B(4,16,4,betternether:quartz_stained_glass:15)
RB(5,16,4,srparasites:parasitestain:1,80,quark:crystal:1,30,srparasites:parasiterubbledense:1,100)
B(6,16,4,betternether:quartz_stained_glass:15)
B(7,16,4,betternether:quartz_stained_glass:15)
B(8,16,4,betternether:quartz_stained_glass:15)
B(1,16,5,betternether:quartz_stained_glass:15)
B(2,16,5,betternether:quartz_stained_glass:15)
B(3,16,5,betternether:quartz_stained_glass:15)
RB(4,16,5,srparasites:parasitestain:1,80,quark:crystal:1,30,srparasites:parasiterubbledense:1,100)
RB(5,16,5,srparasites:parasitestain:1,80,quark:crystal:1,30,srparasites:parasiterubbledense:1,100)
RB(6,16,5,srparasites:parasitestain:1,80,quark:crystal:1,30,srparasites:parasiterubbledense:1,100)
B(7,16,5,betternether:quartz_stained_glass:15)
B(8,16,5,betternether:quartz_stained_glass:15)
B(9,16,5,betternether:quartz_stained_glass:15)
B(2,16,6,betternether:quartz_stained_glass:15)
B(3,16,6,betternether:quartz_stained_glass:15)
B(4,16,6,betternether:quartz_stained_glass:15)
RB(5,16,6,srparasites:parasitestain:1,80,quark:crystal:1,30,srparasites:parasiterubbledense:1,100)
B(6,16,6,betternether:quartz_stained_glass:15)
B(7,16,6,srparasites:parasiterubbledense:1)
B(8,16,6,betternether:quartz_stained_glass:15)
B(3,16,7,betternether:quartz_stained_glass:15)
B(4,16,7,betternether:quartz_stained_glass:15)
B(5,16,7,betternether:quartz_stained_glass:15)
B(6,16,7,betternether:quartz_stained_glass:15)
B(7,16,7,betternether:quartz_stained_glass:15)
B(8,16,7,betternether:quartz_stained_glass:15)
B(3,16,8,betternether:quartz_stained_glass:15)
B(4,16,8,betternether:quartz_stained_glass:15)
B(5,16,8,betternether:quartz_stained_glass:15)
B(6,16,8,betternether:quartz_stained_glass:15)
B(7,16,8,betternether:quartz_stained_glass:15)
B(5,16,9,betternether:quartz_stained_glass:15)
B(4,17,1,betternether:quartz_stained_glass:15)
B(5,17,1,betternether:quartz_stained_glass:15)
B(3,17,2,betternether:quartz_stained_glass:15)
B(4,17,2,betternether:quartz_stained_glass:15)
B(5,17,2,betternether:quartz_stained_glass:15)
B(6,17,2,betternether:quartz_stained_glass:15)
B(7,17,2,betternether:quartz_stained_glass:15)
B(2,17,3,betternether:quartz_stained_glass:15)
B(3,17,3,betternether:quartz_stained_glass:15)
B(4,17,3,betternether:quartz_stained_glass:15)
B(5,17,3,betternether:quartz_stained_glass:15)
B(6,17,3,betternether:quartz_stained_glass:15)
B(7,17,3,betternether:quartz_stained_glass:15)
B(8,17,3,betternether:quartz_stained_glass:15)
B(1,17,4,betternether:quartz_stained_glass:15)
B(2,17,4,betternether:quartz_stained_glass:15)
B(3,17,4,betternether:quartz_stained_glass:15)
RB(4,17,4,srparasites:parasitestain:1,80,quark:crystal:1,30,srparasites:parasiterubbledense:1,100)
RB(5,17,4,srparasites:parasitestain:1,80,quark:crystal:1,30,srparasites:parasiterubbledense:1,100)
B(6,17,4,betternether:quartz_stained_glass:15)
B(7,17,4,betternether:quartz_stained_glass:15)
B(8,17,4,betternether:quartz_stained_glass:15)
B(1,17,5,betternether:quartz_stained_glass:15)
B(2,17,5,betternether:quartz_stained_glass:15)
B(3,17,5,betternether:quartz_stained_glass:15)
RB(4,17,5,srparasites:parasitestain:1,80,quark:crystal:1,30,srparasites:parasiterubbledense:1,100)
RB(5,17,5,srparasites:parasitestain:1,80,quark:crystal:1,30,srparasites:parasiterubbledense:1,100)
B(6,17,5,betternether:quartz_stained_glass:15)
B(7,17,5,betternether:quartz_stained_glass:15)
B(8,17,5,betternether:quartz_stained_glass:15)
B(2,17,6,betternether:quartz_stained_glass:15)
B(3,17,6,betternether:quartz_stained_glass:15)
B(4,17,6,srparasites:parasiterubbledense:1)
B(5,17,6,betternether:quartz_stained_glass:15)
B(6,17,6,betternether:quartz_stained_glass:15)
B(7,17,6,betternether:quartz_stained_glass:15)
B(2,17,7,betternether:quartz_stained_glass:15)
B(3,17,7,betternether:quartz_stained_glass:15)
B(4,17,7,betternether:quartz_stained_glass:15)
B(5,17,7,betternether:quartz_stained_glass:15)
B(6,17,7,betternether:quartz_stained_glass:15)
B(7,17,7,betternether:quartz_stained_glass:15)
B(3,17,8,betternether:quartz_stained_glass:15)
B(4,17,8,betternether:quartz_stained_glass:15)
B(5,17,8,betternether:quartz_stained_glass:15)
B(4,18,0,betternether:quartz_stained_glass:15)
B(3,18,1,betternether:quartz_stained_glass:15)
B(4,18,1,betternether:quartz_stained_glass:15)
B(5,18,1,betternether:quartz_stained_glass:15)
B(2,18,2,betternether:quartz_stained_glass:15)
B(3,18,2,betternether:quartz_stained_glass:15)
B(4,18,2,betternether:quartz_stained_glass:15)
B(5,18,2,betternether:quartz_stained_glass:15)
B(6,18,2,betternether:quartz_stained_glass:15)
B(7,18,2,betternether:quartz_stained_glass:15)
B(1,18,3,betternether:quartz_stained_glass:15)
B(2,18,3,betternether:quartz_stained_glass:15)
B(3,18,3,betternether:quartz_stained_glass:15)
RB(4,18,3,srparasites:parasitestain:1,80,quark:crystal:1,30,srparasites:parasiterubbledense:1,100)
B(5,18,3,betternether:quartz_stained_glass:15)
B(6,18,3,betternether:quartz_stained_glass:15)
B(7,18,3,betternether:quartz_stained_glass:15)
B(0,18,4,betternether:quartz_stained_glass:15)
B(1,18,4,betternether:quartz_stained_glass:15)
B(2,18,4,betternether:quartz_stained_glass:15)
RB(3,18,4,srparasites:parasitestain:1,80,quark:crystal:1,30,srparasites:parasiterubbledense:1,100)
RB(4,18,4,srparasites:parasitestain:1,80,quark:crystal:1,30,srparasites:parasiterubbledense:1,100)
RB(5,18,4,srparasites:parasitestain:1,80,quark:crystal:1,30,srparasites:parasiterubbledense:1,100)
B(6,18,4,betternether:quartz_stained_glass:15)
B(7,18,4,betternether:quartz_stained_glass:15)
B(8,18,4,betternether:quartz_stained_glass:15)
B(1,18,5,betternether:quartz_stained_glass:15)
B(2,18,5,betternether:quartz_stained_glass:15)
B(3,18,5,srparasites:parasiterubbledense:1)
RB(4,18,5,srparasites:parasitestain:1,80,quark:crystal:1,30,srparasites:parasiterubbledense:1,100)
B(5,18,5,srparasites:parasiterubbledense:1)
B(6,18,5,betternether:quartz_stained_glass:15)
B(7,18,5,betternether:quartz_stained_glass:15)
B(2,18,6,betternether:quartz_stained_glass:15)
B(3,18,6,srparasites:parasiterubbledense:1)
B(4,18,6,srparasites:parasiterubbledense:1)
B(5,18,6,srparasites:parasiterubbledense:1)
B(6,18,6,betternether:quartz_stained_glass:15)
B(7,18,6,betternether:quartz_stained_glass:15)
B(2,18,7,betternether:quartz_stained_glass:15)
B(3,18,7,betternether:quartz_stained_glass:15)
B(4,18,7,srparasites:parasiterubbledense:1)
B(5,18,7,betternether:quartz_stained_glass:15)
B(6,18,7,betternether:quartz_stained_glass:15)
B(4,18,8,betternether:quartz_stained_glass:15)
B(3,19,0,betternether:quartz_stained_glass:15)
B(4,19,0,betternether:quartz_stained_glass:15)
B(2,19,1,betternether:quartz_stained_glass:15)
B(3,19,1,betternether:quartz_stained_glass:15)
B(4,19,1,betternether:quartz_stained_glass:15)
B(5,19,1,betternether:quartz_stained_glass:15)
B(6,19,1,betternether:quartz_stained_glass:15)
B(1,19,2,betternether:quartz_stained_glass:15)
B(2,19,2,betternether:quartz_stained_glass:15)
B(3,19,2,betternether:quartz_stained_glass:15)
B(4,19,2,betternether:quartz_stained_glass:15)
B(5,19,2,betternether:quartz_stained_glass:15)
B(6,19,2,betternether:quartz_stained_glass:15)
B(7,19,2,betternether:quartz_stained_glass:15)
B(0,19,3,betternether:quartz_stained_glass:15)
B(1,19,3,betternether:quartz_stained_glass:15)
B(2,19,3,betternether:quartz_stained_glass:15)
RB(3,19,3,srparasites:parasitestain:1,80,quark:crystal:1,30,srparasites:parasiterubbledense:1,100)
RB(4,19,3,srparasites:parasitestain:1,80,quark:crystal:1,30,srparasites:parasiterubbledense:1,100)
B(5,19,3,betternether:quartz_stained_glass:15)
B(6,19,3,betternether:quartz_stained_glass:15)
B(7,19,3,betternether:quartz_stained_glass:15)
B(0,19,4,betternether:quartz_stained_glass:15)
B(1,19,4,betternether:quartz_stained_glass:15)
B(2,19,4,betternether:quartz_stained_glass:15)
RB(3,19,4,srparasites:parasitestain:1,80,quark:crystal:1,30,srparasites:parasiterubbledense:1,100)
RB(4,19,4,srparasites:parasitestain:1,80,quark:crystal:1,30,srparasites:parasiterubbledense:1,100)
B(5,19,4,betternether:quartz_stained_glass:15)
B(6,19,4,betternether:quartz_stained_glass:15)
B(7,19,4,betternether:quartz_stained_glass:15)
B(1,19,5,betternether:quartz_stained_glass:15)
B(2,19,5,betternether:quartz_stained_glass:15)
B(3,19,5,srparasites:parasiterubbledense:1)
B(4,19,5,srparasites:parasiterubbledense:1)
B(5,19,5,srparasites:parasiterubbledense:1)
B(6,19,5,betternether:quartz_stained_glass:15)
B(1,19,6,betternether:quartz_stained_glass:15)
B(2,19,6,betternether:quartz_stained_glass:15)
B(3,19,6,srparasites:parasiterubbledense:1)
B(4,19,6,srparasites:parasiterubbledense:1)
B(5,19,6,betternether:quartz_stained_glass:15)
B(6,19,6,betternether:quartz_stained_glass:15)
B(2,19,7,betternether:quartz_stained_glass:15)
B(3,19,7,betternether:quartz_stained_glass:15)
B(4,19,7,betternether:quartz_stained_glass:15)
B(3,20,0,betternether:quartz_stained_glass:15)
B(4,20,0,betternether:quartz_stained_glass:15)
B(2,20,1,betternether:quartz_stained_glass:15)
B(3,20,1,betternether:quartz_stained_glass:15)
B(4,20,1,betternether:quartz_stained_glass:15)
B(5,20,1,betternether:quartz_stained_glass:15)
B(6,20,1,betternether:quartz_stained_glass:15)
B(1,20,2,betternether:quartz_stained_glass:15)
B(2,20,2,betternether:quartz_stained_glass:15)
RB(3,20,2,srparasites:parasitestain:1,80,quark:crystal:1,30,srparasites:parasiterubbledense:1,100)
B(4,20,2,betternether:quartz_stained_glass:15)
B(5,20,2,betternether:quartz_stained_glass:15)
B(6,20,2,betternether:quartz_stained_glass:15)
B(0,20,3,betternether:quartz_stained_glass:15)
B(1,20,3,betternether:quartz_stained_glass:15)
RB(2,20,3,srparasites:parasitestain:1,80,quark:crystal:1,30,srparasites:parasiterubbledense:1,100)
RB(3,20,3,srparasites:parasitestain:1,80,quark:crystal:1,30,srparasites:parasiterubbledense:1,100)
RB(4,20,3,srparasites:parasitestain:1,80,quark:crystal:1,30,srparasites:parasiterubbledense:1,100)
B(5,20,3,betternether:quartz_stained_glass:15)
B(6,20,3,betternether:quartz_stained_glass:15)
B(7,20,3,betternether:quartz_stained_glass:15)
B(0,20,4,betternether:quartz_stained_glass:15)
B(1,20,4,betternether:quartz_stained_glass:15)
B(2,20,4,betternether:quartz_stained_glass:15)
RB(3,20,4,srparasites:parasitestain:1,80,quark:crystal:1,30,srparasites:parasiterubbledense:1,100)
B(4,20,4,srparasites:parasiterubbledense:1)
B(5,20,4,srparasites:parasiterubbledense:1)
B(6,20,4,betternether:quartz_stained_glass:15)
B(1,20,5,betternether:quartz_stained_glass:15)
B(2,20,5,betternether:quartz_stained_glass:15)
B(3,20,5,srparasites:parasiterubbledense:1)
B(4,20,5,srparasites:parasiterubbledense:1)
B(5,20,5,betternether:quartz_stained_glass:15)
B(6,20,5,betternether:quartz_stained_glass:15)
B(1,20,6,betternether:quartz_stained_glass:15)
B(2,20,6,betternether:quartz_stained_glass:15)
B(3,20,6,srparasites:parasiterubbledense:1)
B(4,20,6,betternether:quartz_stained_glass:15)
B(5,20,6,betternether:quartz_stained_glass:15)
B(3,20,7,betternether:quartz_stained_glass:15)
B(2,21,0,betternether:quartz_stained_glass:15)
B(3,21,0,betternether:quartz_stained_glass:15)
B(4,21,0,betternether:quartz_stained_glass:15)
B(1,21,1,betternether:quartz_stained_glass:15)
B(2,21,1,betternether:quartz_stained_glass:15)
B(3,21,1,betternether:quartz_stained_glass:15)
B(4,21,1,betternether:quartz_stained_glass:15)
B(5,21,1,betternether:quartz_stained_glass:15)
B(0,21,2,betternether:quartz_stained_glass:15)
B(1,21,2,betternether:quartz_stained_glass:15)
RB(2,21,2,srparasites:parasitestain:1,80,quark:crystal:1,30,srparasites:parasiterubbledense:1,100)
RB(3,21,2,srparasites:parasitestain:1,80,quark:crystal:1,30,srparasites:parasiterubbledense:1,100)
B(4,21,2,betternether:quartz_stained_glass:15)
B(5,21,2,betternether:quartz_stained_glass:15)
B(6,21,2,betternether:quartz_stained_glass:15)
B(0,21,3,betternether:quartz_stained_glass:15)
B(1,21,3,betternether:quartz_stained_glass:15)
RB(2,21,3,srparasites:parasitestain:1,80,quark:crystal:1,30,srparasites:parasiterubbledense:1,100)
RB(3,21,3,srparasites:parasitestain:1,80,quark:crystal:1,30,srparasites:parasiterubbledense:1,100)
B(4,21,3,srparasites:parasiterubbledense:1)
B(5,21,3,betternether:quartz_stained_glass:15)
B(6,21,3,betternether:quartz_stained_glass:15)
B(0,21,4,betternether:quartz_stained_glass:15)
B(1,21,4,betternether:quartz_stained_glass:15)
B(2,21,4,betternether:quartz_stained_glass:15)
B(3,21,4,srparasites:parasiterubbledense:1)
B(4,21,4,srparasites:parasiterubbledense:1)
B(5,21,4,betternether:quartz_stained_glass:15)
B(1,21,5,betternether:quartz_stained_glass:15)
B(2,21,5,srparasites:parasiterubbledense:1)
B(3,21,5,srparasites:parasiterubbledense:1)
B(4,21,5,betternether:quartz_stained_glass:15)
B(5,21,5,betternether:quartz_stained_glass:15)
B(2,21,6,betternether:quartz_stained_glass:15)
B(3,21,6,betternether:quartz_stained_glass:15)
B(2,22,0,betternether:quartz_stained_glass:15)
B(3,22,0,betternether:quartz_stained_glass:15)
B(1,22,1,betternether:quartz_stained_glass:15)
B(2,22,1,betternether:quartz_stained_glass:15)
B(3,22,1,betternether:quartz_stained_glass:15)
B(4,22,1,betternether:quartz_stained_glass:15)
B(0,22,2,betternether:quartz_stained_glass:15)
B(1,22,2,betternether:quartz_stained_glass:15)
RB(2,22,2,srparasites:parasitestain:1,80,quark:crystal:1,30,srparasites:parasiterubbledense:1,100)
B(3,22,2,betternether:quartz_stained_glass:15)
B(4,22,2,betternether:quartz_stained_glass:15)
B(5,22,2,betternether:quartz_stained_glass:15)
B(0,22,3,betternether:quartz_stained_glass:15)
B(1,22,3,betternether:quartz_stained_glass:15)
B(2,22,3,srparasites:parasiterubbledense:1)
B(3,22,3,srparasites:parasiterubbledense:1)
B(4,22,3,srparasites:parasiterubbledense:1)
B(5,22,3,betternether:quartz_stained_glass:15)
B(1,22,4,betternether:quartz_stained_glass:15)
B(2,22,4,srparasites:parasiterubbledense:1)
B(3,22,4,srparasites:parasiterubbledense:1)
B(4,22,4,betternether:quartz_stained_glass:15)
B(5,22,4,betternether:quartz_stained_glass:15)
B(2,22,5,betternether:quartz_stained_glass:15)
B(3,22,5,betternether:quartz_stained_glass:15)
B(4,22,5,betternether:quartz_stained_glass:15)
B(1,23,0,betternether:quartz_stained_glass:15)
B(2,23,0,betternether:quartz_stained_glass:15)
B(3,23,0,betternether:quartz_stained_glass:15)
B(0,23,1,betternether:quartz_stained_glass:15)
B(1,23,1,betternether:quartz_stained_glass:15)
B(2,23,1,betternether:quartz_stained_glass:15)
B(3,23,1,betternether:quartz_stained_glass:15)
B(4,23,1,betternether:quartz_stained_glass:15)
B(0,23,2,betternether:quartz_stained_glass:15)
B(1,23,2,betternether:quartz_stained_glass:15)
RB(2,23,2,srparasites:parasitestain:1,80,quark:crystal:1,30,srparasites:parasiterubbledense:1,100)
B(3,23,2,srparasites:parasiterubbledense:1)
B(4,23,2,betternether:quartz_stained_glass:15)
B(0,23,3,betternether:quartz_stained_glass:15)
B(1,23,3,betternether:quartz_stained_glass:15)
B(2,23,3,srparasites:parasiterubbledense:1)
B(3,23,3,srparasites:parasiterubbledense:1)
B(4,23,3,betternether:quartz_stained_glass:15)
B(1,23,4,betternether:quartz_stained_glass:15)
B(2,23,4,betternether:quartz_stained_glass:15)
B(3,23,4,betternether:quartz_stained_glass:15)
B(4,23,4,betternether:quartz_stained_glass:15)
B(1,24,0,betternether:quartz_stained_glass:15)
B(2,24,0,betternether:quartz_stained_glass:15)
B(0,24,1,betternether:quartz_stained_glass:15)
B(1,24,1,betternether:quartz_stained_glass:15)
B(2,24,1,betternether:quartz_stained_glass:15)
B(3,24,1,betternether:quartz_stained_glass:15)
B(0,24,2,betternether:quartz_stained_glass:15)
B(1,24,2,betternether:quartz_stained_glass:15)
B(2,24,2,betternether:quartz_stained_glass:15)
B(3,24,2,betternether:quartz_stained_glass:15)
B(1,24,3,betternether:quartz_stained_glass:15)
B(2,24,3,betternether:quartz_stained_glass:15)
B(3,24,3,betternether:quartz_stained_glass:15)
B(4,24,3,betternether:quartz_stained_glass:15)
B(3,24,4,betternether:quartz_stained_glass:15)
B(1,25,0,betternether:quartz_stained_glass:15)
B(2,25,0,betternether:quartz_stained_glass:15)
B(0,25,1,betternether:quartz_stained_glass:15)
B(1,25,1,betternether:quartz_stained_glass:15)
B(2,25,1,betternether:quartz_stained_glass:15)
B(0,25,2,betternether:quartz_stained_glass:15)
B(1,25,2,betternether:quartz_stained_glass:15)
B(2,25,2,betternether:quartz_stained_glass:15)
B(3,25,2,betternether:quartz_stained_glass:15)
B(2,25,3,betternether:quartz_stained_glass:15)
B(0,26,0,betternether:quartz_stained_glass:15)
B(1,26,0,betternether:quartz_stained_glass:15)
B(0,26,1,betternether:quartz_stained_glass:15)
B(1,26,1,betternether:quartz_stained_glass:15)
B(2,26,1,betternether:quartz_stained_glass:15)
B(1,26,2,betternether:quartz_stained_glass:15)
B(0,27,0,betternether:quartz_stained_glass:15)
B(1,27,0,betternether:quartz_stained_glass:15)
B(0,27,1,betternether:quartz_stained_glass:15)
B(0,28,0,betternether:quartz_stained_glass:15)
BR(0,0,16,true,SPIKE-MED-SMALL-03_0x1,NORTH,100,0)
BR(16,0,0,true,SPIKE-MED-SMALL-03_1x0,NORTH,100,0)
