Author: NLBlackEagle
Description: No description given
Version: 3
SettingsMode: WriteDisable
Tree: true
Frequency: 0
Rarity: 100.0
RotateRandomly: false
SpawnHeight: randomY
SpawnHeightOffset: 0
SpawnHeightVariance: 0
MinHeight: 70
MaxHeight: 255
ExtrudeMode: None
ExtrudeThroughBlocks: AIR
MaxBranchDepth: 10
ExcludedBiomes: All
SourceBlocks: CONCRETE:7
MaxPercentageOutsideSourceBlock: 100
OutsideSourceBlock: dontPlace
DoReplaceBlocks: true
IsOTGPlus: false
RandomBlock(-14,14,1,IRON_FENCE,21)
RandomBlock(-13,9,-1,IRON_FENCE,21)
RandomBlock(-13,9,0,IRON_FENCE,21)
RandomBlock(-13,9,1,IRON_FENCE,21)
RandomBlock(-13,9,2,IRON_FENCE,21)
RandomBlock(-13,9,3,IRON_FENCE,21)
RandomBlock(-13,10,-2,IRON_FENCE,21)
RandomBlock(-13,10,-1,IRON_FENCE,21)
RandomBlock(-13,10,0,IRON_FENCE,21)
RandomBlock(-13,10,1,IRON_FENCE,21)
RandomBlock(-13,10,2,IRON_FENCE,21)
RandomBlock(-13,10,3,IRON_FENCE,21)
RandomBlock(-13,10,4,IRON_FENCE,21)
RandomBlock(-13,11,-3,IRON_FENCE,21)
RandomBlock(-13,11,-2,IRON_FENCE,21)
RandomBlock(-13,11,-1,IRON_FENCE,21)
RandomBlock(-13,11,0,IRON_FENCE,21)
RandomBlock(-13,11,1,IRON_FENCE,21)
RandomBlock(-13,11,2,IRON_FENCE,21)
RandomBlock(-13,11,3,IRON_FENCE,21)
RandomBlock(-13,11,4,IRON_FENCE,21)
RandomBlock(-13,11,5,IRON_FENCE,21)
RandomBlock(-13,12,-4,IRON_FENCE,21)
RandomBlock(-13,12,-3,IRON_FENCE,21)
RandomBlock(-13,12,-2,IRON_FENCE,21)
RandomBlock(-13,12,-1,IRON_FENCE,21)
RandomBlock(-13,12,0,IRON_FENCE,21)
RandomBlock(-13,12,1,IRON_FENCE,21)
RandomBlock(-13,12,2,IRON_FENCE,21)
RandomBlock(-13,12,3,IRON_FENCE,21)
RandomBlock(-13,12,4,IRON_FENCE,21)
RandomBlock(-13,12,5,IRON_FENCE,21)
RandomBlock(-13,12,6,IRON_FENCE,21)
RandomBlock(-13,13,-4,IRON_FENCE,21)
RandomBlock(-13,13,-3,IRON_FENCE,21)
RandomBlock(-13,13,-2,IRON_FENCE,21)
RandomBlock(-13,13,-1,IRON_FENCE,21)
RandomBlock(-13,13,0,IRON_FENCE,21)
RandomBlock(-13,13,1,IRON_FENCE,21)
RandomBlock(-13,13,2,IRON_FENCE,21)
RandomBlock(-13,13,3,IRON_FENCE,21)
RandomBlock(-13,13,4,IRON_FENCE,21)
RandomBlock(-13,13,5,IRON_FENCE,21)
RandomBlock(-13,13,6,IRON_FENCE,21)
RandomBlock(-13,14,-4,IRON_FENCE,21)
RandomBlock(-13,14,-3,IRON_FENCE,21)
RandomBlock(-13,14,-2,IRON_FENCE,21)
RandomBlock(-13,14,-1,IRON_FENCE,21)
RandomBlock(-13,14,0,IRON_FENCE,21)
RandomBlock(-13,14,1,IRON_FENCE,21)
RandomBlock(-13,14,2,IRON_FENCE,21)
RandomBlock(-13,14,3,IRON_FENCE,21)
RandomBlock(-13,14,4,IRON_FENCE,21)
RandomBlock(-13,14,5,IRON_FENCE,21)
RandomBlock(-13,14,6,IRON_FENCE,21)
RandomBlock(-13,15,-4,IRON_FENCE,21)
RandomBlock(-13,15,-3,IRON_FENCE,21)
RandomBlock(-13,15,-2,IRON_FENCE,21)
RandomBlock(-13,15,-1,IRON_FENCE,21)
RandomBlock(-13,15,0,IRON_FENCE,21)
RandomBlock(-13,15,1,IRON_FENCE,21)
RandomBlock(-13,15,2,IRON_FENCE,21)
RandomBlock(-13,15,3,IRON_FENCE,21)
RandomBlock(-13,15,4,IRON_FENCE,21)
RandomBlock(-13,15,5,IRON_FENCE,21)
RandomBlock(-13,15,6,IRON_FENCE,21)
RandomBlock(-13,16,-4,IRON_FENCE,21)
RandomBlock(-13,16,-3,IRON_FENCE,21)
RandomBlock(-13,16,-2,IRON_FENCE,21)
RandomBlock(-13,16,-1,IRON_FENCE,21)
RandomBlock(-13,16,0,IRON_FENCE,21)
RandomBlock(-13,16,1,IRON_FENCE,21)
RandomBlock(-13,16,2,IRON_FENCE,21)
RandomBlock(-13,16,3,IRON_FENCE,21)
RandomBlock(-13,16,4,IRON_FENCE,21)
RandomBlock(-13,16,5,IRON_FENCE,21)
RandomBlock(-13,16,6,IRON_FENCE,21)
RandomBlock(-13,17,-3,IRON_FENCE,21)
RandomBlock(-13,17,-2,IRON_FENCE,21)
RandomBlock(-13,17,-1,IRON_FENCE,21)
RandomBlock(-13,17,0,IRON_FENCE,21)
RandomBlock(-13,17,1,IRON_FENCE,21)
RandomBlock(-13,17,2,IRON_FENCE,21)
RandomBlock(-13,17,3,IRON_FENCE,21)
RandomBlock(-13,17,4,IRON_FENCE,21)
RandomBlock(-13,17,5,IRON_FENCE,21)
RandomBlock(-13,18,-2,IRON_FENCE,21)
RandomBlock(-13,18,-1,IRON_FENCE,21)
RandomBlock(-13,18,0,IRON_FENCE,21)
RandomBlock(-13,18,1,IRON_FENCE,21)
RandomBlock(-13,18,2,IRON_FENCE,21)
RandomBlock(-13,18,3,IRON_FENCE,21)
RandomBlock(-13,18,4,IRON_FENCE,21)
RandomBlock(-13,19,-1,IRON_FENCE,21)
RandomBlock(-13,19,0,IRON_FENCE,21)
RandomBlock(-13,19,1,IRON_FENCE,21)
RandomBlock(-13,19,2,IRON_FENCE,21)
RandomBlock(-13,19,3,IRON_FENCE,21)
RandomBlock(-12,7,-1,IRON_FENCE,21)
RandomBlock(-12,7,0,IRON_FENCE,21)
RandomBlock(-12,7,1,IRON_FENCE,21)
RandomBlock(-12,7,2,IRON_FENCE,21)
RandomBlock(-12,7,3,IRON_FENCE,21)
RandomBlock(-12,8,-3,IRON_FENCE,21)
RandomBlock(-12,8,-2,IRON_FENCE,21)
RandomBlock(-12,8,-1,IRON_FENCE,21)
RandomBlock(-12,8,0,IRON_FENCE,21)
RandomBlock(-12,8,1,IRON_FENCE,21)
RandomBlock(-12,8,2,IRON_FENCE,21)
RandomBlock(-12,8,3,IRON_FENCE,21)
RandomBlock(-12,8,4,IRON_FENCE,21)
RandomBlock(-12,8,5,IRON_FENCE,21)
RandomBlock(-12,9,-4,IRON_FENCE,21)
RandomBlock(-12,9,-3,IRON_FENCE,21)
RandomBlock(-12,9,-2,IRON_FENCE,21)
RandomBlock(-12,9,-1,IRON_FENCE,21)
RandomBlock(-12,9,0,IRON_FENCE,21)
RandomBlock(-12,9,1,IRON_FENCE,21)
RandomBlock(-12,9,2,IRON_FENCE,21)
RandomBlock(-12,9,3,IRON_FENCE,21)
RandomBlock(-12,9,4,IRON_FENCE,21)
RandomBlock(-12,9,5,IRON_FENCE,21)
RandomBlock(-12,9,6,IRON_FENCE,21)
RandomBlock(-12,10,-5,IRON_FENCE,21)
RandomBlock(-12,10,-4,IRON_FENCE,21)
RandomBlock(-12,10,-3,IRON_FENCE,21)
RandomBlock(-12,10,-2,IRON_FENCE,21)
RandomBlock(-12,10,-1,IRON_FENCE,21)
RandomBlock(-12,10,0,IRON_FENCE,21)
RandomBlock(-12,10,1,IRON_FENCE,21)
RandomBlock(-12,10,2,IRON_FENCE,21)
RandomBlock(-12,10,3,IRON_FENCE,21)
RandomBlock(-12,10,4,IRON_FENCE,21)
RandomBlock(-12,10,5,IRON_FENCE,21)
RandomBlock(-12,10,6,IRON_FENCE,21)
RandomBlock(-12,10,7,IRON_FENCE,21)
RandomBlock(-12,11,-5,IRON_FENCE,21)
RandomBlock(-12,11,-4,IRON_FENCE,21)
RandomBlock(-12,11,-3,IRON_FENCE,21)
RandomBlock(-12,11,-2,IRON_FENCE,21)
RandomBlock(-12,11,-1,IRON_FENCE,21)
RandomBlock(-12,11,0,IRON_FENCE,21)
RandomBlock(-12,11,1,IRON_FENCE,21)
RandomBlock(-12,11,2,IRON_FENCE,21)
RandomBlock(-12,11,3,IRON_FENCE,21)
RandomBlock(-12,11,4,IRON_FENCE,21)
RandomBlock(-12,11,5,IRON_FENCE,21)
RandomBlock(-12,11,6,IRON_FENCE,21)
RandomBlock(-12,11,7,IRON_FENCE,21)
RandomBlock(-12,12,-6,IRON_FENCE,21)
RandomBlock(-12,12,-5,IRON_FENCE,21)
RandomBlock(-12,12,-4,IRON_FENCE,21)
RandomBlock(-12,12,-3,IRON_FENCE,21)
RandomBlock(-12,12,-2,IRON_FENCE,21)
RandomBlock(-12,12,-1,IRON_FENCE,21)
RandomBlock(-12,12,0,IRON_FENCE,21)
RandomBlock(-12,12,1,IRON_FENCE,21)
RandomBlock(-12,12,2,IRON_FENCE,21)
RandomBlock(-12,12,3,IRON_FENCE,21)
RandomBlock(-12,12,4,IRON_FENCE,21)
RandomBlock(-12,12,5,IRON_FENCE,21)
RandomBlock(-12,12,6,IRON_FENCE,21)
RandomBlock(-12,12,7,IRON_FENCE,21)
RandomBlock(-12,12,8,IRON_FENCE,21)
RandomBlock(-12,13,-6,IRON_FENCE,21)
RandomBlock(-12,13,-5,IRON_FENCE,21)
RandomBlock(-12,13,-4,IRON_FENCE,21)
RandomBlock(-12,13,-3,IRON_FENCE,21)
RandomBlock(-12,13,-2,IRON_FENCE,21)
RandomBlock(-12,13,-1,IRON_FENCE,21)
RandomBlock(-12,13,0,IRON_FENCE,21)
RandomBlock(-12,13,1,IRON_FENCE,21)
RandomBlock(-12,13,2,IRON_FENCE,21)
RandomBlock(-12,13,3,IRON_FENCE,21)
RandomBlock(-12,13,4,IRON_FENCE,21)
RandomBlock(-12,13,5,IRON_FENCE,21)
RandomBlock(-12,13,6,IRON_FENCE,21)
RandomBlock(-12,13,7,IRON_FENCE,21)
RandomBlock(-12,13,8,IRON_FENCE,21)
RandomBlock(-12,14,-6,IRON_FENCE,21)
RandomBlock(-12,14,-5,IRON_FENCE,21)
RandomBlock(-12,14,-4,IRON_FENCE,21)
RandomBlock(-12,14,-3,IRON_FENCE,21)
RandomBlock(-12,14,-2,IRON_FENCE,21)
RandomBlock(-12,14,-1,IRON_FENCE,21)
RandomBlock(-12,14,0,IRON_FENCE,21)
RandomBlock(-12,14,1,IRON_FENCE,21)
RandomBlock(-12,14,2,IRON_FENCE,21)
RandomBlock(-12,14,3,IRON_FENCE,21)
RandomBlock(-12,14,4,IRON_FENCE,21)
RandomBlock(-12,14,5,IRON_FENCE,21)
RandomBlock(-12,14,6,IRON_FENCE,21)
RandomBlock(-12,14,7,IRON_FENCE,21)
RandomBlock(-12,14,8,IRON_FENCE,21)
RandomBlock(-12,15,-6,IRON_FENCE,21)
RandomBlock(-12,15,-5,IRON_FENCE,21)
RandomBlock(-12,15,-4,IRON_FENCE,21)
RandomBlock(-12,15,-3,IRON_FENCE,21)
RandomBlock(-12,15,-2,IRON_FENCE,21)
RandomBlock(-12,15,-1,IRON_FENCE,21)
RandomBlock(-12,15,0,IRON_FENCE,21)
RandomBlock(-12,15,1,IRON_FENCE,21)
RandomBlock(-12,15,2,IRON_FENCE,21)
RandomBlock(-12,15,3,IRON_FENCE,21)
RandomBlock(-12,15,4,IRON_FENCE,21)
RandomBlock(-12,15,5,IRON_FENCE,21)
RandomBlock(-12,15,6,IRON_FENCE,21)
RandomBlock(-12,15,7,IRON_FENCE,21)
RandomBlock(-12,15,8,IRON_FENCE,21)
RandomBlock(-12,16,-6,IRON_FENCE,21)
RandomBlock(-12,16,-5,IRON_FENCE,21)
RandomBlock(-12,16,-4,IRON_FENCE,21)
RandomBlock(-12,16,-3,IRON_FENCE,21)
RandomBlock(-12,16,-2,IRON_FENCE,21)
RandomBlock(-12,16,-1,IRON_FENCE,21)
RandomBlock(-12,16,0,IRON_FENCE,21)
RandomBlock(-12,16,1,IRON_FENCE,21)
RandomBlock(-12,16,2,IRON_FENCE,21)
RandomBlock(-12,16,3,IRON_FENCE,21)
RandomBlock(-12,16,4,IRON_FENCE,21)
RandomBlock(-12,16,5,IRON_FENCE,21)
RandomBlock(-12,16,6,IRON_FENCE,21)
RandomBlock(-12,16,7,IRON_FENCE,21)
RandomBlock(-12,16,8,IRON_FENCE,21)
RandomBlock(-12,17,-5,IRON_FENCE,21)
RandomBlock(-12,17,-4,IRON_FENCE,21)
RandomBlock(-12,17,-3,IRON_FENCE,21)
RandomBlock(-12,17,-2,IRON_FENCE,21)
RandomBlock(-12,17,-1,IRON_FENCE,21)
RandomBlock(-12,17,0,IRON_FENCE,21)
RandomBlock(-12,17,1,IRON_FENCE,21)
RandomBlock(-12,17,2,IRON_FENCE,21)
RandomBlock(-12,17,3,IRON_FENCE,21)
RandomBlock(-12,17,4,IRON_FENCE,21)
RandomBlock(-12,17,5,IRON_FENCE,21)
RandomBlock(-12,17,6,IRON_FENCE,21)
RandomBlock(-12,17,7,IRON_FENCE,21)
RandomBlock(-12,18,-5,IRON_FENCE,21)
RandomBlock(-12,18,-4,IRON_FENCE,21)
RandomBlock(-12,18,-3,IRON_FENCE,21)
RandomBlock(-12,18,-2,IRON_FENCE,21)
RandomBlock(-12,18,-1,IRON_FENCE,21)
RandomBlock(-12,18,0,IRON_FENCE,21)
RandomBlock(-12,18,1,IRON_FENCE,21)
RandomBlock(-12,18,2,IRON_FENCE,21)
RandomBlock(-12,18,3,IRON_FENCE,21)
RandomBlock(-12,18,4,IRON_FENCE,21)
RandomBlock(-12,18,5,IRON_FENCE,21)
RandomBlock(-12,18,6,IRON_FENCE,21)
RandomBlock(-12,18,7,IRON_FENCE,21)
RandomBlock(-12,19,-4,IRON_FENCE,21)
RandomBlock(-12,19,-3,IRON_FENCE,21)
RandomBlock(-12,19,-2,IRON_FENCE,21)
RandomBlock(-12,19,-1,IRON_FENCE,21)
RandomBlock(-12,19,0,IRON_FENCE,21)
RandomBlock(-12,19,1,IRON_FENCE,21)
RandomBlock(-12,19,2,IRON_FENCE,21)
RandomBlock(-12,19,3,IRON_FENCE,21)
RandomBlock(-12,19,4,IRON_FENCE,21)
RandomBlock(-12,19,5,IRON_FENCE,21)
RandomBlock(-12,19,6,IRON_FENCE,21)
RandomBlock(-12,20,-3,IRON_FENCE,21)
RandomBlock(-12,20,-2,IRON_FENCE,21)
RandomBlock(-12,20,-1,IRON_FENCE,21)
RandomBlock(-12,20,0,IRON_FENCE,21)
RandomBlock(-12,20,1,IRON_FENCE,21)
RandomBlock(-12,20,2,IRON_FENCE,21)
RandomBlock(-12,20,3,IRON_FENCE,21)
RandomBlock(-12,20,4,IRON_FENCE,21)
RandomBlock(-12,20,5,IRON_FENCE,21)
RandomBlock(-12,21,-1,IRON_FENCE,21)
RandomBlock(-12,21,0,IRON_FENCE,21)
RandomBlock(-12,21,1,IRON_FENCE,21)
RandomBlock(-12,21,2,IRON_FENCE,21)
RandomBlock(-12,21,3,IRON_FENCE,21)
RandomBlock(-11,5,1,IRON_FENCE,21)
RandomBlock(-11,6,-3,IRON_FENCE,21)
RandomBlock(-11,6,-2,IRON_FENCE,21)
RandomBlock(-11,6,-1,IRON_FENCE,21)
RandomBlock(-11,6,0,IRON_FENCE,21)
RandomBlock(-11,6,1,IRON_FENCE,21)
RandomBlock(-11,6,2,IRON_FENCE,21)
RandomBlock(-11,6,3,IRON_FENCE,21)
RandomBlock(-11,6,4,IRON_FENCE,21)
RandomBlock(-11,6,5,IRON_FENCE,21)
RandomBlock(-11,7,-4,IRON_FENCE,21)
RandomBlock(-11,7,-3,IRON_FENCE,21)
RandomBlock(-11,7,-2,IRON_FENCE,21)
RandomBlock(-11,7,-1,IRON_FENCE,21)
RandomBlock(-11,7,0,IRON_FENCE,21)
RandomBlock(-11,7,1,IRON_FENCE,21)
RandomBlock(-11,7,2,IRON_FENCE,21)
RandomBlock(-11,7,3,IRON_FENCE,21)
RandomBlock(-11,7,4,IRON_FENCE,21)
RandomBlock(-11,7,5,IRON_FENCE,21)
RandomBlock(-11,7,6,IRON_FENCE,21)
RandomBlock(-11,8,-5,IRON_FENCE,21)
RandomBlock(-11,8,-4,IRON_FENCE,21)
RandomBlock(-11,8,-3,IRON_FENCE,21)
RandomBlock(-11,8,-2,IRON_FENCE,21)
RandomBlock(-11,8,-1,IRON_FENCE,21)
RandomBlock(-11,8,0,IRON_FENCE,21)
RandomBlock(-11,8,1,IRON_FENCE,21)
RandomBlock(-11,8,2,IRON_FENCE,21)
RandomBlock(-11,8,3,IRON_FENCE,21)
RandomBlock(-11,8,4,IRON_FENCE,21)
RandomBlock(-11,8,5,IRON_FENCE,21)
RandomBlock(-11,8,6,IRON_FENCE,21)
RandomBlock(-11,8,7,IRON_FENCE,21)
RandomBlock(-11,9,-6,IRON_FENCE,21)
RandomBlock(-11,9,-5,IRON_FENCE,21)
RandomBlock(-11,9,-4,IRON_FENCE,21)
RandomBlock(-11,9,-3,IRON_FENCE,21)
RandomBlock(-11,9,-2,IRON_FENCE,21)
RandomBlock(-11,9,-1,IRON_FENCE,21)
RandomBlock(-11,9,0,IRON_FENCE,21)
RandomBlock(-11,9,1,IRON_FENCE,21)
RandomBlock(-11,9,2,IRON_FENCE,21)
RandomBlock(-11,9,3,IRON_FENCE,21)
RandomBlock(-11,9,4,IRON_FENCE,21)
RandomBlock(-11,9,5,IRON_FENCE,21)
RandomBlock(-11,9,6,IRON_FENCE,21)
RandomBlock(-11,9,7,IRON_FENCE,21)
RandomBlock(-11,9,8,IRON_FENCE,21)
RandomBlock(-11,10,-7,IRON_FENCE,21)
RandomBlock(-11,10,-6,IRON_FENCE,21)
RandomBlock(-11,10,-5,IRON_FENCE,21)
RandomBlock(-11,10,-4,IRON_FENCE,21)
RandomBlock(-11,10,-3,IRON_FENCE,21)
RandomBlock(-11,10,-2,IRON_FENCE,21)
RandomBlock(-11,10,-1,IRON_FENCE,21)
RandomBlock(-11,10,0,IRON_FENCE,21)
RandomBlock(-11,10,1,IRON_FENCE,21)
RandomBlock(-11,10,2,IRON_FENCE,21)
RandomBlock(-11,10,3,IRON_FENCE,21)
RandomBlock(-11,10,4,IRON_FENCE,21)
RandomBlock(-11,10,5,IRON_FENCE,21)
RandomBlock(-11,10,6,IRON_FENCE,21)
RandomBlock(-11,10,7,IRON_FENCE,21)
RandomBlock(-11,10,8,IRON_FENCE,21)
RandomBlock(-11,10,9,IRON_FENCE,21)
RandomBlock(-11,11,-7,IRON_FENCE,21)
RandomBlock(-11,11,-6,IRON_FENCE,21)
RandomBlock(-11,11,-5,IRON_FENCE,21)
RandomBlock(-11,11,-4,IRON_FENCE,21)
RandomBlock(-11,11,-3,IRON_FENCE,21)
RandomBlock(-11,11,-2,IRON_FENCE,21)
RandomBlock(-11,11,-1,IRON_FENCE,21)
RandomBlock(-11,11,0,IRON_FENCE,21)
RandomBlock(-11,11,1,IRON_FENCE,21)
RandomBlock(-11,11,2,IRON_FENCE,21)
RandomBlock(-11,11,3,IRON_FENCE,21)
RandomBlock(-11,11,4,IRON_FENCE,21)
RandomBlock(-11,11,5,IRON_FENCE,21)
RandomBlock(-11,11,6,IRON_FENCE,21)
RandomBlock(-11,11,7,IRON_FENCE,21)
RandomBlock(-11,11,8,IRON_FENCE,21)
RandomBlock(-11,11,9,IRON_FENCE,21)
RandomBlock(-11,12,-7,IRON_FENCE,21)
RandomBlock(-11,12,-6,IRON_FENCE,21)
RandomBlock(-11,12,-5,IRON_FENCE,21)
RandomBlock(-11,12,-4,IRON_FENCE,21)
RandomBlock(-11,12,-3,IRON_FENCE,21)
RandomBlock(-11,12,-2,IRON_FENCE,21)
RandomBlock(-11,12,-1,IRON_FENCE,21)
RandomBlock(-11,12,0,IRON_FENCE,21)
RandomBlock(-11,12,1,IRON_FENCE,21)
RandomBlock(-11,12,2,IRON_FENCE,21)
RandomBlock(-11,12,3,IRON_FENCE,21)
RandomBlock(-11,12,4,IRON_FENCE,21)
RandomBlock(-11,12,5,IRON_FENCE,21)
RandomBlock(-11,12,6,IRON_FENCE,21)
RandomBlock(-11,12,7,IRON_FENCE,21)
RandomBlock(-11,12,8,IRON_FENCE,21)
RandomBlock(-11,12,9,IRON_FENCE,21)
RandomBlock(-11,13,-7,IRON_FENCE,21)
RandomBlock(-11,13,-6,IRON_FENCE,21)
RandomBlock(-11,13,-5,IRON_FENCE,21)
RandomBlock(-11,13,-4,IRON_FENCE,21)
RandomBlock(-11,13,-3,IRON_FENCE,21)
RandomBlock(-11,13,-2,IRON_FENCE,21)
RandomBlock(-11,13,-1,IRON_FENCE,21)
RandomBlock(-11,13,0,IRON_FENCE,21)
RandomBlock(-11,13,1,IRON_FENCE,21)
RandomBlock(-11,13,2,IRON_FENCE,21)
RandomBlock(-11,13,3,IRON_FENCE,21)
RandomBlock(-11,13,4,IRON_FENCE,21)
RandomBlock(-11,13,5,IRON_FENCE,21)
RandomBlock(-11,13,6,IRON_FENCE,21)
RandomBlock(-11,13,7,IRON_FENCE,21)
RandomBlock(-11,13,8,IRON_FENCE,21)
RandomBlock(-11,13,9,IRON_FENCE,21)
RandomBlock(-11,14,-8,IRON_FENCE,21)
RandomBlock(-11,14,-7,IRON_FENCE,21)
RandomBlock(-11,14,-6,IRON_FENCE,21)
RandomBlock(-11,14,-5,IRON_FENCE,21)
RandomBlock(-11,14,-4,IRON_FENCE,21)
RandomBlock(-11,14,-3,IRON_FENCE,21)
RandomBlock(-11,14,-2,IRON_FENCE,21)
RandomBlock(-11,14,-1,IRON_FENCE,21)
RandomBlock(-11,14,0,IRON_FENCE,21)
RandomBlock(-11,14,1,IRON_FENCE,21)
RandomBlock(-11,14,2,IRON_FENCE,21)
RandomBlock(-11,14,3,IRON_FENCE,21)
RandomBlock(-11,14,4,IRON_FENCE,21)
RandomBlock(-11,14,5,IRON_FENCE,21)
RandomBlock(-11,14,6,IRON_FENCE,21)
RandomBlock(-11,14,7,IRON_FENCE,21)
RandomBlock(-11,14,8,IRON_FENCE,21)
RandomBlock(-11,14,9,IRON_FENCE,21)
RandomBlock(-11,14,10,IRON_FENCE,21)
RandomBlock(-11,15,-7,IRON_FENCE,21)
RandomBlock(-11,15,-6,IRON_FENCE,21)
RandomBlock(-11,15,-5,IRON_FENCE,21)
RandomBlock(-11,15,-4,IRON_FENCE,21)
RandomBlock(-11,15,-3,IRON_FENCE,21)
RandomBlock(-11,15,-2,IRON_FENCE,21)
RandomBlock(-11,15,-1,IRON_FENCE,21)
RandomBlock(-11,15,0,IRON_FENCE,21)
RandomBlock(-11,15,1,IRON_FENCE,21)
RandomBlock(-11,15,2,IRON_FENCE,21)
RandomBlock(-11,15,3,IRON_FENCE,21)
RandomBlock(-11,15,4,IRON_FENCE,21)
RandomBlock(-11,15,5,IRON_FENCE,21)
RandomBlock(-11,15,6,IRON_FENCE,21)
RandomBlock(-11,15,7,IRON_FENCE,21)
RandomBlock(-11,15,8,IRON_FENCE,21)
RandomBlock(-11,15,9,IRON_FENCE,21)
RandomBlock(-11,16,-7,IRON_FENCE,21)
RandomBlock(-11,16,-6,IRON_FENCE,21)
RandomBlock(-11,16,-5,IRON_FENCE,21)
RandomBlock(-11,16,-4,IRON_FENCE,21)
RandomBlock(-11,16,-3,IRON_FENCE,21)
RandomBlock(-11,16,-2,IRON_FENCE,21)
RandomBlock(-11,16,-1,IRON_FENCE,21)
RandomBlock(-11,16,0,IRON_FENCE,21)
RandomBlock(-11,16,1,IRON_FENCE,21)
RandomBlock(-11,16,2,IRON_FENCE,21)
RandomBlock(-11,16,3,IRON_FENCE,21)
RandomBlock(-11,16,4,IRON_FENCE,21)
RandomBlock(-11,16,5,IRON_FENCE,21)
RandomBlock(-11,16,6,IRON_FENCE,21)
RandomBlock(-11,16,7,IRON_FENCE,21)
RandomBlock(-11,16,8,IRON_FENCE,21)
RandomBlock(-11,16,9,IRON_FENCE,21)
RandomBlock(-11,17,-7,IRON_FENCE,21)
RandomBlock(-11,17,-6,IRON_FENCE,21)
RandomBlock(-11,17,-5,IRON_FENCE,21)
RandomBlock(-11,17,-4,IRON_FENCE,21)
RandomBlock(-11,17,-3,IRON_FENCE,21)
RandomBlock(-11,17,-2,IRON_FENCE,21)
RandomBlock(-11,17,-1,IRON_FENCE,21)
RandomBlock(-11,17,0,IRON_FENCE,21)
RandomBlock(-11,17,1,IRON_FENCE,21)
RandomBlock(-11,17,2,IRON_FENCE,21)
RandomBlock(-11,17,3,IRON_FENCE,21)
RandomBlock(-11,17,4,IRON_FENCE,21)
RandomBlock(-11,17,5,IRON_FENCE,21)
RandomBlock(-11,17,6,IRON_FENCE,21)
RandomBlock(-11,17,7,IRON_FENCE,21)
RandomBlock(-11,17,8,IRON_FENCE,21)
RandomBlock(-11,17,9,IRON_FENCE,21)
RandomBlock(-11,18,-7,IRON_FENCE,21)
RandomBlock(-11,18,-6,IRON_FENCE,21)
RandomBlock(-11,18,-5,IRON_FENCE,21)
RandomBlock(-11,18,-4,IRON_FENCE,21)
RandomBlock(-11,18,-3,IRON_FENCE,21)
RandomBlock(-11,18,-2,IRON_FENCE,21)
RandomBlock(-11,18,-1,IRON_FENCE,21)
RandomBlock(-11,18,0,IRON_FENCE,21)
RandomBlock(-11,18,1,IRON_FENCE,21)
RandomBlock(-11,18,2,IRON_FENCE,21)
RandomBlock(-11,18,3,IRON_FENCE,21)
RandomBlock(-11,18,4,IRON_FENCE,21)
RandomBlock(-11,18,5,IRON_FENCE,21)
RandomBlock(-11,18,6,IRON_FENCE,21)
RandomBlock(-11,18,7,IRON_FENCE,21)
RandomBlock(-11,18,8,IRON_FENCE,21)
RandomBlock(-11,18,9,IRON_FENCE,21)
RandomBlock(-11,19,-6,IRON_FENCE,21)
RandomBlock(-11,19,-5,IRON_FENCE,21)
RandomBlock(-11,19,-4,IRON_FENCE,21)
RandomBlock(-11,19,-3,IRON_FENCE,21)
RandomBlock(-11,19,-2,IRON_FENCE,21)
RandomBlock(-11,19,-1,IRON_FENCE,21)
RandomBlock(-11,19,0,IRON_FENCE,21)
RandomBlock(-11,19,1,IRON_FENCE,21)
RandomBlock(-11,19,2,IRON_FENCE,21)
RandomBlock(-11,19,3,IRON_FENCE,21)
RandomBlock(-11,19,4,IRON_FENCE,21)
RandomBlock(-11,19,5,IRON_FENCE,21)
RandomBlock(-11,19,6,IRON_FENCE,21)
RandomBlock(-11,19,7,IRON_FENCE,21)
RandomBlock(-11,19,8,IRON_FENCE,21)
RandomBlock(-11,20,-5,IRON_FENCE,21)
RandomBlock(-11,20,-4,IRON_FENCE,21)
RandomBlock(-11,20,-3,IRON_FENCE,21)
RandomBlock(-11,20,-2,IRON_FENCE,21)
RandomBlock(-11,20,-1,IRON_FENCE,21)
RandomBlock(-11,20,0,IRON_FENCE,21)
RandomBlock(-11,20,1,IRON_FENCE,21)
RandomBlock(-11,20,2,IRON_FENCE,21)
RandomBlock(-11,20,3,IRON_FENCE,21)
RandomBlock(-11,20,4,IRON_FENCE,21)
RandomBlock(-11,20,5,IRON_FENCE,21)
RandomBlock(-11,20,6,IRON_FENCE,21)
RandomBlock(-11,20,7,IRON_FENCE,21)
RandomBlock(-11,21,-4,IRON_FENCE,21)
RandomBlock(-11,21,-3,IRON_FENCE,21)
RandomBlock(-11,21,-2,IRON_FENCE,21)
RandomBlock(-11,21,-1,IRON_FENCE,21)
RandomBlock(-11,21,0,IRON_FENCE,21)
RandomBlock(-11,21,1,IRON_FENCE,21)
RandomBlock(-11,21,2,IRON_FENCE,21)
RandomBlock(-11,21,3,IRON_FENCE,21)
RandomBlock(-11,21,4,IRON_FENCE,21)
RandomBlock(-11,21,5,IRON_FENCE,21)
RandomBlock(-11,21,6,IRON_FENCE,21)
RandomBlock(-11,22,-3,IRON_FENCE,21)
RandomBlock(-11,22,-2,IRON_FENCE,21)
RandomBlock(-11,22,-1,IRON_FENCE,21)
RandomBlock(-11,22,0,IRON_FENCE,21)
RandomBlock(-11,22,1,IRON_FENCE,21)
RandomBlock(-11,22,2,IRON_FENCE,21)
RandomBlock(-11,22,3,IRON_FENCE,21)
RandomBlock(-11,22,4,IRON_FENCE,21)
RandomBlock(-11,22,5,IRON_FENCE,21)
RandomBlock(-11,23,1,IRON_FENCE,21)
RandomBlock(-10,4,-1,IRON_FENCE,21)
RandomBlock(-10,4,0,IRON_FENCE,21)
RandomBlock(-10,4,1,IRON_FENCE,21)
RandomBlock(-10,4,2,IRON_FENCE,21)
RandomBlock(-10,4,3,IRON_FENCE,21)
RandomBlock(-10,5,-3,IRON_FENCE,21)
RandomBlock(-10,5,-2,IRON_FENCE,21)
RandomBlock(-10,5,-1,IRON_FENCE,21)
RandomBlock(-10,5,0,IRON_FENCE,21)
RandomBlock(-10,5,1,IRON_FENCE,21)
RandomBlock(-10,5,2,IRON_FENCE,21)
RandomBlock(-10,5,3,IRON_FENCE,21)
RandomBlock(-10,5,4,IRON_FENCE,21)
RandomBlock(-10,5,5,IRON_FENCE,21)
RandomBlock(-10,6,-5,IRON_FENCE,21)
RandomBlock(-10,6,-4,IRON_FENCE,21)
RandomBlock(-10,6,-3,IRON_FENCE,21)
RandomBlock(-10,6,-2,IRON_FENCE,21)
RandomBlock(-10,6,-1,IRON_FENCE,21)
RandomBlock(-10,6,0,IRON_FENCE,21)
RandomBlock(-10,6,1,IRON_FENCE,21)
RandomBlock(-10,6,2,IRON_FENCE,21)
RandomBlock(-10,6,3,IRON_FENCE,21)
RandomBlock(-10,6,4,IRON_FENCE,21)
RandomBlock(-10,6,5,IRON_FENCE,21)
RandomBlock(-10,6,6,IRON_FENCE,21)
RandomBlock(-10,6,7,IRON_FENCE,21)
RandomBlock(-10,7,-6,IRON_FENCE,21)
RandomBlock(-10,7,-5,IRON_FENCE,21)
RandomBlock(-10,7,-4,IRON_FENCE,21)
RandomBlock(-10,7,-3,IRON_FENCE,21)
RandomBlock(-10,7,-2,IRON_FENCE,21)
RandomBlock(-10,7,-1,IRON_FENCE,21)
RandomBlock(-10,7,0,IRON_FENCE,21)
RandomBlock(-10,7,1,IRON_FENCE,21)
RandomBlock(-10,7,2,IRON_FENCE,21)
RandomBlock(-10,7,3,IRON_FENCE,21)
RandomBlock(-10,7,4,IRON_FENCE,21)
RandomBlock(-10,7,5,IRON_FENCE,21)
RandomBlock(-10,7,6,IRON_FENCE,21)
RandomBlock(-10,7,7,IRON_FENCE,21)
RandomBlock(-10,7,8,IRON_FENCE,21)
RandomBlock(-10,8,-7,IRON_FENCE,21)
RandomBlock(-10,8,-6,IRON_FENCE,21)
RandomBlock(-10,8,-5,IRON_FENCE,21)
RandomBlock(-10,8,-4,IRON_FENCE,21)
RandomBlock(-10,8,-3,IRON_FENCE,21)
RandomBlock(-10,8,-2,IRON_FENCE,21)
RandomBlock(-10,8,-1,IRON_FENCE,21)
RandomBlock(-10,8,0,IRON_FENCE,21)
RandomBlock(-10,8,1,IRON_FENCE,21)
RandomBlock(-10,8,2,IRON_FENCE,21)
RandomBlock(-10,8,3,IRON_FENCE,21)
RandomBlock(-10,8,4,IRON_FENCE,21)
RandomBlock(-10,8,5,IRON_FENCE,21)
RandomBlock(-10,8,6,IRON_FENCE,21)
RandomBlock(-10,8,7,IRON_FENCE,21)
RandomBlock(-10,8,8,IRON_FENCE,21)
RandomBlock(-10,8,9,IRON_FENCE,21)
RandomBlock(-10,9,-7,IRON_FENCE,21)
RandomBlock(-10,9,-6,IRON_FENCE,21)
RandomBlock(-10,9,-5,IRON_FENCE,21)
RandomBlock(-10,9,-4,IRON_FENCE,21)
RandomBlock(-10,9,-3,IRON_FENCE,21)
RandomBlock(-10,9,-2,IRON_FENCE,21)
RandomBlock(-10,9,-1,IRON_FENCE,21)
RandomBlock(-10,9,0,IRON_FENCE,21)
RandomBlock(-10,9,1,IRON_FENCE,21)
RandomBlock(-10,9,2,IRON_FENCE,21)
RandomBlock(-10,9,3,IRON_FENCE,21)
RandomBlock(-10,9,4,IRON_FENCE,21)
RandomBlock(-10,9,5,IRON_FENCE,21)
RandomBlock(-10,9,6,IRON_FENCE,21)
RandomBlock(-10,9,7,IRON_FENCE,21)
RandomBlock(-10,9,8,IRON_FENCE,21)
RandomBlock(-10,9,9,IRON_FENCE,21)
RandomBlock(-10,10,-8,IRON_FENCE,21)
RandomBlock(-10,10,-7,IRON_FENCE,21)
RandomBlock(-10,10,-6,IRON_FENCE,21)
RandomBlock(-10,10,-5,IRON_FENCE,21)
RandomBlock(-10,10,-4,IRON_FENCE,21)
RandomBlock(-10,10,-3,IRON_FENCE,21)
RandomBlock(-10,10,-2,IRON_FENCE,21)
RandomBlock(-10,10,-1,IRON_FENCE,21)
RandomBlock(-10,10,0,IRON_FENCE,21)
RandomBlock(-10,10,1,IRON_FENCE,21)
RandomBlock(-10,10,2,IRON_FENCE,21)
RandomBlock(-10,10,3,IRON_FENCE,21)
RandomBlock(-10,10,4,IRON_FENCE,21)
RandomBlock(-10,10,5,IRON_FENCE,21)
RandomBlock(-10,10,6,IRON_FENCE,21)
RandomBlock(-10,10,7,IRON_FENCE,21)
RandomBlock(-10,10,8,IRON_FENCE,21)
RandomBlock(-10,10,9,IRON_FENCE,21)
RandomBlock(-10,10,10,IRON_FENCE,21)
RandomBlock(-10,11,-8,IRON_FENCE,21)
RandomBlock(-10,11,-7,IRON_FENCE,21)
RandomBlock(-10,11,-6,IRON_FENCE,21)
RandomBlock(-10,11,-5,IRON_FENCE,21)
RandomBlock(-10,11,-4,IRON_FENCE,21)
RandomBlock(-10,11,-3,IRON_FENCE,21)
RandomBlock(-10,11,-2,IRON_FENCE,21)
RandomBlock(-10,11,-1,IRON_FENCE,21)
RandomBlock(-10,11,0,IRON_FENCE,21)
RandomBlock(-10,11,1,IRON_FENCE,21)
RandomBlock(-10,11,2,IRON_FENCE,21)
RandomBlock(-10,11,3,IRON_FENCE,21)
RandomBlock(-10,11,4,IRON_FENCE,21)
RandomBlock(-10,11,5,IRON_FENCE,21)
RandomBlock(-10,11,6,IRON_FENCE,21)
RandomBlock(-10,11,7,IRON_FENCE,21)
RandomBlock(-10,11,8,IRON_FENCE,21)
RandomBlock(-10,11,9,IRON_FENCE,21)
RandomBlock(-10,11,10,IRON_FENCE,21)
RandomBlock(-10,12,-9,IRON_FENCE,21)
RandomBlock(-10,12,-8,IRON_FENCE,21)
RandomBlock(-10,12,-7,IRON_FENCE,21)
RandomBlock(-10,12,-6,IRON_FENCE,21)
RandomBlock(-10,12,-5,IRON_FENCE,21)
RandomBlock(-10,12,-4,IRON_FENCE,21)
RandomBlock(-10,12,-3,IRON_FENCE,21)
RandomBlock(-10,12,-2,IRON_FENCE,21)
RandomBlock(-10,12,-1,IRON_FENCE,21)
RandomBlock(-10,12,0,IRON_FENCE,21)
RandomBlock(-10,12,1,IRON_FENCE,21)
RandomBlock(-10,12,2,IRON_FENCE,21)
RandomBlock(-10,12,3,IRON_FENCE,21)
RandomBlock(-10,12,4,IRON_FENCE,21)
RandomBlock(-10,12,5,IRON_FENCE,21)
RandomBlock(-10,12,6,IRON_FENCE,21)
RandomBlock(-10,12,7,IRON_FENCE,21)
RandomBlock(-10,12,8,IRON_FENCE,21)
RandomBlock(-10,12,9,IRON_FENCE,21)
RandomBlock(-10,12,10,IRON_FENCE,21)
RandomBlock(-10,12,11,IRON_FENCE,21)
RandomBlock(-10,13,-9,IRON_FENCE,21)
RandomBlock(-10,13,-8,IRON_FENCE,21)
RandomBlock(-10,13,-7,IRON_FENCE,21)
RandomBlock(-10,13,-6,IRON_FENCE,21)
RandomBlock(-10,13,-5,IRON_FENCE,21)
RandomBlock(-10,13,-4,IRON_FENCE,21)
RandomBlock(-10,13,-3,IRON_FENCE,21)
RandomBlock(-10,13,-2,IRON_FENCE,21)
RandomBlock(-10,13,-1,IRON_FENCE,21)
RandomBlock(-10,13,0,IRON_FENCE,21)
RandomBlock(-10,13,1,IRON_FENCE,21)
RandomBlock(-10,13,2,IRON_FENCE,21)
RandomBlock(-10,13,3,IRON_FENCE,21)
RandomBlock(-10,13,4,IRON_FENCE,21)
RandomBlock(-10,13,5,IRON_FENCE,21)
RandomBlock(-10,13,6,IRON_FENCE,21)
RandomBlock(-10,13,7,IRON_FENCE,21)
RandomBlock(-10,13,8,IRON_FENCE,21)
RandomBlock(-10,13,9,IRON_FENCE,21)
RandomBlock(-10,13,10,IRON_FENCE,21)
RandomBlock(-10,13,11,IRON_FENCE,21)
RandomBlock(-10,14,-9,IRON_FENCE,21)
RandomBlock(-10,14,-8,IRON_FENCE,21)
RandomBlock(-10,14,-7,IRON_FENCE,21)
RandomBlock(-10,14,-6,IRON_FENCE,21)
RandomBlock(-10,14,-5,IRON_FENCE,21)
RandomBlock(-10,14,-4,IRON_FENCE,21)
RandomBlock(-10,14,-3,IRON_FENCE,21)
RandomBlock(-10,14,-2,IRON_FENCE,21)
RandomBlock(-10,14,-1,IRON_FENCE,21)
RandomBlock(-10,14,0,IRON_FENCE,21)
RandomBlock(-10,14,1,IRON_FENCE,21)
RandomBlock(-10,14,2,IRON_FENCE,21)
RandomBlock(-10,14,3,IRON_FENCE,21)
RandomBlock(-10,14,4,IRON_FENCE,21)
RandomBlock(-10,14,5,IRON_FENCE,21)
RandomBlock(-10,14,6,IRON_FENCE,21)
RandomBlock(-10,14,7,IRON_FENCE,21)
RandomBlock(-10,14,8,IRON_FENCE,21)
RandomBlock(-10,14,9,IRON_FENCE,21)
RandomBlock(-10,14,10,IRON_FENCE,21)
RandomBlock(-10,14,11,IRON_FENCE,21)
RandomBlock(-10,15,-9,IRON_FENCE,21)
RandomBlock(-10,15,-8,IRON_FENCE,21)
RandomBlock(-10,15,-7,IRON_FENCE,21)
RandomBlock(-10,15,-6,IRON_FENCE,21)
RandomBlock(-10,15,-5,IRON_FENCE,21)
RandomBlock(-10,15,-4,IRON_FENCE,21)
RandomBlock(-10,15,-3,IRON_FENCE,21)
RandomBlock(-10,15,-2,IRON_FENCE,21)
RandomBlock(-10,15,-1,IRON_FENCE,21)
RandomBlock(-10,15,0,IRON_FENCE,21)
RandomBlock(-10,15,1,IRON_FENCE,21)
RandomBlock(-10,15,2,IRON_FENCE,21)
RandomBlock(-10,15,3,IRON_FENCE,21)
RandomBlock(-10,15,4,IRON_FENCE,21)
RandomBlock(-10,15,5,IRON_FENCE,21)
RandomBlock(-10,15,6,IRON_FENCE,21)
RandomBlock(-10,15,7,IRON_FENCE,21)
RandomBlock(-10,15,8,IRON_FENCE,21)
RandomBlock(-10,15,9,IRON_FENCE,21)
RandomBlock(-10,15,10,IRON_FENCE,21)
RandomBlock(-10,15,11,IRON_FENCE,21)
RandomBlock(-10,16,-9,IRON_FENCE,21)
RandomBlock(-10,16,-8,IRON_FENCE,21)
RandomBlock(-10,16,-7,IRON_FENCE,21)
RandomBlock(-10,16,-6,IRON_FENCE,21)
RandomBlock(-10,16,-5,IRON_FENCE,21)
RandomBlock(-10,16,-4,IRON_FENCE,21)
RandomBlock(-10,16,-3,IRON_FENCE,21)
RandomBlock(-10,16,-2,IRON_FENCE,21)
RandomBlock(-10,16,-1,IRON_FENCE,21)
RandomBlock(-10,16,0,IRON_FENCE,21)
RandomBlock(-10,16,1,IRON_FENCE,21)
RandomBlock(-10,16,2,IRON_FENCE,21)
RandomBlock(-10,16,3,IRON_FENCE,21)
RandomBlock(-10,16,4,IRON_FENCE,21)
RandomBlock(-10,16,5,IRON_FENCE,21)
RandomBlock(-10,16,6,IRON_FENCE,21)
RandomBlock(-10,16,7,IRON_FENCE,21)
RandomBlock(-10,16,8,IRON_FENCE,21)
RandomBlock(-10,16,9,IRON_FENCE,21)
RandomBlock(-10,16,10,IRON_FENCE,21)
RandomBlock(-10,16,11,IRON_FENCE,21)
RandomBlock(-10,17,-8,IRON_FENCE,21)
RandomBlock(-10,17,-7,IRON_FENCE,21)
RandomBlock(-10,17,-6,IRON_FENCE,21)
RandomBlock(-10,17,-5,IRON_FENCE,21)
RandomBlock(-10,17,-4,IRON_FENCE,21)
RandomBlock(-10,17,-3,IRON_FENCE,21)
RandomBlock(-10,17,-2,IRON_FENCE,21)
RandomBlock(-10,17,-1,IRON_FENCE,21)
RandomBlock(-10,17,0,IRON_FENCE,21)
RandomBlock(-10,17,1,IRON_FENCE,21)
RandomBlock(-10,17,2,IRON_FENCE,21)
RandomBlock(-10,17,3,IRON_FENCE,21)
RandomBlock(-10,17,4,IRON_FENCE,21)
RandomBlock(-10,17,5,IRON_FENCE,21)
RandomBlock(-10,17,6,IRON_FENCE,21)
RandomBlock(-10,17,7,IRON_FENCE,21)
RandomBlock(-10,17,8,IRON_FENCE,21)
RandomBlock(-10,17,9,IRON_FENCE,21)
RandomBlock(-10,17,10,IRON_FENCE,21)
RandomBlock(-10,18,-8,IRON_FENCE,21)
RandomBlock(-10,18,-7,IRON_FENCE,21)
RandomBlock(-10,18,-6,IRON_FENCE,21)
RandomBlock(-10,18,-5,IRON_FENCE,21)
RandomBlock(-10,18,-4,IRON_FENCE,21)
RandomBlock(-10,18,-3,IRON_FENCE,21)
RandomBlock(-10,18,-2,IRON_FENCE,21)
RandomBlock(-10,18,-1,IRON_FENCE,21)
RandomBlock(-10,18,0,IRON_FENCE,21)
RandomBlock(-10,18,1,IRON_FENCE,21)
RandomBlock(-10,18,2,IRON_FENCE,21)
RandomBlock(-10,18,3,IRON_FENCE,21)
RandomBlock(-10,18,4,IRON_FENCE,21)
RandomBlock(-10,18,5,IRON_FENCE,21)
RandomBlock(-10,18,6,IRON_FENCE,21)
RandomBlock(-10,18,7,IRON_FENCE,21)
RandomBlock(-10,18,8,IRON_FENCE,21)
RandomBlock(-10,18,9,IRON_FENCE,21)
RandomBlock(-10,18,10,IRON_FENCE,21)
RandomBlock(-10,19,-7,IRON_FENCE,21)
RandomBlock(-10,19,-6,IRON_FENCE,21)
RandomBlock(-10,19,-5,IRON_FENCE,21)
RandomBlock(-10,19,-4,IRON_FENCE,21)
RandomBlock(-10,19,-3,IRON_FENCE,21)
RandomBlock(-10,19,-2,IRON_FENCE,21)
RandomBlock(-10,19,-1,IRON_FENCE,21)
RandomBlock(-10,19,0,IRON_FENCE,21)
RandomBlock(-10,19,1,IRON_FENCE,21)
RandomBlock(-10,19,2,IRON_FENCE,21)
RandomBlock(-10,19,3,IRON_FENCE,21)
RandomBlock(-10,19,4,IRON_FENCE,21)
RandomBlock(-10,19,5,IRON_FENCE,21)
RandomBlock(-10,19,6,IRON_FENCE,21)
RandomBlock(-10,19,7,IRON_FENCE,21)
RandomBlock(-10,19,8,IRON_FENCE,21)
RandomBlock(-10,19,9,IRON_FENCE,21)
RandomBlock(-10,20,-7,IRON_FENCE,21)
RandomBlock(-10,20,-6,IRON_FENCE,21)
RandomBlock(-10,20,-5,IRON_FENCE,21)
RandomBlock(-10,20,-4,IRON_FENCE,21)
RandomBlock(-10,20,-3,IRON_FENCE,21)
RandomBlock(-10,20,-2,IRON_FENCE,21)
RandomBlock(-10,20,-1,IRON_FENCE,21)
RandomBlock(-10,20,0,IRON_FENCE,21)
RandomBlock(-10,20,1,IRON_FENCE,21)
RandomBlock(-10,20,2,IRON_FENCE,21)
RandomBlock(-10,20,3,IRON_FENCE,21)
RandomBlock(-10,20,4,IRON_FENCE,21)
RandomBlock(-10,20,5,IRON_FENCE,21)
RandomBlock(-10,20,6,IRON_FENCE,21)
RandomBlock(-10,20,7,IRON_FENCE,21)
RandomBlock(-10,20,8,IRON_FENCE,21)
RandomBlock(-10,20,9,IRON_FENCE,21)
RandomBlock(-10,21,-6,IRON_FENCE,21)
RandomBlock(-10,21,-5,IRON_FENCE,21)
RandomBlock(-10,21,-4,IRON_FENCE,21)
RandomBlock(-10,21,-3,IRON_FENCE,21)
RandomBlock(-10,21,-2,IRON_FENCE,21)
RandomBlock(-10,21,-1,IRON_FENCE,21)
RandomBlock(-10,21,0,IRON_FENCE,21)
RandomBlock(-10,21,1,IRON_FENCE,21)
RandomBlock(-10,21,2,IRON_FENCE,21)
RandomBlock(-10,21,3,IRON_FENCE,21)
RandomBlock(-10,21,4,IRON_FENCE,21)
RandomBlock(-10,21,5,IRON_FENCE,21)
RandomBlock(-10,21,6,IRON_FENCE,21)
RandomBlock(-10,21,7,IRON_FENCE,21)
RandomBlock(-10,21,8,IRON_FENCE,21)
RandomBlock(-10,22,-5,IRON_FENCE,21)
RandomBlock(-10,22,-4,IRON_FENCE,21)
RandomBlock(-10,22,-3,IRON_FENCE,21)
RandomBlock(-10,22,-2,IRON_FENCE,21)
RandomBlock(-10,22,-1,IRON_FENCE,21)
RandomBlock(-10,22,0,IRON_FENCE,21)
RandomBlock(-10,22,1,IRON_FENCE,21)
RandomBlock(-10,22,2,IRON_FENCE,21)
RandomBlock(-10,22,3,IRON_FENCE,21)
RandomBlock(-10,22,4,IRON_FENCE,21)
RandomBlock(-10,22,5,IRON_FENCE,21)
RandomBlock(-10,22,6,IRON_FENCE,21)
RandomBlock(-10,22,7,IRON_FENCE,21)
RandomBlock(-10,23,-3,IRON_FENCE,21)
RandomBlock(-10,23,-2,IRON_FENCE,21)
RandomBlock(-10,23,-1,IRON_FENCE,21)
RandomBlock(-10,23,0,IRON_FENCE,21)
RandomBlock(-10,23,1,IRON_FENCE,21)
RandomBlock(-10,23,2,IRON_FENCE,21)
RandomBlock(-10,23,3,IRON_FENCE,21)
RandomBlock(-10,23,4,IRON_FENCE,21)
RandomBlock(-10,23,5,IRON_FENCE,21)
RandomBlock(-10,24,-1,IRON_FENCE,21)
RandomBlock(-10,24,0,IRON_FENCE,21)
RandomBlock(-10,24,1,IRON_FENCE,21)
RandomBlock(-10,24,2,IRON_FENCE,21)
RandomBlock(-10,24,3,IRON_FENCE,21)
RandomBlock(-9,3,-1,IRON_FENCE,21)
RandomBlock(-9,3,0,IRON_FENCE,21)
RandomBlock(-9,3,1,IRON_FENCE,21)
RandomBlock(-9,3,2,IRON_FENCE,21)
RandomBlock(-9,3,3,IRON_FENCE,21)
RandomBlock(-9,4,-4,IRON_FENCE,21)
RandomBlock(-9,4,-3,IRON_FENCE,21)
RandomBlock(-9,4,-2,IRON_FENCE,21)
RandomBlock(-9,4,-1,IRON_FENCE,21)
RandomBlock(-9,4,0,IRON_FENCE,21)
RandomBlock(-9,4,1,IRON_FENCE,21)
RandomBlock(-9,4,2,IRON_FENCE,21)
RandomBlock(-9,4,3,IRON_FENCE,21)
RandomBlock(-9,4,4,IRON_FENCE,21)
RandomBlock(-9,4,5,IRON_FENCE,21)
RandomBlock(-9,4,6,IRON_FENCE,21)
RandomBlock(-9,5,-5,IRON_FENCE,21)
RandomBlock(-9,5,-4,IRON_FENCE,21)
RandomBlock(-9,5,-3,IRON_FENCE,21)
RandomBlock(-9,5,-2,IRON_FENCE,21)
RandomBlock(-9,5,-1,IRON_FENCE,21)
RandomBlock(-9,5,0,IRON_FENCE,21)
RandomBlock(-9,5,1,IRON_FENCE,21)
RandomBlock(-9,5,2,IRON_FENCE,21)
RandomBlock(-9,5,3,IRON_FENCE,21)
RandomBlock(-9,5,4,IRON_FENCE,21)
RandomBlock(-9,5,5,IRON_FENCE,21)
RandomBlock(-9,5,6,IRON_FENCE,21)
RandomBlock(-9,5,7,IRON_FENCE,21)
RandomBlock(-9,6,-6,IRON_FENCE,21)
RandomBlock(-9,6,-5,IRON_FENCE,21)
RandomBlock(-9,6,-4,IRON_FENCE,21)
RandomBlock(-9,6,-3,IRON_FENCE,21)
RandomBlock(-9,6,-2,IRON_FENCE,21)
RandomBlock(-9,6,-1,IRON_FENCE,21)
RandomBlock(-9,6,0,IRON_FENCE,21)
RandomBlock(-9,6,1,IRON_FENCE,21)
RandomBlock(-9,6,2,IRON_FENCE,21)
RandomBlock(-9,6,3,IRON_FENCE,21)
RandomBlock(-9,6,4,IRON_FENCE,21)
RandomBlock(-9,6,5,IRON_FENCE,21)
RandomBlock(-9,6,6,IRON_FENCE,21)
RandomBlock(-9,6,7,IRON_FENCE,21)
RandomBlock(-9,6,8,IRON_FENCE,21)
RandomBlock(-9,7,-7,IRON_FENCE,21)
RandomBlock(-9,7,-6,IRON_FENCE,21)
RandomBlock(-9,7,-5,IRON_FENCE,21)
RandomBlock(-9,7,-4,IRON_FENCE,21)
RandomBlock(-9,7,-3,IRON_FENCE,21)
RandomBlock(-9,7,-2,IRON_FENCE,21)
RandomBlock(-9,7,-1,IRON_FENCE,21)
RandomBlock(-9,7,0,IRON_FENCE,21)
RandomBlock(-9,7,1,IRON_FENCE,21)
RandomBlock(-9,7,2,IRON_FENCE,21)
RandomBlock(-9,7,3,IRON_FENCE,21)
RandomBlock(-9,7,4,IRON_FENCE,21)
RandomBlock(-9,7,5,IRON_FENCE,21)
RandomBlock(-9,7,6,IRON_FENCE,21)
RandomBlock(-9,7,7,IRON_FENCE,21)
RandomBlock(-9,7,8,IRON_FENCE,21)
RandomBlock(-9,7,9,IRON_FENCE,21)
RandomBlock(-9,8,-8,IRON_FENCE,21)
RandomBlock(-9,8,-7,IRON_FENCE,21)
RandomBlock(-9,8,-6,IRON_FENCE,21)
RandomBlock(-9,8,-5,IRON_FENCE,21)
RandomBlock(-9,8,-4,IRON_FENCE,21)
RandomBlock(-9,8,-3,IRON_FENCE,21)
RandomBlock(-9,8,-2,IRON_FENCE,21)
RandomBlock(-9,8,-1,IRON_FENCE,21)
RandomBlock(-9,8,0,IRON_FENCE,21)
RandomBlock(-9,8,1,IRON_FENCE,21)
RandomBlock(-9,8,2,IRON_FENCE,21)
RandomBlock(-9,8,3,IRON_FENCE,21)
RandomBlock(-9,8,4,IRON_FENCE,21)
RandomBlock(-9,8,5,IRON_FENCE,21)
RandomBlock(-9,8,6,IRON_FENCE,21)
RandomBlock(-9,8,7,IRON_FENCE,21)
RandomBlock(-9,8,8,IRON_FENCE,21)
RandomBlock(-9,8,9,IRON_FENCE,21)
RandomBlock(-9,8,10,IRON_FENCE,21)
RandomBlock(-9,9,-9,IRON_FENCE,21)
RandomBlock(-9,9,-8,IRON_FENCE,21)
RandomBlock(-9,9,-7,IRON_FENCE,21)
RandomBlock(-9,9,-6,IRON_FENCE,21)
RandomBlock(-9,9,-5,IRON_FENCE,21)
RandomBlock(-9,9,-4,IRON_FENCE,21)
RandomBlock(-9,9,-3,IRON_FENCE,21)
RandomBlock(-9,9,-2,IRON_FENCE,21)
RandomBlock(-9,9,-1,IRON_FENCE,21)
RandomBlock(-9,9,0,IRON_FENCE,21)
RandomBlock(-9,9,1,IRON_FENCE,21)
RandomBlock(-9,9,2,IRON_FENCE,21)
RandomBlock(-9,9,3,IRON_FENCE,21)
RandomBlock(-9,9,4,IRON_FENCE,21)
RandomBlock(-9,9,5,IRON_FENCE,21)
RandomBlock(-9,9,6,IRON_FENCE,21)
RandomBlock(-9,9,7,IRON_FENCE,21)
RandomBlock(-9,9,8,IRON_FENCE,21)
RandomBlock(-9,9,9,IRON_FENCE,21)
RandomBlock(-9,9,10,IRON_FENCE,21)
RandomBlock(-9,9,11,IRON_FENCE,21)
RandomBlock(-9,10,-9,IRON_FENCE,21)
RandomBlock(-9,10,-8,IRON_FENCE,21)
RandomBlock(-9,10,-7,IRON_FENCE,21)
RandomBlock(-9,10,-6,IRON_FENCE,21)
RandomBlock(-9,10,-5,IRON_FENCE,21)
RandomBlock(-9,10,-4,IRON_FENCE,21)
RandomBlock(-9,10,-3,IRON_FENCE,21)
RandomBlock(-9,10,-2,IRON_FENCE,21)
RandomBlock(-9,10,-1,IRON_FENCE,21)
RandomBlock(-9,10,0,IRON_FENCE,21)
RandomBlock(-9,10,1,IRON_FENCE,21)
RandomBlock(-9,10,2,IRON_FENCE,21)
RandomBlock(-9,10,3,IRON_FENCE,21)
RandomBlock(-9,10,4,IRON_FENCE,21)
RandomBlock(-9,10,5,IRON_FENCE,21)
RandomBlock(-9,10,6,IRON_FENCE,21)
RandomBlock(-9,10,7,IRON_FENCE,21)
RandomBlock(-9,10,8,IRON_FENCE,21)
RandomBlock(-9,10,9,IRON_FENCE,21)
RandomBlock(-9,10,10,IRON_FENCE,21)
RandomBlock(-9,10,11,IRON_FENCE,21)
RandomBlock(-9,11,-9,IRON_FENCE,21)
RandomBlock(-9,11,-8,IRON_FENCE,21)
RandomBlock(-9,11,-7,IRON_FENCE,21)
RandomBlock(-9,11,-6,IRON_FENCE,21)
RandomBlock(-9,11,-5,IRON_FENCE,21)
RandomBlock(-9,11,-4,IRON_FENCE,21)
RandomBlock(-9,11,-3,IRON_FENCE,21)
RandomBlock(-9,11,-2,IRON_FENCE,21)
RandomBlock(-9,11,-1,IRON_FENCE,21)
RandomBlock(-9,11,0,IRON_FENCE,21)
RandomBlock(-9,11,1,IRON_FENCE,21)
RandomBlock(-9,11,2,IRON_FENCE,21)
RandomBlock(-9,11,3,IRON_FENCE,21)
RandomBlock(-9,11,4,IRON_FENCE,21)
RandomBlock(-9,11,5,IRON_FENCE,21)
RandomBlock(-9,11,6,IRON_FENCE,21)
RandomBlock(-9,11,7,IRON_FENCE,21)
RandomBlock(-9,11,8,IRON_FENCE,21)
RandomBlock(-9,11,9,IRON_FENCE,21)
RandomBlock(-9,11,10,IRON_FENCE,21)
RandomBlock(-9,11,11,IRON_FENCE,21)
RandomBlock(-9,12,-10,IRON_FENCE,21)
RandomBlock(-9,12,-9,IRON_FENCE,21)
RandomBlock(-9,12,-8,IRON_FENCE,21)
RandomBlock(-9,12,-7,IRON_FENCE,21)
RandomBlock(-9,12,-6,IRON_FENCE,21)
RandomBlock(-9,12,-5,IRON_FENCE,21)
RandomBlock(-9,12,-4,IRON_FENCE,21)
RandomBlock(-9,12,-3,IRON_FENCE,21)
RandomBlock(-9,12,-2,IRON_FENCE,21)
RandomBlock(-9,12,-1,IRON_FENCE,21)
RandomBlock(-9,12,0,IRON_FENCE,21)
RandomBlock(-9,12,1,IRON_FENCE,21)
RandomBlock(-9,12,2,IRON_FENCE,21)
RandomBlock(-9,12,3,IRON_FENCE,21)
RandomBlock(-9,12,4,IRON_FENCE,21)
RandomBlock(-9,12,5,IRON_FENCE,21)
RandomBlock(-9,12,6,IRON_FENCE,21)
RandomBlock(-9,12,7,IRON_FENCE,21)
RandomBlock(-9,12,8,IRON_FENCE,21)
RandomBlock(-9,12,9,IRON_FENCE,21)
RandomBlock(-9,12,10,IRON_FENCE,21)
RandomBlock(-9,12,11,IRON_FENCE,21)
RandomBlock(-9,12,12,IRON_FENCE,21)
RandomBlock(-9,13,-10,IRON_FENCE,21)
RandomBlock(-9,13,-9,IRON_FENCE,21)
RandomBlock(-9,13,-8,IRON_FENCE,21)
RandomBlock(-9,13,-7,IRON_FENCE,21)
RandomBlock(-9,13,-6,IRON_FENCE,21)
RandomBlock(-9,13,-5,IRON_FENCE,21)
RandomBlock(-9,13,-4,IRON_FENCE,21)
RandomBlock(-9,13,-3,IRON_FENCE,21)
RandomBlock(-9,13,-2,IRON_FENCE,21)
RandomBlock(-9,13,-1,IRON_FENCE,21)
RandomBlock(-9,13,0,IRON_FENCE,21)
RandomBlock(-9,13,1,IRON_FENCE,21)
RandomBlock(-9,13,2,IRON_FENCE,21)
RandomBlock(-9,13,3,IRON_FENCE,21)
RandomBlock(-9,13,4,IRON_FENCE,21)
RandomBlock(-9,13,5,IRON_FENCE,21)
RandomBlock(-9,13,6,IRON_FENCE,21)
RandomBlock(-9,13,7,IRON_FENCE,21)
RandomBlock(-9,13,8,IRON_FENCE,21)
RandomBlock(-9,13,9,IRON_FENCE,21)
RandomBlock(-9,13,10,IRON_FENCE,21)
RandomBlock(-9,13,11,IRON_FENCE,21)
RandomBlock(-9,13,12,IRON_FENCE,21)
RandomBlock(-9,14,-10,IRON_FENCE,21)
RandomBlock(-9,14,-9,IRON_FENCE,21)
RandomBlock(-9,14,-8,IRON_FENCE,21)
RandomBlock(-9,14,-7,IRON_FENCE,21)
RandomBlock(-9,14,-6,IRON_FENCE,21)
RandomBlock(-9,14,-5,IRON_FENCE,21)
RandomBlock(-9,14,-4,IRON_FENCE,21)
RandomBlock(-9,14,-3,IRON_FENCE,21)
RandomBlock(-9,14,-2,IRON_FENCE,21)
RandomBlock(-9,14,-1,IRON_FENCE,21)
RandomBlock(-9,14,0,IRON_FENCE,21)
RandomBlock(-9,14,1,IRON_FENCE,21)
RandomBlock(-9,14,2,IRON_FENCE,21)
RandomBlock(-9,14,3,IRON_FENCE,21)
RandomBlock(-9,14,4,IRON_FENCE,21)
RandomBlock(-9,14,5,IRON_FENCE,21)
RandomBlock(-9,14,6,IRON_FENCE,21)
RandomBlock(-9,14,7,IRON_FENCE,21)
RandomBlock(-9,14,8,IRON_FENCE,21)
RandomBlock(-9,14,9,IRON_FENCE,21)
RandomBlock(-9,14,10,IRON_FENCE,21)
RandomBlock(-9,14,11,IRON_FENCE,21)
RandomBlock(-9,14,12,IRON_FENCE,21)
RandomBlock(-9,15,-10,IRON_FENCE,21)
RandomBlock(-9,15,-9,IRON_FENCE,21)
RandomBlock(-9,15,-8,IRON_FENCE,21)
RandomBlock(-9,15,-7,IRON_FENCE,21)
RandomBlock(-9,15,-6,IRON_FENCE,21)
RandomBlock(-9,15,-5,IRON_FENCE,21)
RandomBlock(-9,15,-4,IRON_FENCE,21)
RandomBlock(-9,15,-3,IRON_FENCE,21)
RandomBlock(-9,15,-2,IRON_FENCE,21)
RandomBlock(-9,15,-1,IRON_FENCE,21)
RandomBlock(-9,15,0,IRON_FENCE,21)
RandomBlock(-9,15,1,IRON_FENCE,21)
RandomBlock(-9,15,2,IRON_FENCE,21)
RandomBlock(-9,15,3,IRON_FENCE,21)
RandomBlock(-9,15,4,IRON_FENCE,21)
RandomBlock(-9,15,5,IRON_FENCE,21)
RandomBlock(-9,15,6,IRON_FENCE,21)
RandomBlock(-9,15,7,IRON_FENCE,21)
RandomBlock(-9,15,8,IRON_FENCE,21)
RandomBlock(-9,15,9,IRON_FENCE,21)
RandomBlock(-9,15,10,IRON_FENCE,21)
RandomBlock(-9,15,11,IRON_FENCE,21)
RandomBlock(-9,15,12,IRON_FENCE,21)
RandomBlock(-9,16,-10,IRON_FENCE,21)
RandomBlock(-9,16,-9,IRON_FENCE,21)
RandomBlock(-9,16,-8,IRON_FENCE,21)
RandomBlock(-9,16,-7,IRON_FENCE,21)
RandomBlock(-9,16,-6,IRON_FENCE,21)
RandomBlock(-9,16,-5,IRON_FENCE,21)
RandomBlock(-9,16,-4,IRON_FENCE,21)
RandomBlock(-9,16,-3,IRON_FENCE,21)
RandomBlock(-9,16,-2,IRON_FENCE,21)
RandomBlock(-9,16,-1,IRON_FENCE,21)
RandomBlock(-9,16,0,IRON_FENCE,21)
RandomBlock(-9,16,1,IRON_FENCE,21)
RandomBlock(-9,16,2,IRON_FENCE,21)
RandomBlock(-9,16,3,IRON_FENCE,21)
RandomBlock(-9,16,4,IRON_FENCE,21)
RandomBlock(-9,16,5,IRON_FENCE,21)
RandomBlock(-9,16,6,IRON_FENCE,21)
RandomBlock(-9,16,7,IRON_FENCE,21)
RandomBlock(-9,16,8,IRON_FENCE,21)
RandomBlock(-9,16,9,IRON_FENCE,21)
RandomBlock(-9,16,10,IRON_FENCE,21)
RandomBlock(-9,16,11,IRON_FENCE,21)
RandomBlock(-9,16,12,IRON_FENCE,21)
RandomBlock(-9,17,-9,IRON_FENCE,21)
RandomBlock(-9,17,-8,IRON_FENCE,21)
RandomBlock(-9,17,-7,IRON_FENCE,21)
RandomBlock(-9,17,-6,IRON_FENCE,21)
RandomBlock(-9,17,-5,IRON_FENCE,21)
RandomBlock(-9,17,-4,IRON_FENCE,21)
RandomBlock(-9,17,-3,IRON_FENCE,21)
RandomBlock(-9,17,-2,IRON_FENCE,21)
RandomBlock(-9,17,-1,IRON_FENCE,21)
RandomBlock(-9,17,0,IRON_FENCE,21)
RandomBlock(-9,17,1,IRON_FENCE,21)
RandomBlock(-9,17,2,IRON_FENCE,21)
RandomBlock(-9,17,3,IRON_FENCE,21)
RandomBlock(-9,17,4,IRON_FENCE,21)
RandomBlock(-9,17,5,IRON_FENCE,21)
RandomBlock(-9,17,6,IRON_FENCE,21)
RandomBlock(-9,17,7,IRON_FENCE,21)
RandomBlock(-9,17,8,IRON_FENCE,21)
RandomBlock(-9,17,9,IRON_FENCE,21)
RandomBlock(-9,17,10,IRON_FENCE,21)
RandomBlock(-9,17,11,IRON_FENCE,21)
RandomBlock(-9,18,-9,IRON_FENCE,21)
RandomBlock(-9,18,-8,IRON_FENCE,21)
RandomBlock(-9,18,-7,IRON_FENCE,21)
RandomBlock(-9,18,-6,IRON_FENCE,21)
RandomBlock(-9,18,-5,IRON_FENCE,21)
RandomBlock(-9,18,-4,IRON_FENCE,21)
RandomBlock(-9,18,-3,IRON_FENCE,21)
RandomBlock(-9,18,-2,IRON_FENCE,21)
RandomBlock(-9,18,-1,IRON_FENCE,21)
RandomBlock(-9,18,0,IRON_FENCE,21)
RandomBlock(-9,18,1,IRON_FENCE,21)
RandomBlock(-9,18,2,IRON_FENCE,21)
RandomBlock(-9,18,3,IRON_FENCE,21)
RandomBlock(-9,18,4,IRON_FENCE,21)
RandomBlock(-9,18,5,IRON_FENCE,21)
RandomBlock(-9,18,6,IRON_FENCE,21)
RandomBlock(-9,18,7,IRON_FENCE,21)
RandomBlock(-9,18,8,IRON_FENCE,21)
RandomBlock(-9,18,9,IRON_FENCE,21)
RandomBlock(-9,18,10,IRON_FENCE,21)
RandomBlock(-9,18,11,IRON_FENCE,21)
RandomBlock(-9,19,-9,IRON_FENCE,21)
RandomBlock(-9,19,-8,IRON_FENCE,21)
RandomBlock(-9,19,-7,IRON_FENCE,21)
RandomBlock(-9,19,-6,IRON_FENCE,21)
RandomBlock(-9,19,-5,IRON_FENCE,21)
RandomBlock(-9,19,-4,IRON_FENCE,21)
RandomBlock(-9,19,-3,IRON_FENCE,21)
RandomBlock(-9,19,-2,IRON_FENCE,21)
RandomBlock(-9,19,-1,IRON_FENCE,21)
RandomBlock(-9,19,0,IRON_FENCE,21)
RandomBlock(-9,19,1,IRON_FENCE,21)
RandomBlock(-9,19,2,IRON_FENCE,21)
RandomBlock(-9,19,3,IRON_FENCE,21)
RandomBlock(-9,19,4,IRON_FENCE,21)
RandomBlock(-9,19,5,IRON_FENCE,21)
RandomBlock(-9,19,6,IRON_FENCE,21)
RandomBlock(-9,19,7,IRON_FENCE,21)
RandomBlock(-9,19,8,IRON_FENCE,21)
RandomBlock(-9,19,9,IRON_FENCE,21)
RandomBlock(-9,19,10,IRON_FENCE,21)
RandomBlock(-9,19,11,IRON_FENCE,21)
RandomBlock(-9,20,-8,IRON_FENCE,21)
RandomBlock(-9,20,-7,IRON_FENCE,21)
RandomBlock(-9,20,-6,IRON_FENCE,21)
RandomBlock(-9,20,-5,IRON_FENCE,21)
RandomBlock(-9,20,-4,IRON_FENCE,21)
RandomBlock(-9,20,-3,IRON_FENCE,21)
RandomBlock(-9,20,-2,IRON_FENCE,21)
RandomBlock(-9,20,-1,IRON_FENCE,21)
RandomBlock(-9,20,0,IRON_FENCE,21)
RandomBlock(-9,20,1,IRON_FENCE,21)
RandomBlock(-9,20,2,IRON_FENCE,21)
RandomBlock(-9,20,3,IRON_FENCE,21)
RandomBlock(-9,20,4,IRON_FENCE,21)
RandomBlock(-9,20,5,IRON_FENCE,21)
RandomBlock(-9,20,6,IRON_FENCE,21)
RandomBlock(-9,20,7,IRON_FENCE,21)
RandomBlock(-9,20,8,IRON_FENCE,21)
RandomBlock(-9,20,9,IRON_FENCE,21)
RandomBlock(-9,20,10,IRON_FENCE,21)
RandomBlock(-9,21,-7,IRON_FENCE,21)
RandomBlock(-9,21,-6,IRON_FENCE,21)
RandomBlock(-9,21,-5,IRON_FENCE,21)
RandomBlock(-9,21,-4,IRON_FENCE,21)
RandomBlock(-9,21,-3,IRON_FENCE,21)
RandomBlock(-9,21,-2,IRON_FENCE,21)
RandomBlock(-9,21,-1,IRON_FENCE,21)
RandomBlock(-9,21,0,IRON_FENCE,21)
RandomBlock(-9,21,1,IRON_FENCE,21)
RandomBlock(-9,21,2,IRON_FENCE,21)
RandomBlock(-9,21,3,IRON_FENCE,21)
RandomBlock(-9,21,4,IRON_FENCE,21)
RandomBlock(-9,21,5,IRON_FENCE,21)
RandomBlock(-9,21,6,IRON_FENCE,21)
RandomBlock(-9,21,7,IRON_FENCE,21)
RandomBlock(-9,21,8,IRON_FENCE,21)
RandomBlock(-9,21,9,IRON_FENCE,21)
RandomBlock(-9,22,-6,IRON_FENCE,21)
RandomBlock(-9,22,-5,IRON_FENCE,21)
RandomBlock(-9,22,-4,IRON_FENCE,21)
RandomBlock(-9,22,-3,IRON_FENCE,21)
RandomBlock(-9,22,-2,IRON_FENCE,21)
RandomBlock(-9,22,-1,IRON_FENCE,21)
RandomBlock(-9,22,0,IRON_FENCE,21)
RandomBlock(-9,22,1,IRON_FENCE,21)
RandomBlock(-9,22,2,IRON_FENCE,21)
RandomBlock(-9,22,3,IRON_FENCE,21)
RandomBlock(-9,22,4,IRON_FENCE,21)
RandomBlock(-9,22,5,IRON_FENCE,21)
RandomBlock(-9,22,6,IRON_FENCE,21)
RandomBlock(-9,22,7,IRON_FENCE,21)
RandomBlock(-9,22,8,IRON_FENCE,21)
RandomBlock(-9,23,-5,IRON_FENCE,21)
RandomBlock(-9,23,-4,IRON_FENCE,21)
RandomBlock(-9,23,-3,IRON_FENCE,21)
RandomBlock(-9,23,-2,IRON_FENCE,21)
RandomBlock(-9,23,-1,IRON_FENCE,21)
RandomBlock(-9,23,0,IRON_FENCE,21)
RandomBlock(-9,23,1,IRON_FENCE,21)
RandomBlock(-9,23,2,IRON_FENCE,21)
RandomBlock(-9,23,3,IRON_FENCE,21)
RandomBlock(-9,23,4,IRON_FENCE,21)
RandomBlock(-9,23,5,IRON_FENCE,21)
RandomBlock(-9,23,6,IRON_FENCE,21)
RandomBlock(-9,23,7,IRON_FENCE,21)
RandomBlock(-9,24,-4,IRON_FENCE,21)
RandomBlock(-9,24,-3,IRON_FENCE,21)
RandomBlock(-9,24,-2,IRON_FENCE,21)
RandomBlock(-9,24,-1,IRON_FENCE,21)
RandomBlock(-9,24,0,IRON_FENCE,21)
RandomBlock(-9,24,1,IRON_FENCE,21)
RandomBlock(-9,24,2,IRON_FENCE,21)
RandomBlock(-9,24,3,IRON_FENCE,21)
RandomBlock(-9,24,4,IRON_FENCE,21)
RandomBlock(-9,24,5,IRON_FENCE,21)
RandomBlock(-9,24,6,IRON_FENCE,21)
RandomBlock(-9,25,-1,IRON_FENCE,21)
RandomBlock(-9,25,0,IRON_FENCE,21)
RandomBlock(-9,25,1,IRON_FENCE,21)
RandomBlock(-9,25,2,IRON_FENCE,21)
RandomBlock(-9,25,3,IRON_FENCE,21)
RandomBlock(-8,2,1,IRON_FENCE,21)
RandomBlock(-8,3,-3,IRON_FENCE,21)
RandomBlock(-8,3,-2,IRON_FENCE,21)
RandomBlock(-8,3,-1,IRON_FENCE,21)
RandomBlock(-8,3,0,IRON_FENCE,21)
RandomBlock(-8,3,1,IRON_FENCE,21)
RandomBlock(-8,3,2,IRON_FENCE,21)
RandomBlock(-8,3,3,IRON_FENCE,21)
RandomBlock(-8,3,4,IRON_FENCE,21)
RandomBlock(-8,3,5,IRON_FENCE,21)
RandomBlock(-8,4,-5,IRON_FENCE,21)
RandomBlock(-8,4,-4,IRON_FENCE,21)
RandomBlock(-8,4,-3,IRON_FENCE,21)
RandomBlock(-8,4,-2,IRON_FENCE,21)
RandomBlock(-8,4,-1,IRON_FENCE,21)
RandomBlock(-8,4,0,IRON_FENCE,21)
RandomBlock(-8,4,1,IRON_FENCE,21)
RandomBlock(-8,4,2,IRON_FENCE,21)
RandomBlock(-8,4,3,IRON_FENCE,21)
RandomBlock(-8,4,4,IRON_FENCE,21)
RandomBlock(-8,4,5,IRON_FENCE,21)
RandomBlock(-8,4,6,IRON_FENCE,21)
RandomBlock(-8,4,7,IRON_FENCE,21)
RandomBlock(-8,5,-6,IRON_FENCE,21)
RandomBlock(-8,5,-5,IRON_FENCE,21)
RandomBlock(-8,5,-4,IRON_FENCE,21)
RandomBlock(-8,5,-3,IRON_FENCE,21)
RandomBlock(-8,5,-2,IRON_FENCE,21)
RandomBlock(-8,5,-1,IRON_FENCE,21)
RandomBlock(-8,5,0,IRON_FENCE,21)
RandomBlock(-8,5,1,IRON_FENCE,21)
RandomBlock(-8,5,2,IRON_FENCE,21)
RandomBlock(-8,5,3,IRON_FENCE,21)
RandomBlock(-8,5,4,IRON_FENCE,21)
RandomBlock(-8,5,5,IRON_FENCE,21)
RandomBlock(-8,5,6,IRON_FENCE,21)
RandomBlock(-8,5,7,IRON_FENCE,21)
RandomBlock(-8,5,8,IRON_FENCE,21)
RandomBlock(-8,6,-7,IRON_FENCE,21)
RandomBlock(-8,6,-6,IRON_FENCE,21)
RandomBlock(-8,6,-5,IRON_FENCE,21)
RandomBlock(-8,6,-4,IRON_FENCE,21)
RandomBlock(-8,6,-3,IRON_FENCE,21)
RandomBlock(-8,6,-2,IRON_FENCE,21)
RandomBlock(-8,6,-1,IRON_FENCE,21)
RandomBlock(-8,6,0,IRON_FENCE,21)
RandomBlock(-8,6,1,IRON_FENCE,21)
RandomBlock(-8,6,2,IRON_FENCE,21)
RandomBlock(-8,6,3,IRON_FENCE,21)
RandomBlock(-8,6,4,IRON_FENCE,21)
RandomBlock(-8,6,5,IRON_FENCE,21)
RandomBlock(-8,6,6,IRON_FENCE,21)
RandomBlock(-8,6,7,IRON_FENCE,21)
RandomBlock(-8,6,8,IRON_FENCE,21)
RandomBlock(-8,6,9,IRON_FENCE,21)
RandomBlock(-8,7,-8,IRON_FENCE,21)
RandomBlock(-8,7,-7,IRON_FENCE,21)
RandomBlock(-8,7,-6,IRON_FENCE,21)
RandomBlock(-8,7,-5,IRON_FENCE,21)
RandomBlock(-8,7,-4,IRON_FENCE,21)
RandomBlock(-8,7,-3,IRON_FENCE,21)
RandomBlock(-8,7,-2,IRON_FENCE,21)
RandomBlock(-8,7,-1,IRON_FENCE,21)
RandomBlock(-8,7,0,IRON_FENCE,21)
RandomBlock(-8,7,1,IRON_FENCE,21)
RandomBlock(-8,7,2,IRON_FENCE,21)
RandomBlock(-8,7,3,IRON_FENCE,21)
RandomBlock(-8,7,4,IRON_FENCE,21)
RandomBlock(-8,7,5,IRON_FENCE,21)
RandomBlock(-8,7,6,IRON_FENCE,21)
RandomBlock(-8,7,7,IRON_FENCE,21)
RandomBlock(-8,7,8,IRON_FENCE,21)
RandomBlock(-8,7,9,IRON_FENCE,21)
RandomBlock(-8,7,10,IRON_FENCE,21)
RandomBlock(-8,8,-9,IRON_FENCE,21)
RandomBlock(-8,8,-8,IRON_FENCE,21)
RandomBlock(-8,8,-7,IRON_FENCE,21)
RandomBlock(-8,8,-6,IRON_FENCE,21)
RandomBlock(-8,8,-5,IRON_FENCE,21)
RandomBlock(-8,8,-4,IRON_FENCE,21)
RandomBlock(-8,8,-3,IRON_FENCE,21)
RandomBlock(-8,8,-2,IRON_FENCE,21)
RandomBlock(-8,8,-1,IRON_FENCE,21)
RandomBlock(-8,8,0,IRON_FENCE,21)
RandomBlock(-8,8,1,IRON_FENCE,21)
RandomBlock(-8,8,2,IRON_FENCE,21)
RandomBlock(-8,8,3,IRON_FENCE,21)
RandomBlock(-8,8,4,IRON_FENCE,21)
RandomBlock(-8,8,5,IRON_FENCE,21)
RandomBlock(-8,8,6,IRON_FENCE,21)
RandomBlock(-8,8,7,IRON_FENCE,21)
RandomBlock(-8,8,8,IRON_FENCE,21)
RandomBlock(-8,8,9,IRON_FENCE,21)
RandomBlock(-8,8,10,IRON_FENCE,21)
RandomBlock(-8,8,11,IRON_FENCE,21)
RandomBlock(-8,9,-9,IRON_FENCE,21)
RandomBlock(-8,9,-8,IRON_FENCE,21)
RandomBlock(-8,9,-7,IRON_FENCE,21)
RandomBlock(-8,9,-6,IRON_FENCE,21)
RandomBlock(-8,9,-5,IRON_FENCE,21)
RandomBlock(-8,9,-4,IRON_FENCE,21)
RandomBlock(-8,9,-3,IRON_FENCE,21)
RandomBlock(-8,9,-2,IRON_FENCE,21)
RandomBlock(-8,9,-1,IRON_FENCE,21)
RandomBlock(-8,9,0,IRON_FENCE,21)
RandomBlock(-8,9,1,IRON_FENCE,21)
RandomBlock(-8,9,2,IRON_FENCE,21)
RandomBlock(-8,9,3,IRON_FENCE,21)
RandomBlock(-8,9,4,IRON_FENCE,21)
RandomBlock(-8,9,5,IRON_FENCE,21)
RandomBlock(-8,9,6,IRON_FENCE,21)
RandomBlock(-8,9,7,IRON_FENCE,21)
RandomBlock(-8,9,8,IRON_FENCE,21)
RandomBlock(-8,9,9,IRON_FENCE,21)
RandomBlock(-8,9,10,IRON_FENCE,21)
RandomBlock(-8,9,11,IRON_FENCE,21)
RandomBlock(-8,10,-10,IRON_FENCE,21)
RandomBlock(-8,10,-9,IRON_FENCE,21)
RandomBlock(-8,10,-8,IRON_FENCE,21)
RandomBlock(-8,10,-7,IRON_FENCE,21)
RandomBlock(-8,10,-6,IRON_FENCE,21)
RandomBlock(-8,10,-5,IRON_FENCE,21)
RandomBlock(-8,10,-4,IRON_FENCE,21)
RandomBlock(-8,10,-3,IRON_FENCE,21)
RandomBlock(-8,10,-2,IRON_FENCE,21)
RandomBlock(-8,10,-1,IRON_FENCE,21)
RandomBlock(-8,10,0,IRON_FENCE,21)
RandomBlock(-8,10,1,IRON_FENCE,21)
RandomBlock(-8,10,2,IRON_FENCE,21)
RandomBlock(-8,10,3,IRON_FENCE,21)
RandomBlock(-8,10,4,IRON_FENCE,21)
RandomBlock(-8,10,5,IRON_FENCE,21)
RandomBlock(-8,10,6,IRON_FENCE,21)
RandomBlock(-8,10,7,IRON_FENCE,21)
RandomBlock(-8,10,8,IRON_FENCE,21)
RandomBlock(-8,10,9,IRON_FENCE,21)
RandomBlock(-8,10,10,IRON_FENCE,21)
RandomBlock(-8,10,11,IRON_FENCE,21)
RandomBlock(-8,10,12,IRON_FENCE,21)
RandomBlock(-8,11,-10,IRON_FENCE,21)
RandomBlock(-8,11,-9,IRON_FENCE,21)
RandomBlock(-8,11,-8,IRON_FENCE,21)
RandomBlock(-8,11,-7,IRON_FENCE,21)
RandomBlock(-8,11,-6,IRON_FENCE,21)
RandomBlock(-8,11,-5,IRON_FENCE,21)
RandomBlock(-8,11,-4,IRON_FENCE,21)
RandomBlock(-8,11,-3,IRON_FENCE,21)
RandomBlock(-8,11,-2,IRON_FENCE,21)
RandomBlock(-8,11,-1,IRON_FENCE,21)
RandomBlock(-8,11,0,IRON_FENCE,21)
RandomBlock(-8,11,1,IRON_FENCE,21)
RandomBlock(-8,11,2,IRON_FENCE,21)
RandomBlock(-8,11,3,IRON_FENCE,21)
RandomBlock(-8,11,4,IRON_FENCE,21)
RandomBlock(-8,11,5,IRON_FENCE,21)
RandomBlock(-8,11,6,IRON_FENCE,21)
RandomBlock(-8,11,7,IRON_FENCE,21)
RandomBlock(-8,11,8,IRON_FENCE,21)
RandomBlock(-8,11,9,IRON_FENCE,21)
RandomBlock(-8,11,10,IRON_FENCE,21)
RandomBlock(-8,11,11,IRON_FENCE,21)
RandomBlock(-8,11,12,IRON_FENCE,21)
RandomBlock(-8,12,-10,IRON_FENCE,21)
RandomBlock(-8,12,-9,IRON_FENCE,21)
RandomBlock(-8,12,-8,IRON_FENCE,21)
RandomBlock(-8,12,-7,IRON_FENCE,21)
RandomBlock(-8,12,-6,IRON_FENCE,21)
RandomBlock(-8,12,-5,IRON_FENCE,21)
RandomBlock(-8,12,-4,IRON_FENCE,21)
RandomBlock(-8,12,-3,IRON_FENCE,21)
RandomBlock(-8,12,-2,IRON_FENCE,21)
RandomBlock(-8,12,-1,IRON_FENCE,21)
RandomBlock(-8,12,0,IRON_FENCE,21)
RandomBlock(-8,12,1,IRON_FENCE,21)
RandomBlock(-8,12,2,IRON_FENCE,21)
RandomBlock(-8,12,3,IRON_FENCE,21)
RandomBlock(-8,12,4,IRON_FENCE,21)
RandomBlock(-8,12,5,IRON_FENCE,21)
RandomBlock(-8,12,6,IRON_FENCE,21)
RandomBlock(-8,12,7,IRON_FENCE,21)
RandomBlock(-8,12,8,IRON_FENCE,21)
RandomBlock(-8,12,9,IRON_FENCE,21)
RandomBlock(-8,12,10,IRON_FENCE,21)
RandomBlock(-8,12,11,IRON_FENCE,21)
RandomBlock(-8,12,12,IRON_FENCE,21)
RandomBlock(-8,13,-10,IRON_FENCE,21)
RandomBlock(-8,13,-9,IRON_FENCE,21)
RandomBlock(-8,13,-8,IRON_FENCE,21)
RandomBlock(-8,13,-7,IRON_FENCE,21)
RandomBlock(-8,13,-6,IRON_FENCE,21)
RandomBlock(-8,13,-5,IRON_FENCE,21)
RandomBlock(-8,13,-4,IRON_FENCE,21)
RandomBlock(-8,13,-3,IRON_FENCE,21)
RandomBlock(-8,13,-2,IRON_FENCE,21)
RandomBlock(-8,13,-1,IRON_FENCE,21)
RandomBlock(-8,13,0,IRON_FENCE,21)
RandomBlock(-8,13,1,IRON_FENCE,21)
RandomBlock(-8,13,2,IRON_FENCE,21)
RandomBlock(-8,13,3,IRON_FENCE,21)
RandomBlock(-8,13,4,IRON_FENCE,21)
RandomBlock(-8,13,5,IRON_FENCE,21)
RandomBlock(-8,13,6,IRON_FENCE,21)
RandomBlock(-8,13,7,IRON_FENCE,21)
RandomBlock(-8,13,8,IRON_FENCE,21)
RandomBlock(-8,13,9,IRON_FENCE,21)
RandomBlock(-8,13,10,IRON_FENCE,21)
RandomBlock(-8,13,11,IRON_FENCE,21)
RandomBlock(-8,13,12,IRON_FENCE,21)
RandomBlock(-8,14,-11,IRON_FENCE,21)
RandomBlock(-8,14,-10,IRON_FENCE,21)
RandomBlock(-8,14,-9,IRON_FENCE,21)
RandomBlock(-8,14,-8,IRON_FENCE,21)
RandomBlock(-8,14,-7,IRON_FENCE,21)
RandomBlock(-8,14,-6,IRON_FENCE,21)
RandomBlock(-8,14,-5,IRON_FENCE,21)
RandomBlock(-8,14,-4,IRON_FENCE,21)
RandomBlock(-8,14,-3,IRON_FENCE,21)
RandomBlock(-8,14,-2,IRON_FENCE,21)
RandomBlock(-8,14,-1,IRON_FENCE,21)
RandomBlock(-8,14,0,IRON_FENCE,21)
RandomBlock(-8,14,1,IRON_FENCE,21)
RandomBlock(-8,14,2,IRON_FENCE,21)
RandomBlock(-8,14,3,IRON_FENCE,21)
RandomBlock(-8,14,4,IRON_FENCE,21)
RandomBlock(-8,14,5,IRON_FENCE,21)
RandomBlock(-8,14,6,IRON_FENCE,21)
RandomBlock(-8,14,7,IRON_FENCE,21)
RandomBlock(-8,14,8,IRON_FENCE,21)
RandomBlock(-8,14,9,IRON_FENCE,21)
RandomBlock(-8,14,10,IRON_FENCE,21)
RandomBlock(-8,14,11,IRON_FENCE,21)
RandomBlock(-8,14,12,IRON_FENCE,21)
RandomBlock(-8,14,13,IRON_FENCE,21)
RandomBlock(-8,15,-10,IRON_FENCE,21)
RandomBlock(-8,15,-9,IRON_FENCE,21)
RandomBlock(-8,15,-8,IRON_FENCE,21)
RandomBlock(-8,15,-7,IRON_FENCE,21)
RandomBlock(-8,15,-6,IRON_FENCE,21)
RandomBlock(-8,15,-5,IRON_FENCE,21)
RandomBlock(-8,15,-4,IRON_FENCE,21)
RandomBlock(-8,15,-3,IRON_FENCE,21)
RandomBlock(-8,15,-2,IRON_FENCE,21)
RandomBlock(-8,15,-1,IRON_FENCE,21)
RandomBlock(-8,15,0,IRON_FENCE,21)
RandomBlock(-8,15,1,IRON_FENCE,21)
RandomBlock(-8,15,2,IRON_FENCE,21)
RandomBlock(-8,15,3,IRON_FENCE,21)
RandomBlock(-8,15,4,IRON_FENCE,21)
RandomBlock(-8,15,5,IRON_FENCE,21)
RandomBlock(-8,15,6,IRON_FENCE,21)
RandomBlock(-8,15,7,IRON_FENCE,21)
RandomBlock(-8,15,8,IRON_FENCE,21)
RandomBlock(-8,15,9,IRON_FENCE,21)
RandomBlock(-8,15,10,IRON_FENCE,21)
RandomBlock(-8,15,11,IRON_FENCE,21)
RandomBlock(-8,15,12,IRON_FENCE,21)
RandomBlock(-8,16,-10,IRON_FENCE,21)
RandomBlock(-8,16,-9,IRON_FENCE,21)
RandomBlock(-8,16,-8,IRON_FENCE,21)
RandomBlock(-8,16,-7,IRON_FENCE,21)
RandomBlock(-8,16,-6,IRON_FENCE,21)
RandomBlock(-8,16,-5,IRON_FENCE,21)
RandomBlock(-8,16,-4,IRON_FENCE,21)
RandomBlock(-8,16,-3,IRON_FENCE,21)
RandomBlock(-8,16,-2,IRON_FENCE,21)
RandomBlock(-8,16,-1,IRON_FENCE,21)
RandomBlock(-8,16,0,IRON_FENCE,21)
RandomBlock(-8,16,1,IRON_FENCE,21)
RandomBlock(-8,16,2,IRON_FENCE,21)
RandomBlock(-8,16,3,IRON_FENCE,21)
RandomBlock(-8,16,4,IRON_FENCE,21)
RandomBlock(-8,16,5,IRON_FENCE,21)
RandomBlock(-8,16,6,IRON_FENCE,21)
RandomBlock(-8,16,7,IRON_FENCE,21)
RandomBlock(-8,16,8,IRON_FENCE,21)
RandomBlock(-8,16,9,IRON_FENCE,21)
RandomBlock(-8,16,10,IRON_FENCE,21)
RandomBlock(-8,16,11,IRON_FENCE,21)
RandomBlock(-8,16,12,IRON_FENCE,21)
RandomBlock(-8,17,-10,IRON_FENCE,21)
RandomBlock(-8,17,-9,IRON_FENCE,21)
RandomBlock(-8,17,-8,IRON_FENCE,21)
RandomBlock(-8,17,-7,IRON_FENCE,21)
RandomBlock(-8,17,-6,IRON_FENCE,21)
RandomBlock(-8,17,-5,IRON_FENCE,21)
RandomBlock(-8,17,-4,IRON_FENCE,21)
RandomBlock(-8,17,-3,IRON_FENCE,21)
RandomBlock(-8,17,-2,IRON_FENCE,21)
RandomBlock(-8,17,-1,IRON_FENCE,21)
RandomBlock(-8,17,0,IRON_FENCE,21)
RandomBlock(-8,17,1,IRON_FENCE,21)
RandomBlock(-8,17,2,IRON_FENCE,21)
RandomBlock(-8,17,3,IRON_FENCE,21)
RandomBlock(-8,17,4,IRON_FENCE,21)
RandomBlock(-8,17,5,IRON_FENCE,21)
RandomBlock(-8,17,6,IRON_FENCE,21)
RandomBlock(-8,17,7,IRON_FENCE,21)
RandomBlock(-8,17,8,IRON_FENCE,21)
RandomBlock(-8,17,9,IRON_FENCE,21)
RandomBlock(-8,17,10,IRON_FENCE,21)
RandomBlock(-8,17,11,IRON_FENCE,21)
RandomBlock(-8,17,12,IRON_FENCE,21)
RandomBlock(-8,18,-10,IRON_FENCE,21)
RandomBlock(-8,18,-9,IRON_FENCE,21)
RandomBlock(-8,18,-8,IRON_FENCE,21)
RandomBlock(-8,18,-7,IRON_FENCE,21)
RandomBlock(-8,18,-6,IRON_FENCE,21)
RandomBlock(-8,18,-5,IRON_FENCE,21)
RandomBlock(-8,18,-4,IRON_FENCE,21)
RandomBlock(-8,18,-3,IRON_FENCE,21)
RandomBlock(-8,18,-2,IRON_FENCE,21)
RandomBlock(-8,18,-1,IRON_FENCE,21)
RandomBlock(-8,18,0,IRON_FENCE,21)
RandomBlock(-8,18,1,IRON_FENCE,21)
RandomBlock(-8,18,2,IRON_FENCE,21)
RandomBlock(-8,18,3,IRON_FENCE,21)
RandomBlock(-8,18,4,IRON_FENCE,21)
RandomBlock(-8,18,5,IRON_FENCE,21)
RandomBlock(-8,18,6,IRON_FENCE,21)
RandomBlock(-8,18,7,IRON_FENCE,21)
RandomBlock(-8,18,8,IRON_FENCE,21)
RandomBlock(-8,18,9,IRON_FENCE,21)
RandomBlock(-8,18,10,IRON_FENCE,21)
RandomBlock(-8,18,11,IRON_FENCE,21)
RandomBlock(-8,18,12,IRON_FENCE,21)
RandomBlock(-8,19,-9,IRON_FENCE,21)
RandomBlock(-8,19,-8,IRON_FENCE,21)
RandomBlock(-8,19,-7,IRON_FENCE,21)
RandomBlock(-8,19,-6,IRON_FENCE,21)
RandomBlock(-8,19,-5,IRON_FENCE,21)
RandomBlock(-8,19,-4,IRON_FENCE,21)
RandomBlock(-8,19,-3,IRON_FENCE,21)
RandomBlock(-8,19,-2,IRON_FENCE,21)
RandomBlock(-8,19,-1,IRON_FENCE,21)
RandomBlock(-8,19,0,IRON_FENCE,21)
RandomBlock(-8,19,1,IRON_FENCE,21)
RandomBlock(-8,19,2,IRON_FENCE,21)
RandomBlock(-8,19,3,IRON_FENCE,21)
RandomBlock(-8,19,4,IRON_FENCE,21)
RandomBlock(-8,19,5,IRON_FENCE,21)
RandomBlock(-8,19,6,IRON_FENCE,21)
RandomBlock(-8,19,7,IRON_FENCE,21)
RandomBlock(-8,19,8,IRON_FENCE,21)
RandomBlock(-8,19,9,IRON_FENCE,21)
RandomBlock(-8,19,10,IRON_FENCE,21)
RandomBlock(-8,19,11,IRON_FENCE,21)
RandomBlock(-8,20,-9,IRON_FENCE,21)
RandomBlock(-8,20,-8,IRON_FENCE,21)
RandomBlock(-8,20,-7,IRON_FENCE,21)
RandomBlock(-8,20,-6,IRON_FENCE,21)
RandomBlock(-8,20,-5,IRON_FENCE,21)
RandomBlock(-8,20,-4,IRON_FENCE,21)
RandomBlock(-8,20,-3,IRON_FENCE,21)
RandomBlock(-8,20,-2,IRON_FENCE,21)
RandomBlock(-8,20,-1,IRON_FENCE,21)
RandomBlock(-8,20,0,IRON_FENCE,21)
RandomBlock(-8,20,1,IRON_FENCE,21)
RandomBlock(-8,20,2,IRON_FENCE,21)
RandomBlock(-8,20,3,IRON_FENCE,21)
RandomBlock(-8,20,4,IRON_FENCE,21)
RandomBlock(-8,20,5,IRON_FENCE,21)
RandomBlock(-8,20,6,IRON_FENCE,21)
RandomBlock(-8,20,7,IRON_FENCE,21)
RandomBlock(-8,20,8,IRON_FENCE,21)
RandomBlock(-8,20,9,IRON_FENCE,21)
RandomBlock(-8,20,10,IRON_FENCE,21)
RandomBlock(-8,20,11,IRON_FENCE,21)
RandomBlock(-8,21,-8,IRON_FENCE,21)
RandomBlock(-8,21,-7,IRON_FENCE,21)
RandomBlock(-8,21,-6,IRON_FENCE,21)
RandomBlock(-8,21,-5,IRON_FENCE,21)
RandomBlock(-8,21,-4,IRON_FENCE,21)
RandomBlock(-8,21,-3,IRON_FENCE,21)
RandomBlock(-8,21,-2,IRON_FENCE,21)
RandomBlock(-8,21,-1,IRON_FENCE,21)
RandomBlock(-8,21,0,IRON_FENCE,21)
RandomBlock(-8,21,1,IRON_FENCE,21)
RandomBlock(-8,21,2,IRON_FENCE,21)
RandomBlock(-8,21,3,IRON_FENCE,21)
RandomBlock(-8,21,4,IRON_FENCE,21)
RandomBlock(-8,21,5,IRON_FENCE,21)
RandomBlock(-8,21,6,IRON_FENCE,21)
RandomBlock(-8,21,7,IRON_FENCE,21)
RandomBlock(-8,21,8,IRON_FENCE,21)
RandomBlock(-8,21,9,IRON_FENCE,21)
RandomBlock(-8,21,10,IRON_FENCE,21)
RandomBlock(-8,22,-7,IRON_FENCE,21)
RandomBlock(-8,22,-6,IRON_FENCE,21)
RandomBlock(-8,22,-5,IRON_FENCE,21)
RandomBlock(-8,22,-4,IRON_FENCE,21)
RandomBlock(-8,22,-3,IRON_FENCE,21)
RandomBlock(-8,22,-2,IRON_FENCE,21)
RandomBlock(-8,22,-1,IRON_FENCE,21)
RandomBlock(-8,22,0,IRON_FENCE,21)
RandomBlock(-8,22,1,IRON_FENCE,21)
RandomBlock(-8,22,2,IRON_FENCE,21)
RandomBlock(-8,22,3,IRON_FENCE,21)
RandomBlock(-8,22,4,IRON_FENCE,21)
RandomBlock(-8,22,5,IRON_FENCE,21)
RandomBlock(-8,22,6,IRON_FENCE,21)
RandomBlock(-8,22,7,IRON_FENCE,21)
RandomBlock(-8,22,8,IRON_FENCE,21)
RandomBlock(-8,22,9,IRON_FENCE,21)
RandomBlock(-8,23,-6,IRON_FENCE,21)
RandomBlock(-8,23,-5,IRON_FENCE,21)
RandomBlock(-8,23,-4,IRON_FENCE,21)
RandomBlock(-8,23,-3,IRON_FENCE,21)
RandomBlock(-8,23,-2,IRON_FENCE,21)
RandomBlock(-8,23,-1,IRON_FENCE,21)
RandomBlock(-8,23,0,IRON_FENCE,21)
RandomBlock(-8,23,1,IRON_FENCE,21)
RandomBlock(-8,23,2,IRON_FENCE,21)
RandomBlock(-8,23,3,IRON_FENCE,21)
RandomBlock(-8,23,4,IRON_FENCE,21)
RandomBlock(-8,23,5,IRON_FENCE,21)
RandomBlock(-8,23,6,IRON_FENCE,21)
RandomBlock(-8,23,7,IRON_FENCE,21)
RandomBlock(-8,23,8,IRON_FENCE,21)
RandomBlock(-8,24,-5,IRON_FENCE,21)
RandomBlock(-8,24,-4,IRON_FENCE,21)
RandomBlock(-8,24,-3,IRON_FENCE,21)
RandomBlock(-8,24,-2,IRON_FENCE,21)
RandomBlock(-8,24,-1,IRON_FENCE,21)
RandomBlock(-8,24,0,IRON_FENCE,21)
RandomBlock(-8,24,1,IRON_FENCE,21)
RandomBlock(-8,24,2,IRON_FENCE,21)
RandomBlock(-8,24,3,IRON_FENCE,21)
RandomBlock(-8,24,4,IRON_FENCE,21)
RandomBlock(-8,24,5,IRON_FENCE,21)
RandomBlock(-8,24,6,IRON_FENCE,21)
RandomBlock(-8,24,7,IRON_FENCE,21)
RandomBlock(-8,25,-3,IRON_FENCE,21)
RandomBlock(-8,25,-2,IRON_FENCE,21)
RandomBlock(-8,25,-1,IRON_FENCE,21)
RandomBlock(-8,25,0,IRON_FENCE,21)
RandomBlock(-8,25,1,IRON_FENCE,21)
RandomBlock(-8,25,2,IRON_FENCE,21)
RandomBlock(-8,25,3,IRON_FENCE,21)
RandomBlock(-8,25,4,IRON_FENCE,21)
RandomBlock(-8,25,5,IRON_FENCE,21)
RandomBlock(-8,26,1,IRON_FENCE,21)
RandomBlock(-7,2,-3,IRON_FENCE,21)
RandomBlock(-7,2,-2,IRON_FENCE,21)
RandomBlock(-7,2,-1,IRON_FENCE,21)
RandomBlock(-7,2,0,IRON_FENCE,21)
RandomBlock(-7,2,1,IRON_FENCE,21)
RandomBlock(-7,2,2,IRON_FENCE,21)
RandomBlock(-7,2,3,IRON_FENCE,21)
RandomBlock(-7,2,4,IRON_FENCE,21)
RandomBlock(-7,2,5,IRON_FENCE,21)
RandomBlock(-7,3,-5,IRON_FENCE,21)
RandomBlock(-7,3,-4,IRON_FENCE,21)
RandomBlock(-7,3,-3,IRON_FENCE,21)
RandomBlock(-7,3,-2,IRON_FENCE,21)
RandomBlock(-7,3,-1,IRON_FENCE,21)
RandomBlock(-7,3,0,IRON_FENCE,21)
RandomBlock(-7,3,1,IRON_FENCE,21)
RandomBlock(-7,3,2,IRON_FENCE,21)
RandomBlock(-7,3,3,IRON_FENCE,21)
RandomBlock(-7,3,4,IRON_FENCE,21)
RandomBlock(-7,3,5,IRON_FENCE,21)
RandomBlock(-7,3,6,IRON_FENCE,21)
RandomBlock(-7,3,7,IRON_FENCE,21)
RandomBlock(-7,4,-6,IRON_FENCE,21)
RandomBlock(-7,4,-5,IRON_FENCE,21)
RandomBlock(-7,4,-4,IRON_FENCE,21)
RandomBlock(-7,4,-3,IRON_FENCE,21)
RandomBlock(-7,4,-2,IRON_FENCE,21)
RandomBlock(-7,4,-1,IRON_FENCE,21)
RandomBlock(-7,4,0,IRON_FENCE,21)
RandomBlock(-7,4,1,IRON_FENCE,21)
RandomBlock(-7,4,2,IRON_FENCE,21)
RandomBlock(-7,4,3,IRON_FENCE,21)
RandomBlock(-7,4,4,IRON_FENCE,21)
RandomBlock(-7,4,5,IRON_FENCE,21)
RandomBlock(-7,4,6,IRON_FENCE,21)
RandomBlock(-7,4,7,IRON_FENCE,21)
RandomBlock(-7,4,8,IRON_FENCE,21)
RandomBlock(-7,5,-7,IRON_FENCE,21)
RandomBlock(-7,5,-6,IRON_FENCE,21)
RandomBlock(-7,5,-5,IRON_FENCE,21)
RandomBlock(-7,5,-4,IRON_FENCE,21)
RandomBlock(-7,5,-3,IRON_FENCE,21)
RandomBlock(-7,5,-2,IRON_FENCE,21)
RandomBlock(-7,5,-1,IRON_FENCE,21)
RandomBlock(-7,5,0,IRON_FENCE,21)
RandomBlock(-7,5,1,IRON_FENCE,21)
RandomBlock(-7,5,2,IRON_FENCE,21)
RandomBlock(-7,5,3,IRON_FENCE,21)
RandomBlock(-7,5,4,IRON_FENCE,21)
RandomBlock(-7,5,5,IRON_FENCE,21)
RandomBlock(-7,5,6,IRON_FENCE,21)
RandomBlock(-7,5,7,IRON_FENCE,21)
RandomBlock(-7,5,8,IRON_FENCE,21)
RandomBlock(-7,5,9,IRON_FENCE,21)
RandomBlock(-7,6,-8,IRON_FENCE,21)
RandomBlock(-7,6,-7,IRON_FENCE,21)
RandomBlock(-7,6,-6,IRON_FENCE,21)
RandomBlock(-7,6,-5,IRON_FENCE,21)
RandomBlock(-7,6,-4,IRON_FENCE,21)
RandomBlock(-7,6,-3,IRON_FENCE,21)
RandomBlock(-7,6,-2,IRON_FENCE,21)
RandomBlock(-7,6,-1,IRON_FENCE,21)
RandomBlock(-7,6,0,IRON_FENCE,21)
RandomBlock(-7,6,1,IRON_FENCE,21)
RandomBlock(-7,6,2,IRON_FENCE,21)
RandomBlock(-7,6,3,IRON_FENCE,21)
RandomBlock(-7,6,4,IRON_FENCE,21)
RandomBlock(-7,6,5,IRON_FENCE,21)
RandomBlock(-7,6,6,IRON_FENCE,21)
RandomBlock(-7,6,7,IRON_FENCE,21)
RandomBlock(-7,6,8,IRON_FENCE,21)
RandomBlock(-7,6,9,IRON_FENCE,21)
RandomBlock(-7,6,10,IRON_FENCE,21)
RandomBlock(-7,7,-9,IRON_FENCE,21)
RandomBlock(-7,7,-8,IRON_FENCE,21)
RandomBlock(-7,7,-7,IRON_FENCE,21)
RandomBlock(-7,7,-6,IRON_FENCE,21)
RandomBlock(-7,7,-5,IRON_FENCE,21)
RandomBlock(-7,7,-4,IRON_FENCE,21)
RandomBlock(-7,7,-3,IRON_FENCE,21)
RandomBlock(-7,7,-2,IRON_FENCE,21)
RandomBlock(-7,7,-1,IRON_FENCE,21)
RandomBlock(-7,7,0,IRON_FENCE,21)
RandomBlock(-7,7,1,IRON_FENCE,21)
RandomBlock(-7,7,2,IRON_FENCE,21)
RandomBlock(-7,7,3,IRON_FENCE,21)
RandomBlock(-7,7,4,IRON_FENCE,21)
RandomBlock(-7,7,5,IRON_FENCE,21)
RandomBlock(-7,7,6,IRON_FENCE,21)
RandomBlock(-7,7,7,IRON_FENCE,21)
RandomBlock(-7,7,8,IRON_FENCE,21)
RandomBlock(-7,7,9,IRON_FENCE,21)
RandomBlock(-7,7,10,IRON_FENCE,21)
RandomBlock(-7,7,11,IRON_FENCE,21)
RandomBlock(-7,8,-10,IRON_FENCE,21)
RandomBlock(-7,8,-9,IRON_FENCE,21)
RandomBlock(-7,8,-8,IRON_FENCE,21)
RandomBlock(-7,8,-7,IRON_FENCE,21)
RandomBlock(-7,8,-6,IRON_FENCE,21)
RandomBlock(-7,8,-5,IRON_FENCE,21)
RandomBlock(-7,8,-4,IRON_FENCE,21)
RandomBlock(-7,8,-3,IRON_FENCE,21)
RandomBlock(-7,8,-2,IRON_FENCE,21)
RandomBlock(-7,8,-1,IRON_FENCE,21)
RandomBlock(-7,8,0,IRON_FENCE,21)
RandomBlock(-7,8,1,IRON_FENCE,21)
RandomBlock(-7,8,2,IRON_FENCE,21)
RandomBlock(-7,8,3,IRON_FENCE,21)
RandomBlock(-7,8,4,IRON_FENCE,21)
RandomBlock(-7,8,5,IRON_FENCE,21)
RandomBlock(-7,8,6,IRON_FENCE,21)
RandomBlock(-7,8,7,IRON_FENCE,21)
RandomBlock(-7,8,8,IRON_FENCE,21)
RandomBlock(-7,8,9,IRON_FENCE,21)
RandomBlock(-7,8,10,IRON_FENCE,21)
RandomBlock(-7,8,11,IRON_FENCE,21)
RandomBlock(-7,8,12,IRON_FENCE,21)
RandomBlock(-7,9,-10,IRON_FENCE,21)
RandomBlock(-7,9,-9,IRON_FENCE,21)
RandomBlock(-7,9,-8,IRON_FENCE,21)
RandomBlock(-7,9,-7,IRON_FENCE,21)
RandomBlock(-7,9,-6,IRON_FENCE,21)
RandomBlock(-7,9,-5,IRON_FENCE,21)
RandomBlock(-7,9,-4,IRON_FENCE,21)
RandomBlock(-7,9,-3,IRON_FENCE,21)
RandomBlock(-7,9,-2,IRON_FENCE,21)
RandomBlock(-7,9,-1,IRON_FENCE,21)
RandomBlock(-7,9,0,IRON_FENCE,21)
RandomBlock(-7,9,1,IRON_FENCE,21)
RandomBlock(-7,9,2,IRON_FENCE,21)
RandomBlock(-7,9,3,IRON_FENCE,21)
RandomBlock(-7,9,4,IRON_FENCE,21)
RandomBlock(-7,9,5,IRON_FENCE,21)
RandomBlock(-7,9,6,IRON_FENCE,21)
RandomBlock(-7,9,7,IRON_FENCE,21)
RandomBlock(-7,9,8,IRON_FENCE,21)
RandomBlock(-7,9,9,IRON_FENCE,21)
RandomBlock(-7,9,10,IRON_FENCE,21)
RandomBlock(-7,9,11,IRON_FENCE,21)
RandomBlock(-7,9,12,IRON_FENCE,21)
RandomBlock(-7,10,-11,IRON_FENCE,21)
RandomBlock(-7,10,-10,IRON_FENCE,21)
RandomBlock(-7,10,-9,IRON_FENCE,21)
RandomBlock(-7,10,-8,IRON_FENCE,21)
RandomBlock(-7,10,-7,IRON_FENCE,21)
RandomBlock(-7,10,-6,IRON_FENCE,21)
RandomBlock(-7,10,-5,IRON_FENCE,21)
RandomBlock(-7,10,-4,IRON_FENCE,21)
RandomBlock(-7,10,-3,IRON_FENCE,21)
RandomBlock(-7,10,-2,IRON_FENCE,21)
RandomBlock(-7,10,-1,IRON_FENCE,21)
RandomBlock(-7,10,0,IRON_FENCE,21)
RandomBlock(-7,10,1,IRON_FENCE,21)
RandomBlock(-7,10,2,IRON_FENCE,21)
RandomBlock(-7,10,3,IRON_FENCE,21)
RandomBlock(-7,10,4,IRON_FENCE,21)
RandomBlock(-7,10,5,IRON_FENCE,21)
RandomBlock(-7,10,6,IRON_FENCE,21)
RandomBlock(-7,10,7,IRON_FENCE,21)
RandomBlock(-7,10,8,IRON_FENCE,21)
RandomBlock(-7,10,9,IRON_FENCE,21)
RandomBlock(-7,10,10,IRON_FENCE,21)
RandomBlock(-7,10,11,IRON_FENCE,21)
RandomBlock(-7,10,12,IRON_FENCE,21)
RandomBlock(-7,10,13,IRON_FENCE,21)
RandomBlock(-7,11,-11,IRON_FENCE,21)
RandomBlock(-7,11,-10,IRON_FENCE,21)
RandomBlock(-7,11,-9,IRON_FENCE,21)
RandomBlock(-7,11,-8,IRON_FENCE,21)
RandomBlock(-7,11,-7,IRON_FENCE,21)
RandomBlock(-7,11,-6,IRON_FENCE,21)
RandomBlock(-7,11,-5,IRON_FENCE,21)
RandomBlock(-7,11,-4,IRON_FENCE,21)
RandomBlock(-7,11,-3,IRON_FENCE,21)
RandomBlock(-7,11,-2,IRON_FENCE,21)
RandomBlock(-7,11,-1,IRON_FENCE,21)
RandomBlock(-7,11,0,IRON_FENCE,21)
RandomBlock(-7,11,1,IRON_FENCE,21)
RandomBlock(-7,11,2,IRON_FENCE,21)
RandomBlock(-7,11,3,IRON_FENCE,21)
RandomBlock(-7,11,4,IRON_FENCE,21)
RandomBlock(-7,11,5,IRON_FENCE,21)
RandomBlock(-7,11,6,IRON_FENCE,21)
RandomBlock(-7,11,7,IRON_FENCE,21)
RandomBlock(-7,11,8,IRON_FENCE,21)
RandomBlock(-7,11,9,IRON_FENCE,21)
RandomBlock(-7,11,10,IRON_FENCE,21)
RandomBlock(-7,11,11,IRON_FENCE,21)
RandomBlock(-7,11,12,IRON_FENCE,21)
RandomBlock(-7,11,13,IRON_FENCE,21)
RandomBlock(-7,12,-11,IRON_FENCE,21)
RandomBlock(-7,12,-10,IRON_FENCE,21)
RandomBlock(-7,12,-9,IRON_FENCE,21)
RandomBlock(-7,12,-8,IRON_FENCE,21)
RandomBlock(-7,12,-7,IRON_FENCE,21)
RandomBlock(-7,12,-6,IRON_FENCE,21)
RandomBlock(-7,12,-5,IRON_FENCE,21)
RandomBlock(-7,12,-4,IRON_FENCE,21)
RandomBlock(-7,12,-3,IRON_FENCE,21)
RandomBlock(-7,12,-2,IRON_FENCE,21)
RandomBlock(-7,12,-1,IRON_FENCE,21)
RandomBlock(-7,12,0,IRON_FENCE,21)
RandomBlock(-7,12,1,IRON_FENCE,21)
RandomBlock(-7,12,2,IRON_FENCE,21)
RandomBlock(-7,12,3,IRON_FENCE,21)
RandomBlock(-7,12,4,IRON_FENCE,21)
RandomBlock(-7,12,5,IRON_FENCE,21)
RandomBlock(-7,12,6,IRON_FENCE,21)
RandomBlock(-7,12,7,IRON_FENCE,21)
RandomBlock(-7,12,8,IRON_FENCE,21)
RandomBlock(-7,12,9,IRON_FENCE,21)
RandomBlock(-7,12,10,IRON_FENCE,21)
RandomBlock(-7,12,11,IRON_FENCE,21)
RandomBlock(-7,12,12,IRON_FENCE,21)
RandomBlock(-7,12,13,IRON_FENCE,21)
RandomBlock(-7,13,-11,IRON_FENCE,21)
RandomBlock(-7,13,-10,IRON_FENCE,21)
RandomBlock(-7,13,-9,IRON_FENCE,21)
RandomBlock(-7,13,-8,IRON_FENCE,21)
RandomBlock(-7,13,-7,IRON_FENCE,21)
RandomBlock(-7,13,-6,IRON_FENCE,21)
RandomBlock(-7,13,-5,IRON_FENCE,21)
RandomBlock(-7,13,-4,IRON_FENCE,21)
RandomBlock(-7,13,-3,IRON_FENCE,21)
RandomBlock(-7,13,-2,IRON_FENCE,21)
RandomBlock(-7,13,-1,IRON_FENCE,21)
RandomBlock(-7,13,0,IRON_FENCE,21)
RandomBlock(-7,13,1,IRON_FENCE,21)
RandomBlock(-7,13,2,IRON_FENCE,21)
RandomBlock(-7,13,3,IRON_FENCE,21)
RandomBlock(-7,13,4,IRON_FENCE,21)
RandomBlock(-7,13,5,IRON_FENCE,21)
RandomBlock(-7,13,6,IRON_FENCE,21)
RandomBlock(-7,13,7,IRON_FENCE,21)
RandomBlock(-7,13,8,IRON_FENCE,21)
RandomBlock(-7,13,9,IRON_FENCE,21)
RandomBlock(-7,13,10,IRON_FENCE,21)
RandomBlock(-7,13,11,IRON_FENCE,21)
RandomBlock(-7,13,12,IRON_FENCE,21)
RandomBlock(-7,13,13,IRON_FENCE,21)
RandomBlock(-7,14,-11,IRON_FENCE,21)
RandomBlock(-7,14,-10,IRON_FENCE,21)
RandomBlock(-7,14,-9,IRON_FENCE,21)
RandomBlock(-7,14,-8,IRON_FENCE,21)
RandomBlock(-7,14,-7,IRON_FENCE,21)
RandomBlock(-7,14,-6,IRON_FENCE,21)
RandomBlock(-7,14,-5,IRON_FENCE,21)
RandomBlock(-7,14,-4,IRON_FENCE,21)
RandomBlock(-7,14,-3,IRON_FENCE,21)
RandomBlock(-7,14,-2,IRON_FENCE,21)
RandomBlock(-7,14,-1,IRON_FENCE,21)
RandomBlock(-7,14,0,IRON_FENCE,21)
RandomBlock(-7,14,1,IRON_FENCE,21)
RandomBlock(-7,14,2,IRON_FENCE,21)
RandomBlock(-7,14,3,IRON_FENCE,21)
RandomBlock(-7,14,4,IRON_FENCE,21)
RandomBlock(-7,14,5,IRON_FENCE,21)
RandomBlock(-7,14,6,IRON_FENCE,21)
RandomBlock(-7,14,7,IRON_FENCE,21)
RandomBlock(-7,14,8,IRON_FENCE,21)
RandomBlock(-7,14,9,IRON_FENCE,21)
RandomBlock(-7,14,10,IRON_FENCE,21)
RandomBlock(-7,14,11,IRON_FENCE,21)
RandomBlock(-7,14,12,IRON_FENCE,21)
RandomBlock(-7,14,13,IRON_FENCE,21)
RandomBlock(-7,15,-11,IRON_FENCE,21)
RandomBlock(-7,15,-10,IRON_FENCE,21)
RandomBlock(-7,15,-9,IRON_FENCE,21)
RandomBlock(-7,15,-8,IRON_FENCE,21)
RandomBlock(-7,15,-7,IRON_FENCE,21)
RandomBlock(-7,15,-6,IRON_FENCE,21)
RandomBlock(-7,15,-5,IRON_FENCE,21)
RandomBlock(-7,15,-4,IRON_FENCE,21)
RandomBlock(-7,15,-3,IRON_FENCE,21)
RandomBlock(-7,15,-2,IRON_FENCE,21)
RandomBlock(-7,15,-1,IRON_FENCE,21)
RandomBlock(-7,15,0,IRON_FENCE,21)
RandomBlock(-7,15,1,IRON_FENCE,21)
RandomBlock(-7,15,2,IRON_FENCE,21)
RandomBlock(-7,15,3,IRON_FENCE,21)
RandomBlock(-7,15,4,IRON_FENCE,21)
RandomBlock(-7,15,5,IRON_FENCE,21)
RandomBlock(-7,15,6,IRON_FENCE,21)
RandomBlock(-7,15,7,IRON_FENCE,21)
RandomBlock(-7,15,8,IRON_FENCE,21)
RandomBlock(-7,15,9,IRON_FENCE,21)
RandomBlock(-7,15,10,IRON_FENCE,21)
RandomBlock(-7,15,11,IRON_FENCE,21)
RandomBlock(-7,15,12,IRON_FENCE,21)
RandomBlock(-7,15,13,IRON_FENCE,21)
RandomBlock(-7,16,-11,IRON_FENCE,21)
RandomBlock(-7,16,-10,IRON_FENCE,21)
RandomBlock(-7,16,-9,IRON_FENCE,21)
RandomBlock(-7,16,-8,IRON_FENCE,21)
RandomBlock(-7,16,-7,IRON_FENCE,21)
RandomBlock(-7,16,-6,IRON_FENCE,21)
RandomBlock(-7,16,-5,IRON_FENCE,21)
RandomBlock(-7,16,-4,IRON_FENCE,21)
RandomBlock(-7,16,-3,IRON_FENCE,21)
RandomBlock(-7,16,-2,IRON_FENCE,21)
RandomBlock(-7,16,-1,IRON_FENCE,21)
RandomBlock(-7,16,0,IRON_FENCE,21)
RandomBlock(-7,16,1,IRON_FENCE,21)
RandomBlock(-7,16,2,IRON_FENCE,21)
RandomBlock(-7,16,3,IRON_FENCE,21)
RandomBlock(-7,16,4,IRON_FENCE,21)
RandomBlock(-7,16,5,IRON_FENCE,21)
RandomBlock(-7,16,6,IRON_FENCE,21)
RandomBlock(-7,16,7,IRON_FENCE,21)
RandomBlock(-7,16,8,IRON_FENCE,21)
RandomBlock(-7,16,9,IRON_FENCE,21)
RandomBlock(-7,16,10,IRON_FENCE,21)
RandomBlock(-7,16,11,IRON_FENCE,21)
RandomBlock(-7,16,12,IRON_FENCE,21)
RandomBlock(-7,16,13,IRON_FENCE,21)
RandomBlock(-7,17,-11,IRON_FENCE,21)
RandomBlock(-7,17,-10,IRON_FENCE,21)
RandomBlock(-7,17,-9,IRON_FENCE,21)
RandomBlock(-7,17,-8,IRON_FENCE,21)
RandomBlock(-7,17,-7,IRON_FENCE,21)
RandomBlock(-7,17,-6,IRON_FENCE,21)
RandomBlock(-7,17,-5,IRON_FENCE,21)
RandomBlock(-7,17,-4,IRON_FENCE,21)
RandomBlock(-7,17,-3,IRON_FENCE,21)
RandomBlock(-7,17,-2,IRON_FENCE,21)
RandomBlock(-7,17,-1,IRON_FENCE,21)
RandomBlock(-7,17,0,IRON_FENCE,21)
RandomBlock(-7,17,1,IRON_FENCE,21)
RandomBlock(-7,17,2,IRON_FENCE,21)
RandomBlock(-7,17,3,IRON_FENCE,21)
RandomBlock(-7,17,4,IRON_FENCE,21)
RandomBlock(-7,17,5,IRON_FENCE,21)
RandomBlock(-7,17,6,IRON_FENCE,21)
RandomBlock(-7,17,7,IRON_FENCE,21)
RandomBlock(-7,17,8,IRON_FENCE,21)
RandomBlock(-7,17,9,IRON_FENCE,21)
RandomBlock(-7,17,10,IRON_FENCE,21)
RandomBlock(-7,17,11,IRON_FENCE,21)
RandomBlock(-7,17,12,IRON_FENCE,21)
RandomBlock(-7,17,13,IRON_FENCE,21)
RandomBlock(-7,18,-11,IRON_FENCE,21)
RandomBlock(-7,18,-10,IRON_FENCE,21)
RandomBlock(-7,18,-9,IRON_FENCE,21)
RandomBlock(-7,18,-8,IRON_FENCE,21)
RandomBlock(-7,18,-7,IRON_FENCE,21)
RandomBlock(-7,18,-6,IRON_FENCE,21)
RandomBlock(-7,18,-5,IRON_FENCE,21)
RandomBlock(-7,18,-4,IRON_FENCE,21)
RandomBlock(-7,18,-3,IRON_FENCE,21)
RandomBlock(-7,18,-2,IRON_FENCE,21)
RandomBlock(-7,18,-1,IRON_FENCE,21)
RandomBlock(-7,18,0,IRON_FENCE,21)
RandomBlock(-7,18,1,IRON_FENCE,21)
RandomBlock(-7,18,2,IRON_FENCE,21)
RandomBlock(-7,18,3,IRON_FENCE,21)
RandomBlock(-7,18,4,IRON_FENCE,21)
RandomBlock(-7,18,5,IRON_FENCE,21)
RandomBlock(-7,18,6,IRON_FENCE,21)
RandomBlock(-7,18,7,IRON_FENCE,21)
RandomBlock(-7,18,8,IRON_FENCE,21)
RandomBlock(-7,18,9,IRON_FENCE,21)
RandomBlock(-7,18,10,IRON_FENCE,21)
RandomBlock(-7,18,11,IRON_FENCE,21)
RandomBlock(-7,18,12,IRON_FENCE,21)
RandomBlock(-7,18,13,IRON_FENCE,21)
RandomBlock(-7,19,-10,IRON_FENCE,21)
RandomBlock(-7,19,-9,IRON_FENCE,21)
RandomBlock(-7,19,-8,IRON_FENCE,21)
RandomBlock(-7,19,-7,IRON_FENCE,21)
RandomBlock(-7,19,-6,IRON_FENCE,21)
RandomBlock(-7,19,-5,IRON_FENCE,21)
RandomBlock(-7,19,-4,IRON_FENCE,21)
RandomBlock(-7,19,-3,IRON_FENCE,21)
RandomBlock(-7,19,-2,IRON_FENCE,21)
RandomBlock(-7,19,-1,IRON_FENCE,21)
RandomBlock(-7,19,0,IRON_FENCE,21)
RandomBlock(-7,19,1,IRON_FENCE,21)
RandomBlock(-7,19,2,IRON_FENCE,21)
RandomBlock(-7,19,3,IRON_FENCE,21)
RandomBlock(-7,19,4,IRON_FENCE,21)
RandomBlock(-7,19,5,IRON_FENCE,21)
RandomBlock(-7,19,6,IRON_FENCE,21)
RandomBlock(-7,19,7,IRON_FENCE,21)
RandomBlock(-7,19,8,IRON_FENCE,21)
RandomBlock(-7,19,9,IRON_FENCE,21)
RandomBlock(-7,19,10,IRON_FENCE,21)
RandomBlock(-7,19,11,IRON_FENCE,21)
RandomBlock(-7,19,12,IRON_FENCE,21)
RandomBlock(-7,20,-10,IRON_FENCE,21)
RandomBlock(-7,20,-9,IRON_FENCE,21)
RandomBlock(-7,20,-8,IRON_FENCE,21)
RandomBlock(-7,20,-7,IRON_FENCE,21)
RandomBlock(-7,20,-6,IRON_FENCE,21)
RandomBlock(-7,20,-5,IRON_FENCE,21)
RandomBlock(-7,20,-4,IRON_FENCE,21)
RandomBlock(-7,20,-3,IRON_FENCE,21)
RandomBlock(-7,20,-2,IRON_FENCE,21)
RandomBlock(-7,20,-1,IRON_FENCE,21)
RandomBlock(-7,20,0,IRON_FENCE,21)
RandomBlock(-7,20,1,IRON_FENCE,21)
RandomBlock(-7,20,2,IRON_FENCE,21)
RandomBlock(-7,20,3,IRON_FENCE,21)
RandomBlock(-7,20,4,IRON_FENCE,21)
RandomBlock(-7,20,5,IRON_FENCE,21)
RandomBlock(-7,20,6,IRON_FENCE,21)
RandomBlock(-7,20,7,IRON_FENCE,21)
RandomBlock(-7,20,8,IRON_FENCE,21)
RandomBlock(-7,20,9,IRON_FENCE,21)
RandomBlock(-7,20,10,IRON_FENCE,21)
RandomBlock(-7,20,11,IRON_FENCE,21)
RandomBlock(-7,20,12,IRON_FENCE,21)
RandomBlock(-7,21,-9,IRON_FENCE,21)
RandomBlock(-7,21,-8,IRON_FENCE,21)
RandomBlock(-7,21,-7,IRON_FENCE,21)
RandomBlock(-7,21,-6,IRON_FENCE,21)
RandomBlock(-7,21,-5,IRON_FENCE,21)
RandomBlock(-7,21,-4,IRON_FENCE,21)
RandomBlock(-7,21,-3,IRON_FENCE,21)
RandomBlock(-7,21,-2,IRON_FENCE,21)
RandomBlock(-7,21,-1,IRON_FENCE,21)
RandomBlock(-7,21,0,IRON_FENCE,21)
RandomBlock(-7,21,1,IRON_FENCE,21)
RandomBlock(-7,21,2,IRON_FENCE,21)
RandomBlock(-7,21,3,IRON_FENCE,21)
RandomBlock(-7,21,4,IRON_FENCE,21)
RandomBlock(-7,21,5,IRON_FENCE,21)
RandomBlock(-7,21,6,IRON_FENCE,21)
RandomBlock(-7,21,7,IRON_FENCE,21)
RandomBlock(-7,21,8,IRON_FENCE,21)
RandomBlock(-7,21,9,IRON_FENCE,21)
RandomBlock(-7,21,10,IRON_FENCE,21)
RandomBlock(-7,21,11,IRON_FENCE,21)
RandomBlock(-7,22,-8,IRON_FENCE,21)
RandomBlock(-7,22,-7,IRON_FENCE,21)
RandomBlock(-7,22,-6,IRON_FENCE,21)
RandomBlock(-7,22,-5,IRON_FENCE,21)
RandomBlock(-7,22,-4,IRON_FENCE,21)
RandomBlock(-7,22,-3,IRON_FENCE,21)
RandomBlock(-7,22,-2,IRON_FENCE,21)
RandomBlock(-7,22,-1,IRON_FENCE,21)
RandomBlock(-7,22,0,IRON_FENCE,21)
RandomBlock(-7,22,1,IRON_FENCE,21)
RandomBlock(-7,22,2,IRON_FENCE,21)
RandomBlock(-7,22,3,IRON_FENCE,21)
RandomBlock(-7,22,4,IRON_FENCE,21)
RandomBlock(-7,22,5,IRON_FENCE,21)
RandomBlock(-7,22,6,IRON_FENCE,21)
RandomBlock(-7,22,7,IRON_FENCE,21)
RandomBlock(-7,22,8,IRON_FENCE,21)
RandomBlock(-7,22,9,IRON_FENCE,21)
RandomBlock(-7,22,10,IRON_FENCE,21)
RandomBlock(-7,23,-7,IRON_FENCE,21)
RandomBlock(-7,23,-6,IRON_FENCE,21)
RandomBlock(-7,23,-5,IRON_FENCE,21)
RandomBlock(-7,23,-4,IRON_FENCE,21)
RandomBlock(-7,23,-3,IRON_FENCE,21)
RandomBlock(-7,23,-2,IRON_FENCE,21)
RandomBlock(-7,23,-1,IRON_FENCE,21)
RandomBlock(-7,23,0,IRON_FENCE,21)
RandomBlock(-7,23,1,IRON_FENCE,21)
RandomBlock(-7,23,2,IRON_FENCE,21)
RandomBlock(-7,23,3,IRON_FENCE,21)
RandomBlock(-7,23,4,IRON_FENCE,21)
RandomBlock(-7,23,5,IRON_FENCE,21)
RandomBlock(-7,23,6,IRON_FENCE,21)
RandomBlock(-7,23,7,IRON_FENCE,21)
RandomBlock(-7,23,8,IRON_FENCE,21)
RandomBlock(-7,23,9,IRON_FENCE,21)
RandomBlock(-7,24,-6,IRON_FENCE,21)
RandomBlock(-7,24,-5,IRON_FENCE,21)
RandomBlock(-7,24,-4,IRON_FENCE,21)
RandomBlock(-7,24,-3,IRON_FENCE,21)
RandomBlock(-7,24,-2,IRON_FENCE,21)
RandomBlock(-7,24,-1,IRON_FENCE,21)
RandomBlock(-7,24,0,IRON_FENCE,21)
RandomBlock(-7,24,1,IRON_FENCE,21)
RandomBlock(-7,24,2,IRON_FENCE,21)
RandomBlock(-7,24,3,IRON_FENCE,21)
RandomBlock(-7,24,4,IRON_FENCE,21)
RandomBlock(-7,24,5,IRON_FENCE,21)
RandomBlock(-7,24,6,IRON_FENCE,21)
RandomBlock(-7,24,7,IRON_FENCE,21)
RandomBlock(-7,24,8,IRON_FENCE,21)
RandomBlock(-7,25,-5,IRON_FENCE,21)
RandomBlock(-7,25,-4,IRON_FENCE,21)
RandomBlock(-7,25,-3,IRON_FENCE,21)
RandomBlock(-7,25,-2,IRON_FENCE,21)
RandomBlock(-7,25,-1,IRON_FENCE,21)
RandomBlock(-7,25,0,IRON_FENCE,21)
RandomBlock(-7,25,1,IRON_FENCE,21)
RandomBlock(-7,25,2,IRON_FENCE,21)
RandomBlock(-7,25,3,IRON_FENCE,21)
RandomBlock(-7,25,4,IRON_FENCE,21)
RandomBlock(-7,25,5,IRON_FENCE,21)
RandomBlock(-7,25,6,IRON_FENCE,21)
RandomBlock(-7,25,7,IRON_FENCE,21)
RandomBlock(-7,26,-3,IRON_FENCE,21)
RandomBlock(-7,26,-2,IRON_FENCE,21)
RandomBlock(-7,26,-1,IRON_FENCE,21)
RandomBlock(-7,26,0,IRON_FENCE,21)
RandomBlock(-7,26,1,IRON_FENCE,21)
RandomBlock(-7,26,2,IRON_FENCE,21)
RandomBlock(-7,26,3,IRON_FENCE,21)
RandomBlock(-7,26,4,IRON_FENCE,21)
RandomBlock(-7,26,5,IRON_FENCE,21)
RandomBlock(-6,1,-1,IRON_FENCE,21)
RandomBlock(-6,1,0,IRON_FENCE,21)
RandomBlock(-6,1,1,IRON_FENCE,21)
RandomBlock(-6,1,2,IRON_FENCE,21)
RandomBlock(-6,1,3,IRON_FENCE,21)
RandomBlock(-6,2,-4,IRON_FENCE,21)
RandomBlock(-6,2,-3,IRON_FENCE,21)
RandomBlock(-6,2,-2,IRON_FENCE,21)
RandomBlock(-6,2,-1,IRON_FENCE,21)
RandomBlock(-6,2,0,IRON_FENCE,21)
RandomBlock(-6,2,1,IRON_FENCE,21)
RandomBlock(-6,2,2,IRON_FENCE,21)
RandomBlock(-6,2,3,IRON_FENCE,21)
RandomBlock(-6,2,4,IRON_FENCE,21)
RandomBlock(-6,2,5,IRON_FENCE,21)
RandomBlock(-6,2,6,IRON_FENCE,21)
RandomBlock(-6,3,-6,IRON_FENCE,21)
RandomBlock(-6,3,-5,IRON_FENCE,21)
RandomBlock(-6,3,-4,IRON_FENCE,21)
RandomBlock(-6,3,-3,IRON_FENCE,21)
RandomBlock(-6,3,-2,IRON_FENCE,21)
RandomBlock(-6,3,-1,IRON_FENCE,21)
RandomBlock(-6,3,0,IRON_FENCE,21)
RandomBlock(-6,3,1,IRON_FENCE,21)
RandomBlock(-6,3,2,IRON_FENCE,21)
RandomBlock(-6,3,3,IRON_FENCE,21)
RandomBlock(-6,3,4,IRON_FENCE,21)
RandomBlock(-6,3,5,IRON_FENCE,21)
RandomBlock(-6,3,6,IRON_FENCE,21)
RandomBlock(-6,3,7,IRON_FENCE,21)
RandomBlock(-6,3,8,IRON_FENCE,21)
RandomBlock(-6,4,-7,IRON_FENCE,21)
RandomBlock(-6,4,-6,IRON_FENCE,21)
RandomBlock(-6,4,-5,IRON_FENCE,21)
RandomBlock(-6,4,-4,IRON_FENCE,21)
RandomBlock(-6,4,-3,IRON_FENCE,21)
RandomBlock(-6,4,-2,IRON_FENCE,21)
RandomBlock(-6,4,-1,IRON_FENCE,21)
RandomBlock(-6,4,0,IRON_FENCE,21)
RandomBlock(-6,4,1,IRON_FENCE,21)
RandomBlock(-6,4,2,IRON_FENCE,21)
RandomBlock(-6,4,3,IRON_FENCE,21)
RandomBlock(-6,4,4,IRON_FENCE,21)
RandomBlock(-6,4,5,IRON_FENCE,21)
RandomBlock(-6,4,6,IRON_FENCE,21)
RandomBlock(-6,4,7,IRON_FENCE,21)
RandomBlock(-6,4,8,IRON_FENCE,21)
RandomBlock(-6,4,9,IRON_FENCE,21)
RandomBlock(-6,5,-8,IRON_FENCE,21)
RandomBlock(-6,5,-7,IRON_FENCE,21)
RandomBlock(-6,5,-6,IRON_FENCE,21)
RandomBlock(-6,5,-5,IRON_FENCE,21)
RandomBlock(-6,5,-4,IRON_FENCE,21)
RandomBlock(-6,5,-3,IRON_FENCE,21)
RandomBlock(-6,5,-2,IRON_FENCE,21)
RandomBlock(-6,5,-1,IRON_FENCE,21)
RandomBlock(-6,5,0,IRON_FENCE,21)
RandomBlock(-6,5,1,IRON_FENCE,21)
RandomBlock(-6,5,2,IRON_FENCE,21)
RandomBlock(-6,5,3,IRON_FENCE,21)
RandomBlock(-6,5,4,IRON_FENCE,21)
RandomBlock(-6,5,5,IRON_FENCE,21)
RandomBlock(-6,5,6,IRON_FENCE,21)
RandomBlock(-6,5,7,IRON_FENCE,21)
RandomBlock(-6,5,8,IRON_FENCE,21)
RandomBlock(-6,5,9,IRON_FENCE,21)
RandomBlock(-6,5,10,IRON_FENCE,21)
RandomBlock(-6,6,-9,IRON_FENCE,21)
RandomBlock(-6,6,-8,IRON_FENCE,21)
RandomBlock(-6,6,-7,IRON_FENCE,21)
RandomBlock(-6,6,-6,IRON_FENCE,21)
RandomBlock(-6,6,-5,IRON_FENCE,21)
RandomBlock(-6,6,-4,IRON_FENCE,21)
RandomBlock(-6,6,-3,IRON_FENCE,21)
RandomBlock(-6,6,-2,IRON_FENCE,21)
RandomBlock(-6,6,-1,IRON_FENCE,21)
RandomBlock(-6,6,0,IRON_FENCE,21)
RandomBlock(-6,6,1,IRON_FENCE,21)
RandomBlock(-6,6,2,IRON_FENCE,21)
RandomBlock(-6,6,3,IRON_FENCE,21)
RandomBlock(-6,6,4,IRON_FENCE,21)
RandomBlock(-6,6,5,IRON_FENCE,21)
RandomBlock(-6,6,6,IRON_FENCE,21)
RandomBlock(-6,6,7,IRON_FENCE,21)
RandomBlock(-6,6,8,IRON_FENCE,21)
RandomBlock(-6,6,9,IRON_FENCE,21)
RandomBlock(-6,6,10,IRON_FENCE,21)
RandomBlock(-6,6,11,IRON_FENCE,21)
RandomBlock(-6,7,-10,IRON_FENCE,21)
RandomBlock(-6,7,-9,IRON_FENCE,21)
RandomBlock(-6,7,-8,IRON_FENCE,21)
RandomBlock(-6,7,-7,IRON_FENCE,21)
RandomBlock(-6,7,-6,IRON_FENCE,21)
RandomBlock(-6,7,-5,IRON_FENCE,21)
RandomBlock(-6,7,-4,IRON_FENCE,21)
RandomBlock(-6,7,-3,IRON_FENCE,21)
RandomBlock(-6,7,-2,IRON_FENCE,21)
RandomBlock(-6,7,-1,IRON_FENCE,21)
RandomBlock(-6,7,0,IRON_FENCE,21)
RandomBlock(-6,7,1,IRON_FENCE,21)
RandomBlock(-6,7,2,IRON_FENCE,21)
RandomBlock(-6,7,3,IRON_FENCE,21)
RandomBlock(-6,7,4,IRON_FENCE,21)
RandomBlock(-6,7,5,IRON_FENCE,21)
RandomBlock(-6,7,6,IRON_FENCE,21)
RandomBlock(-6,7,7,IRON_FENCE,21)
RandomBlock(-6,7,8,IRON_FENCE,21)
RandomBlock(-6,7,9,IRON_FENCE,21)
RandomBlock(-6,7,10,IRON_FENCE,21)
RandomBlock(-6,7,11,IRON_FENCE,21)
RandomBlock(-6,7,12,IRON_FENCE,21)
RandomBlock(-6,8,-10,IRON_FENCE,21)
RandomBlock(-6,8,-9,IRON_FENCE,21)
RandomBlock(-6,8,-8,IRON_FENCE,21)
RandomBlock(-6,8,-7,IRON_FENCE,21)
RandomBlock(-6,8,-6,IRON_FENCE,21)
RandomBlock(-6,8,-5,IRON_FENCE,21)
RandomBlock(-6,8,-4,IRON_FENCE,21)
RandomBlock(-6,8,-3,IRON_FENCE,21)
RandomBlock(-6,8,-2,IRON_FENCE,21)
RandomBlock(-6,8,-1,IRON_FENCE,21)
RandomBlock(-6,8,0,IRON_FENCE,21)
RandomBlock(-6,8,1,IRON_FENCE,21)
RandomBlock(-6,8,2,IRON_FENCE,21)
RandomBlock(-6,8,3,IRON_FENCE,21)
RandomBlock(-6,8,4,IRON_FENCE,21)
RandomBlock(-6,8,5,IRON_FENCE,21)
RandomBlock(-6,8,6,IRON_FENCE,21)
RandomBlock(-6,8,7,IRON_FENCE,21)
RandomBlock(-6,8,8,IRON_FENCE,21)
RandomBlock(-6,8,9,IRON_FENCE,21)
RandomBlock(-6,8,10,IRON_FENCE,21)
RandomBlock(-6,8,11,IRON_FENCE,21)
RandomBlock(-6,8,12,IRON_FENCE,21)
RandomBlock(-6,9,-11,IRON_FENCE,21)
RandomBlock(-6,9,-10,IRON_FENCE,21)
RandomBlock(-6,9,-9,IRON_FENCE,21)
RandomBlock(-6,9,-8,IRON_FENCE,21)
RandomBlock(-6,9,-7,IRON_FENCE,21)
RandomBlock(-6,9,-6,IRON_FENCE,21)
RandomBlock(-6,9,-5,IRON_FENCE,21)
RandomBlock(-6,9,-4,IRON_FENCE,21)
RandomBlock(-6,9,-3,IRON_FENCE,21)
RandomBlock(-6,9,-2,IRON_FENCE,21)
RandomBlock(-6,9,-1,IRON_FENCE,21)
RandomBlock(-6,9,0,IRON_FENCE,21)
RandomBlock(-6,9,1,IRON_FENCE,21)
RandomBlock(-6,9,2,IRON_FENCE,21)
RandomBlock(-6,9,3,IRON_FENCE,21)
RandomBlock(-6,9,4,IRON_FENCE,21)
RandomBlock(-6,9,5,IRON_FENCE,21)
RandomBlock(-6,9,6,IRON_FENCE,21)
RandomBlock(-6,9,7,IRON_FENCE,21)
RandomBlock(-6,9,8,IRON_FENCE,21)
RandomBlock(-6,9,9,IRON_FENCE,21)
RandomBlock(-6,9,10,IRON_FENCE,21)
RandomBlock(-6,9,11,IRON_FENCE,21)
RandomBlock(-6,9,12,IRON_FENCE,21)
RandomBlock(-6,9,13,IRON_FENCE,21)
RandomBlock(-6,10,-11,IRON_FENCE,21)
RandomBlock(-6,10,-10,IRON_FENCE,21)
RandomBlock(-6,10,-9,IRON_FENCE,21)
RandomBlock(-6,10,-8,IRON_FENCE,21)
RandomBlock(-6,10,-7,IRON_FENCE,21)
RandomBlock(-6,10,-6,IRON_FENCE,21)
RandomBlock(-6,10,-5,IRON_FENCE,21)
RandomBlock(-6,10,-4,IRON_FENCE,21)
RandomBlock(-6,10,-3,IRON_FENCE,21)
RandomBlock(-6,10,-2,IRON_FENCE,21)
RandomBlock(-6,10,-1,IRON_FENCE,21)
RandomBlock(-6,10,0,IRON_FENCE,21)
RandomBlock(-6,10,1,IRON_FENCE,21)
RandomBlock(-6,10,2,IRON_FENCE,21)
RandomBlock(-6,10,3,IRON_FENCE,21)
RandomBlock(-6,10,4,IRON_FENCE,21)
RandomBlock(-6,10,5,IRON_FENCE,21)
RandomBlock(-6,10,6,IRON_FENCE,21)
RandomBlock(-6,10,7,IRON_FENCE,21)
RandomBlock(-6,10,8,IRON_FENCE,21)
RandomBlock(-6,10,9,IRON_FENCE,21)
RandomBlock(-6,10,10,IRON_FENCE,21)
RandomBlock(-6,10,11,IRON_FENCE,21)
RandomBlock(-6,10,12,IRON_FENCE,21)
RandomBlock(-6,10,13,IRON_FENCE,21)
RandomBlock(-6,11,-11,IRON_FENCE,21)
RandomBlock(-6,11,-10,IRON_FENCE,21)
RandomBlock(-6,11,-9,IRON_FENCE,21)
RandomBlock(-6,11,-8,IRON_FENCE,21)
RandomBlock(-6,11,-7,IRON_FENCE,21)
RandomBlock(-6,11,-6,IRON_FENCE,21)
RandomBlock(-6,11,-5,IRON_FENCE,21)
RandomBlock(-6,11,-4,IRON_FENCE,21)
RandomBlock(-6,11,-3,IRON_FENCE,21)
RandomBlock(-6,11,-2,IRON_FENCE,21)
RandomBlock(-6,11,-1,IRON_FENCE,21)
RandomBlock(-6,11,0,IRON_FENCE,21)
RandomBlock(-6,11,1,IRON_FENCE,21)
RandomBlock(-6,11,2,IRON_FENCE,21)
RandomBlock(-6,11,3,IRON_FENCE,21)
RandomBlock(-6,11,4,IRON_FENCE,21)
RandomBlock(-6,11,5,IRON_FENCE,21)
RandomBlock(-6,11,6,IRON_FENCE,21)
RandomBlock(-6,11,7,IRON_FENCE,21)
RandomBlock(-6,11,8,IRON_FENCE,21)
RandomBlock(-6,11,9,IRON_FENCE,21)
RandomBlock(-6,11,10,IRON_FENCE,21)
RandomBlock(-6,11,11,IRON_FENCE,21)
RandomBlock(-6,11,12,IRON_FENCE,21)
RandomBlock(-6,11,13,IRON_FENCE,21)
RandomBlock(-6,12,-12,IRON_FENCE,21)
RandomBlock(-6,12,-11,IRON_FENCE,21)
RandomBlock(-6,12,-10,IRON_FENCE,21)
RandomBlock(-6,12,-9,IRON_FENCE,21)
RandomBlock(-6,12,-8,IRON_FENCE,21)
RandomBlock(-6,12,-7,IRON_FENCE,21)
RandomBlock(-6,12,-6,IRON_FENCE,21)
RandomBlock(-6,12,-5,IRON_FENCE,21)
RandomBlock(-6,12,-4,IRON_FENCE,21)
RandomBlock(-6,12,-3,IRON_FENCE,21)
RandomBlock(-6,12,-2,IRON_FENCE,21)
RandomBlock(-6,12,-1,IRON_FENCE,21)
RandomBlock(-6,12,0,IRON_FENCE,21)
RandomBlock(-6,12,1,IRON_FENCE,21)
RandomBlock(-6,12,2,IRON_FENCE,21)
RandomBlock(-6,12,3,IRON_FENCE,21)
RandomBlock(-6,12,4,IRON_FENCE,21)
RandomBlock(-6,12,5,IRON_FENCE,21)
RandomBlock(-6,12,6,IRON_FENCE,21)
RandomBlock(-6,12,7,IRON_FENCE,21)
RandomBlock(-6,12,8,IRON_FENCE,21)
RandomBlock(-6,12,9,IRON_FENCE,21)
RandomBlock(-6,12,10,IRON_FENCE,21)
RandomBlock(-6,12,11,IRON_FENCE,21)
RandomBlock(-6,12,12,IRON_FENCE,21)
RandomBlock(-6,12,13,IRON_FENCE,21)
RandomBlock(-6,12,14,IRON_FENCE,21)
RandomBlock(-6,13,-12,IRON_FENCE,21)
RandomBlock(-6,13,-11,IRON_FENCE,21)
RandomBlock(-6,13,-10,IRON_FENCE,21)
RandomBlock(-6,13,-9,IRON_FENCE,21)
RandomBlock(-6,13,-8,IRON_FENCE,21)
RandomBlock(-6,13,-7,IRON_FENCE,21)
RandomBlock(-6,13,-6,IRON_FENCE,21)
RandomBlock(-6,13,-5,IRON_FENCE,21)
RandomBlock(-6,13,-4,IRON_FENCE,21)
RandomBlock(-6,13,-3,IRON_FENCE,21)
RandomBlock(-6,13,-2,IRON_FENCE,21)
RandomBlock(-6,13,-1,IRON_FENCE,21)
RandomBlock(-6,13,0,IRON_FENCE,21)
RandomBlock(-6,13,1,IRON_FENCE,21)
RandomBlock(-6,13,2,IRON_FENCE,21)
RandomBlock(-6,13,3,IRON_FENCE,21)
RandomBlock(-6,13,4,IRON_FENCE,21)
RandomBlock(-6,13,5,IRON_FENCE,21)
RandomBlock(-6,13,6,IRON_FENCE,21)
RandomBlock(-6,13,7,IRON_FENCE,21)
RandomBlock(-6,13,8,IRON_FENCE,21)
RandomBlock(-6,13,9,IRON_FENCE,21)
RandomBlock(-6,13,10,IRON_FENCE,21)
RandomBlock(-6,13,11,IRON_FENCE,21)
RandomBlock(-6,13,12,IRON_FENCE,21)
RandomBlock(-6,13,13,IRON_FENCE,21)
RandomBlock(-6,13,14,IRON_FENCE,21)
RandomBlock(-6,14,-12,IRON_FENCE,21)
RandomBlock(-6,14,-11,IRON_FENCE,21)
RandomBlock(-6,14,-10,IRON_FENCE,21)
RandomBlock(-6,14,-9,IRON_FENCE,21)
RandomBlock(-6,14,-8,IRON_FENCE,21)
RandomBlock(-6,14,-7,IRON_FENCE,21)
RandomBlock(-6,14,-6,IRON_FENCE,21)
RandomBlock(-6,14,-5,IRON_FENCE,21)
RandomBlock(-6,14,-4,IRON_FENCE,21)
RandomBlock(-6,14,-3,IRON_FENCE,21)
RandomBlock(-6,14,-2,IRON_FENCE,21)
RandomBlock(-6,14,-1,IRON_FENCE,21)
RandomBlock(-6,14,0,IRON_FENCE,21)
RandomBlock(-6,14,1,IRON_FENCE,21)
RandomBlock(-6,14,2,IRON_FENCE,21)
RandomBlock(-6,14,3,IRON_FENCE,21)
RandomBlock(-6,14,4,IRON_FENCE,21)
RandomBlock(-6,14,5,IRON_FENCE,21)
RandomBlock(-6,14,6,IRON_FENCE,21)
RandomBlock(-6,14,7,IRON_FENCE,21)
RandomBlock(-6,14,8,IRON_FENCE,21)
RandomBlock(-6,14,9,IRON_FENCE,21)
RandomBlock(-6,14,10,IRON_FENCE,21)
RandomBlock(-6,14,11,IRON_FENCE,21)
RandomBlock(-6,14,12,IRON_FENCE,21)
RandomBlock(-6,14,13,IRON_FENCE,21)
RandomBlock(-6,14,14,IRON_FENCE,21)
RandomBlock(-6,15,-12,IRON_FENCE,21)
RandomBlock(-6,15,-11,IRON_FENCE,21)
RandomBlock(-6,15,-10,IRON_FENCE,21)
RandomBlock(-6,15,-9,IRON_FENCE,21)
RandomBlock(-6,15,-8,IRON_FENCE,21)
RandomBlock(-6,15,-7,IRON_FENCE,21)
RandomBlock(-6,15,-6,IRON_FENCE,21)
RandomBlock(-6,15,-5,IRON_FENCE,21)
RandomBlock(-6,15,-4,IRON_FENCE,21)
RandomBlock(-6,15,-3,IRON_FENCE,21)
RandomBlock(-6,15,-2,IRON_FENCE,21)
RandomBlock(-6,15,-1,IRON_FENCE,21)
RandomBlock(-6,15,0,IRON_FENCE,21)
RandomBlock(-6,15,1,IRON_FENCE,21)
RandomBlock(-6,15,2,IRON_FENCE,21)
RandomBlock(-6,15,3,IRON_FENCE,21)
RandomBlock(-6,15,4,IRON_FENCE,21)
RandomBlock(-6,15,5,IRON_FENCE,21)
RandomBlock(-6,15,6,IRON_FENCE,21)
RandomBlock(-6,15,7,IRON_FENCE,21)
RandomBlock(-6,15,8,IRON_FENCE,21)
RandomBlock(-6,15,9,IRON_FENCE,21)
RandomBlock(-6,15,10,IRON_FENCE,21)
RandomBlock(-6,15,11,IRON_FENCE,21)
RandomBlock(-6,15,12,IRON_FENCE,21)
RandomBlock(-6,15,13,IRON_FENCE,21)
RandomBlock(-6,15,14,IRON_FENCE,21)
RandomBlock(-6,16,-12,IRON_FENCE,21)
RandomBlock(-6,16,-11,IRON_FENCE,21)
RandomBlock(-6,16,-10,IRON_FENCE,21)
RandomBlock(-6,16,-9,IRON_FENCE,21)
RandomBlock(-6,16,-8,IRON_FENCE,21)
RandomBlock(-6,16,-7,IRON_FENCE,21)
RandomBlock(-6,16,-6,IRON_FENCE,21)
RandomBlock(-6,16,-5,IRON_FENCE,21)
RandomBlock(-6,16,-4,IRON_FENCE,21)
RandomBlock(-6,16,-3,IRON_FENCE,21)
RandomBlock(-6,16,-2,IRON_FENCE,21)
RandomBlock(-6,16,-1,IRON_FENCE,21)
RandomBlock(-6,16,0,IRON_FENCE,21)
RandomBlock(-6,16,1,IRON_FENCE,21)
RandomBlock(-6,16,2,IRON_FENCE,21)
RandomBlock(-6,16,3,IRON_FENCE,21)
RandomBlock(-6,16,4,IRON_FENCE,21)
RandomBlock(-6,16,5,IRON_FENCE,21)
RandomBlock(-6,16,6,IRON_FENCE,21)
RandomBlock(-6,16,7,IRON_FENCE,21)
RandomBlock(-6,16,8,IRON_FENCE,21)
RandomBlock(-6,16,9,IRON_FENCE,21)
RandomBlock(-6,16,10,IRON_FENCE,21)
RandomBlock(-6,16,11,IRON_FENCE,21)
RandomBlock(-6,16,12,IRON_FENCE,21)
RandomBlock(-6,16,13,IRON_FENCE,21)
RandomBlock(-6,16,14,IRON_FENCE,21)
RandomBlock(-6,17,-11,IRON_FENCE,21)
RandomBlock(-6,17,-10,IRON_FENCE,21)
RandomBlock(-6,17,-9,IRON_FENCE,21)
RandomBlock(-6,17,-8,IRON_FENCE,21)
RandomBlock(-6,17,-7,IRON_FENCE,21)
RandomBlock(-6,17,-6,IRON_FENCE,21)
RandomBlock(-6,17,-5,IRON_FENCE,21)
RandomBlock(-6,17,-4,IRON_FENCE,21)
RandomBlock(-6,17,-3,IRON_FENCE,21)
RandomBlock(-6,17,-2,IRON_FENCE,21)
RandomBlock(-6,17,-1,IRON_FENCE,21)
RandomBlock(-6,17,0,IRON_FENCE,21)
RandomBlock(-6,17,1,IRON_FENCE,21)
RandomBlock(-6,17,2,IRON_FENCE,21)
RandomBlock(-6,17,3,IRON_FENCE,21)
RandomBlock(-6,17,4,IRON_FENCE,21)
RandomBlock(-6,17,5,IRON_FENCE,21)
RandomBlock(-6,17,6,IRON_FENCE,21)
RandomBlock(-6,17,7,IRON_FENCE,21)
RandomBlock(-6,17,8,IRON_FENCE,21)
RandomBlock(-6,17,9,IRON_FENCE,21)
RandomBlock(-6,17,10,IRON_FENCE,21)
RandomBlock(-6,17,11,IRON_FENCE,21)
RandomBlock(-6,17,12,IRON_FENCE,21)
RandomBlock(-6,17,13,IRON_FENCE,21)
RandomBlock(-6,18,-11,IRON_FENCE,21)
RandomBlock(-6,18,-10,IRON_FENCE,21)
RandomBlock(-6,18,-9,IRON_FENCE,21)
RandomBlock(-6,18,-8,IRON_FENCE,21)
RandomBlock(-6,18,-7,IRON_FENCE,21)
RandomBlock(-6,18,-6,IRON_FENCE,21)
RandomBlock(-6,18,-5,IRON_FENCE,21)
RandomBlock(-6,18,-4,IRON_FENCE,21)
RandomBlock(-6,18,-3,IRON_FENCE,21)
RandomBlock(-6,18,-2,IRON_FENCE,21)
RandomBlock(-6,18,-1,IRON_FENCE,21)
RandomBlock(-6,18,0,IRON_FENCE,21)
RandomBlock(-6,18,1,IRON_FENCE,21)
RandomBlock(-6,18,2,IRON_FENCE,21)
RandomBlock(-6,18,3,IRON_FENCE,21)
RandomBlock(-6,18,4,IRON_FENCE,21)
RandomBlock(-6,18,5,IRON_FENCE,21)
RandomBlock(-6,18,6,IRON_FENCE,21)
RandomBlock(-6,18,7,IRON_FENCE,21)
RandomBlock(-6,18,8,IRON_FENCE,21)
RandomBlock(-6,18,9,IRON_FENCE,21)
RandomBlock(-6,18,10,IRON_FENCE,21)
RandomBlock(-6,18,11,IRON_FENCE,21)
RandomBlock(-6,18,12,IRON_FENCE,21)
RandomBlock(-6,18,13,IRON_FENCE,21)
RandomBlock(-6,19,-11,IRON_FENCE,21)
RandomBlock(-6,19,-10,IRON_FENCE,21)
RandomBlock(-6,19,-9,IRON_FENCE,21)
RandomBlock(-6,19,-8,IRON_FENCE,21)
RandomBlock(-6,19,-7,IRON_FENCE,21)
RandomBlock(-6,19,-6,IRON_FENCE,21)
RandomBlock(-6,19,-5,IRON_FENCE,21)
RandomBlock(-6,19,-4,IRON_FENCE,21)
RandomBlock(-6,19,-3,IRON_FENCE,21)
RandomBlock(-6,19,-2,IRON_FENCE,21)
RandomBlock(-6,19,-1,IRON_FENCE,21)
RandomBlock(-6,19,0,IRON_FENCE,21)
RandomBlock(-6,19,1,IRON_FENCE,21)
RandomBlock(-6,19,2,IRON_FENCE,21)
RandomBlock(-6,19,3,IRON_FENCE,21)
RandomBlock(-6,19,4,IRON_FENCE,21)
RandomBlock(-6,19,5,IRON_FENCE,21)
RandomBlock(-6,19,6,IRON_FENCE,21)
RandomBlock(-6,19,7,IRON_FENCE,21)
RandomBlock(-6,19,8,IRON_FENCE,21)
RandomBlock(-6,19,9,IRON_FENCE,21)
RandomBlock(-6,19,10,IRON_FENCE,21)
RandomBlock(-6,19,11,IRON_FENCE,21)
RandomBlock(-6,19,12,IRON_FENCE,21)
RandomBlock(-6,19,13,IRON_FENCE,21)
RandomBlock(-6,20,-10,IRON_FENCE,21)
RandomBlock(-6,20,-9,IRON_FENCE,21)
RandomBlock(-6,20,-8,IRON_FENCE,21)
RandomBlock(-6,20,-7,IRON_FENCE,21)
RandomBlock(-6,20,-6,IRON_FENCE,21)
RandomBlock(-6,20,-5,IRON_FENCE,21)
RandomBlock(-6,20,-4,IRON_FENCE,21)
RandomBlock(-6,20,-3,IRON_FENCE,21)
RandomBlock(-6,20,-2,IRON_FENCE,21)
RandomBlock(-6,20,-1,IRON_FENCE,21)
RandomBlock(-6,20,0,IRON_FENCE,21)
RandomBlock(-6,20,1,IRON_FENCE,21)
RandomBlock(-6,20,2,IRON_FENCE,21)
RandomBlock(-6,20,3,IRON_FENCE,21)
RandomBlock(-6,20,4,IRON_FENCE,21)
RandomBlock(-6,20,5,IRON_FENCE,21)
RandomBlock(-6,20,6,IRON_FENCE,21)
RandomBlock(-6,20,7,IRON_FENCE,21)
RandomBlock(-6,20,8,IRON_FENCE,21)
RandomBlock(-6,20,9,IRON_FENCE,21)
RandomBlock(-6,20,10,IRON_FENCE,21)
RandomBlock(-6,20,11,IRON_FENCE,21)
RandomBlock(-6,20,12,IRON_FENCE,21)
RandomBlock(-6,21,-10,IRON_FENCE,21)
RandomBlock(-6,21,-9,IRON_FENCE,21)
RandomBlock(-6,21,-8,IRON_FENCE,21)
RandomBlock(-6,21,-7,IRON_FENCE,21)
RandomBlock(-6,21,-6,IRON_FENCE,21)
RandomBlock(-6,21,-5,IRON_FENCE,21)
RandomBlock(-6,21,-4,IRON_FENCE,21)
RandomBlock(-6,21,-3,IRON_FENCE,21)
RandomBlock(-6,21,-2,IRON_FENCE,21)
RandomBlock(-6,21,-1,IRON_FENCE,21)
RandomBlock(-6,21,0,IRON_FENCE,21)
RandomBlock(-6,21,1,IRON_FENCE,21)
RandomBlock(-6,21,2,IRON_FENCE,21)
RandomBlock(-6,21,3,IRON_FENCE,21)
RandomBlock(-6,21,4,IRON_FENCE,21)
RandomBlock(-6,21,5,IRON_FENCE,21)
RandomBlock(-6,21,6,IRON_FENCE,21)
RandomBlock(-6,21,7,IRON_FENCE,21)
RandomBlock(-6,21,8,IRON_FENCE,21)
RandomBlock(-6,21,9,IRON_FENCE,21)
RandomBlock(-6,21,10,IRON_FENCE,21)
RandomBlock(-6,21,11,IRON_FENCE,21)
RandomBlock(-6,21,12,IRON_FENCE,21)
RandomBlock(-6,22,-9,IRON_FENCE,21)
RandomBlock(-6,22,-8,IRON_FENCE,21)
RandomBlock(-6,22,-7,IRON_FENCE,21)
RandomBlock(-6,22,-6,IRON_FENCE,21)
RandomBlock(-6,22,-5,IRON_FENCE,21)
RandomBlock(-6,22,-4,IRON_FENCE,21)
RandomBlock(-6,22,-3,IRON_FENCE,21)
RandomBlock(-6,22,-2,IRON_FENCE,21)
RandomBlock(-6,22,-1,IRON_FENCE,21)
RandomBlock(-6,22,0,IRON_FENCE,21)
RandomBlock(-6,22,1,IRON_FENCE,21)
RandomBlock(-6,22,2,IRON_FENCE,21)
RandomBlock(-6,22,3,IRON_FENCE,21)
RandomBlock(-6,22,4,IRON_FENCE,21)
RandomBlock(-6,22,5,IRON_FENCE,21)
RandomBlock(-6,22,6,IRON_FENCE,21)
RandomBlock(-6,22,7,IRON_FENCE,21)
RandomBlock(-6,22,8,IRON_FENCE,21)
RandomBlock(-6,22,9,IRON_FENCE,21)
RandomBlock(-6,22,10,IRON_FENCE,21)
RandomBlock(-6,22,11,IRON_FENCE,21)
RandomBlock(-6,23,-8,IRON_FENCE,21)
RandomBlock(-6,23,-7,IRON_FENCE,21)
RandomBlock(-6,23,-6,IRON_FENCE,21)
RandomBlock(-6,23,-5,IRON_FENCE,21)
RandomBlock(-6,23,-4,IRON_FENCE,21)
RandomBlock(-6,23,-3,IRON_FENCE,21)
RandomBlock(-6,23,-2,IRON_FENCE,21)
RandomBlock(-6,23,-1,IRON_FENCE,21)
RandomBlock(-6,23,0,IRON_FENCE,21)
RandomBlock(-6,23,1,IRON_FENCE,21)
RandomBlock(-6,23,2,IRON_FENCE,21)
RandomBlock(-6,23,3,IRON_FENCE,21)
RandomBlock(-6,23,4,IRON_FENCE,21)
RandomBlock(-6,23,5,IRON_FENCE,21)
RandomBlock(-6,23,6,IRON_FENCE,21)
RandomBlock(-6,23,7,IRON_FENCE,21)
RandomBlock(-6,23,8,IRON_FENCE,21)
RandomBlock(-6,23,9,IRON_FENCE,21)
RandomBlock(-6,23,10,IRON_FENCE,21)
RandomBlock(-6,24,-7,IRON_FENCE,21)
RandomBlock(-6,24,-6,IRON_FENCE,21)
RandomBlock(-6,24,-5,IRON_FENCE,21)
RandomBlock(-6,24,-4,IRON_FENCE,21)
RandomBlock(-6,24,-3,IRON_FENCE,21)
RandomBlock(-6,24,-2,IRON_FENCE,21)
RandomBlock(-6,24,-1,IRON_FENCE,21)
RandomBlock(-6,24,0,IRON_FENCE,21)
RandomBlock(-6,24,1,IRON_FENCE,21)
RandomBlock(-6,24,2,IRON_FENCE,21)
RandomBlock(-6,24,3,IRON_FENCE,21)
RandomBlock(-6,24,4,IRON_FENCE,21)
RandomBlock(-6,24,5,IRON_FENCE,21)
RandomBlock(-6,24,6,IRON_FENCE,21)
RandomBlock(-6,24,7,IRON_FENCE,21)
RandomBlock(-6,24,8,IRON_FENCE,21)
RandomBlock(-6,24,9,IRON_FENCE,21)
RandomBlock(-6,25,-6,IRON_FENCE,21)
RandomBlock(-6,25,-5,IRON_FENCE,21)
RandomBlock(-6,25,-4,IRON_FENCE,21)
RandomBlock(-6,25,-3,IRON_FENCE,21)
RandomBlock(-6,25,-2,IRON_FENCE,21)
RandomBlock(-6,25,-1,IRON_FENCE,21)
RandomBlock(-6,25,0,IRON_FENCE,21)
RandomBlock(-6,25,1,IRON_FENCE,21)
RandomBlock(-6,25,2,IRON_FENCE,21)
RandomBlock(-6,25,3,IRON_FENCE,21)
RandomBlock(-6,25,4,IRON_FENCE,21)
RandomBlock(-6,25,5,IRON_FENCE,21)
RandomBlock(-6,25,6,IRON_FENCE,21)
RandomBlock(-6,25,7,IRON_FENCE,21)
RandomBlock(-6,25,8,IRON_FENCE,21)
RandomBlock(-6,26,-4,IRON_FENCE,21)
RandomBlock(-6,26,-3,IRON_FENCE,21)
RandomBlock(-6,26,-2,IRON_FENCE,21)
RandomBlock(-6,26,-1,IRON_FENCE,21)
RandomBlock(-6,26,0,IRON_FENCE,21)
RandomBlock(-6,26,1,IRON_FENCE,21)
RandomBlock(-6,26,2,IRON_FENCE,21)
RandomBlock(-6,26,3,IRON_FENCE,21)
RandomBlock(-6,26,4,IRON_FENCE,21)
RandomBlock(-6,26,5,IRON_FENCE,21)
RandomBlock(-6,26,6,IRON_FENCE,21)
RandomBlock(-6,27,-1,IRON_FENCE,21)
RandomBlock(-6,27,0,IRON_FENCE,21)
RandomBlock(-6,27,1,IRON_FENCE,21)
RandomBlock(-6,27,2,IRON_FENCE,21)
RandomBlock(-6,27,3,IRON_FENCE,21)
RandomBlock(-5,1,-3,IRON_FENCE,21)
RandomBlock(-5,1,-2,IRON_FENCE,21)
RandomBlock(-5,1,-1,IRON_FENCE,21)
RandomBlock(-5,1,0,IRON_FENCE,21)
RandomBlock(-5,1,1,IRON_FENCE,21)
RandomBlock(-5,1,2,IRON_FENCE,21)
RandomBlock(-5,1,3,IRON_FENCE,21)
RandomBlock(-5,1,4,IRON_FENCE,21)
RandomBlock(-5,1,5,IRON_FENCE,21)
RandomBlock(-5,2,-5,IRON_FENCE,21)
RandomBlock(-5,2,-4,IRON_FENCE,21)
RandomBlock(-5,2,-3,IRON_FENCE,21)
RandomBlock(-5,2,-2,IRON_FENCE,21)
RandomBlock(-5,2,-1,IRON_FENCE,21)
RandomBlock(-5,2,0,IRON_FENCE,21)
RandomBlock(-5,2,1,IRON_FENCE,21)
RandomBlock(-5,2,2,IRON_FENCE,21)
RandomBlock(-5,2,3,IRON_FENCE,21)
RandomBlock(-5,2,4,IRON_FENCE,21)
RandomBlock(-5,2,5,IRON_FENCE,21)
RandomBlock(-5,2,6,IRON_FENCE,21)
RandomBlock(-5,2,7,IRON_FENCE,21)
RandomBlock(-5,3,-7,IRON_FENCE,21)
RandomBlock(-5,3,-6,IRON_FENCE,21)
RandomBlock(-5,3,-5,IRON_FENCE,21)
RandomBlock(-5,3,-4,IRON_FENCE,21)
RandomBlock(-5,3,-3,IRON_FENCE,21)
RandomBlock(-5,3,-2,IRON_FENCE,21)
RandomBlock(-5,3,-1,IRON_FENCE,21)
RandomBlock(-5,3,0,IRON_FENCE,21)
RandomBlock(-5,3,1,IRON_FENCE,21)
RandomBlock(-5,3,2,IRON_FENCE,21)
RandomBlock(-5,3,3,IRON_FENCE,21)
RandomBlock(-5,3,4,IRON_FENCE,21)
RandomBlock(-5,3,5,IRON_FENCE,21)
RandomBlock(-5,3,6,IRON_FENCE,21)
RandomBlock(-5,3,7,IRON_FENCE,21)
RandomBlock(-5,3,8,IRON_FENCE,21)
