Author: Bo3 BulkEdit
Description: Converted Schematic - Modified by Bo3BulkEdit
Version: 3
SettingsMode: WriteDisable
Frequency: 0
SpawnHeight: randomY
MinHeight: 0
MaxHeight: 256
CanOverride: true
MaxPercentageOutsideSourceBlock: 100
OutsideSourceBlock: placeAnyway
B(0,750,0,AIR)
B(15,750,15,AIR)
B(15,-1,1,betternether:quartz_stained_glass:15)
B(15,-1,2,betternether:quartz_stained_glass:15)
B(14,0,0,betternether:quartz_stained_glass:15)
B(15,0,0,betternether:quartz_stained_glass:15)
B(14,0,1,betternether:quartz_stained_glass:15)
B(15,0,1,betternether:quartz_stained_glass:15)
B(14,0,2,betternether:quartz_stained_glass:15)
B(15,0,2,betternether:quartz_stained_glass:15)
B(15,0,3,betternether:quartz_stained_glass:15)
B(13,1,0,betternether:quartz_stained_glass:15)
B(14,1,0,betternether:quartz_stained_glass:15)
B(15,1,0,betternether:quartz_stained_glass:15)
B(13,1,1,betternether:quartz_stained_glass:15)
B(14,1,1,betternether:quartz_stained_glass:15)
B(15,1,1,betternether:quartz_stained_glass:15)
B(14,1,2,betternether:quartz_stained_glass:15)
B(15,1,2,betternether:quartz_stained_glass:15)
B(14,1,3,betternether:quartz_stained_glass:15)
B(15,1,3,betternether:quartz_stained_glass:15)
B(15,1,4,betternether:quartz_stained_glass:15)
B(12,2,0,betternether:quartz_stained_glass:15)
B(13,2,0,betternether:quartz_stained_glass:15)
B(14,2,0,betternether:quartz_stained_glass:15)
RB(15,2,0,srparasites:parasitestain:1,80,quark:crystal:1,30,srparasites:parasiterubbledense:1,100)
B(13,2,1,betternether:quartz_stained_glass:15)
B(14,2,1,betternether:quartz_stained_glass:15)
B(15,2,1,betternether:quartz_stained_glass:15)
B(14,2,2,betternether:quartz_stained_glass:15)
B(15,2,2,betternether:quartz_stained_glass:15)
B(14,2,3,betternether:quartz_stained_glass:15)
B(15,2,3,betternether:quartz_stained_glass:15)
B(12,3,0,betternether:quartz_stained_glass:15)
B(13,3,0,betternether:quartz_stained_glass:15)
B(14,3,0,betternether:quartz_stained_glass:15)
RB(15,3,0,srparasites:parasitestain:1,80,quark:crystal:1,30,srparasites:parasiterubbledense:1,100)
B(13,3,1,betternether:quartz_stained_glass:15)
B(14,3,1,betternether:quartz_stained_glass:15)
B(15,3,1,betternether:quartz_stained_glass:15)
B(13,3,2,betternether:quartz_stained_glass:15)
B(14,3,2,betternether:quartz_stained_glass:15)
B(15,3,2,srparasites:parasiterubbledense:1)
B(14,3,3,betternether:quartz_stained_glass:15)
B(15,3,3,betternether:quartz_stained_glass:15)
B(12,4,0,betternether:quartz_stained_glass:15)
B(13,4,0,betternether:quartz_stained_glass:15)
B(14,4,0,betternether:quartz_stained_glass:15)
RB(15,4,0,srparasites:parasitestain:1,80,quark:crystal:1,30,srparasites:parasiterubbledense:1,100)
B(13,4,1,betternether:quartz_stained_glass:15)
B(14,4,1,srparasites:parasiterubbledense:1)
B(15,4,1,srparasites:parasiterubbledense:1)
B(13,4,2,betternether:quartz_stained_glass:15)
B(14,4,2,betternether:quartz_stained_glass:15)
B(15,4,2,srparasites:parasiterubbledense:1)
B(15,4,3,betternether:quartz_stained_glass:15)
B(12,5,0,betternether:quartz_stained_glass:15)
B(13,5,0,betternether:quartz_stained_glass:15)
B(14,5,0,betternether:quartz_stained_glass:15)
B(15,5,0,srparasites:parasiterubbledense:1)
B(12,5,1,betternether:quartz_stained_glass:15)
B(13,5,1,betternether:quartz_stained_glass:15)
B(14,5,1,srparasites:parasiterubbledense:1)
B(15,5,1,srparasites:parasiterubbledense:1)
B(13,5,2,betternether:quartz_stained_glass:15)
B(14,5,2,betternether:quartz_stained_glass:15)
B(15,5,2,betternether:quartz_stained_glass:15)
B(12,6,0,betternether:quartz_stained_glass:15)
B(13,6,0,betternether:quartz_stained_glass:15)
B(14,6,0,betternether:quartz_stained_glass:15)
B(15,6,0,betternether:quartz_stained_glass:15)
B(12,6,1,betternether:quartz_stained_glass:15)
B(13,6,1,betternether:quartz_stained_glass:15)
B(14,6,1,srparasites:parasiterubbledense:1)
B(15,6,1,betternether:quartz_stained_glass:15)
B(14,6,2,betternether:quartz_stained_glass:15)
B(11,7,0,betternether:quartz_stained_glass:15)
B(12,7,0,betternether:quartz_stained_glass:15)
B(13,7,0,srparasites:parasiterubbledense:1)
B(14,7,0,srparasites:parasiterubbledense:1)
B(15,7,0,betternether:quartz_stained_glass:15)
B(12,7,1,betternether:quartz_stained_glass:15)
B(13,7,1,betternether:quartz_stained_glass:15)
B(14,7,1,betternether:quartz_stained_glass:15)
B(11,8,0,betternether:quartz_stained_glass:15)
B(12,8,0,betternether:quartz_stained_glass:15)
B(13,8,0,srparasites:parasiterubbledense:1)
B(14,8,0,betternether:quartz_stained_glass:15)
B(15,8,0,betternether:quartz_stained_glass:15)
B(13,8,1,betternether:quartz_stained_glass:15)
B(11,9,0,betternether:quartz_stained_glass:15)
B(12,9,0,betternether:quartz_stained_glass:15)
B(13,9,0,betternether:quartz_stained_glass:15)
B(12,10,0,betternether:quartz_stained_glass:15)
