Author: Bo3 BulkEdit
Description: Converted Schematic - Modified by Bo3BulkEdit
Version: 3
SettingsMode: WriteDisable
IsOTGPlus: true
Tree: false
Frequency: 1
Rarity: 100.0
RotateRandomly: false
SpawnHeight: randomY
MaxBranchDepth: 10
ExcludedBiomes: All
MinHeight: 0
MaxHeight: 255
CanOverride: true
MaxPercentageOutsideSourceBlock: 100
OutsideSourceBlock: placeAnyway
BO3Group: CeilingCrystals:0
B(0,750,0,AIR)
B(15,750,15,AIR)
B(1,-30,1,betternether:quartz_stained_glass:15)
B(2,-30,1,betternether:quartz_stained_glass:15)
B(1,-30,2,betternether:quartz_stained_glass:15)
B(2,-30,2,betternether:quartz_stained_glass:15)
B(0,-29,0,betternether:quartz_stained_glass:15)
B(1,-29,0,betternether:quartz_stained_glass:15)
B(2,-29,0,betternether:quartz_stained_glass:15)
B(0,-29,1,betternether:quartz_stained_glass:15)
B(1,-29,1,betternether:quartz_stained_glass:15)
B(2,-29,1,betternether:quartz_stained_glass:15)
B(0,-29,2,betternether:quartz_stained_glass:15)
B(1,-29,2,betternether:quartz_stained_glass:15)
B(2,-29,2,betternether:quartz_stained_glass:15)
B(0,-28,0,betternether:quartz_stained_glass:15)
B(1,-28,0,betternether:quartz_stained_glass:15)
B(2,-28,0,betternether:quartz_stained_glass:15)
B(0,-28,1,betternether:quartz_stained_glass:15)
B(1,-28,1,betternether:quartz_stained_glass:15)
B(2,-28,1,betternether:quartz_stained_glass:15)
B(0,-28,2,betternether:quartz_stained_glass:15)
B(1,-28,2,betternether:quartz_stained_glass:15)
B(1,-27,0,betternether:quartz_stained_glass:15)
B(2,-27,0,betternether:quartz_stained_glass:15)
B(0,-27,1,betternether:quartz_stained_glass:15)
B(1,-27,1,betternether:quartz_stained_glass:15)
B(0,-27,2,betternether:quartz_stained_glass:15)
B(0,-26,0,betternether:quartz_stained_glass:15)
B(1,-26,0,betternether:quartz_stained_glass:15)
B(0,-26,1,betternether:quartz_stained_glass:15)
B(0,-25,0,betternether:quartz_stained_glass:15)
B(1,-25,0,betternether:quartz_stained_glass:15)
