Author: Bo3 BulkEdit
Description: Converted Schematic - Modified by Bo3BulkEdit
Version: 3
SettingsMode: WriteDisable
IsOTGPlus: true
Tree: false
Frequency: 1
Rarity: 100.0
RotateRandomly: false
SpawnHeight: randomY
MaxBranchDepth: 10
ExcludedBiomes: All
MinHeight: 0
MaxHeight: 255
CanOverride: true
MaxPercentageOutsideSourceBlock: 100
OutsideSourceBlock: placeAnyway
BO3Group: CeilingCrystals:0
B(0,750,0,AIR)
B(15,750,15,AIR)
B(15,-16,1,betternether:quartz_stained_glass:15)
B(15,-16,2,betternether:quartz_stained_glass:15)
B(14,-15,0,betternether:quartz_stained_glass:15)
B(15,-15,0,betternether:quartz_stained_glass:15)
B(14,-15,1,betternether:quartz_stained_glass:15)
B(15,-15,1,betternether:quartz_stained_glass:15)
B(15,-15,2,betternether:quartz_stained_glass:15)
B(13,-14,0,betternether:quartz_stained_glass:15)
B(14,-14,0,betternether:quartz_stained_glass:15)
B(15,-14,0,betternether:quartz_stained_glass:15)
B(14,-14,1,betternether:quartz_stained_glass:15)
B(15,-14,1,betternether:quartz_stained_glass:15)
B(15,-14,2,betternether:quartz_stained_glass:15)
B(13,-13,0,betternether:quartz_stained_glass:15)
B(14,-13,0,betternether:quartz_stained_glass:15)
RB(15,-13,0,srparasites:parasitestain:1,80,quark:crystal:1,30,srparasites:parasiterubbledense:1,100)
B(14,-13,1,betternether:quartz_stained_glass:15)
B(15,-13,1,betternether:quartz_stained_glass:15)
B(15,-13,2,betternether:quartz_stained_glass:15)
B(13,-12,0,betternether:quartz_stained_glass:15)
B(14,-12,0,betternether:quartz_stained_glass:15)
B(15,-12,0,betternether:quartz_stained_glass:15)
B(14,-12,1,betternether:quartz_stained_glass:15)
B(15,-12,1,betternether:quartz_stained_glass:15)
B(15,-12,2,betternether:quartz_stained_glass:15)
B(13,-11,0,betternether:quartz_stained_glass:15)
B(14,-11,0,betternether:quartz_stained_glass:15)
B(15,-11,0,betternether:quartz_stained_glass:15)
B(14,-11,1,betternether:quartz_stained_glass:15)
B(15,-11,1,betternether:quartz_stained_glass:15)
B(13,-10,0,betternether:quartz_stained_glass:15)
B(14,-10,0,betternether:quartz_stained_glass:15)
B(15,-10,0,betternether:quartz_stained_glass:15)
BR(16,0,0,true,CEILING_SPIKE-DIAG-BIG-01_1x1,NORTH,100,0)
