Author: NLBlackEagle
Description: No description given
SettingsMode: WriteDisable
Frequency: 0
SpawnHeight: highestBlock
UseCenterForHighestBlock: true
MinHeight: 0
MaxHeight: 255
InheritBO3: 
InheritBO3Rotation: NORTH
OverrideChildSettings: true
OverrideParentHeight: false
CanOverride: true
BranchFrequency: 0
BranchFrequencyGroup: 
MustBeBelowOther: false
MustBeInside: 
CannotBeInside: 
ReplacesBO3: L4-M-CrossC0R0, L4-M-CrossC0R1, L4-M-CrossC0R2, L4-M-CrossC0R3, L4-M-CrossC1R0, L4-M-CrossC1R1, L4-M-CrossC1R2, L4-M-CrossC1R3, L4-M-CrossC2R0, L4-M-CrossC2R1, L4-M-CrossC2R2, L4-M-CrossC2R3, L4-M-CrossC3R0, L4-M-CrossC3R1, L4-M-CrossC3R2, L4-M-CrossC3R3, L4-M-Straigth-START_01-C0R0, L4-M-Straigth-START_01-C0R1, L4-M-Straigth-START_01-C1R0, L4-M-Straigth-START_01-C1R1, L4-M-Straigth-START_01-C2R0, L4-M-Straigth-START_01-C2R1, L4-M-Straigth-START_01-C3R0, L4-M-Straigth-START_01-C3R1, L4-M-Straigth-3CC0R0, L4-M-Straigth-3CC0R1, L4-M-Straigth-3CC0R2, L4-M-Straigth-3CC1R0, L4-M-Straigth-3CC1R1, L4-M-Straigth-3CC1R2, L4-M-Straigth-3CC2R0, L4-M-Straigth-3CC2R1, L4-M-Straigth-3CC2R2, L4-M-Straigth-3CC3R0, L4-M-Straigth-3CC3R1, L4-M-Straigth-3CC3R2, L4-M-Cross, ruinscraper_2x2_01, ruinscraper_2x2_02, ruinscraper_2x2_03, ruinscraper_2x2_04, ruinscraper_2x2_05, ruinscraper_3x3_01, ruinscraper_3x3_02, ruinscraper_3x3_03, L3-M-Straigth-2CC0R0, L3-M-Straigth-2CC0R1, L3-M-Straigth-2CC1R0, L3-M-Straigth-2CC1R1, L3-M-Straigth-2CC2R0, L3-M-Straigth-2CC2R1, L3-M-Straigth-2CC3R0, L3-M-Straigth-2CC3R1, L3-M-Straigth-3CC0R0, L3-M-Straigth-3CC0R1, L3-M-Straigth-3CC0R2, L3-M-Straigth-3CC1R0, L3-M-Straigth-3CC1R1, L3-M-Straigth-3CC1R2, L3-M-Straigth-3CC2R0, L3-M-Straigth-3CC2R1, L3-M-Straigth-3CC2R2, L3-M-Straigth-3CC3R0, L3-M-Straigth-3CC3R1, L3-M-Straigth-3CC3R2L4-M-CrossC0R0, L4-M-CrossC0R1, L4-M-CrossC0R2, L4-M-CrossC0R3, L4-M-CrossC1R0, L4-M-CrossC1R1, L4-M-CrossC1R2, L4-M-CrossC1R3, L4-M-CrossC2R0, L4-M-CrossC2R1, L4-M-CrossC2R2, L4-M-CrossC2R3, L4-M-CrossC3R0, L4-M-CrossC3R1, L4-M-CrossC3R2, L4-M-CrossC3R3, L4-M-Straigth-START_01-C0R0, L4-M-Straigth-START_01-C0R1, L4-M-Straigth-START_01-C1R0, L4-M-Straigth-START_01-C1R1, L4-M-Straigth-START_01-C2R0, L4-M-Straigth-START_01-C2R1, L4-M-Straigth-START_01-C3R0, L4-M-Straigth-START_01-C3R1, L4-M-Straigth-3CC0R0, L4-M-Straigth-3CC0R1, L4-M-Straigth-3CC0R2, L4-M-Straigth-3CC1R0, L4-M-Straigth-3CC1R1, L4-M-Straigth-3CC1R2, L4-M-Straigth-3CC2R0, L4-M-Straigth-3CC2R1, L4-M-Straigth-3CC2R2, L4-M-Straigth-3CC3R0, L4-M-Straigth-3CC3R1, L4-M-Straigth-3CC3R2, L4-M-Cross, ruinscraper_2x2_01, ruinscraper_2x2_02, ruinscraper_2x2_03, ruinscraper_2x2_04, ruinscraper_2x2_05, ruinscraper_3x3_01, ruinscraper_3x3_02, ruinscraper_3x3_03
MustBeInsideWorldBorders: false
CanSpawnOnWater: true
SpawnOnWaterOnly: false
SpawnUnderWater: false
SpawnAtWaterLevel: false
HeightOffset: 0
RemoveAir: false
ReplaceAbove: 
ReplaceBelow: 
ReplaceWithBiomeBlocks: false
ReplaceWithSurfaceBlock: GRASS
ReplaceWithGroundBlock: DIRT
ReplaceWithStoneBlock: eaglemixins:deepslate
SmoothRadius: 0
SmoothHeightOffset: 0
SmoothStartTop: false
SmoothStartWood: false
SmoothingSurfaceBlock: 
SmoothingGroundBlock: 
BO3Group: 
IsSpawnPoint: false
DoReplaceBlocks: false
RandomBlock(-8,0,-7,CONCRETE:7,60,quark:iron_plate,20,STAINED_CLAY:12,15,STAINED_CLAY:15,5,AIR,7,IRON_BARS,12,CONCRETE:7,100)
RandomBlock(-8,0,-6,CONCRETE:7,60,quark:iron_plate,20,STAINED_CLAY:12,15,STAINED_CLAY:15,5,AIR,7,IRON_BARS,12,CONCRETE:7,100)
RandomBlock(-8,0,-5,CONCRETE:7,60,quark:iron_plate,20,STAINED_CLAY:12,15,STAINED_CLAY:15,5,AIR,7,IRON_BARS,12,CONCRETE:7,100)
RandomBlock(-8,0,-4,CONCRETE:7,60,quark:iron_plate,20,STAINED_CLAY:12,15,STAINED_CLAY:15,5,AIR,7,IRON_BARS,12,CONCRETE:7,100)
RandomBlock(-8,0,-3,CONCRETE:7,60,quark:iron_plate,20,STAINED_CLAY:12,15,STAINED_CLAY:15,5,AIR,7,IRON_BARS,12,CONCRETE:7,100)
RandomBlock(-8,0,-2,CONCRETE:7,60,quark:iron_plate,20,STAINED_CLAY:12,15,STAINED_CLAY:15,5,AIR,7,IRON_BARS,12,CONCRETE:7,100)
RandomBlock(-8,0,-1,CONCRETE:7,60,quark:iron_plate,20,STAINED_CLAY:12,15,STAINED_CLAY:15,5,AIR,7,IRON_BARS,12,CONCRETE:7,100)
RandomBlock(-8,0,0,CONCRETE:7,60,quark:iron_plate,20,STAINED_CLAY:12,15,STAINED_CLAY:15,5,AIR,7,IRON_BARS,12,CONCRETE:7,100)
RandomBlock(-8,0,1,CONCRETE:7,60,quark:iron_plate,20,STAINED_CLAY:12,15,STAINED_CLAY:15,5,AIR,7,IRON_BARS,12,CONCRETE:7,100)
RandomBlock(-8,0,2,CONCRETE:7,60,quark:iron_plate,20,STAINED_CLAY:12,15,STAINED_CLAY:15,5,AIR,7,IRON_BARS,12,CONCRETE:7,100)
RandomBlock(-8,0,3,CONCRETE:7,60,quark:iron_plate,20,STAINED_CLAY:12,15,STAINED_CLAY:15,5,AIR,7,IRON_BARS,12,CONCRETE:7,100)
RandomBlock(-8,0,4,CONCRETE:7,60,quark:iron_plate,20,STAINED_CLAY:12,15,STAINED_CLAY:15,5,AIR,7,IRON_BARS,12,CONCRETE:7,100)
RandomBlock(-8,0,5,CONCRETE:7,60,quark:iron_plate,20,STAINED_CLAY:12,15,STAINED_CLAY:15,5,AIR,7,IRON_BARS,12,CONCRETE:7,100)
RandomBlock(-8,0,6,CONCRETE:7,60,quark:iron_plate,20,STAINED_CLAY:12,15,STAINED_CLAY:15,5,AIR,7,IRON_BARS,12,CONCRETE:7,100)
RandomBlock(-8,0,7,CONCRETE:7,60,quark:iron_plate,20,STAINED_CLAY:12,15,STAINED_CLAY:15,5,AIR,7,IRON_BARS,12,CONCRETE:7,100)
RandomBlock(-8,0,8,CONCRETE:7,60,quark:iron_plate,20,STAINED_CLAY:12,15,STAINED_CLAY:15,5,AIR,7,IRON_BARS,12,CONCRETE:7,100)
Block(-8,1,-7,OBSIDIAN:0)
Block(-8,1,-6,OBSIDIAN:0)
Block(-8,1,-5,OBSIDIAN:0)
Block(-8,1,-4,OBSIDIAN:0)
Block(-8,1,-3,OBSIDIAN:0)
Block(-8,1,-2,OBSIDIAN:0)
Block(-8,1,-1,OBSIDIAN:0)
Block(-8,1,0,OBSIDIAN:0)
Block(-8,1,1,OBSIDIAN:0)
Block(-8,1,2,OBSIDIAN:0)
Block(-8,1,3,OBSIDIAN:0)
Block(-8,1,4,OBSIDIAN:0)
Block(-8,1,5,OBSIDIAN:0)
Block(-8,1,6,OBSIDIAN:0)
Block(-8,1,7,OBSIDIAN:0)
Block(-8,1,8,OBSIDIAN:0)
Block(-8,2,-7,OBSIDIAN:0)
Block(-8,2,-6,OBSIDIAN:0)
RandomBlock(-8,2,-5,CONCRETE:7,60,quark:iron_plate,20,STAINED_CLAY:12,15,STAINED_CLAY:15,5,AIR,7,IRON_BARS,12,CONCRETE:7,100)
RandomBlock(-8,2,-4,CONCRETE:7,60,quark:iron_plate,20,STAINED_CLAY:12,15,STAINED_CLAY:15,5,AIR,7,IRON_BARS,12,CONCRETE:7,100)
RandomBlock(-8,2,-3,CONCRETE:7,60,quark:iron_plate,20,STAINED_CLAY:12,15,STAINED_CLAY:15,5,AIR,7,IRON_BARS,12,CONCRETE:7,100)
RandomBlock(-8,2,-2,CONCRETE:7,60,quark:iron_plate,20,STAINED_CLAY:12,15,STAINED_CLAY:15,5,AIR,7,IRON_BARS,12,CONCRETE:7,100)
RandomBlock(-8,2,-1,CONCRETE:7,60,quark:iron_plate,20,STAINED_CLAY:12,15,STAINED_CLAY:15,5,AIR,7,IRON_BARS,12,CONCRETE:7,100)
RandomBlock(-8,2,0,CONCRETE:7,60,quark:iron_plate,20,STAINED_CLAY:12,15,STAINED_CLAY:15,5,AIR,7,IRON_BARS,12,CONCRETE:7,100)
RandomBlock(-8,2,1,CONCRETE:7,60,quark:iron_plate,20,STAINED_CLAY:12,15,STAINED_CLAY:15,5,AIR,7,IRON_BARS,12,CONCRETE:7,100)
RandomBlock(-8,2,2,CONCRETE:7,60,quark:iron_plate,20,STAINED_CLAY:12,15,STAINED_CLAY:15,5,AIR,7,IRON_BARS,12,CONCRETE:7,100)
RandomBlock(-8,2,3,CONCRETE:7,60,quark:iron_plate,20,STAINED_CLAY:12,15,STAINED_CLAY:15,5,AIR,7,IRON_BARS,12,CONCRETE:7,100)
RandomBlock(-8,2,4,CONCRETE:7,60,quark:iron_plate,20,STAINED_CLAY:12,15,STAINED_CLAY:15,5,AIR,7,IRON_BARS,12,CONCRETE:7,100)
RandomBlock(-8,2,5,CONCRETE:7,60,quark:iron_plate,20,STAINED_CLAY:12,15,STAINED_CLAY:15,5,AIR,7,IRON_BARS,12,CONCRETE:7,100)
RandomBlock(-8,2,6,CONCRETE:7,60,quark:iron_plate,20,STAINED_CLAY:12,15,STAINED_CLAY:15,5,AIR,7,IRON_BARS,12,CONCRETE:7,100)
RandomBlock(-8,2,7,CONCRETE:7,60,quark:iron_plate,20,STAINED_CLAY:12,15,STAINED_CLAY:15,5,AIR,7,IRON_BARS,12,CONCRETE:7,100)
RandomBlock(-8,2,8,CONCRETE:7,60,quark:iron_plate,20,STAINED_CLAY:12,15,STAINED_CLAY:15,5,AIR,7,IRON_BARS,12,CONCRETE:7,100)
Block(-8,3,-7,OBSIDIAN:0)
Block(-8,3,-6,OBSIDIAN:0)
RandomBlock(-8,3,-5,CONCRETE:7,60,quark:iron_plate,20,STAINED_CLAY:12,15,STAINED_CLAY:15,5,AIR,7,IRON_BARS,12,CONCRETE:7,100)
RandomBlock(-8,3,-4,CONCRETE:7,60,quark:iron_plate,20,STAINED_CLAY:12,15,STAINED_CLAY:15,5,AIR,7,IRON_BARS,12,CONCRETE:7,100)
RandomBlock(-8,3,-3,CONCRETE:7,60,quark:iron_plate,20,STAINED_CLAY:12,15,STAINED_CLAY:15,5,AIR,7,IRON_BARS,12,CONCRETE:7,100)
RandomBlock(-8,3,-2,CONCRETE:7,60,quark:iron_plate,20,STAINED_CLAY:12,15,STAINED_CLAY:15,5,AIR,7,IRON_BARS,12,CONCRETE:7,100)
RandomBlock(-8,3,-1,CONCRETE:7,60,quark:iron_plate,20,STAINED_CLAY:12,15,STAINED_CLAY:15,5,AIR,7,IRON_BARS,12,CONCRETE:7,100)
RandomBlock(-8,3,0,CONCRETE:7,60,quark:iron_plate,20,STAINED_CLAY:12,15,STAINED_CLAY:15,5,AIR,7,IRON_BARS,12,CONCRETE:7,100)
RandomBlock(-8,3,1,CONCRETE:7,60,quark:iron_plate,20,STAINED_CLAY:12,15,STAINED_CLAY:15,5,AIR,7,IRON_BARS,12,CONCRETE:7,100)
RandomBlock(-8,3,2,CONCRETE:7,60,quark:iron_plate,20,STAINED_CLAY:12,15,STAINED_CLAY:15,5,AIR,7,IRON_BARS,12,CONCRETE:7,100)
RandomBlock(-8,3,3,CONCRETE:7,60,quark:iron_plate,20,STAINED_CLAY:12,15,STAINED_CLAY:15,5,AIR,7,IRON_BARS,12,CONCRETE:7,100)
RandomBlock(-8,3,4,CONCRETE:7,60,quark:iron_plate,20,STAINED_CLAY:12,15,STAINED_CLAY:15,5,AIR,7,IRON_BARS,12,CONCRETE:7,100)
RandomBlock(-8,3,5,CONCRETE:7,60,quark:iron_plate,20,STAINED_CLAY:12,15,STAINED_CLAY:15,5,AIR,7,IRON_BARS,12,CONCRETE:7,100)
RandomBlock(-8,3,6,CONCRETE:7,60,quark:iron_plate,20,STAINED_CLAY:12,15,STAINED_CLAY:15,5,AIR,7,IRON_BARS,12,CONCRETE:7,100)
RandomBlock(-8,3,7,CONCRETE:7,60,quark:iron_plate,20,STAINED_CLAY:12,15,STAINED_CLAY:15,5,AIR,7,IRON_BARS,12,CONCRETE:7,100)
RandomBlock(-8,3,8,CONCRETE:7,60,quark:iron_plate,20,STAINED_CLAY:12,15,STAINED_CLAY:15,5,AIR,7,IRON_BARS,12,CONCRETE:7,100)
Block(-8,4,-7,OBSIDIAN:0)
Block(-8,4,-6,OBSIDIAN:0)
RandomBlock(-8,4,-5,CONCRETE:7,60,quark:iron_plate,20,STAINED_CLAY:12,15,STAINED_CLAY:15,5,AIR,7,IRON_BARS,12,CONCRETE:7,100)
RandomBlock(-8,4,-4,CONCRETE:7,60,quark:iron_plate,20,STAINED_CLAY:12,15,STAINED_CLAY:15,5,AIR,7,IRON_BARS,12,CONCRETE:7,100)
RandomBlock(-8,4,-3,CONCRETE:7,60,quark:iron_plate,20,STAINED_CLAY:12,15,STAINED_CLAY:15,5,AIR,7,IRON_BARS,12,CONCRETE:7,100)
RandomBlock(-8,4,-2,CONCRETE:7,60,quark:iron_plate,20,STAINED_CLAY:12,15,STAINED_CLAY:15,5,AIR,7,IRON_BARS,12,CONCRETE:7,100)
RandomBlock(-8,4,-1,CONCRETE:7,60,quark:iron_plate,20,STAINED_CLAY:12,15,STAINED_CLAY:15,5,AIR,7,IRON_BARS,12,CONCRETE:7,100)
RandomBlock(-8,4,0,CONCRETE:7,60,quark:iron_plate,20,STAINED_CLAY:12,15,STAINED_CLAY:15,5,AIR,7,IRON_BARS,12,CONCRETE:7,100)
RandomBlock(-8,4,1,CONCRETE:7,60,quark:iron_plate,20,STAINED_CLAY:12,15,STAINED_CLAY:15,5,AIR,7,IRON_BARS,12,CONCRETE:7,100)
RandomBlock(-8,4,2,CONCRETE:7,60,quark:iron_plate,20,STAINED_CLAY:12,15,STAINED_CLAY:15,5,AIR,7,IRON_BARS,12,CONCRETE:7,100)
RandomBlock(-8,4,3,CONCRETE:7,60,quark:iron_plate,20,STAINED_CLAY:12,15,STAINED_CLAY:15,5,AIR,7,IRON_BARS,12,CONCRETE:7,100)
RandomBlock(-8,4,4,CONCRETE:7,60,quark:iron_plate,20,STAINED_CLAY:12,15,STAINED_CLAY:15,5,AIR,7,IRON_BARS,12,CONCRETE:7,100)
RandomBlock(-8,4,5,CONCRETE:7,60,quark:iron_plate,20,STAINED_CLAY:12,15,STAINED_CLAY:15,5,AIR,7,IRON_BARS,12,CONCRETE:7,100)
RandomBlock(-8,4,6,CONCRETE:7,60,quark:iron_plate,20,STAINED_CLAY:12,15,STAINED_CLAY:15,5,AIR,7,IRON_BARS,12,CONCRETE:7,100)
RandomBlock(-8,4,7,CONCRETE:7,60,quark:iron_plate,20,STAINED_CLAY:12,15,STAINED_CLAY:15,5,AIR,7,IRON_BARS,12,CONCRETE:7,100)
RandomBlock(-8,4,8,CONCRETE:7,60,quark:iron_plate,20,STAINED_CLAY:12,15,STAINED_CLAY:15,5,AIR,7,IRON_BARS,12,CONCRETE:7,100)
Block(-8,5,-7,OBSIDIAN:0)
Block(-8,5,-6,OBSIDIAN:0)
RandomBlock(-8,5,-5,CONCRETE:7,60,quark:iron_plate,20,STAINED_CLAY:12,15,STAINED_CLAY:15,5,AIR,7,IRON_BARS,12,CONCRETE:7,100)
RandomBlock(-8,5,-4,CONCRETE:7,60,quark:iron_plate,20,STAINED_CLAY:12,15,STAINED_CLAY:15,5,AIR,7,IRON_BARS,12,CONCRETE:7,100)
Block(-8,5,-3,OBSIDIAN:0)
Block(-8,5,-2,OBSIDIAN:0)
Block(-8,5,-1,OBSIDIAN:0)
Block(-8,5,0,OBSIDIAN:0)
Block(-8,5,1,OBSIDIAN:0)
Block(-8,5,2,OBSIDIAN:0)
Block(-8,5,3,OBSIDIAN:0)
RandomBlock(-8,5,4,COBBLESTONE,65,FURNACE:3,../AllScraperData/skyscraper_8x6_01/154-furnaceC32R48.nbt,100)
Block(-8,5,5,AIR:0)
Block(-8,5,6,AIR:0)
Block(-8,5,7,AIR:0)
Block(-8,5,8,AIR:0)
Block(-8,6,-7,OBSIDIAN:0)
Block(-8,6,-6,OBSIDIAN:0)
RandomBlock(-8,6,-5,CONCRETE:7,60,quark:iron_plate,20,STAINED_CLAY:12,15,STAINED_CLAY:15,5,AIR,7,IRON_BARS,12,CONCRETE:7,100)
RandomBlock(-8,6,-4,CONCRETE:7,60,quark:iron_plate,20,STAINED_CLAY:12,15,STAINED_CLAY:15,5,AIR,7,IRON_BARS,12,CONCRETE:7,100)
Block(-8,6,-3,OBSIDIAN:0)
Block(-8,6,-2,OBSIDIAN:0)
Block(-8,6,-1,OBSIDIAN:0)
Block(-8,6,0,OBSIDIAN:0)
Block(-8,6,1,OBSIDIAN:0)
Block(-8,6,2,OBSIDIAN:0)
Block(-8,6,3,OBSIDIAN:0)
RandomBlock(-8,6,4,STONE:6,80,STONE:6,90,DROPPER:1,../../../../../Chests/Loot/toilet_loot.nbt,100)
Block(-8,6,5,STONE_BUTTON:3)
Block(-8,6,6,AIR:0)
Block(-8,6,7,AIR:0)
Block(-8,6,8,AIR:0)
Block(-8,7,-7,OBSIDIAN:0)
Block(-8,7,-6,OBSIDIAN:0)
RandomBlock(-8,7,-5,CONCRETE:7,60,quark:iron_plate,20,STAINED_CLAY:12,15,STAINED_CLAY:15,5,AIR,7,IRON_BARS,12,CONCRETE:7,100)
RandomBlock(-8,7,-4,CONCRETE:7,60,quark:iron_plate,20,STAINED_CLAY:12,15,STAINED_CLAY:15,5,AIR,7,IRON_BARS,12,CONCRETE:7,100)
Block(-8,7,-3,OBSIDIAN:0)
Block(-8,7,-2,OBSIDIAN:0)
Block(-8,7,-1,OBSIDIAN:0)
Block(-8,7,0,OBSIDIAN:0)
Block(-8,7,1,OBSIDIAN:0)
Block(-8,7,2,OBSIDIAN:0)
Block(-8,7,3,OBSIDIAN:0)
Block(-8,7,4,REDSTONE_LAMP_OFF:0)
Block(-8,7,5,TRIPWIRE_HOOK:0)
Block(-8,7,6,AIR:0)
Block(-8,7,7,AIR:0)
Block(-8,7,8,AIR:0)
Block(-8,8,-7,OBSIDIAN:0)
Block(-8,8,-6,OBSIDIAN:0)
RandomBlock(-8,8,-5,CONCRETE:7,60,quark:iron_plate,20,STAINED_CLAY:12,15,STAINED_CLAY:15,5,AIR,7,IRON_BARS,12,CONCRETE:7,100)
RandomBlock(-8,8,-4,CONCRETE:7,60,quark:iron_plate,20,STAINED_CLAY:12,15,STAINED_CLAY:15,5,AIR,7,IRON_BARS,12,CONCRETE:7,100)
Block(-8,8,-3,OBSIDIAN:0)
Block(-8,8,-2,OBSIDIAN:0)
Block(-8,8,-1,OBSIDIAN:0)
Block(-8,8,0,OBSIDIAN:0)
Block(-8,8,1,OBSIDIAN:0)
Block(-8,8,2,OBSIDIAN:0)
RandomBlock(-8,8,3,CONCRETE:7,60,quark:iron_plate,20,STAINED_CLAY:12,15,STAINED_CLAY:15,5,AIR,7,IRON_BARS,12,CONCRETE:7,100)
RandomBlock(-8,8,4,AIR,90,IRON_TRAPDOOR:10,100)
RandomBlock(-8,8,5,AIR,90,IRON_TRAPDOOR:10,100)
RandomBlock(-8,8,6,AIR,90,IRON_TRAPDOOR:10,100)
RandomBlock(-8,8,7,CONCRETE:7,60,quark:iron_plate,20,STAINED_CLAY:12,15,STAINED_CLAY:15,5,AIR,7,IRON_BARS,12,CONCRETE:7,100)
RandomBlock(-8,8,8,AIR,90,IRON_TRAPDOOR:9,100)
Block(-8,9,-7,OBSIDIAN:0)
Block(-8,9,-6,OBSIDIAN:0)
RandomBlock(-8,9,-5,CONCRETE:7,60,quark:iron_plate,20,STAINED_CLAY:12,15,STAINED_CLAY:15,5,AIR,7,IRON_BARS,12,CONCRETE:7,100)
RandomBlock(-8,9,-4,CONCRETE:7,60,quark:iron_plate,20,STAINED_CLAY:12,15,STAINED_CLAY:15,5,AIR,7,IRON_BARS,12,CONCRETE:7,100)
Block(-8,9,-3,OBSIDIAN:0)
Block(-8,9,-2,OBSIDIAN:0)
Block(-8,9,-1,OBSIDIAN:0)
Block(-8,9,0,OBSIDIAN:0)
Block(-8,9,1,OBSIDIAN:0)
Block(-8,9,2,OBSIDIAN:0)
Block(-8,9,3,OBSIDIAN:0)
Block(-8,9,6,AIR:0)
Block(-8,9,7,AIR:0)
Block(-8,9,8,AIR:0)
Block(-8,10,-7,OBSIDIAN:0)
Block(-8,10,-6,OBSIDIAN:0)
RandomBlock(-8,10,-5,CONCRETE:7,60,quark:iron_plate,20,STAINED_CLAY:12,15,STAINED_CLAY:15,5,AIR,7,IRON_BARS,12,CONCRETE:7,100)
RandomBlock(-8,10,-4,CONCRETE:7,60,quark:iron_plate,20,STAINED_CLAY:12,15,STAINED_CLAY:15,5,AIR,7,IRON_BARS,12,CONCRETE:7,100)
Block(-8,10,-3,OBSIDIAN:0)
Block(-8,10,-2,OBSIDIAN:0)
Block(-8,10,-1,OBSIDIAN:0)
Block(-8,10,0,OBSIDIAN:0)
Block(-8,10,1,OBSIDIAN:0)
Block(-8,10,2,OBSIDIAN:0)
Block(-8,10,3,OBSIDIAN:0)
Block(-8,10,4,AIR:0)
Block(-8,10,5,AIR:0)
Block(-8,10,6,AIR:0)
Block(-8,10,7,AIR:0)
Block(-8,10,8,AIR:0)
Block(-8,11,-7,OBSIDIAN:0)
Block(-8,11,-6,OBSIDIAN:0)
RandomBlock(-8,11,-5,CONCRETE:7,60,quark:iron_plate,20,STAINED_CLAY:12,15,STAINED_CLAY:15,5,AIR,7,IRON_BARS,12,CONCRETE:7,100)
RandomBlock(-8,11,-4,CONCRETE:7,60,quark:iron_plate,20,STAINED_CLAY:12,15,STAINED_CLAY:15,5,AIR,7,IRON_BARS,12,CONCRETE:7,100)
Block(-8,11,-3,OBSIDIAN:0)
Block(-8,11,-2,OBSIDIAN:0)
Block(-8,11,-1,OBSIDIAN:0)
Block(-8,11,0,OBSIDIAN:0)
Block(-8,11,1,OBSIDIAN:0)
Block(-8,11,2,OBSIDIAN:0)
Block(-8,11,3,OBSIDIAN:0)
Block(-8,11,4,AIR:0)
Block(-8,11,5,AIR:0)
Block(-8,11,6,AIR:0)
Block(-8,11,7,AIR:0)
Block(-8,11,8,AIR:0)
Block(-8,12,-7,OBSIDIAN:0)
Block(-8,12,-6,OBSIDIAN:0)
RandomBlock(-8,12,-5,CONCRETE:7,60,quark:iron_plate,20,STAINED_CLAY:12,15,STAINED_CLAY:15,5,AIR,7,IRON_BARS,12,CONCRETE:7,100)
RandomBlock(-8,12,-4,CONCRETE:7,60,quark:iron_plate,20,STAINED_CLAY:12,15,STAINED_CLAY:15,5,AIR,7,IRON_BARS,12,CONCRETE:7,100)
Block(-8,12,-3,OBSIDIAN:0)
Block(-8,12,-2,OBSIDIAN:0)
Block(-8,12,-1,OBSIDIAN:0)
Block(-8,12,0,OBSIDIAN:0)
Block(-8,12,1,OBSIDIAN:0)
Block(-8,12,2,OBSIDIAN:0)
RandomBlock(-8,12,3,CONCRETE:7,60,quark:iron_plate,20,STAINED_CLAY:12,15,STAINED_CLAY:15,5,AIR,7,IRON_BARS,12,CONCRETE:7,100)
RandomBlock(-8,12,4,AIR,90,IRON_TRAPDOOR:9,100)
RandomBlock(-8,12,5,AIR,90,IRON_TRAPDOOR:10,100)
RandomBlock(-8,12,6,AIR,90,IRON_TRAPDOOR:8,100)
RandomBlock(-8,12,7,CONCRETE:7,60,quark:iron_plate,20,STAINED_CLAY:12,15,STAINED_CLAY:15,5,AIR,7,IRON_BARS,12,CONCRETE:7,100)
RandomBlock(-8,12,8,AIR,90,IRON_TRAPDOOR:9,100)
Block(-8,13,-7,OBSIDIAN:0)
Block(-8,13,-6,OBSIDIAN:0)
RandomBlock(-8,13,-5,CONCRETE:7,60,quark:iron_plate,20,STAINED_CLAY:12,15,STAINED_CLAY:15,5,AIR,7,IRON_BARS,12,CONCRETE:7,100)
RandomBlock(-8,13,-4,CONCRETE:7,60,quark:iron_plate,20,STAINED_CLAY:12,15,STAINED_CLAY:15,5,AIR,7,IRON_BARS,12,CONCRETE:7,100)
Block(-8,13,-3,OBSIDIAN:0)
Block(-8,13,-2,OBSIDIAN:0)
Block(-8,13,-1,OBSIDIAN:0)
Block(-8,13,0,OBSIDIAN:0)
Block(-8,13,1,OBSIDIAN:0)
Block(-8,13,2,OBSIDIAN:0)
Block(-8,13,3,OBSIDIAN:0)
Block(-8,13,4,AIR:0)
Block(-8,13,5,AIR:0)
Block(-8,13,6,AIR:0)
Block(-8,13,7,AIR:0)
Block(-8,13,8,AIR:0)
Block(-8,14,-7,OBSIDIAN:0)
Block(-8,14,-6,OBSIDIAN:0)
RandomBlock(-8,14,-5,CONCRETE:7,60,quark:iron_plate,20,STAINED_CLAY:12,15,STAINED_CLAY:15,5,AIR,7,IRON_BARS,12,CONCRETE:7,100)
RandomBlock(-8,14,-4,CONCRETE:7,60,quark:iron_plate,20,STAINED_CLAY:12,15,STAINED_CLAY:15,5,AIR,7,IRON_BARS,12,CONCRETE:7,100)
Block(-8,14,-3,OBSIDIAN:0)
Block(-8,14,-2,OBSIDIAN:0)
Block(-8,14,-1,OBSIDIAN:0)
Block(-8,14,0,OBSIDIAN:0)
Block(-8,14,1,OBSIDIAN:0)
Block(-8,14,2,OBSIDIAN:0)
Block(-8,14,3,OBSIDIAN:0)
Block(-8,14,4,STEP:8)
Block(-8,14,5,STEP:8)
Block(-8,14,6,STEP:8)
RandomBlock(-8,14,7,CONCRETE:7,60,quark:iron_plate,20,STAINED_CLAY:12,15,STAINED_CLAY:15,5,AIR,7,IRON_BARS,12,CONCRETE:7,100)
Block(-8,14,8,STEP:8)
Block(-8,15,-7,OBSIDIAN:0)
Block(-8,15,-6,OBSIDIAN:0)
RandomBlock(-8,15,-5,CONCRETE:7,60,quark:iron_plate,20,STAINED_CLAY:12,15,STAINED_CLAY:15,5,AIR,7,IRON_BARS,12,CONCRETE:7,100)
RandomBlock(-8,15,-4,CONCRETE:7,60,quark:iron_plate,20,STAINED_CLAY:12,15,STAINED_CLAY:15,5,AIR,7,IRON_BARS,12,CONCRETE:7,100)
RandomBlock(-8,15,-3,CONCRETE:7,60,quark:iron_plate,20,STAINED_CLAY:12,15,STAINED_CLAY:15,5,AIR,7,IRON_BARS,12,CONCRETE:7,100)
RandomBlock(-8,15,-2,CONCRETE:7,60,quark:iron_plate,20,STAINED_CLAY:12,15,STAINED_CLAY:15,5,AIR,7,IRON_BARS,12,CONCRETE:7,100)
RandomBlock(-8,15,-1,CONCRETE:7,60,quark:iron_plate,20,STAINED_CLAY:12,15,STAINED_CLAY:15,5,AIR,7,IRON_BARS,12,CONCRETE:7,100)
RandomBlock(-8,15,0,CONCRETE:7,60,quark:iron_plate,20,STAINED_CLAY:12,15,STAINED_CLAY:15,5,AIR,7,IRON_BARS,12,CONCRETE:7,100)
RandomBlock(-8,15,1,CONCRETE:7,60,quark:iron_plate,20,STAINED_CLAY:12,15,STAINED_CLAY:15,5,AIR,7,IRON_BARS,12,CONCRETE:7,100)
RandomBlock(-8,15,2,CONCRETE:7,60,quark:iron_plate,20,STAINED_CLAY:12,15,STAINED_CLAY:15,5,AIR,7,IRON_BARS,12,CONCRETE:7,100)
RandomBlock(-8,15,3,CONCRETE:7,60,quark:iron_plate,20,STAINED_CLAY:12,15,STAINED_CLAY:15,5,AIR,7,IRON_BARS,12,CONCRETE:7,100)
RandomBlock(-8,15,4,CONCRETE:7,60,quark:iron_plate,20,STAINED_CLAY:12,15,STAINED_CLAY:15,5,AIR,7,IRON_BARS,12,CONCRETE:7,100)
RandomBlock(-8,15,5,CONCRETE:7,60,quark:iron_plate,20,STAINED_CLAY:12,15,STAINED_CLAY:15,5,AIR,7,IRON_BARS,12,CONCRETE:7,100)
RandomBlock(-8,15,6,CONCRETE:7,60,quark:iron_plate,20,STAINED_CLAY:12,15,STAINED_CLAY:15,5,AIR,7,IRON_BARS,12,CONCRETE:7,100)
RandomBlock(-8,15,7,CONCRETE:7,60,quark:iron_plate,20,STAINED_CLAY:12,15,STAINED_CLAY:15,5,AIR,7,IRON_BARS,12,CONCRETE:7,100)
RandomBlock(-8,15,8,CONCRETE:7,60,quark:iron_plate,20,STAINED_CLAY:12,15,STAINED_CLAY:15,5,AIR,7,IRON_BARS,12,CONCRETE:7,100)
Block(-8,16,-7,OBSIDIAN:0)
Block(-8,16,-6,OBSIDIAN:0)
RandomBlock(-8,16,-5,CONCRETE:7,60,quark:iron_plate,20,STAINED_CLAY:12,15,STAINED_CLAY:15,5,AIR,7,IRON_BARS,12,CONCRETE:7,100)
Block(-8,16,-4,OBSIDIAN:0)
Block(-8,16,-3,OBSIDIAN:0)
Block(-8,16,-2,OBSIDIAN:0)
Block(-8,16,-1,OBSIDIAN:0)
Block(-8,16,0,OBSIDIAN:0)
Block(-8,16,1,OBSIDIAN:0)
Block(-8,16,2,OBSIDIAN:0)
Block(-8,16,3,OBSIDIAN:0)
Block(-8,16,4,OBSIDIAN:0)
Block(-8,16,5,OBSIDIAN:0)
Block(-8,16,6,OBSIDIAN:0)
Block(-8,16,7,OBSIDIAN:0)
Block(-8,16,8,OBSIDIAN:0)
Block(-8,17,-7,OBSIDIAN:0)
Block(-8,17,-6,OBSIDIAN:0)
RandomBlock(-8,17,-5,CONCRETE:7,60,quark:iron_plate,20,STAINED_CLAY:12,15,STAINED_CLAY:15,5,AIR,7,IRON_BARS,12,CONCRETE:7,100)
RandomBlock(-8,17,-4,CONCRETE:7,60,quark:iron_plate,20,STAINED_CLAY:12,15,STAINED_CLAY:15,5,AIR,7,IRON_BARS,12,CONCRETE:7,100)
RandomBlock(-8,17,-3,CONCRETE:7,60,quark:iron_plate,20,STAINED_CLAY:12,15,STAINED_CLAY:15,5,AIR,7,IRON_BARS,12,CONCRETE:7,100)
RandomBlock(-8,17,-2,CONCRETE:7,60,quark:iron_plate,20,STAINED_CLAY:12,15,STAINED_CLAY:15,5,AIR,7,IRON_BARS,12,CONCRETE:7,100)
RandomBlock(-8,17,-1,CONCRETE:7,60,quark:iron_plate,20,STAINED_CLAY:12,15,STAINED_CLAY:15,5,AIR,7,IRON_BARS,12,CONCRETE:7,100)
RandomBlock(-8,17,0,CONCRETE:7,60,quark:iron_plate,20,STAINED_CLAY:12,15,STAINED_CLAY:15,5,AIR,7,IRON_BARS,12,CONCRETE:7,100)
RandomBlock(-8,17,1,CONCRETE:7,60,quark:iron_plate,20,STAINED_CLAY:12,15,STAINED_CLAY:15,5,AIR,7,IRON_BARS,12,CONCRETE:7,100)
RandomBlock(-8,17,2,CONCRETE:7,60,quark:iron_plate,20,STAINED_CLAY:12,15,STAINED_CLAY:15,5,AIR,7,IRON_BARS,12,CONCRETE:7,100)
RandomBlock(-8,17,3,CONCRETE:7,60,quark:iron_plate,20,STAINED_CLAY:12,15,STAINED_CLAY:15,5,AIR,7,IRON_BARS,12,CONCRETE:7,100)
RandomBlock(-8,17,4,CONCRETE:7,60,quark:iron_plate,20,STAINED_CLAY:12,15,STAINED_CLAY:15,5,AIR,7,IRON_BARS,12,CONCRETE:7,100)
RandomBlock(-8,17,5,CONCRETE:7,60,quark:iron_plate,20,STAINED_CLAY:12,15,STAINED_CLAY:15,5,AIR,7,IRON_BARS,12,CONCRETE:7,100)
RandomBlock(-8,17,6,CONCRETE:7,60,quark:iron_plate,20,STAINED_CLAY:12,15,STAINED_CLAY:15,5,AIR,7,IRON_BARS,12,CONCRETE:7,100)
RandomBlock(-8,17,7,CONCRETE:7,60,quark:iron_plate,20,STAINED_CLAY:12,15,STAINED_CLAY:15,5,AIR,7,IRON_BARS,12,CONCRETE:7,100)
RandomBlock(-8,17,8,CONCRETE:7,60,quark:iron_plate,20,STAINED_CLAY:12,15,STAINED_CLAY:15,5,AIR,7,IRON_BARS,12,CONCRETE:7,100)
Block(-8,18,-7,OBSIDIAN:0)
Block(-8,18,-6,OBSIDIAN:0)
RandomBlock(-8,18,-5,CONCRETE:7,60,quark:iron_plate,20,STAINED_CLAY:12,15,STAINED_CLAY:15,5,AIR,7,IRON_BARS,12,CONCRETE:7,100)
Block(-8,18,-3,IRON_FENCE:0)
Block(-8,18,-2,DOUBLE_STEP:0)
Block(-8,18,-1,STEP:8)
Block(-8,18,0,STEP:8)
Block(-8,18,1,DOUBLE_STEP:0)
Block(-8,18,2,IRON_FENCE:0)
RandomBlock(-8,18,3,CONCRETE:7,60,quark:iron_plate,20,STAINED_CLAY:12,15,STAINED_CLAY:15,5,AIR,7,IRON_BARS,12,CONCRETE:7,100)
RandomBlock(-8,18,4,CONCRETE:7,60,quark:iron_plate,20,STAINED_CLAY:12,15,STAINED_CLAY:15,5,AIR,7,IRON_BARS,12,CONCRETE:7,100)
Block(-8,18,5,OBSIDIAN:0)
Block(-8,18,6,OBSIDIAN:0)
Block(-8,18,7,OBSIDIAN:0)
Block(-8,18,8,OBSIDIAN:0)
Block(-8,19,-7,OBSIDIAN:0)
Block(-8,19,-6,OBSIDIAN:0)
RandomBlock(-8,19,-5,CONCRETE:7,60,quark:iron_plate,20,STAINED_CLAY:12,15,STAINED_CLAY:15,5,AIR,7,IRON_BARS,12,CONCRETE:7,100)
Block(-8,19,-3,IRON_FENCE:0)
Block(-8,19,2,IRON_FENCE:0)
RandomBlock(-8,19,3,CONCRETE:7,60,quark:iron_plate,20,STAINED_CLAY:12,15,STAINED_CLAY:15,5,AIR,7,IRON_BARS,12,CONCRETE:7,100)
RandomBlock(-8,19,4,CONCRETE:7,60,quark:iron_plate,20,STAINED_CLAY:12,15,STAINED_CLAY:15,5,AIR,7,IRON_BARS,12,CONCRETE:7,100)
Block(-8,19,5,OBSIDIAN:0)
Block(-8,19,6,OBSIDIAN:0)
Block(-8,19,7,OBSIDIAN:0)
Block(-8,19,8,OBSIDIAN:0)
Block(-8,20,-7,OBSIDIAN:0)
Block(-8,20,-6,OBSIDIAN:0)
RandomBlock(-8,20,-5,CONCRETE:7,60,quark:iron_plate,20,STAINED_CLAY:12,15,STAINED_CLAY:15,5,AIR,7,IRON_BARS,12,CONCRETE:7,100)
Block(-8,20,-3,IRON_FENCE:0)
Block(-8,20,2,IRON_FENCE:0)
RandomBlock(-8,20,3,CONCRETE:7,60,quark:iron_plate,20,STAINED_CLAY:12,15,STAINED_CLAY:15,5,AIR,7,IRON_BARS,12,CONCRETE:7,100)
RandomBlock(-8,20,4,CONCRETE:7,60,quark:iron_plate,20,STAINED_CLAY:12,15,STAINED_CLAY:15,5,AIR,7,IRON_BARS,12,CONCRETE:7,100)
Block(-8,20,5,OBSIDIAN:0)
Block(-8,20,6,OBSIDIAN:0)
Block(-8,20,7,OBSIDIAN:0)
Block(-8,20,8,OBSIDIAN:0)
Block(-8,21,-7,OBSIDIAN:0)
Block(-8,21,-6,OBSIDIAN:0)
RandomBlock(-8,21,-5,CONCRETE:7,60,quark:iron_plate,20,STAINED_CLAY:12,15,STAINED_CLAY:15,5,AIR,7,IRON_BARS,12,CONCRETE:7,100)
Block(-8,21,-4,STEP:8)
Block(-8,21,-3,IRON_FENCE:0)
Block(-8,21,-2,STEP:8)
Block(-8,21,-1,STEP:8)
Block(-8,21,0,STEP:8)
Block(-8,21,1,STEP:8)
RandomBlock(-8,21,2,CONCRETE:7,60,quark:iron_plate,20,STAINED_CLAY:12,15,STAINED_CLAY:15,5,AIR,7,IRON_BARS,12,CONCRETE:7,100)
RandomBlock(-8,21,3,CONCRETE:7,60,quark:iron_plate,20,STAINED_CLAY:12,15,STAINED_CLAY:15,5,AIR,7,IRON_BARS,12,CONCRETE:7,100)
RandomBlock(-8,21,4,CONCRETE:7,60,quark:iron_plate,20,STAINED_CLAY:12,15,STAINED_CLAY:15,5,AIR,7,IRON_BARS,12,CONCRETE:7,100)
Block(-8,21,5,OBSIDIAN:0)
Block(-8,21,6,OBSIDIAN:0)
Block(-8,21,7,OBSIDIAN:0)
Block(-8,21,8,OBSIDIAN:0)
Block(-8,22,-7,OBSIDIAN:0)
Block(-8,22,-6,OBSIDIAN:0)
RandomBlock(-8,22,-5,CONCRETE:7,60,quark:iron_plate,20,STAINED_CLAY:12,15,STAINED_CLAY:15,5,AIR,7,IRON_BARS,12,CONCRETE:7,100)
RandomBlock(-8,22,-4,CONCRETE:7,60,quark:iron_plate,20,STAINED_CLAY:12,15,STAINED_CLAY:15,5,AIR,7,IRON_BARS,12,CONCRETE:7,100)
RandomBlock(-8,22,-3,CONCRETE:7,60,quark:iron_plate,20,STAINED_CLAY:12,15,STAINED_CLAY:15,5,AIR,7,IRON_BARS,12,CONCRETE:7,100)
RandomBlock(-8,22,-2,CONCRETE:7,60,quark:iron_plate,20,STAINED_CLAY:12,15,STAINED_CLAY:15,5,AIR,7,IRON_BARS,12,CONCRETE:7,100)
RandomBlock(-8,22,-1,CONCRETE:7,60,quark:iron_plate,20,STAINED_CLAY:12,15,STAINED_CLAY:15,5,AIR,7,IRON_BARS,12,CONCRETE:7,100)
RandomBlock(-8,22,0,CONCRETE:7,60,quark:iron_plate,20,STAINED_CLAY:12,15,STAINED_CLAY:15,5,AIR,7,IRON_BARS,12,CONCRETE:7,100)
RandomBlock(-8,22,1,CONCRETE:7,60,quark:iron_plate,20,STAINED_CLAY:12,15,STAINED_CLAY:15,5,AIR,7,IRON_BARS,12,CONCRETE:7,100)
RandomBlock(-8,22,2,CONCRETE:7,60,quark:iron_plate,20,STAINED_CLAY:12,15,STAINED_CLAY:15,5,AIR,7,IRON_BARS,12,CONCRETE:7,100)
RandomBlock(-8,22,3,CONCRETE:7,60,quark:iron_plate,20,STAINED_CLAY:12,15,STAINED_CLAY:15,5,AIR,7,IRON_BARS,12,CONCRETE:7,100)
RandomBlock(-8,22,4,CONCRETE:7,60,quark:iron_plate,20,STAINED_CLAY:12,15,STAINED_CLAY:15,5,AIR,7,IRON_BARS,12,CONCRETE:7,100)
Block(-8,22,5,OBSIDIAN:0)
Block(-8,22,6,OBSIDIAN:0)
Block(-8,22,7,OBSIDIAN:0)
Block(-8,22,8,OBSIDIAN:0)
Block(-8,23,-7,OBSIDIAN:0)
Block(-8,23,-6,OBSIDIAN:0)
Block(-8,23,-5,OBSIDIAN:0)
Block(-8,23,-4,OBSIDIAN:0)
Block(-8,23,-3,OBSIDIAN:0)
Block(-8,23,-2,OBSIDIAN:0)
Block(-8,23,-1,OBSIDIAN:0)
Block(-8,23,0,OBSIDIAN:0)
Block(-8,23,1,OBSIDIAN:0)
Block(-8,23,2,OBSIDIAN:0)
Block(-8,23,3,OBSIDIAN:0)
Block(-8,23,4,OBSIDIAN:0)
Block(-8,23,5,OBSIDIAN:0)
Block(-8,23,6,CONCRETE:0)
Block(-8,23,7,CONCRETE:0)
Block(-8,23,8,CONCRETE:0)
Block(-8,24,-7,CONCRETE:0)
Block(-8,24,-6,CONCRETE:15)
Block(-8,24,-5,CONCRETE:0)
Block(-8,24,-4,CONCRETE:0)
Block(-8,24,-3,CONCRETE:15)
Block(-8,24,-2,CONCRETE:0)
Block(-8,24,-1,CONCRETE:0)
Block(-8,24,0,CONCRETE:0)
Block(-8,24,1,CONCRETE:0)
Block(-8,24,2,STONE:4)
Block(-8,24,3,CONCRETE:0)
Block(-8,24,4,CONCRETE:0)
Block(-8,24,5,QUARTZ_STAIRS:3)
Block(-8,25,-5,AIR)
Block(-8,25,-4,CONCRETE:0)
Block(-8,25,-3,AIR)
Block(-8,25,4,CONCRETE:0)
RandomBlock(-8,26,-4,STAINED_GLASS_PANE:15,40,AIR,100)
Block(-8,26,4,CONCRETE:0)
Block(-8,27,4,CONCRETE:0)
Block(-8,28,4,CONCRETE:0)
Block(-8,28,5,QUARTZ_STAIRS:7)
Block(-8,29,2,STEP:8)
Block(-8,29,3,CONCRETE:0)
Block(-8,29,4,CONCRETE:0)
Block(-8,29,5,CONCRETE:0)
Block(-8,29,6,QUARTZ_STAIRS:7)
RandomBlock(-8,30,2,STAINED_GLASS_PANE:15,40,AIR,100)
Block(-8,30,4,CONCRETE:0)
Block(-8,30,5,CONCRETE:0)
Block(-8,30,6,COBBLE_WALL:0)
Block(-8,31,4,CONCRETE:0)
Block(-8,31,5,CONCRETE:0)
Block(-8,32,4,CONCRETE:0)
Block(-8,32,5,CONCRETE:0)
Block(-8,33,1,CONCRETE:0)
Block(-8,33,2,STEP:8)
Block(-8,33,3,STEP:8)
Block(-8,33,4,CONCRETE:0)
Block(-8,33,5,CONCRETE:0)
Block(-8,33,6,QUARTZ_STAIRS:7)
RandomBlock(-8,34,1,STAINED_GLASS_PANE:15,40,AIR,100)
Block(-8,34,4,CONCRETE:0)
Block(-8,34,5,CONCRETE:0)
Block(-8,34,6,COBBLE_WALL:0)
Block(-8,35,4,CONCRETE:0)
Block(-8,35,5,CONCRETE:0)
RandomBlock(-8,36,-4,AIR,90,IRON_TRAPDOOR:10,100)
Block(-8,36,4,CONCRETE:0)
Block(-8,36,5,CONCRETE:0)
Block(-8,37,-4,CONCRETE:0)
Block(-8,37,3,QUARTZ_STAIRS:6)
Block(-8,37,4,CONCRETE:0)
Block(-8,37,5,CONCRETE:0)
Block(-8,38,-4,IRON_FENCE:0)
Block(-8,38,1,QUARTZ_STAIRS:6)
Block(-8,38,2,CONCRETE:0)
Block(-8,38,3,CONCRETE:0)
Block(-8,38,4,CONCRETE:0)
Block(-8,38,5,CONCRETE:0)
Block(-8,39,-4,IRON_FENCE:0)
Block(-8,39,-1,QUARTZ_STAIRS:6)
Block(-8,39,0,CONCRETE:0)
Block(-8,39,1,CONCRETE:0)
Block(-8,39,2,QUARTZ_STAIRS:3)
Block(-8,39,3,STEP:7)
Block(-8,39,4,CONCRETE:0)
Block(-8,39,5,CONCRETE:0)
Block(-8,40,-4,IRON_FENCE:0)
Block(-8,40,-3,QUARTZ_STAIRS:6)
Block(-8,40,-2,CONCRETE:0)
Block(-8,40,-1,CONCRETE:0)
Block(-8,40,0,QUARTZ_STAIRS:3)
Block(-8,40,1,CONCRETE:0)
Block(-8,40,2,STEP:15)
Block(-8,40,3,STEP:15)
Block(-8,40,4,DOUBLE_STEP:7)
Block(-8,40,5,CONCRETE:0)
Block(-8,40,6,QUARTZ_STAIRS:7)
Block(-8,41,-6,QUARTZ_STAIRS:6)
Block(-8,41,-5,CONCRETE:0)
Block(-8,41,-4,CONCRETE:0)
Block(-8,41,-3,CONCRETE:0)
Block(-8,41,-2,QUARTZ_STAIRS:3)
Block(-8,41,-1,STEP:15)
Block(-8,41,0,DOUBLE_STEP:7)
Block(-8,41,1,STEP:7)
Block(-8,41,2,STEP:7)
Block(-8,41,5,CONCRETE:0)
Block(-8,41,6,IRON_FENCE:0)
Block(-8,42,-7,CONCRETE:0)
Block(-8,42,-6,CONCRETE:0)
Block(-8,42,-5,QUARTZ_STAIRS:3)
Block(-8,42,-4,IRON_FENCE:0)
RandomBlock(-8,42,-1,STAINED_GLASS:15,40,AIR,100)
Block(-8,42,5,COBBLE_WALL:0)
Block(-8,43,-6,IRON_FENCE:0)
Block(-8,43,-4,IRON_FENCE:0)
RandomBlock(-8,43,-1,STAINED_GLASS:15,40,AIR,100)
Block(-8,44,-6,IRON_FENCE:0)
Block(-8,44,-4,IRON_FENCE:0)
RandomBlock(-8,44,-1,STAINED_GLASS:15,40,AIR,100)
Block(-8,45,-6,IRON_FENCE:0)
Block(-8,45,-4,IRON_FENCE:0)
RandomBlock(-8,45,-1,STAINED_GLASS:15,40,AIR,100)
Block(-8,46,-6,IRON_FENCE:0)
Block(-8,46,-4,IRON_FENCE:0)
Block(-8,46,-1,CONCRETE:0)
Block(-8,47,-6,IRON_FENCE:0)
Block(-8,47,-4,IRON_FENCE:0)
RandomBlock(-8,47,-2,CONCRETE:7,60,quark:iron_plate,20,STAINED_CLAY:12,15,STAINED_CLAY:15,5,AIR,7,IRON_BARS,12,CONCRETE:7,100)
Block(-8,48,-6,IRON_FENCE:0)
Block(-8,48,-4,IRON_FENCE:0)
RandomBlock(-8,48,-2,CONCRETE:7,60,quark:iron_plate,20,STAINED_CLAY:12,15,STAINED_CLAY:15,5,AIR,7,IRON_BARS,12,CONCRETE:7,100)
Block(-8,49,-6,IRON_FENCE:0)
RandomBlock(-8,49,-4,CONCRETE:7,60,quark:iron_plate,20,STAINED_CLAY:12,15,STAINED_CLAY:15,5,AIR,7,IRON_BARS,12,CONCRETE:7,100)
RandomBlock(-8,49,-3,CONCRETE:7,60,quark:iron_plate,20,STAINED_CLAY:12,15,STAINED_CLAY:15,5,AIR,7,IRON_BARS,12,CONCRETE:7,100)
Block(-8,50,-7,CONCRETE:0)
Block(-8,50,-6,CONCRETE:0)
Block(-8,50,-5,CONCRETE:0)
RandomBlock(-7,0,-7,CONCRETE:7,60,quark:iron_plate,20,STAINED_CLAY:12,15,STAINED_CLAY:15,5,AIR,7,IRON_BARS,12,CONCRETE:7,100)
RandomBlock(-7,0,-6,CONCRETE:7,60,quark:iron_plate,20,STAINED_CLAY:12,15,STAINED_CLAY:15,5,AIR,7,IRON_BARS,12,CONCRETE:7,100)
RandomBlock(-7,0,-5,CONCRETE:7,60,quark:iron_plate,20,STAINED_CLAY:12,15,STAINED_CLAY:15,5,AIR,7,IRON_BARS,12,CONCRETE:7,100)
RandomBlock(-7,0,-4,CONCRETE:7,60,quark:iron_plate,20,STAINED_CLAY:12,15,STAINED_CLAY:15,5,AIR,7,IRON_BARS,12,CONCRETE:7,100)
RandomBlock(-7,0,-3,CONCRETE:7,60,quark:iron_plate,20,STAINED_CLAY:12,15,STAINED_CLAY:15,5,AIR,7,IRON_BARS,12,CONCRETE:7,100)
RandomBlock(-7,0,-2,CONCRETE:7,60,quark:iron_plate,20,STAINED_CLAY:12,15,STAINED_CLAY:15,5,AIR,7,IRON_BARS,12,CONCRETE:7,100)
RandomBlock(-7,0,-1,CONCRETE:7,60,quark:iron_plate,20,STAINED_CLAY:12,15,STAINED_CLAY:15,5,AIR,7,IRON_BARS,12,CONCRETE:7,100)
RandomBlock(-7,0,0,CONCRETE:7,60,quark:iron_plate,20,STAINED_CLAY:12,15,STAINED_CLAY:15,5,AIR,7,IRON_BARS,12,CONCRETE:7,100)
RandomBlock(-7,0,1,CONCRETE:7,60,quark:iron_plate,20,STAINED_CLAY:12,15,STAINED_CLAY:15,5,AIR,7,IRON_BARS,12,CONCRETE:7,100)
RandomBlock(-7,0,2,CONCRETE:7,60,quark:iron_plate,20,STAINED_CLAY:12,15,STAINED_CLAY:15,5,AIR,7,IRON_BARS,12,CONCRETE:7,100)
RandomBlock(-7,0,3,CONCRETE:7,60,quark:iron_plate,20,STAINED_CLAY:12,15,STAINED_CLAY:15,5,AIR,7,IRON_BARS,12,CONCRETE:7,100)
RandomBlock(-7,0,4,CONCRETE:7,60,quark:iron_plate,20,STAINED_CLAY:12,15,STAINED_CLAY:15,5,AIR,7,IRON_BARS,12,CONCRETE:7,100)
RandomBlock(-7,0,5,CONCRETE:7,60,quark:iron_plate,20,STAINED_CLAY:12,15,STAINED_CLAY:15,5,AIR,7,IRON_BARS,12,CONCRETE:7,100)
RandomBlock(-7,0,6,CONCRETE:7,60,quark:iron_plate,20,STAINED_CLAY:12,15,STAINED_CLAY:15,5,AIR,7,IRON_BARS,12,CONCRETE:7,100)
RandomBlock(-7,0,7,CONCRETE:7,60,quark:iron_plate,20,STAINED_CLAY:12,15,STAINED_CLAY:15,5,AIR,7,IRON_BARS,12,CONCRETE:7,100)
RandomBlock(-7,0,8,CONCRETE:7,60,quark:iron_plate,20,STAINED_CLAY:12,15,STAINED_CLAY:15,5,AIR,7,IRON_BARS,12,CONCRETE:7,100)
Block(-7,1,-7,OBSIDIAN:0)
Block(-7,1,-6,OBSIDIAN:0)
Block(-7,1,-5,OBSIDIAN:0)
Block(-7,1,-4,OBSIDIAN:0)
Block(-7,1,-3,OBSIDIAN:0)
Block(-7,1,-2,OBSIDIAN:0)
Block(-7,1,-1,OBSIDIAN:0)
Block(-7,1,0,OBSIDIAN:0)
Block(-7,1,1,OBSIDIAN:0)
Block(-7,1,2,OBSIDIAN:0)
Block(-7,1,3,OBSIDIAN:0)
Block(-7,1,4,OBSIDIAN:0)
Block(-7,1,5,OBSIDIAN:0)
Block(-7,1,6,OBSIDIAN:0)
Block(-7,1,7,OBSIDIAN:0)
Block(-7,1,8,OBSIDIAN:0)
RandomBlock(-7,2,-7,CONCRETE:7,60,quark:iron_plate,20,STAINED_CLAY:12,15,STAINED_CLAY:15,5,AIR,7,IRON_BARS,12,CONCRETE:7,100)
RandomBlock(-7,2,-6,CONCRETE:7,60,quark:iron_plate,20,STAINED_CLAY:12,15,STAINED_CLAY:15,5,AIR,7,IRON_BARS,12,CONCRETE:7,100)
RandomBlock(-7,2,-5,CONCRETE:7,60,quark:iron_plate,20,STAINED_CLAY:12,15,STAINED_CLAY:15,5,AIR,7,IRON_BARS,12,CONCRETE:7,100)
RandomBlock(-7,2,-4,CONCRETE:7,60,quark:iron_plate,20,STAINED_CLAY:12,15,STAINED_CLAY:15,5,AIR,7,IRON_BARS,12,CONCRETE:7,100)
RandomBlock(-7,2,-3,CONCRETE:7,60,quark:iron_plate,20,STAINED_CLAY:12,15,STAINED_CLAY:15,5,AIR,7,IRON_BARS,12,CONCRETE:7,100)
RandomBlock(-7,2,-2,CONCRETE:7,60,quark:iron_plate,20,STAINED_CLAY:12,15,STAINED_CLAY:15,5,AIR,7,IRON_BARS,12,CONCRETE:7,100)
RandomBlock(-7,2,-1,CONCRETE:7,60,quark:iron_plate,20,STAINED_CLAY:12,15,STAINED_CLAY:15,5,AIR,7,IRON_BARS,12,CONCRETE:7,100)
RandomBlock(-7,2,0,CONCRETE:7,60,quark:iron_plate,20,STAINED_CLAY:12,15,STAINED_CLAY:15,5,AIR,7,IRON_BARS,12,CONCRETE:7,100)
RandomBlock(-7,2,1,CONCRETE:7,60,quark:iron_plate,20,STAINED_CLAY:12,15,STAINED_CLAY:15,5,AIR,7,IRON_BARS,12,CONCRETE:7,100)
RandomBlock(-7,2,2,CONCRETE:7,60,quark:iron_plate,20,STAINED_CLAY:12,15,STAINED_CLAY:15,5,AIR,7,IRON_BARS,12,CONCRETE:7,100)
RandomBlock(-7,2,3,CONCRETE:7,60,quark:iron_plate,20,STAINED_CLAY:12,15,STAINED_CLAY:15,5,AIR,7,IRON_BARS,12,CONCRETE:7,100)
RandomBlock(-7,2,4,CONCRETE:7,60,quark:iron_plate,20,STAINED_CLAY:12,15,STAINED_CLAY:15,5,AIR,7,IRON_BARS,12,CONCRETE:7,100)
RandomBlock(-7,2,5,CONCRETE:7,60,quark:iron_plate,20,STAINED_CLAY:12,15,STAINED_CLAY:15,5,AIR,7,IRON_BARS,12,CONCRETE:7,100)
RandomBlock(-7,2,6,CONCRETE:7,60,quark:iron_plate,20,STAINED_CLAY:12,15,STAINED_CLAY:15,5,AIR,7,IRON_BARS,12,CONCRETE:7,100)
RandomBlock(-7,2,7,CONCRETE:7,60,quark:iron_plate,20,STAINED_CLAY:12,15,STAINED_CLAY:15,5,AIR,7,IRON_BARS,12,CONCRETE:7,100)
RandomBlock(-7,2,8,CONCRETE:7,60,quark:iron_plate,20,STAINED_CLAY:12,15,STAINED_CLAY:15,5,AIR,7,IRON_BARS,12,CONCRETE:7,100)
RandomBlock(-7,3,-7,CONCRETE:7,60,quark:iron_plate,20,STAINED_CLAY:12,15,STAINED_CLAY:15,5,AIR,7,IRON_BARS,12,CONCRETE:7,100)
RandomBlock(-7,3,-6,CONCRETE:7,60,quark:iron_plate,20,STAINED_CLAY:12,15,STAINED_CLAY:15,5,AIR,7,IRON_BARS,12,CONCRETE:7,100)
RandomBlock(-7,3,-5,CONCRETE:7,60,quark:iron_plate,20,STAINED_CLAY:12,15,STAINED_CLAY:15,5,AIR,7,IRON_BARS,12,CONCRETE:7,100)
RandomBlock(-7,3,-4,CONCRETE:7,60,quark:iron_plate,20,STAINED_CLAY:12,15,STAINED_CLAY:15,5,AIR,7,IRON_BARS,12,CONCRETE:7,100)
RandomBlock(-7,3,-3,CONCRETE:7,60,quark:iron_plate,20,STAINED_CLAY:12,15,STAINED_CLAY:15,5,AIR,7,IRON_BARS,12,CONCRETE:7,100)
RandomBlock(-7,3,-2,CONCRETE:7,60,quark:iron_plate,20,STAINED_CLAY:12,15,STAINED_CLAY:15,5,AIR,7,IRON_BARS,12,CONCRETE:7,100)
RandomBlock(-7,3,-1,CONCRETE:7,60,quark:iron_plate,20,STAINED_CLAY:12,15,STAINED_CLAY:15,5,AIR,7,IRON_BARS,12,CONCRETE:7,100)
RandomBlock(-7,3,0,CONCRETE:7,60,quark:iron_plate,20,STAINED_CLAY:12,15,STAINED_CLAY:15,5,AIR,7,IRON_BARS,12,CONCRETE:7,100)
RandomBlock(-7,3,1,CONCRETE:7,60,quark:iron_plate,20,STAINED_CLAY:12,15,STAINED_CLAY:15,5,AIR,7,IRON_BARS,12,CONCRETE:7,100)
RandomBlock(-7,3,2,CONCRETE:7,60,quark:iron_plate,20,STAINED_CLAY:12,15,STAINED_CLAY:15,5,AIR,7,IRON_BARS,12,CONCRETE:7,100)
RandomBlock(-7,3,3,CONCRETE:7,60,quark:iron_plate,20,STAINED_CLAY:12,15,STAINED_CLAY:15,5,AIR,7,IRON_BARS,12,CONCRETE:7,100)
RandomBlock(-7,3,4,CONCRETE:7,60,quark:iron_plate,20,STAINED_CLAY:12,15,STAINED_CLAY:15,5,AIR,7,IRON_BARS,12,CONCRETE:7,100)
RandomBlock(-7,3,5,CONCRETE:7,60,quark:iron_plate,20,STAINED_CLAY:12,15,STAINED_CLAY:15,5,AIR,7,IRON_BARS,12,CONCRETE:7,100)
RandomBlock(-7,3,6,CONCRETE:7,60,quark:iron_plate,20,STAINED_CLAY:12,15,STAINED_CLAY:15,5,AIR,7,IRON_BARS,12,CONCRETE:7,100)
RandomBlock(-7,3,7,CONCRETE:7,60,quark:iron_plate,20,STAINED_CLAY:12,15,STAINED_CLAY:15,5,AIR,7,IRON_BARS,12,CONCRETE:7,100)
RandomBlock(-7,3,8,CONCRETE:7,60,quark:iron_plate,20,STAINED_CLAY:12,15,STAINED_CLAY:15,5,AIR,7,IRON_BARS,12,CONCRETE:7,100)
RandomBlock(-7,4,-7,CONCRETE:7,60,quark:iron_plate,20,STAINED_CLAY:12,15,STAINED_CLAY:15,5,AIR,7,IRON_BARS,12,CONCRETE:7,100)
RandomBlock(-7,4,-6,CONCRETE:7,60,quark:iron_plate,20,STAINED_CLAY:12,15,STAINED_CLAY:15,5,AIR,7,IRON_BARS,12,CONCRETE:7,100)
RandomBlock(-7,4,-5,CONCRETE:7,60,quark:iron_plate,20,STAINED_CLAY:12,15,STAINED_CLAY:15,5,AIR,7,IRON_BARS,12,CONCRETE:7,100)
RandomBlock(-7,4,-4,CONCRETE:7,60,quark:iron_plate,20,STAINED_CLAY:12,15,STAINED_CLAY:15,5,AIR,7,IRON_BARS,12,CONCRETE:7,100)
RandomBlock(-7,4,-3,CONCRETE:7,60,quark:iron_plate,20,STAINED_CLAY:12,15,STAINED_CLAY:15,5,AIR,7,IRON_BARS,12,CONCRETE:7,100)
RandomBlock(-7,4,-2,CONCRETE:7,60,quark:iron_plate,20,STAINED_CLAY:12,15,STAINED_CLAY:15,5,AIR,7,IRON_BARS,12,CONCRETE:7,100)
RandomBlock(-7,4,-1,CONCRETE:7,60,quark:iron_plate,20,STAINED_CLAY:12,15,STAINED_CLAY:15,5,AIR,7,IRON_BARS,12,CONCRETE:7,100)
RandomBlock(-7,4,0,CONCRETE:7,60,quark:iron_plate,20,STAINED_CLAY:12,15,STAINED_CLAY:15,5,AIR,7,IRON_BARS,12,CONCRETE:7,100)
RandomBlock(-7,4,1,CONCRETE:7,60,quark:iron_plate,20,STAINED_CLAY:12,15,STAINED_CLAY:15,5,AIR,7,IRON_BARS,12,CONCRETE:7,100)
RandomBlock(-7,4,2,CONCRETE:7,60,quark:iron_plate,20,STAINED_CLAY:12,15,STAINED_CLAY:15,5,AIR,7,IRON_BARS,12,CONCRETE:7,100)
RandomBlock(-7,4,3,CONCRETE:7,60,quark:iron_plate,20,STAINED_CLAY:12,15,STAINED_CLAY:15,5,AIR,7,IRON_BARS,12,CONCRETE:7,100)
RandomBlock(-7,4,4,CONCRETE:7,60,quark:iron_plate,20,STAINED_CLAY:12,15,STAINED_CLAY:15,5,AIR,7,IRON_BARS,12,CONCRETE:7,100)
RandomBlock(-7,4,5,CONCRETE:7,60,quark:iron_plate,20,STAINED_CLAY:12,15,STAINED_CLAY:15,5,AIR,7,IRON_BARS,12,CONCRETE:7,100)
RandomBlock(-7,4,6,CONCRETE:7,60,quark:iron_plate,20,STAINED_CLAY:12,15,STAINED_CLAY:15,5,AIR,7,IRON_BARS,12,CONCRETE:7,100)
RandomBlock(-7,4,7,CONCRETE:7,60,quark:iron_plate,20,STAINED_CLAY:12,15,STAINED_CLAY:15,5,AIR,7,IRON_BARS,12,CONCRETE:7,100)
RandomBlock(-7,4,8,CONCRETE:7,60,quark:iron_plate,20,STAINED_CLAY:12,15,STAINED_CLAY:15,5,AIR,7,IRON_BARS,12,CONCRETE:7,100)
Block(-7,5,-7,OBSIDIAN:0)
Block(-7,5,-6,OBSIDIAN:0)
RandomBlock(-7,5,-5,CONCRETE:7,60,quark:iron_plate,20,STAINED_CLAY:12,15,STAINED_CLAY:15,5,AIR,7,IRON_BARS,12,CONCRETE:7,100)
Block(-7,5,-4,OBSIDIAN:0)
Block(-7,5,-3,OBSIDIAN:0)
Block(-7,5,-2,OBSIDIAN:0)
Block(-7,5,-1,OBSIDIAN:0)
Block(-7,5,0,OBSIDIAN:0)
Block(-7,5,1,OBSIDIAN:0)
Block(-7,5,2,OBSIDIAN:0)
Block(-7,5,3,OBSIDIAN:0)
RandomBlock(-7,5,4,STONE:6,80,STONE:6,90,DROPPER:1,../../../../../Chests/Loot/toilet_loot.nbt,100)
Block(-7,5,5,TRIPWIRE_HOOK:0)
Block(-7,5,6,AIR:0)
Block(-7,5,7,AIR:0)
Block(-7,5,8,AIR:0)
Block(-7,6,-7,OBSIDIAN:0)
Block(-7,6,-6,OBSIDIAN:0)
RandomBlock(-7,6,-5,CONCRETE:7,60,quark:iron_plate,20,STAINED_CLAY:12,15,STAINED_CLAY:15,5,AIR,7,IRON_BARS,12,CONCRETE:7,100)
Block(-7,6,-4,OBSIDIAN:0)
Block(-7,6,-3,OBSIDIAN:0)
Block(-7,6,-2,OBSIDIAN:0)
Block(-7,6,-1,OBSIDIAN:0)
Block(-7,6,0,OBSIDIAN:0)
Block(-7,6,1,OBSIDIAN:0)
Block(-7,6,2,OBSIDIAN:0)
Block(-7,6,3,OBSIDIAN:0)
RandomBlock(-7,6,4,STONE:6,90,STONE:6,90,DROPPER:4,../../../../../Chests/Loot/city_potions.nbt,100)
Block(-7,6,5,STONE_BUTTON:3)
Block(-7,6,6,AIR:0)
Block(-7,6,7,AIR:0)
Block(-7,6,8,AIR:0)
Block(-7,7,-7,OBSIDIAN:0)
Block(-7,7,-6,OBSIDIAN:0)
RandomBlock(-7,7,-5,CONCRETE:7,60,quark:iron_plate,20,STAINED_CLAY:12,15,STAINED_CLAY:15,5,AIR,7,IRON_BARS,12,CONCRETE:7,100)
Block(-7,7,-4,OBSIDIAN:0)
Block(-7,7,-3,OBSIDIAN:0)
Block(-7,7,-2,OBSIDIAN:0)
Block(-7,7,-1,OBSIDIAN:0)
Block(-7,7,0,OBSIDIAN:0)
Block(-7,7,1,OBSIDIAN:0)
Block(-7,7,2,OBSIDIAN:0)
Block(-7,7,3,OBSIDIAN:0)
RandomBlock(-7,7,4,STONE:6,90,STONE:6,90,DROPPER:0,../../../../../Chests/Loot/city_potions.nbt,100)
Block(-7,7,5,STONE_BUTTON:3)
Block(-7,7,6,AIR:0)
Block(-7,7,7,AIR:0)
Block(-7,7,8,AIR:0)
RandomBlock(-7,8,-7,CONCRETE:7,60,quark:iron_plate,20,STAINED_CLAY:12,15,STAINED_CLAY:15,5,AIR,7,IRON_BARS,12,CONCRETE:7,100)
RandomBlock(-7,8,-6,CONCRETE:7,60,quark:iron_plate,20,STAINED_CLAY:12,15,STAINED_CLAY:15,5,AIR,7,IRON_BARS,12,CONCRETE:7,100)
RandomBlock(-7,8,-5,CONCRETE:7,60,quark:iron_plate,20,STAINED_CLAY:12,15,STAINED_CLAY:15,5,AIR,7,IRON_BARS,12,CONCRETE:7,100)
Block(-7,8,-4,OBSIDIAN:0)
Block(-7,8,-3,OBSIDIAN:0)
Block(-7,8,-2,OBSIDIAN:0)
Block(-7,8,-1,OBSIDIAN:0)
Block(-7,8,0,OBSIDIAN:0)
Block(-7,8,1,OBSIDIAN:0)
Block(-7,8,2,OBSIDIAN:0)
RandomBlock(-7,8,3,CONCRETE:7,60,quark:iron_plate,20,STAINED_CLAY:12,15,STAINED_CLAY:15,5,AIR,7,IRON_BARS,12,CONCRETE:7,100)
RandomBlock(-7,8,4,AIR,90,IRON_TRAPDOOR:10,100)
RandomBlock(-7,8,5,AIR,90,IRON_TRAPDOOR:10,100)
RandomBlock(-7,8,6,AIR,90,IRON_TRAPDOOR:10,100)
RandomBlock(-7,8,7,CONCRETE:7,60,quark:iron_plate,20,STAINED_CLAY:12,15,STAINED_CLAY:15,5,AIR,7,IRON_BARS,12,CONCRETE:7,100)
RandomBlock(-7,8,8,AIR,90,IRON_TRAPDOOR:10,100)
Block(-7,9,-7,OBSIDIAN:0)
Block(-7,9,-6,OBSIDIAN:0)
RandomBlock(-7,9,-5,CONCRETE:7,60,quark:iron_plate,20,STAINED_CLAY:12,15,STAINED_CLAY:15,5,AIR,7,IRON_BARS,12,CONCRETE:7,100)
Block(-7,9,-4,OBSIDIAN:0)
Block(-7,9,-3,OBSIDIAN:0)
Block(-7,9,-2,OBSIDIAN:0)
Block(-7,9,-1,OBSIDIAN:0)
Block(-7,9,0,OBSIDIAN:0)
Block(-7,9,1,OBSIDIAN:0)
Block(-7,9,2,OBSIDIAN:0)
Block(-7,9,3,OBSIDIAN:0)
Block(-7,9,7,AIR:0)
RandomBlock(-7,9,8,STONE:6,85,CAULDRON:0,100)
Block(-7,10,-7,OBSIDIAN:0)
Block(-7,10,-6,OBSIDIAN:0)
RandomBlock(-7,10,-5,CONCRETE:7,60,quark:iron_plate,20,STAINED_CLAY:12,15,STAINED_CLAY:15,5,AIR,7,IRON_BARS,12,CONCRETE:7,100)
Block(-7,10,-4,OBSIDIAN:0)
Block(-7,10,-3,OBSIDIAN:0)
Block(-7,10,-2,OBSIDIAN:0)
Block(-7,10,-1,OBSIDIAN:0)
Block(-7,10,0,OBSIDIAN:0)
Block(-7,10,1,OBSIDIAN:0)
Block(-7,10,2,OBSIDIAN:0)
Block(-7,10,3,OBSIDIAN:0)
RandomBlock(-7,10,4,AIR,90,IRON_TRAPDOOR:2,100)
RandomBlock(-7,10,5,AIR,90,IRON_TRAPDOOR:1,100)
Block(-7,10,6,AIR:0)
Block(-7,10,7,AIR:0)
RandomBlock(-7,10,8,AIR,90,IRON_TRAPDOOR:1,100)
Block(-7,11,-7,OBSIDIAN:0)
Block(-7,11,-6,OBSIDIAN:0)
RandomBlock(-7,11,-5,CONCRETE:7,60,quark:iron_plate,20,STAINED_CLAY:12,15,STAINED_CLAY:15,5,AIR,7,IRON_BARS,12,CONCRETE:7,100)
Block(-7,11,-4,OBSIDIAN:0)
Block(-7,11,-3,OBSIDIAN:0)
Block(-7,11,-2,OBSIDIAN:0)
Block(-7,11,-1,OBSIDIAN:0)
Block(-7,11,0,OBSIDIAN:0)
Block(-7,11,1,OBSIDIAN:0)
Block(-7,11,2,OBSIDIAN:0)
Block(-7,11,3,OBSIDIAN:0)
Block(-7,11,4,AIR:0)
Block(-7,11,5,AIR:0)
Block(-7,11,6,AIR:0)
Block(-7,11,7,AIR:0)
Block(-7,11,8,AIR:0)
RandomBlock(-7,12,-7,CONCRETE:7,60,quark:iron_plate,20,STAINED_CLAY:12,15,STAINED_CLAY:15,5,AIR,7,IRON_BARS,12,CONCRETE:7,100)
RandomBlock(-7,12,-6,CONCRETE:7,60,quark:iron_plate,20,STAINED_CLAY:12,15,STAINED_CLAY:15,5,AIR,7,IRON_BARS,12,CONCRETE:7,100)
RandomBlock(-7,12,-5,CONCRETE:7,60,quark:iron_plate,20,STAINED_CLAY:12,15,STAINED_CLAY:15,5,AIR,7,IRON_BARS,12,CONCRETE:7,100)
Block(-7,12,-4,OBSIDIAN:0)
Block(-7,12,-3,OBSIDIAN:0)
Block(-7,12,-2,OBSIDIAN:0)
Block(-7,12,-1,OBSIDIAN:0)
Block(-7,12,0,OBSIDIAN:0)
Block(-7,12,1,OBSIDIAN:0)
Block(-7,12,2,OBSIDIAN:0)
RandomBlock(-7,12,3,CONCRETE:7,60,quark:iron_plate,20,STAINED_CLAY:12,15,STAINED_CLAY:15,5,AIR,7,IRON_BARS,12,CONCRETE:7,100)
RandomBlock(-7,12,4,AIR,90,IRON_TRAPDOOR:9,100)
RandomBlock(-7,12,5,AIR,90,IRON_TRAPDOOR:10,100)
RandomBlock(-7,12,6,AIR,90,IRON_TRAPDOOR:8,100)
RandomBlock(-7,12,7,CONCRETE:7,60,quark:iron_plate,20,STAINED_CLAY:12,15,STAINED_CLAY:15,5,AIR,7,IRON_BARS,12,CONCRETE:7,100)
RandomBlock(-7,12,8,AIR,90,IRON_TRAPDOOR:9,100)
Block(-7,13,-7,OBSIDIAN:0)
Block(-7,13,-6,OBSIDIAN:0)
RandomBlock(-7,13,-5,CONCRETE:7,60,quark:iron_plate,20,STAINED_CLAY:12,15,STAINED_CLAY:15,5,AIR,7,IRON_BARS,12,CONCRETE:7,100)
Block(-7,13,-4,OBSIDIAN:0)
Block(-7,13,-3,OBSIDIAN:0)
Block(-7,13,-2,OBSIDIAN:0)
Block(-7,13,-1,OBSIDIAN:0)
Block(-7,13,0,OBSIDIAN:0)
Block(-7,13,1,OBSIDIAN:0)
Block(-7,13,2,OBSIDIAN:0)
Block(-7,13,3,OBSIDIAN:0)
Block(-7,13,4,AIR:0)
Block(-7,13,5,AIR:0)
Block(-7,13,6,AIR:0)
Block(-7,13,7,AIR:0)
Block(-7,13,8,AIR:0)
Block(-7,14,-7,OBSIDIAN:0)
Block(-7,14,-6,OBSIDIAN:0)
RandomBlock(-7,14,-5,CONCRETE:7,60,quark:iron_plate,20,STAINED_CLAY:12,15,STAINED_CLAY:15,5,AIR,7,IRON_BARS,12,CONCRETE:7,100)
Block(-7,14,-4,OBSIDIAN:0)
Block(-7,14,-3,OBSIDIAN:0)
Block(-7,14,-2,OBSIDIAN:0)
Block(-7,14,-1,OBSIDIAN:0)
Block(-7,14,0,OBSIDIAN:0)
Block(-7,14,1,OBSIDIAN:0)
Block(-7,14,2,OBSIDIAN:0)
Block(-7,14,3,OBSIDIAN:0)
Block(-7,14,4,STEP:8)
Block(-7,14,5,STEP:8)
Block(-7,14,6,STEP:8)
RandomBlock(-7,14,7,CONCRETE:7,60,quark:iron_plate,20,STAINED_CLAY:12,15,STAINED_CLAY:15,5,AIR,7,IRON_BARS,12,CONCRETE:7,100)
Block(-7,14,8,STEP:8)
RandomBlock(-7,15,-7,CONCRETE:7,60,quark:iron_plate,20,STAINED_CLAY:12,15,STAINED_CLAY:15,5,AIR,7,IRON_BARS,12,CONCRETE:7,100)
RandomBlock(-7,15,-6,CONCRETE:7,60,quark:iron_plate,20,STAINED_CLAY:12,15,STAINED_CLAY:15,5,AIR,7,IRON_BARS,12,CONCRETE:7,100)
RandomBlock(-7,15,-5,CONCRETE:7,60,quark:iron_plate,20,STAINED_CLAY:12,15,STAINED_CLAY:15,5,AIR,7,IRON_BARS,12,CONCRETE:7,100)
RandomBlock(-7,15,-4,CONCRETE:7,60,quark:iron_plate,20,STAINED_CLAY:12,15,STAINED_CLAY:15,5,AIR,7,IRON_BARS,12,CONCRETE:7,100)
RandomBlock(-7,15,-3,CONCRETE:7,60,quark:iron_plate,20,STAINED_CLAY:12,15,STAINED_CLAY:15,5,AIR,7,IRON_BARS,12,CONCRETE:7,100)
RandomBlock(-7,15,-2,CONCRETE:7,60,quark:iron_plate,20,STAINED_CLAY:12,15,STAINED_CLAY:15,5,AIR,7,IRON_BARS,12,CONCRETE:7,100)
RandomBlock(-7,15,-1,CONCRETE:7,60,quark:iron_plate,20,STAINED_CLAY:12,15,STAINED_CLAY:15,5,AIR,7,IRON_BARS,12,CONCRETE:7,100)
RandomBlock(-7,15,0,CONCRETE:7,60,quark:iron_plate,20,STAINED_CLAY:12,15,STAINED_CLAY:15,5,AIR,7,IRON_BARS,12,CONCRETE:7,100)
RandomBlock(-7,15,1,CONCRETE:7,60,quark:iron_plate,20,STAINED_CLAY:12,15,STAINED_CLAY:15,5,AIR,7,IRON_BARS,12,CONCRETE:7,100)
RandomBlock(-7,15,2,CONCRETE:7,60,quark:iron_plate,20,STAINED_CLAY:12,15,STAINED_CLAY:15,5,AIR,7,IRON_BARS,12,CONCRETE:7,100)
RandomBlock(-7,15,3,CONCRETE:7,60,quark:iron_plate,20,STAINED_CLAY:12,15,STAINED_CLAY:15,5,AIR,7,IRON_BARS,12,CONCRETE:7,100)
RandomBlock(-7,15,4,CONCRETE:7,60,quark:iron_plate,20,STAINED_CLAY:12,15,STAINED_CLAY:15,5,AIR,7,IRON_BARS,12,CONCRETE:7,100)
RandomBlock(-7,15,5,CONCRETE:7,60,quark:iron_plate,20,STAINED_CLAY:12,15,STAINED_CLAY:15,5,AIR,7,IRON_BARS,12,CONCRETE:7,100)
RandomBlock(-7,15,6,CONCRETE:7,60,quark:iron_plate,20,STAINED_CLAY:12,15,STAINED_CLAY:15,5,AIR,7,IRON_BARS,12,CONCRETE:7,100)
RandomBlock(-7,15,7,CONCRETE:7,60,quark:iron_plate,20,STAINED_CLAY:12,15,STAINED_CLAY:15,5,AIR,7,IRON_BARS,12,CONCRETE:7,100)
RandomBlock(-7,15,8,CONCRETE:7,60,quark:iron_plate,20,STAINED_CLAY:12,15,STAINED_CLAY:15,5,AIR,7,IRON_BARS,12,CONCRETE:7,100)
Block(-7,16,-7,OBSIDIAN:0)
Block(-7,16,-6,OBSIDIAN:0)
Block(-7,16,-5,OBSIDIAN:0)
Block(-7,16,-4,OBSIDIAN:0)
Block(-7,16,-3,OBSIDIAN:0)
Block(-7,16,-2,OBSIDIAN:0)
Block(-7,16,-1,OBSIDIAN:0)
Block(-7,16,0,OBSIDIAN:0)
Block(-7,16,1,OBSIDIAN:0)
Block(-7,16,2,OBSIDIAN:0)
Block(-7,16,3,OBSIDIAN:0)
Block(-7,16,4,OBSIDIAN:0)
Block(-7,16,5,OBSIDIAN:0)
Block(-7,16,6,OBSIDIAN:0)
Block(-7,16,7,OBSIDIAN:0)
Block(-7,16,8,OBSIDIAN:0)
RandomBlock(-7,17,-7,CONCRETE:7,60,quark:iron_plate,20,STAINED_CLAY:12,15,STAINED_CLAY:15,5,AIR,7,IRON_BARS,12,CONCRETE:7,100)
RandomBlock(-7,17,-6,CONCRETE:7,60,quark:iron_plate,20,STAINED_CLAY:12,15,STAINED_CLAY:15,5,AIR,7,IRON_BARS,12,CONCRETE:7,100)
RandomBlock(-7,17,-5,CONCRETE:7,60,quark:iron_plate,20,STAINED_CLAY:12,15,STAINED_CLAY:15,5,AIR,7,IRON_BARS,12,CONCRETE:7,100)
RandomBlock(-7,17,-4,CONCRETE:7,60,quark:iron_plate,20,STAINED_CLAY:12,15,STAINED_CLAY:15,5,AIR,7,IRON_BARS,12,CONCRETE:7,100)
RandomBlock(-7,17,-3,CONCRETE:7,60,quark:iron_plate,20,STAINED_CLAY:12,15,STAINED_CLAY:15,5,AIR,7,IRON_BARS,12,CONCRETE:7,100)
RandomBlock(-7,17,-2,CONCRETE:7,60,quark:iron_plate,20,STAINED_CLAY:12,15,STAINED_CLAY:15,5,AIR,7,IRON_BARS,12,CONCRETE:7,100)
RandomBlock(-7,17,-1,CONCRETE:7,60,quark:iron_plate,20,STAINED_CLAY:12,15,STAINED_CLAY:15,5,AIR,7,IRON_BARS,12,CONCRETE:7,100)
RandomBlock(-7,17,0,CONCRETE:7,60,quark:iron_plate,20,STAINED_CLAY:12,15,STAINED_CLAY:15,5,AIR,7,IRON_BARS,12,CONCRETE:7,100)
RandomBlock(-7,17,1,CONCRETE:7,60,quark:iron_plate,20,STAINED_CLAY:12,15,STAINED_CLAY:15,5,AIR,7,IRON_BARS,12,CONCRETE:7,100)
RandomBlock(-7,17,2,CONCRETE:7,60,quark:iron_plate,20,STAINED_CLAY:12,15,STAINED_CLAY:15,5,AIR,7,IRON_BARS,12,CONCRETE:7,100)
RandomBlock(-7,17,3,CONCRETE:7,60,quark:iron_plate,20,STAINED_CLAY:12,15,STAINED_CLAY:15,5,AIR,7,IRON_BARS,12,CONCRETE:7,100)
RandomBlock(-7,17,4,CONCRETE:7,60,quark:iron_plate,20,STAINED_CLAY:12,15,STAINED_CLAY:15,5,AIR,7,IRON_BARS,12,CONCRETE:7,100)
RandomBlock(-7,17,5,CONCRETE:7,60,quark:iron_plate,20,STAINED_CLAY:12,15,STAINED_CLAY:15,5,AIR,7,IRON_BARS,12,CONCRETE:7,100)
RandomBlock(-7,17,6,CONCRETE:7,60,quark:iron_plate,20,STAINED_CLAY:12,15,STAINED_CLAY:15,5,AIR,7,IRON_BARS,12,CONCRETE:7,100)
RandomBlock(-7,17,7,CONCRETE:7,60,quark:iron_plate,20,STAINED_CLAY:12,15,STAINED_CLAY:15,5,AIR,7,IRON_BARS,12,CONCRETE:7,100)
RandomBlock(-7,17,8,CONCRETE:7,60,quark:iron_plate,20,STAINED_CLAY:12,15,STAINED_CLAY:15,5,AIR,7,IRON_BARS,12,CONCRETE:7,100)
RandomBlock(-7,18,-3,CONCRETE:7,60,quark:iron_plate,20,STAINED_CLAY:12,15,STAINED_CLAY:15,5,AIR,7,IRON_BARS,12,CONCRETE:7,100)
Block(-7,18,-2,IRON_FENCE:0)
Block(-7,18,-1,IRON_FENCE:0)
Block(-7,18,0,IRON_FENCE:0)
Block(-7,18,1,IRON_FENCE:0)
RandomBlock(-7,18,2,CONCRETE:7,60,quark:iron_plate,20,STAINED_CLAY:12,15,STAINED_CLAY:15,5,AIR,7,IRON_BARS,12,CONCRETE:7,100)
RandomBlock(-7,18,3,CONCRETE:7,60,quark:iron_plate,20,STAINED_CLAY:12,15,STAINED_CLAY:15,5,AIR,7,IRON_BARS,12,CONCRETE:7,100)
RandomBlock(-7,18,4,CONCRETE:7,60,quark:iron_plate,20,STAINED_CLAY:12,15,STAINED_CLAY:15,5,AIR,7,IRON_BARS,12,CONCRETE:7,100)
Block(-7,18,5,OBSIDIAN:0)
Block(-7,18,6,OBSIDIAN:0)
Block(-7,18,7,OBSIDIAN:0)
Block(-7,18,8,OBSIDIAN:0)
RandomBlock(-7,19,-3,CONCRETE:7,60,quark:iron_plate,20,STAINED_CLAY:12,15,STAINED_CLAY:15,5,AIR,7,IRON_BARS,12,CONCRETE:7,100)
Block(-7,19,-2,IRON_FENCE:0)
Block(-7,19,1,IRON_FENCE:0)
RandomBlock(-7,19,2,CONCRETE:7,60,quark:iron_plate,20,STAINED_CLAY:12,15,STAINED_CLAY:15,5,AIR,7,IRON_BARS,12,CONCRETE:7,100)
RandomBlock(-7,19,3,CONCRETE:7,60,quark:iron_plate,20,STAINED_CLAY:12,15,STAINED_CLAY:15,5,AIR,7,IRON_BARS,12,CONCRETE:7,100)
RandomBlock(-7,19,4,CONCRETE:7,60,quark:iron_plate,20,STAINED_CLAY:12,15,STAINED_CLAY:15,5,AIR,7,IRON_BARS,12,CONCRETE:7,100)
Block(-7,19,5,OBSIDIAN:0)
Block(-7,19,6,OBSIDIAN:0)
Block(-7,19,7,OBSIDIAN:0)
Block(-7,19,8,OBSIDIAN:0)
RandomBlock(-7,20,-3,CONCRETE:7,60,quark:iron_plate,20,STAINED_CLAY:12,15,STAINED_CLAY:15,5,AIR,7,IRON_BARS,12,CONCRETE:7,100)
Block(-7,20,-2,IRON_FENCE:0)
Block(-7,20,-1,IRON_FENCE:0)
Block(-7,20,0,IRON_FENCE:0)
Block(-7,20,1,IRON_FENCE:0)
RandomBlock(-7,20,2,CONCRETE:7,60,quark:iron_plate,20,STAINED_CLAY:12,15,STAINED_CLAY:15,5,AIR,7,IRON_BARS,12,CONCRETE:7,100)
RandomBlock(-7,20,3,CONCRETE:7,60,quark:iron_plate,20,STAINED_CLAY:12,15,STAINED_CLAY:15,5,AIR,7,IRON_BARS,12,CONCRETE:7,100)
RandomBlock(-7,20,4,CONCRETE:7,60,quark:iron_plate,20,STAINED_CLAY:12,15,STAINED_CLAY:15,5,AIR,7,IRON_BARS,12,CONCRETE:7,100)
Block(-7,20,5,OBSIDIAN:0)
Block(-7,20,6,OBSIDIAN:0)
Block(-7,20,7,OBSIDIAN:0)
Block(-7,20,8,OBSIDIAN:0)
Block(-7,21,-7,STEP:8)
Block(-7,21,-6,STEP:8)
Block(-7,21,-5,STEP:8)
Block(-7,21,-4,STEP:8)
RandomBlock(-7,21,-3,CONCRETE:7,60,quark:iron_plate,20,STAINED_CLAY:12,15,STAINED_CLAY:15,5,AIR,7,IRON_BARS,12,CONCRETE:7,100)
RandomBlock(-7,21,-2,CONCRETE:7,60,quark:iron_plate,20,STAINED_CLAY:12,15,STAINED_CLAY:15,5,AIR,7,IRON_BARS,12,CONCRETE:7,100)
RandomBlock(-7,21,-1,CONCRETE:7,60,quark:iron_plate,20,STAINED_CLAY:12,15,STAINED_CLAY:15,5,AIR,7,IRON_BARS,12,CONCRETE:7,100)
RandomBlock(-7,21,0,CONCRETE:7,60,quark:iron_plate,20,STAINED_CLAY:12,15,STAINED_CLAY:15,5,AIR,7,IRON_BARS,12,CONCRETE:7,100)
RandomBlock(-7,21,1,CONCRETE:7,60,quark:iron_plate,20,STAINED_CLAY:12,15,STAINED_CLAY:15,5,AIR,7,IRON_BARS,12,CONCRETE:7,100)
RandomBlock(-7,21,2,CONCRETE:7,60,quark:iron_plate,20,STAINED_CLAY:12,15,STAINED_CLAY:15,5,AIR,7,IRON_BARS,12,CONCRETE:7,100)
RandomBlock(-7,21,3,CONCRETE:7,60,quark:iron_plate,20,STAINED_CLAY:12,15,STAINED_CLAY:15,5,AIR,7,IRON_BARS,12,CONCRETE:7,100)
RandomBlock(-7,21,4,CONCRETE:7,60,quark:iron_plate,20,STAINED_CLAY:12,15,STAINED_CLAY:15,5,AIR,7,IRON_BARS,12,CONCRETE:7,100)
Block(-7,21,5,OBSIDIAN:0)
Block(-7,21,6,OBSIDIAN:0)
Block(-7,21,7,OBSIDIAN:0)
Block(-7,21,8,OBSIDIAN:0)
RandomBlock(-7,22,-7,CONCRETE:7,60,quark:iron_plate,20,STAINED_CLAY:12,15,STAINED_CLAY:15,5,AIR,7,IRON_BARS,12,CONCRETE:7,100)
RandomBlock(-7,22,-6,CONCRETE:7,60,quark:iron_plate,20,STAINED_CLAY:12,15,STAINED_CLAY:15,5,AIR,7,IRON_BARS,12,CONCRETE:7,100)
RandomBlock(-7,22,-5,CONCRETE:7,60,quark:iron_plate,20,STAINED_CLAY:12,15,STAINED_CLAY:15,5,AIR,7,IRON_BARS,12,CONCRETE:7,100)
RandomBlock(-7,22,-4,CONCRETE:7,60,quark:iron_plate,20,STAINED_CLAY:12,15,STAINED_CLAY:15,5,AIR,7,IRON_BARS,12,CONCRETE:7,100)
RandomBlock(-7,22,-3,CONCRETE:7,60,quark:iron_plate,20,STAINED_CLAY:12,15,STAINED_CLAY:15,5,AIR,7,IRON_BARS,12,CONCRETE:7,100)
RandomBlock(-7,22,-2,CONCRETE:7,60,quark:iron_plate,20,STAINED_CLAY:12,15,STAINED_CLAY:15,5,AIR,7,IRON_BARS,12,CONCRETE:7,100)
RandomBlock(-7,22,-1,CONCRETE:7,60,quark:iron_plate,20,STAINED_CLAY:12,15,STAINED_CLAY:15,5,AIR,7,IRON_BARS,12,CONCRETE:7,100)
RandomBlock(-7,22,0,CONCRETE:7,60,quark:iron_plate,20,STAINED_CLAY:12,15,STAINED_CLAY:15,5,AIR,7,IRON_BARS,12,CONCRETE:7,100)
RandomBlock(-7,22,1,CONCRETE:7,60,quark:iron_plate,20,STAINED_CLAY:12,15,STAINED_CLAY:15,5,AIR,7,IRON_BARS,12,CONCRETE:7,100)
RandomBlock(-7,22,2,CONCRETE:7,60,quark:iron_plate,20,STAINED_CLAY:12,15,STAINED_CLAY:15,5,AIR,7,IRON_BARS,12,CONCRETE:7,100)
RandomBlock(-7,22,3,CONCRETE:7,60,quark:iron_plate,20,STAINED_CLAY:12,15,STAINED_CLAY:15,5,AIR,7,IRON_BARS,12,CONCRETE:7,100)
RandomBlock(-7,22,4,CONCRETE:7,60,quark:iron_plate,20,STAINED_CLAY:12,15,STAINED_CLAY:15,5,AIR,7,IRON_BARS,12,CONCRETE:7,100)
Block(-7,22,5,OBSIDIAN:0)
Block(-7,22,6,OBSIDIAN:0)
Block(-7,22,7,OBSIDIAN:0)
Block(-7,22,8,OBSIDIAN:0)
Block(-7,23,-7,OBSIDIAN:0)
Block(-7,23,-6,OBSIDIAN:0)
Block(-7,23,-5,OBSIDIAN:0)
Block(-7,23,-4,OBSIDIAN:0)
Block(-7,23,-3,OBSIDIAN:0)
Block(-7,23,-2,OBSIDIAN:0)
Block(-7,23,-1,OBSIDIAN:0)
Block(-7,23,0,OBSIDIAN:0)
Block(-7,23,1,OBSIDIAN:0)
Block(-7,23,2,OBSIDIAN:0)
Block(-7,23,3,OBSIDIAN:0)
Block(-7,23,4,OBSIDIAN:0)
Block(-7,23,5,OBSIDIAN:0)
Block(-7,23,6,OBSIDIAN:0)
Block(-7,23,7,CONCRETE:0)
Block(-7,23,8,CONCRETE:0)
Block(-7,24,-7,CONCRETE:0)
Block(-7,24,-6,CONCRETE:15)
Block(-7,24,-5,CONCRETE:0)
Block(-7,24,-4,CONCRETE:0)
Block(-7,24,-3,CONCRETE:15)
Block(-7,24,-2,CONCRETE:0)
Block(-7,24,-1,CONCRETE:0)
Block(-7,24,0,CONCRETE:0)
Block(-7,24,1,CONCRETE:0)
Block(-7,24,2,STONE:4)
Block(-7,24,3,CONCRETE:0)
RandomBlock(-7,24,4,CONCRETE:7,60,quark:iron_plate,20,STAINED_CLAY:12,15,STAINED_CLAY:15,5,AIR,7,IRON_BARS,12,CONCRETE:7,100)
Block(-7,24,5,CONCRETE:0)
Block(-7,24,6,QUARTZ_STAIRS:3)
Block(-7,25,-5,AIR)
Block(-7,25,-4,CONCRETE:0)
Block(-7,25,-3,AIR)
Block(-7,25,3,CONCRETE:0)
Block(-7,25,5,CONCRETE:0)
RandomBlock(-7,26,-4,STAINED_GLASS_PANE:15,40,AIR,100)
Block(-7,26,2,QUARTZ_STAIRS:6)
Block(-7,26,3,CONCRETE:0)
Block(-7,26,5,CONCRETE:0)
Block(-7,27,0,QUARTZ_STAIRS:6)
Block(-7,27,1,CONCRETE:0)
Block(-7,27,2,CONCRETE:0)
Block(-7,27,3,CONCRETE:0)
Block(-7,27,5,CONCRETE:0)
Block(-7,28,-6,IRON_FENCE:0)
Block(-7,28,-3,QUARTZ_STAIRS:6)
Block(-7,28,-2,CONCRETE:0)
Block(-7,28,-1,CONCRETE:0)
Block(-7,28,0,CONCRETE:0)
Block(-7,28,1,QUARTZ_STAIRS:3)
Block(-7,28,3,CONCRETE:0)
Block(-7,28,5,CONCRETE:0)
Block(-7,28,6,QUARTZ_STAIRS:7)
Block(-7,29,-7,STEP:15)
Block(-7,29,-6,DOUBLE_STEP:7)
Block(-7,29,-5,QUARTZ_STAIRS:6)
Block(-7,29,-4,CONCRETE:0)
Block(-7,29,-3,CONCRETE:0)
Block(-7,29,-2,STEP:15)
Block(-7,29,-1,STEP:15)
Block(-7,29,0,STEP:15)
Block(-7,29,1,STEP:15)
Block(-7,29,2,QUARTZ_STAIRS:6)
Block(-7,29,3,CONCRETE:0)
Block(-7,29,4,CONCRETE:0)
Block(-7,29,5,CONCRETE:0)
Block(-7,29,6,CONCRETE:0)
Block(-7,29,7,QUARTZ_STAIRS:7)
RandomBlock(-7,30,-7,STAINED_GLASS_PANE:15,40,AIR,100)
RandomBlock(-7,30,-6,STAINED_GLASS_PANE:15,40,AIR,100)
RandomBlock(-7,30,-5,STAINED_GLASS_PANE:15,40,AIR,100)
RandomBlock(-7,30,-4,STAINED_GLASS_PANE:15,40,AIR,100)
RandomBlock(-7,30,-3,STAINED_GLASS_PANE:15,40,AIR,100)
RandomBlock(-7,30,-2,STAINED_GLASS_PANE:15,40,AIR,100)
RandomBlock(-7,30,-1,STAINED_GLASS_PANE:15,40,AIR,100)
RandomBlock(-7,30,0,STAINED_GLASS_PANE:15,40,AIR,100)
RandomBlock(-7,30,1,STAINED_GLASS_PANE:15,40,AIR,100)
Block(-7,30,2,CONCRETE:0)
Block(-7,30,4,CONCRETE:0)
Block(-7,30,5,CONCRETE:0)
Block(-7,30,6,CONCRETE:0)
Block(-7,30,7,COBBLE_WALL:0)
Block(-7,31,2,STEP:0)
Block(-7,31,4,CONCRETE:0)
Block(-7,31,5,CONCRETE:0)
Block(-7,31,6,CONCRETE:0)
Block(-7,32,3,QUARTZ_STAIRS:6)
Block(-7,32,4,CONCRETE:0)
Block(-7,32,5,CONCRETE:0)
Block(-7,32,6,CONCRETE:0)
Block(-7,33,1,CONCRETE:0)
Block(-7,33,2,CONCRETE:0)
Block(-7,33,3,CONCRETE:0)
Block(-7,33,4,CONCRETE:0)
Block(-7,33,5,CONCRETE:0)
Block(-7,33,6,CONCRETE:0)
Block(-7,33,7,QUARTZ_STAIRS:7)
Block(-7,34,1,CONCRETE:0)
RandomBlock(-7,34,4,CONCRETE:7,60,quark:iron_plate,20,STAINED_CLAY:12,15,STAINED_CLAY:15,5,AIR,7,IRON_BARS,12,CONCRETE:7,100)
Block(-7,34,5,STEP:7)
Block(-7,34,7,COBBLE_WALL:0)
Block(-7,35,1,STEP:0)
RandomBlock(-7,35,4,STAINED_GLASS_PANE:15,40,AIR,100)
RandomBlock(-7,36,4,STAINED_GLASS_PANE:15,40,AIR,100)
RandomBlock(-7,37,4,STAINED_GLASS_PANE:15,40,AIR,100)
RandomBlock(-7,38,4,STAINED_GLASS_PANE:15,40,AIR,100)
Block(-7,39,0,QUARTZ_STAIRS:5)
RandomBlock(-7,39,4,STAINED_GLASS_PANE:15,40,AIR,100)
Block(-7,39,5,QUARTZ_STAIRS:5)
Block(-7,40,0,CONCRETE:0)
Block(-7,40,2,STEP:15)
Block(-7,40,3,STEP:15)
Block(-7,40,4,QUARTZ_STAIRS:6)
Block(-7,40,5,CONCRETE:0)
Block(-7,40,6,STEP:8)
RandomBlock(-7,41,0,CONCRETE:7,60,quark:iron_plate,20,STAINED_CLAY:12,15,STAINED_CLAY:15,5,AIR,7,IRON_BARS,12,CONCRETE:7,100)
Block(-7,41,1,STEP:7)
Block(-7,41,2,STEP:7)
Block(-7,41,5,STEP:0)
RandomBlock(-7,42,0,CONCRETE:7,60,quark:iron_plate,20,STAINED_CLAY:12,15,STAINED_CLAY:15,5,AIR,7,IRON_BARS,12,CONCRETE:7,100)
RandomBlock(-7,43,0,CONCRETE:7,60,quark:iron_plate,20,STAINED_CLAY:12,15,STAINED_CLAY:15,5,AIR,7,IRON_BARS,12,CONCRETE:7,100)
RandomBlock(-7,44,0,CONCRETE:7,60,quark:iron_plate,20,STAINED_CLAY:12,15,STAINED_CLAY:15,5,AIR,7,IRON_BARS,12,CONCRETE:7,100)
RandomBlock(-7,45,0,CONCRETE:7,60,quark:iron_plate,20,STAINED_CLAY:12,15,STAINED_CLAY:15,5,AIR,7,IRON_BARS,12,CONCRETE:7,100)
Block(-7,46,0,CONCRETE:0)
RandomBlock(-7,47,-2,CONCRETE:7,60,quark:iron_plate,20,STAINED_CLAY:12,15,STAINED_CLAY:15,5,AIR,7,IRON_BARS,12,CONCRETE:7,100)
RandomBlock(-7,47,-1,CONCRETE:7,60,quark:iron_plate,20,STAINED_CLAY:12,15,STAINED_CLAY:15,5,AIR,7,IRON_BARS,12,CONCRETE:7,100)
Block(-7,47,0,QUARTZ_STAIRS:3)
RandomBlock(-7,48,-2,CONCRETE:7,60,quark:iron_plate,20,STAINED_CLAY:12,15,STAINED_CLAY:15,5,AIR,7,IRON_BARS,12,CONCRETE:7,100)
RandomBlock(-7,48,-1,CONCRETE:7,60,quark:iron_plate,20,STAINED_CLAY:12,15,STAINED_CLAY:15,5,AIR,7,IRON_BARS,12,CONCRETE:7,100)
RandomBlock(-7,49,-3,CONCRETE:7,60,quark:iron_plate,20,STAINED_CLAY:12,15,STAINED_CLAY:15,5,AIR,7,IRON_BARS,12,CONCRETE:7,100)
Block(-7,50,-6,CONCRETE:0)
Block(-7,50,-5,CONCRETE:0)
Block(-7,50,-4,CONCRETE:0)
RandomBlock(-7,51,-7,CONCRETE:7,60,quark:iron_plate,20,STAINED_CLAY:12,15,STAINED_CLAY:15,5,AIR,7,IRON_BARS,12,CONCRETE:7,100)
RandomBlock(-6,0,-7,CONCRETE:7,60,quark:iron_plate,20,STAINED_CLAY:12,15,STAINED_CLAY:15,5,AIR,7,IRON_BARS,12,CONCRETE:7,100)
RandomBlock(-6,0,-6,CONCRETE:7,60,quark:iron_plate,20,STAINED_CLAY:12,15,STAINED_CLAY:15,5,AIR,7,IRON_BARS,12,CONCRETE:7,100)
RandomBlock(-6,0,-5,CONCRETE:7,60,quark:iron_plate,20,STAINED_CLAY:12,15,STAINED_CLAY:15,5,AIR,7,IRON_BARS,12,CONCRETE:7,100)
RandomBlock(-6,0,-4,CONCRETE:7,60,quark:iron_plate,20,STAINED_CLAY:12,15,STAINED_CLAY:15,5,AIR,7,IRON_BARS,12,CONCRETE:7,100)
RandomBlock(-6,0,-3,CONCRETE:7,60,quark:iron_plate,20,STAINED_CLAY:12,15,STAINED_CLAY:15,5,AIR,7,IRON_BARS,12,CONCRETE:7,100)
RandomBlock(-6,0,-2,CONCRETE:7,60,quark:iron_plate,20,STAINED_CLAY:12,15,STAINED_CLAY:15,5,AIR,7,IRON_BARS,12,CONCRETE:7,100)
RandomBlock(-6,0,-1,CONCRETE:7,60,quark:iron_plate,20,STAINED_CLAY:12,15,STAINED_CLAY:15,5,AIR,7,IRON_BARS,12,CONCRETE:7,100)
RandomBlock(-6,0,0,CONCRETE:7,60,quark:iron_plate,20,STAINED_CLAY:12,15,STAINED_CLAY:15,5,AIR,7,IRON_BARS,12,CONCRETE:7,100)
RandomBlock(-6,0,1,CONCRETE:7,60,quark:iron_plate,20,STAINED_CLAY:12,15,STAINED_CLAY:15,5,AIR,7,IRON_BARS,12,CONCRETE:7,100)
RandomBlock(-6,0,2,CONCRETE:7,60,quark:iron_plate,20,STAINED_CLAY:12,15,STAINED_CLAY:15,5,AIR,7,IRON_BARS,12,CONCRETE:7,100)
RandomBlock(-6,0,3,CONCRETE:7,60,quark:iron_plate,20,STAINED_CLAY:12,15,STAINED_CLAY:15,5,AIR,7,IRON_BARS,12,CONCRETE:7,100)
RandomBlock(-6,0,4,CONCRETE:7,60,quark:iron_plate,20,STAINED_CLAY:12,15,STAINED_CLAY:15,5,AIR,7,IRON_BARS,12,CONCRETE:7,100)
RandomBlock(-6,0,5,CONCRETE:7,60,quark:iron_plate,20,STAINED_CLAY:12,15,STAINED_CLAY:15,5,AIR,7,IRON_BARS,12,CONCRETE:7,100)
RandomBlock(-6,0,6,CONCRETE:7,60,quark:iron_plate,20,STAINED_CLAY:12,15,STAINED_CLAY:15,5,AIR,7,IRON_BARS,12,CONCRETE:7,100)
RandomBlock(-6,0,7,CONCRETE:7,60,quark:iron_plate,20,STAINED_CLAY:12,15,STAINED_CLAY:15,5,AIR,7,IRON_BARS,12,CONCRETE:7,100)
RandomBlock(-6,0,8,CONCRETE:7,60,quark:iron_plate,20,STAINED_CLAY:12,15,STAINED_CLAY:15,5,AIR,7,IRON_BARS,12,CONCRETE:7,100)
Block(-6,1,-7,OBSIDIAN:0)
Block(-6,1,-6,OBSIDIAN:0)
Block(-6,1,-5,OBSIDIAN:0)
Block(-6,1,-4,OBSIDIAN:0)
Block(-6,1,-3,OBSIDIAN:0)
Block(-6,1,-2,OBSIDIAN:0)
Block(-6,1,-1,OBSIDIAN:0)
Block(-6,1,0,OBSIDIAN:0)
Block(-6,1,1,OBSIDIAN:0)
Block(-6,1,2,OBSIDIAN:0)
Block(-6,1,3,OBSIDIAN:0)
Block(-6,1,4,OBSIDIAN:0)
Block(-6,1,5,OBSIDIAN:0)
Block(-6,1,6,OBSIDIAN:0)
Block(-6,1,7,OBSIDIAN:0)
Block(-6,1,8,OBSIDIAN:0)
RandomBlock(-6,2,-7,CONCRETE:7,60,quark:iron_plate,20,STAINED_CLAY:12,15,STAINED_CLAY:15,5,AIR,7,IRON_BARS,12,CONCRETE:7,100)
RandomBlock(-6,2,-6,CONCRETE:7,60,quark:iron_plate,20,STAINED_CLAY:12,15,STAINED_CLAY:15,5,AIR,7,IRON_BARS,12,CONCRETE:7,100)
RandomBlock(-6,2,-5,CONCRETE:7,60,quark:iron_plate,20,STAINED_CLAY:12,15,STAINED_CLAY:15,5,AIR,7,IRON_BARS,12,CONCRETE:7,100)
RandomBlock(-6,2,-4,CONCRETE:7,60,quark:iron_plate,20,STAINED_CLAY:12,15,STAINED_CLAY:15,5,AIR,7,IRON_BARS,12,CONCRETE:7,100)
RandomBlock(-6,2,-3,CONCRETE:7,60,quark:iron_plate,20,STAINED_CLAY:12,15,STAINED_CLAY:15,5,AIR,7,IRON_BARS,12,CONCRETE:7,100)
RandomBlock(-6,2,-2,CONCRETE:7,60,quark:iron_plate,20,STAINED_CLAY:12,15,STAINED_CLAY:15,5,AIR,7,IRON_BARS,12,CONCRETE:7,100)
RandomBlock(-6,2,-1,CONCRETE:7,60,quark:iron_plate,20,STAINED_CLAY:12,15,STAINED_CLAY:15,5,AIR,7,IRON_BARS,12,CONCRETE:7,100)
RandomBlock(-6,2,0,CONCRETE:7,60,quark:iron_plate,20,STAINED_CLAY:12,15,STAINED_CLAY:15,5,AIR,7,IRON_BARS,12,CONCRETE:7,100)
RandomBlock(-6,2,1,CONCRETE:7,60,quark:iron_plate,20,STAINED_CLAY:12,15,STAINED_CLAY:15,5,AIR,7,IRON_BARS,12,CONCRETE:7,100)
RandomBlock(-6,2,2,CONCRETE:7,60,quark:iron_plate,20,STAINED_CLAY:12,15,STAINED_CLAY:15,5,AIR,7,IRON_BARS,12,CONCRETE:7,100)
RandomBlock(-6,2,3,CONCRETE:7,60,quark:iron_plate,20,STAINED_CLAY:12,15,STAINED_CLAY:15,5,AIR,7,IRON_BARS,12,CONCRETE:7,100)
RandomBlock(-6,2,4,CONCRETE:7,60,quark:iron_plate,20,STAINED_CLAY:12,15,STAINED_CLAY:15,5,AIR,7,IRON_BARS,12,CONCRETE:7,100)
RandomBlock(-6,2,5,CONCRETE:7,60,quark:iron_plate,20,STAINED_CLAY:12,15,STAINED_CLAY:15,5,AIR,7,IRON_BARS,12,CONCRETE:7,100)
RandomBlock(-6,2,6,CONCRETE:7,60,quark:iron_plate,20,STAINED_CLAY:12,15,STAINED_CLAY:15,5,AIR,7,IRON_BARS,12,CONCRETE:7,100)
RandomBlock(-6,2,7,CONCRETE:7,60,quark:iron_plate,20,STAINED_CLAY:12,15,STAINED_CLAY:15,5,AIR,7,IRON_BARS,12,CONCRETE:7,100)
RandomBlock(-6,2,8,CONCRETE:7,60,quark:iron_plate,20,STAINED_CLAY:12,15,STAINED_CLAY:15,5,AIR,7,IRON_BARS,12,CONCRETE:7,100)
RandomBlock(-6,3,-7,CONCRETE:7,60,quark:iron_plate,20,STAINED_CLAY:12,15,STAINED_CLAY:15,5,AIR,7,IRON_BARS,12,CONCRETE:7,100)
RandomBlock(-6,3,-6,CONCRETE:7,60,quark:iron_plate,20,STAINED_CLAY:12,15,STAINED_CLAY:15,5,AIR,7,IRON_BARS,12,CONCRETE:7,100)
RandomBlock(-6,3,-5,CONCRETE:7,60,quark:iron_plate,20,STAINED_CLAY:12,15,STAINED_CLAY:15,5,AIR,7,IRON_BARS,12,CONCRETE:7,100)
RandomBlock(-6,3,-4,CONCRETE:7,60,quark:iron_plate,20,STAINED_CLAY:12,15,STAINED_CLAY:15,5,AIR,7,IRON_BARS,12,CONCRETE:7,100)
RandomBlock(-6,3,-3,CONCRETE:7,60,quark:iron_plate,20,STAINED_CLAY:12,15,STAINED_CLAY:15,5,AIR,7,IRON_BARS,12,CONCRETE:7,100)
RandomBlock(-6,3,-2,CONCRETE:7,60,quark:iron_plate,20,STAINED_CLAY:12,15,STAINED_CLAY:15,5,AIR,7,IRON_BARS,12,CONCRETE:7,100)
RandomBlock(-6,3,-1,CONCRETE:7,60,quark:iron_plate,20,STAINED_CLAY:12,15,STAINED_CLAY:15,5,AIR,7,IRON_BARS,12,CONCRETE:7,100)
RandomBlock(-6,3,0,CONCRETE:7,60,quark:iron_plate,20,STAINED_CLAY:12,15,STAINED_CLAY:15,5,AIR,7,IRON_BARS,12,CONCRETE:7,100)
RandomBlock(-6,3,1,CONCRETE:7,60,quark:iron_plate,20,STAINED_CLAY:12,15,STAINED_CLAY:15,5,AIR,7,IRON_BARS,12,CONCRETE:7,100)
RandomBlock(-6,3,2,CONCRETE:7,60,quark:iron_plate,20,STAINED_CLAY:12,15,STAINED_CLAY:15,5,AIR,7,IRON_BARS,12,CONCRETE:7,100)
RandomBlock(-6,3,3,CONCRETE:7,60,quark:iron_plate,20,STAINED_CLAY:12,15,STAINED_CLAY:15,5,AIR,7,IRON_BARS,12,CONCRETE:7,100)
RandomBlock(-6,3,4,CONCRETE:7,60,quark:iron_plate,20,STAINED_CLAY:12,15,STAINED_CLAY:15,5,AIR,7,IRON_BARS,12,CONCRETE:7,100)
RandomBlock(-6,3,5,CONCRETE:7,60,quark:iron_plate,20,STAINED_CLAY:12,15,STAINED_CLAY:15,5,AIR,7,IRON_BARS,12,CONCRETE:7,100)
RandomBlock(-6,3,6,CONCRETE:7,60,quark:iron_plate,20,STAINED_CLAY:12,15,STAINED_CLAY:15,5,AIR,7,IRON_BARS,12,CONCRETE:7,100)
RandomBlock(-6,3,7,CONCRETE:7,60,quark:iron_plate,20,STAINED_CLAY:12,15,STAINED_CLAY:15,5,AIR,7,IRON_BARS,12,CONCRETE:7,100)
RandomBlock(-6,3,8,CONCRETE:7,60,quark:iron_plate,20,STAINED_CLAY:12,15,STAINED_CLAY:15,5,AIR,7,IRON_BARS,12,CONCRETE:7,100)
RandomBlock(-6,4,-7,CONCRETE:7,60,quark:iron_plate,20,STAINED_CLAY:12,15,STAINED_CLAY:15,5,AIR,7,IRON_BARS,12,CONCRETE:7,100)
RandomBlock(-6,4,-6,CONCRETE:7,60,quark:iron_plate,20,STAINED_CLAY:12,15,STAINED_CLAY:15,5,AIR,7,IRON_BARS,12,CONCRETE:7,100)
RandomBlock(-6,4,-5,CONCRETE:7,60,quark:iron_plate,20,STAINED_CLAY:12,15,STAINED_CLAY:15,5,AIR,7,IRON_BARS,12,CONCRETE:7,100)
RandomBlock(-6,4,-4,CONCRETE:7,60,quark:iron_plate,20,STAINED_CLAY:12,15,STAINED_CLAY:15,5,AIR,7,IRON_BARS,12,CONCRETE:7,100)
RandomBlock(-6,4,-3,CONCRETE:7,60,quark:iron_plate,20,STAINED_CLAY:12,15,STAINED_CLAY:15,5,AIR,7,IRON_BARS,12,CONCRETE:7,100)
RandomBlock(-6,4,-2,CONCRETE:7,60,quark:iron_plate,20,STAINED_CLAY:12,15,STAINED_CLAY:15,5,AIR,7,IRON_BARS,12,CONCRETE:7,100)
RandomBlock(-6,4,-1,CONCRETE:7,60,quark:iron_plate,20,STAINED_CLAY:12,15,STAINED_CLAY:15,5,AIR,7,IRON_BARS,12,CONCRETE:7,100)
RandomBlock(-6,4,0,CONCRETE:7,60,quark:iron_plate,20,STAINED_CLAY:12,15,STAINED_CLAY:15,5,AIR,7,IRON_BARS,12,CONCRETE:7,100)
RandomBlock(-6,4,1,CONCRETE:7,60,quark:iron_plate,20,STAINED_CLAY:12,15,STAINED_CLAY:15,5,AIR,7,IRON_BARS,12,CONCRETE:7,100)
RandomBlock(-6,4,2,CONCRETE:7,60,quark:iron_plate,20,STAINED_CLAY:12,15,STAINED_CLAY:15,5,AIR,7,IRON_BARS,12,CONCRETE:7,100)
RandomBlock(-6,4,3,CONCRETE:7,60,quark:iron_plate,20,STAINED_CLAY:12,15,STAINED_CLAY:15,5,AIR,7,IRON_BARS,12,CONCRETE:7,100)
RandomBlock(-6,4,4,CONCRETE:7,60,quark:iron_plate,20,STAINED_CLAY:12,15,STAINED_CLAY:15,5,AIR,7,IRON_BARS,12,CONCRETE:7,100)
RandomBlock(-6,4,5,CONCRETE:7,60,quark:iron_plate,20,STAINED_CLAY:12,15,STAINED_CLAY:15,5,AIR,7,IRON_BARS,12,CONCRETE:7,100)
RandomBlock(-6,4,6,CONCRETE:7,60,quark:iron_plate,20,STAINED_CLAY:12,15,STAINED_CLAY:15,5,AIR,7,IRON_BARS,12,CONCRETE:7,100)
RandomBlock(-6,4,7,CONCRETE:7,60,quark:iron_plate,20,STAINED_CLAY:12,15,STAINED_CLAY:15,5,AIR,7,IRON_BARS,12,CONCRETE:7,100)
RandomBlock(-6,4,8,CONCRETE:7,60,quark:iron_plate,20,STAINED_CLAY:12,15,STAINED_CLAY:15,5,AIR,7,IRON_BARS,12,CONCRETE:7,100)
Block(-6,5,-7,OBSIDIAN:0)
Block(-6,5,-6,OBSIDIAN:0)
Block(-6,5,-5,OBSIDIAN:0)
Block(-6,5,-4,OBSIDIAN:0)
Block(-6,5,-3,OBSIDIAN:0)
Block(-6,5,-2,OBSIDIAN:0)
Block(-6,5,-1,OBSIDIAN:0)
Block(-6,5,0,OBSIDIAN:0)
Block(-6,5,1,OBSIDIAN:0)
Block(-6,5,2,OBSIDIAN:0)
RandomBlock(-6,5,3,CONCRETE:7,60,quark:iron_plate,20,STAINED_CLAY:12,15,STAINED_CLAY:15,5,AIR,7,IRON_BARS,12,CONCRETE:7,100)
RandomBlock(-6,5,4,COBBLESTONE,65,FURNACE:3,../AllScraperData/skyscraper_8x6_01/169-furnaceC32R48.nbt,100)
Block(-6,5,5,STEP:8)
Block(-6,5,6,STEP:8)
Block(-6,5,7,STEP:8)
Block(-6,5,8,STEP:8)
Block(-6,6,-7,OBSIDIAN:0)
Block(-6,6,-6,OBSIDIAN:0)
Block(-6,6,-5,OBSIDIAN:0)
Block(-6,6,-4,OBSIDIAN:0)
Block(-6,6,-3,OBSIDIAN:0)
Block(-6,6,-2,OBSIDIAN:0)
Block(-6,6,-1,OBSIDIAN:0)
Block(-6,6,0,OBSIDIAN:0)
Block(-6,6,1,OBSIDIAN:0)
Block(-6,6,2,OBSIDIAN:0)
RandomBlock(-6,6,3,CONCRETE:7,60,quark:iron_plate,20,STAINED_CLAY:12,15,STAINED_CLAY:15,5,AIR,7,IRON_BARS,12,CONCRETE:7,100)
RandomBlock(-6,6,4,STONE:6,80,STONE:6,90,DROPPER:1,../../../../../Chests/Loot/toilet_loot.nbt,100)
Block(-6,6,5,LEVER:3)
Block(-6,6,6,AIR:0)
Block(-6,6,7,AIR:0)
Block(-6,6,8,AIR:0)
Block(-6,7,-7,OBSIDIAN:0)
Block(-6,7,-6,OBSIDIAN:0)
Block(-6,7,-5,OBSIDIAN:0)
Block(-6,7,-4,OBSIDIAN:0)
Block(-6,7,-3,OBSIDIAN:0)
Block(-6,7,-2,OBSIDIAN:0)
Block(-6,7,-1,OBSIDIAN:0)
Block(-6,7,0,OBSIDIAN:0)
Block(-6,7,1,OBSIDIAN:0)
Block(-6,7,2,OBSIDIAN:0)
RandomBlock(-6,7,3,CONCRETE:7,60,quark:iron_plate,20,STAINED_CLAY:12,15,STAINED_CLAY:15,5,AIR,7,IRON_BARS,12,CONCRETE:7,100)
Block(-6,7,4,REDSTONE_LAMP_OFF:0)
Block(-6,7,5,STEP:0)
Block(-6,7,6,STEP:0)
Block(-6,7,7,STEP:0)
Block(-6,7,8,STEP:0)
Block(-6,8,-7,OBSIDIAN:0)
Block(-6,8,-6,OBSIDIAN:0)
Block(-6,8,-5,OBSIDIAN:0)
Block(-6,8,-4,OBSIDIAN:0)
Block(-6,8,-3,OBSIDIAN:0)
Block(-6,8,-2,OBSIDIAN:0)
Block(-6,8,-1,OBSIDIAN:0)
Block(-6,8,0,OBSIDIAN:0)
Block(-6,8,1,OBSIDIAN:0)
Block(-6,8,2,OBSIDIAN:0)
RandomBlock(-6,8,3,CONCRETE:7,60,quark:iron_plate,20,STAINED_CLAY:12,15,STAINED_CLAY:15,5,AIR,7,IRON_BARS,12,CONCRETE:7,100)
RandomBlock(-6,8,4,CONCRETE:7,60,quark:iron_plate,20,STAINED_CLAY:12,15,STAINED_CLAY:15,5,AIR,7,IRON_BARS,12,CONCRETE:7,100)
RandomBlock(-6,8,5,CONCRETE:7,60,quark:iron_plate,20,STAINED_CLAY:12,15,STAINED_CLAY:15,5,AIR,7,IRON_BARS,12,CONCRETE:7,100)
RandomBlock(-6,8,6,CONCRETE:7,60,quark:iron_plate,20,STAINED_CLAY:12,15,STAINED_CLAY:15,5,AIR,7,IRON_BARS,12,CONCRETE:7,100)
RandomBlock(-6,8,7,CONCRETE:7,60,quark:iron_plate,20,STAINED_CLAY:12,15,STAINED_CLAY:15,5,AIR,7,IRON_BARS,12,CONCRETE:7,100)
RandomBlock(-6,8,8,CONCRETE:7,60,quark:iron_plate,20,STAINED_CLAY:12,15,STAINED_CLAY:15,5,AIR,7,IRON_BARS,12,CONCRETE:7,100)
Block(-6,9,-7,OBSIDIAN:0)
Block(-6,9,-6,OBSIDIAN:0)
Block(-6,9,-5,OBSIDIAN:0)
Block(-6,9,-4,OBSIDIAN:0)
Block(-6,9,-3,OBSIDIAN:0)
Block(-6,9,-2,OBSIDIAN:0)
Block(-6,9,-1,OBSIDIAN:0)
Block(-6,9,0,OBSIDIAN:0)
Block(-6,9,1,OBSIDIAN:0)
Block(-6,9,2,OBSIDIAN:0)
RandomBlock(-6,9,3,CONCRETE:7,60,quark:iron_plate,20,STAINED_CLAY:12,15,STAINED_CLAY:15,5,AIR,7,IRON_BARS,12,CONCRETE:7,100)
RandomBlock(-6,9,4,CONCRETE:7,60,quark:iron_plate,20,STAINED_CLAY:12,15,STAINED_CLAY:15,5,AIR,7,IRON_BARS,12,CONCRETE:7,100)
Block(-6,9,5,STEP:8)
Block(-6,9,6,STEP:8)
Block(-6,9,7,STEP:8)
Block(-6,9,8,STEP:8)
Block(-6,10,-7,OBSIDIAN:0)
Block(-6,10,-6,OBSIDIAN:0)
Block(-6,10,-5,OBSIDIAN:0)
Block(-6,10,-4,OBSIDIAN:0)
Block(-6,10,-3,OBSIDIAN:0)
Block(-6,10,-2,OBSIDIAN:0)
Block(-6,10,-1,OBSIDIAN:0)
Block(-6,10,0,OBSIDIAN:0)
Block(-6,10,1,OBSIDIAN:0)
Block(-6,10,2,OBSIDIAN:0)
RandomBlock(-6,10,3,CONCRETE:7,60,quark:iron_plate,20,STAINED_CLAY:12,15,STAINED_CLAY:15,5,AIR,7,IRON_BARS,12,CONCRETE:7,100)
RandomBlock(-6,10,4,CONCRETE:7,60,quark:iron_plate,20,STAINED_CLAY:12,15,STAINED_CLAY:15,5,AIR,7,IRON_BARS,12,CONCRETE:7,100)
Block(-6,10,5,IRON_FENCE:0)
Block(-6,10,6,AIR:0)
Block(-6,10,7,AIR:0)
Block(-6,10,8,AIR:0)
Block(-6,11,-7,OBSIDIAN:0)
Block(-6,11,-6,OBSIDIAN:0)
Block(-6,11,-5,OBSIDIAN:0)
Block(-6,11,-4,OBSIDIAN:0)
Block(-6,11,-3,OBSIDIAN:0)
Block(-6,11,-2,OBSIDIAN:0)
Block(-6,11,-1,OBSIDIAN:0)
Block(-6,11,0,OBSIDIAN:0)
Block(-6,11,1,OBSIDIAN:0)
Block(-6,11,2,OBSIDIAN:0)
RandomBlock(-6,11,3,CONCRETE:7,60,quark:iron_plate,20,STAINED_CLAY:12,15,STAINED_CLAY:15,5,AIR,7,IRON_BARS,12,CONCRETE:7,100)
RandomBlock(-6,11,4,CONCRETE:7,60,quark:iron_plate,20,STAINED_CLAY:12,15,STAINED_CLAY:15,5,AIR,7,IRON_BARS,12,CONCRETE:7,100)
Block(-6,11,5,IRON_FENCE:0)
Block(-6,11,6,IRON_FENCE:0)
Block(-6,11,7,IRON_FENCE:0)
Block(-6,11,8,IRON_FENCE:0)
Block(-6,12,-7,OBSIDIAN:0)
Block(-6,12,-6,OBSIDIAN:0)
Block(-6,12,-5,OBSIDIAN:0)
Block(-6,12,-4,OBSIDIAN:0)
Block(-6,12,-3,OBSIDIAN:0)
Block(-6,12,-2,OBSIDIAN:0)
Block(-6,12,-1,OBSIDIAN:0)
Block(-6,12,0,OBSIDIAN:0)
Block(-6,12,1,OBSIDIAN:0)
Block(-6,12,2,OBSIDIAN:0)
Block(-6,12,3,OBSIDIAN:0)
RandomBlock(-6,12,4,CONCRETE:7,60,quark:iron_plate,20,STAINED_CLAY:12,15,STAINED_CLAY:15,5,AIR,7,IRON_BARS,12,CONCRETE:7,100)
RandomBlock(-6,12,5,CONCRETE:7,60,quark:iron_plate,20,STAINED_CLAY:12,15,STAINED_CLAY:15,5,AIR,7,IRON_BARS,12,CONCRETE:7,100)
RandomBlock(-6,12,6,CONCRETE:7,60,quark:iron_plate,20,STAINED_CLAY:12,15,STAINED_CLAY:15,5,AIR,7,IRON_BARS,12,CONCRETE:7,100)
RandomBlock(-6,12,7,CONCRETE:7,60,quark:iron_plate,20,STAINED_CLAY:12,15,STAINED_CLAY:15,5,AIR,7,IRON_BARS,12,CONCRETE:7,100)
RandomBlock(-6,12,8,CONCRETE:7,60,quark:iron_plate,20,STAINED_CLAY:12,15,STAINED_CLAY:15,5,AIR,7,IRON_BARS,12,CONCRETE:7,100)
Block(-6,13,-7,OBSIDIAN:0)
Block(-6,13,-6,OBSIDIAN:0)
Block(-6,13,-5,OBSIDIAN:0)
Block(-6,13,-4,OBSIDIAN:0)
Block(-6,13,-3,OBSIDIAN:0)
Block(-6,13,-2,OBSIDIAN:0)
Block(-6,13,-1,OBSIDIAN:0)
Block(-6,13,0,OBSIDIAN:0)
Block(-6,13,1,OBSIDIAN:0)
Block(-6,13,2,OBSIDIAN:0)
Block(-6,13,3,OBSIDIAN:0)
Block(-6,13,4,AIR:0)
Block(-6,13,5,AIR:0)
Block(-6,13,6,AIR:0)
Block(-6,13,7,AIR:0)
Block(-6,13,8,AIR:0)
Block(-6,14,-7,OBSIDIAN:0)
Block(-6,14,-6,OBSIDIAN:0)
Block(-6,14,-5,OBSIDIAN:0)
Block(-6,14,-4,OBSIDIAN:0)
Block(-6,14,-3,OBSIDIAN:0)
Block(-6,14,-2,OBSIDIAN:0)
Block(-6,14,-1,OBSIDIAN:0)
Block(-6,14,0,OBSIDIAN:0)
Block(-6,14,1,OBSIDIAN:0)
Block(-6,14,2,OBSIDIAN:0)
Block(-6,14,3,OBSIDIAN:0)
RandomBlock(-6,14,4,CONCRETE:7,60,quark:iron_plate,20,STAINED_CLAY:12,15,STAINED_CLAY:15,5,AIR,7,IRON_BARS,12,CONCRETE:7,100)
RandomBlock(-6,14,5,CONCRETE:7,60,quark:iron_plate,20,STAINED_CLAY:12,15,STAINED_CLAY:15,5,AIR,7,IRON_BARS,12,CONCRETE:7,100)
RandomBlock(-6,14,6,CONCRETE:7,60,quark:iron_plate,20,STAINED_CLAY:12,15,STAINED_CLAY:15,5,AIR,7,IRON_BARS,12,CONCRETE:7,100)
RandomBlock(-6,14,7,CONCRETE:7,60,quark:iron_plate,20,STAINED_CLAY:12,15,STAINED_CLAY:15,5,AIR,7,IRON_BARS,12,CONCRETE:7,100)
RandomBlock(-6,14,8,CONCRETE:7,60,quark:iron_plate,20,STAINED_CLAY:12,15,STAINED_CLAY:15,5,AIR,7,IRON_BARS,12,CONCRETE:7,100)
RandomBlock(-6,15,-7,CONCRETE:7,60,quark:iron_plate,20,STAINED_CLAY:12,15,STAINED_CLAY:15,5,AIR,7,IRON_BARS,12,CONCRETE:7,100)
RandomBlock(-6,15,-6,CONCRETE:7,60,quark:iron_plate,20,STAINED_CLAY:12,15,STAINED_CLAY:15,5,AIR,7,IRON_BARS,12,CONCRETE:7,100)
RandomBlock(-6,15,-5,CONCRETE:7,60,quark:iron_plate,20,STAINED_CLAY:12,15,STAINED_CLAY:15,5,AIR,7,IRON_BARS,12,CONCRETE:7,100)
RandomBlock(-6,15,-4,CONCRETE:7,60,quark:iron_plate,20,STAINED_CLAY:12,15,STAINED_CLAY:15,5,AIR,7,IRON_BARS,12,CONCRETE:7,100)
RandomBlock(-6,15,-3,CONCRETE:7,60,quark:iron_plate,20,STAINED_CLAY:12,15,STAINED_CLAY:15,5,AIR,7,IRON_BARS,12,CONCRETE:7,100)
RandomBlock(-6,15,-2,CONCRETE:7,60,quark:iron_plate,20,STAINED_CLAY:12,15,STAINED_CLAY:15,5,AIR,7,IRON_BARS,12,CONCRETE:7,100)
RandomBlock(-6,15,-1,CONCRETE:7,60,quark:iron_plate,20,STAINED_CLAY:12,15,STAINED_CLAY:15,5,AIR,7,IRON_BARS,12,CONCRETE:7,100)
RandomBlock(-6,15,0,CONCRETE:7,60,quark:iron_plate,20,STAINED_CLAY:12,15,STAINED_CLAY:15,5,AIR,7,IRON_BARS,12,CONCRETE:7,100)
RandomBlock(-6,15,1,CONCRETE:7,60,quark:iron_plate,20,STAINED_CLAY:12,15,STAINED_CLAY:15,5,AIR,7,IRON_BARS,12,CONCRETE:7,100)
RandomBlock(-6,15,2,CONCRETE:7,60,quark:iron_plate,20,STAINED_CLAY:12,15,STAINED_CLAY:15,5,AIR,7,IRON_BARS,12,CONCRETE:7,100)
RandomBlock(-6,15,3,CONCRETE:7,60,quark:iron_plate,20,STAINED_CLAY:12,15,STAINED_CLAY:15,5,AIR,7,IRON_BARS,12,CONCRETE:7,100)
RandomBlock(-6,15,4,CONCRETE:7,60,quark:iron_plate,20,STAINED_CLAY:12,15,STAINED_CLAY:15,5,AIR,7,IRON_BARS,12,CONCRETE:7,100)
RandomBlock(-6,15,5,CONCRETE:7,60,quark:iron_plate,20,STAINED_CLAY:12,15,STAINED_CLAY:15,5,AIR,7,IRON_BARS,12,CONCRETE:7,100)
RandomBlock(-6,15,6,CONCRETE:7,60,quark:iron_plate,20,STAINED_CLAY:12,15,STAINED_CLAY:15,5,AIR,7,IRON_BARS,12,CONCRETE:7,100)
RandomBlock(-6,15,7,CONCRETE:7,60,quark:iron_plate,20,STAINED_CLAY:12,15,STAINED_CLAY:15,5,AIR,7,IRON_BARS,12,CONCRETE:7,100)
RandomBlock(-6,15,8,CONCRETE:7,60,quark:iron_plate,20,STAINED_CLAY:12,15,STAINED_CLAY:15,5,AIR,7,IRON_BARS,12,CONCRETE:7,100)
Block(-6,16,-7,OBSIDIAN:0)
Block(-6,16,-6,OBSIDIAN:0)
Block(-6,16,-5,OBSIDIAN:0)
Block(-6,16,-4,OBSIDIAN:0)
Block(-6,16,-3,OBSIDIAN:0)
Block(-6,16,-2,OBSIDIAN:0)
Block(-6,16,-1,OBSIDIAN:0)
Block(-6,16,0,OBSIDIAN:0)
Block(-6,16,1,OBSIDIAN:0)
Block(-6,16,2,OBSIDIAN:0)
Block(-6,16,3,OBSIDIAN:0)
Block(-6,16,4,OBSIDIAN:0)
Block(-6,16,5,OBSIDIAN:0)
Block(-6,16,6,OBSIDIAN:0)
Block(-6,16,7,OBSIDIAN:0)
Block(-6,16,8,OBSIDIAN:0)
RandomBlock(-6,17,-7,CONCRETE:7,60,quark:iron_plate,20,STAINED_CLAY:12,15,STAINED_CLAY:15,5,AIR,7,IRON_BARS,12,CONCRETE:7,100)
RandomBlock(-6,17,-6,CONCRETE:7,60,quark:iron_plate,20,STAINED_CLAY:12,15,STAINED_CLAY:15,5,AIR,7,IRON_BARS,12,CONCRETE:7,100)
RandomBlock(-6,17,-5,CONCRETE:7,60,quark:iron_plate,20,STAINED_CLAY:12,15,STAINED_CLAY:15,5,AIR,7,IRON_BARS,12,CONCRETE:7,100)
RandomBlock(-6,17,-4,CONCRETE:7,60,quark:iron_plate,20,STAINED_CLAY:12,15,STAINED_CLAY:15,5,AIR,7,IRON_BARS,12,CONCRETE:7,100)
RandomBlock(-6,17,-3,CONCRETE:7,60,quark:iron_plate,20,STAINED_CLAY:12,15,STAINED_CLAY:15,5,AIR,7,IRON_BARS,12,CONCRETE:7,100)
RandomBlock(-6,17,-2,CONCRETE:7,60,quark:iron_plate,20,STAINED_CLAY:12,15,STAINED_CLAY:15,5,AIR,7,IRON_BARS,12,CONCRETE:7,100)
RandomBlock(-6,17,-1,CONCRETE:7,60,quark:iron_plate,20,STAINED_CLAY:12,15,STAINED_CLAY:15,5,AIR,7,IRON_BARS,12,CONCRETE:7,100)
RandomBlock(-6,17,0,CONCRETE:7,60,quark:iron_plate,20,STAINED_CLAY:12,15,STAINED_CLAY:15,5,AIR,7,IRON_BARS,12,CONCRETE:7,100)
RandomBlock(-6,17,1,CONCRETE:7,60,quark:iron_plate,20,STAINED_CLAY:12,15,STAINED_CLAY:15,5,AIR,7,IRON_BARS,12,CONCRETE:7,100)
RandomBlock(-6,17,2,CONCRETE:7,60,quark:iron_plate,20,STAINED_CLAY:12,15,STAINED_CLAY:15,5,AIR,7,IRON_BARS,12,CONCRETE:7,100)
RandomBlock(-6,17,3,CONCRETE:7,60,quark:iron_plate,20,STAINED_CLAY:12,15,STAINED_CLAY:15,5,AIR,7,IRON_BARS,12,CONCRETE:7,100)
RandomBlock(-6,17,4,CONCRETE:7,60,quark:iron_plate,20,STAINED_CLAY:12,15,STAINED_CLAY:15,5,AIR,7,IRON_BARS,12,CONCRETE:7,100)
RandomBlock(-6,17,5,CONCRETE:7,60,quark:iron_plate,20,STAINED_CLAY:12,15,STAINED_CLAY:15,5,AIR,7,IRON_BARS,12,CONCRETE:7,100)
RandomBlock(-6,17,6,CONCRETE:7,60,quark:iron_plate,20,STAINED_CLAY:12,15,STAINED_CLAY:15,5,AIR,7,IRON_BARS,12,CONCRETE:7,100)
RandomBlock(-6,17,7,CONCRETE:7,60,quark:iron_plate,20,STAINED_CLAY:12,15,STAINED_CLAY:15,5,AIR,7,IRON_BARS,12,CONCRETE:7,100)
RandomBlock(-6,17,8,CONCRETE:7,60,quark:iron_plate,20,STAINED_CLAY:12,15,STAINED_CLAY:15,5,AIR,7,IRON_BARS,12,CONCRETE:7,100)
Block(-6,18,-7,IRON_FENCE:0)
RandomBlock(-6,18,-6,CONCRETE:7,60,quark:iron_plate,20,STAINED_CLAY:12,15,STAINED_CLAY:15,5,AIR,7,IRON_BARS,12,CONCRETE:7,100)
Block(-6,18,-5,IRON_FENCE:0)
RandomBlock(-6,18,-4,CONCRETE:7,60,quark:iron_plate,20,STAINED_CLAY:12,15,STAINED_CLAY:15,5,AIR,7,IRON_BARS,12,CONCRETE:7,100)
Block(-6,18,-3,IRON_FENCE:0)
Block(-6,18,2,IRON_FENCE:0)
RandomBlock(-6,18,3,CONCRETE:7,60,quark:iron_plate,20,STAINED_CLAY:12,15,STAINED_CLAY:15,5,AIR,7,IRON_BARS,12,CONCRETE:7,100)
RandomBlock(-6,18,4,CONCRETE:7,60,quark:iron_plate,20,STAINED_CLAY:12,15,STAINED_CLAY:15,5,AIR,7,IRON_BARS,12,CONCRETE:7,100)
RandomBlock(-6,18,5,CONCRETE:7,60,quark:iron_plate,20,STAINED_CLAY:12,15,STAINED_CLAY:15,5,AIR,7,IRON_BARS,12,CONCRETE:7,100)
Block(-6,18,6,OBSIDIAN:0)
Block(-6,18,7,OBSIDIAN:0)
Block(-6,18,8,OBSIDIAN:0)
Block(-6,19,-7,IRON_FENCE:0)
RandomBlock(-6,19,-6,CONCRETE:7,60,quark:iron_plate,20,STAINED_CLAY:12,15,STAINED_CLAY:15,5,AIR,7,IRON_BARS,12,CONCRETE:7,100)
Block(-6,19,-5,IRON_FENCE:0)
RandomBlock(-6,19,-4,CONCRETE:7,60,quark:iron_plate,20,STAINED_CLAY:12,15,STAINED_CLAY:15,5,AIR,7,IRON_BARS,12,CONCRETE:7,100)
Block(-6,19,-3,IRON_FENCE:0)
Block(-6,19,2,IRON_FENCE:0)
RandomBlock(-6,19,3,CONCRETE:7,60,quark:iron_plate,20,STAINED_CLAY:12,15,STAINED_CLAY:15,5,AIR,7,IRON_BARS,12,CONCRETE:7,100)
RandomBlock(-6,19,4,CONCRETE:7,60,quark:iron_plate,20,STAINED_CLAY:12,15,STAINED_CLAY:15,5,AIR,7,IRON_BARS,12,CONCRETE:7,100)
RandomBlock(-6,19,5,CONCRETE:7,60,quark:iron_plate,20,STAINED_CLAY:12,15,STAINED_CLAY:15,5,AIR,7,IRON_BARS,12,CONCRETE:7,100)
Block(-6,19,6,OBSIDIAN:0)
Block(-6,19,7,OBSIDIAN:0)
Block(-6,19,8,OBSIDIAN:0)
Block(-6,20,-7,IRON_FENCE:0)
RandomBlock(-6,20,-6,CONCRETE:7,60,quark:iron_plate,20,STAINED_CLAY:12,15,STAINED_CLAY:15,5,AIR,7,IRON_BARS,12,CONCRETE:7,100)
Block(-6,20,-5,IRON_FENCE:0)
RandomBlock(-6,20,-4,CONCRETE:7,60,quark:iron_plate,20,STAINED_CLAY:12,15,STAINED_CLAY:15,5,AIR,7,IRON_BARS,12,CONCRETE:7,100)
Block(-6,20,-3,IRON_FENCE:0)
Block(-6,20,2,IRON_FENCE:0)
RandomBlock(-6,20,3,CONCRETE:7,60,quark:iron_plate,20,STAINED_CLAY:12,15,STAINED_CLAY:15,5,AIR,7,IRON_BARS,12,CONCRETE:7,100)
RandomBlock(-6,20,4,CONCRETE:7,60,quark:iron_plate,20,STAINED_CLAY:12,15,STAINED_CLAY:15,5,AIR,7,IRON_BARS,12,CONCRETE:7,100)
RandomBlock(-6,20,5,CONCRETE:7,60,quark:iron_plate,20,STAINED_CLAY:12,15,STAINED_CLAY:15,5,AIR,7,IRON_BARS,12,CONCRETE:7,100)
Block(-6,20,6,OBSIDIAN:0)
Block(-6,20,7,OBSIDIAN:0)
Block(-6,20,8,OBSIDIAN:0)
Block(-6,21,-7,IRON_FENCE:0)
RandomBlock(-6,21,-6,CONCRETE:7,60,quark:iron_plate,20,STAINED_CLAY:12,15,STAINED_CLAY:15,5,AIR,7,IRON_BARS,12,CONCRETE:7,100)
Block(-6,21,-5,IRON_FENCE:0)
RandomBlock(-6,21,-4,CONCRETE:7,60,quark:iron_plate,20,STAINED_CLAY:12,15,STAINED_CLAY:15,5,AIR,7,IRON_BARS,12,CONCRETE:7,100)
Block(-6,21,-3,IRON_FENCE:0)
Block(-6,21,-2,STEP:8)
Block(-6,21,-1,STEP:8)
Block(-6,21,0,STEP:8)
Block(-6,21,1,STEP:8)
RandomBlock(-6,21,2,CONCRETE:7,60,quark:iron_plate,20,STAINED_CLAY:12,15,STAINED_CLAY:15,5,AIR,7,IRON_BARS,12,CONCRETE:7,100)
RandomBlock(-6,21,3,CONCRETE:7,60,quark:iron_plate,20,STAINED_CLAY:12,15,STAINED_CLAY:15,5,AIR,7,IRON_BARS,12,CONCRETE:7,100)
RandomBlock(-6,21,4,CONCRETE:7,60,quark:iron_plate,20,STAINED_CLAY:12,15,STAINED_CLAY:15,5,AIR,7,IRON_BARS,12,CONCRETE:7,100)
RandomBlock(-6,21,5,CONCRETE:7,60,quark:iron_plate,20,STAINED_CLAY:12,15,STAINED_CLAY:15,5,AIR,7,IRON_BARS,12,CONCRETE:7,100)
Block(-6,21,6,OBSIDIAN:0)
Block(-6,21,7,OBSIDIAN:0)
Block(-6,21,8,OBSIDIAN:0)
RandomBlock(-6,22,-7,CONCRETE:7,60,quark:iron_plate,20,STAINED_CLAY:12,15,STAINED_CLAY:15,5,AIR,7,IRON_BARS,12,CONCRETE:7,100)
RandomBlock(-6,22,-6,CONCRETE:7,60,quark:iron_plate,20,STAINED_CLAY:12,15,STAINED_CLAY:15,5,AIR,7,IRON_BARS,12,CONCRETE:7,100)
RandomBlock(-6,22,-5,CONCRETE:7,60,quark:iron_plate,20,STAINED_CLAY:12,15,STAINED_CLAY:15,5,AIR,7,IRON_BARS,12,CONCRETE:7,100)
RandomBlock(-6,22,-4,CONCRETE:7,60,quark:iron_plate,20,STAINED_CLAY:12,15,STAINED_CLAY:15,5,AIR,7,IRON_BARS,12,CONCRETE:7,100)
RandomBlock(-6,22,-3,CONCRETE:7,60,quark:iron_plate,20,STAINED_CLAY:12,15,STAINED_CLAY:15,5,AIR,7,IRON_BARS,12,CONCRETE:7,100)
RandomBlock(-6,22,-2,CONCRETE:7,60,quark:iron_plate,20,STAINED_CLAY:12,15,STAINED_CLAY:15,5,AIR,7,IRON_BARS,12,CONCRETE:7,100)
RandomBlock(-6,22,-1,CONCRETE:7,60,quark:iron_plate,20,STAINED_CLAY:12,15,STAINED_CLAY:15,5,AIR,7,IRON_BARS,12,CONCRETE:7,100)
RandomBlock(-6,22,0,CONCRETE:7,60,quark:iron_plate,20,STAINED_CLAY:12,15,STAINED_CLAY:15,5,AIR,7,IRON_BARS,12,CONCRETE:7,100)
RandomBlock(-6,22,1,CONCRETE:7,60,quark:iron_plate,20,STAINED_CLAY:12,15,STAINED_CLAY:15,5,AIR,7,IRON_BARS,12,CONCRETE:7,100)
RandomBlock(-6,22,2,CONCRETE:7,60,quark:iron_plate,20,STAINED_CLAY:12,15,STAINED_CLAY:15,5,AIR,7,IRON_BARS,12,CONCRETE:7,100)
RandomBlock(-6,22,3,CONCRETE:7,60,quark:iron_plate,20,STAINED_CLAY:12,15,STAINED_CLAY:15,5,AIR,7,IRON_BARS,12,CONCRETE:7,100)
RandomBlock(-6,22,4,CONCRETE:7,60,quark:iron_plate,20,STAINED_CLAY:12,15,STAINED_CLAY:15,5,AIR,7,IRON_BARS,12,CONCRETE:7,100)
RandomBlock(-6,22,5,CONCRETE:7,60,quark:iron_plate,20,STAINED_CLAY:12,15,STAINED_CLAY:15,5,AIR,7,IRON_BARS,12,CONCRETE:7,100)
Block(-6,22,6,OBSIDIAN:0)
Block(-6,22,7,OBSIDIAN:0)
Block(-6,22,8,OBSIDIAN:0)
Block(-6,23,-7,OBSIDIAN:0)
Block(-6,23,-6,OBSIDIAN:0)
Block(-6,23,-5,OBSIDIAN:0)
Block(-6,23,-4,OBSIDIAN:0)
Block(-6,23,-3,OBSIDIAN:0)
Block(-6,23,-2,OBSIDIAN:0)
Block(-6,23,-1,OBSIDIAN:0)
Block(-6,23,0,OBSIDIAN:0)
Block(-6,23,1,OBSIDIAN:0)
Block(-6,23,2,OBSIDIAN:0)
Block(-6,23,3,OBSIDIAN:0)
Block(-6,23,4,OBSIDIAN:0)
Block(-6,23,5,OBSIDIAN:0)
Block(-6,23,6,OBSIDIAN:0)
Block(-6,23,7,CONCRETE:0)
Block(-6,23,8,CONCRETE:0)
Block(-6,24,-7,CONCRETE:0)
Block(-6,24,-6,CONCRETE:0)
Block(-6,24,-5,CONCRETE:15)
Block(-6,24,-4,CONCRETE:0)
Block(-6,24,-3,CONCRETE:0)
Block(-6,24,-2,CONCRETE:15)
Block(-6,24,-1,CONCRETE:15)
Block(-6,24,0,CONCRETE:0)
Block(-6,24,1,CONCRETE:0)
Block(-6,24,2,STONE:4)
Block(-6,24,3,CONCRETE:0)
Block(-6,24,4,CONCRETE:0)
RandomBlock(-6,24,5,CONCRETE:7,60,quark:iron_plate,20,STAINED_CLAY:12,15,STAINED_CLAY:15,5,AIR,7,IRON_BARS,12,CONCRETE:7,100)
Block(-6,24,6,STEP:0)
RandomBlock(-6,25,-5,CONCRETE:7,60,quark:iron_plate,20,STAINED_CLAY:12,15,STAINED_CLAY:15,5,AIR,7,IRON_BARS,12,CONCRETE:7,100)
RandomBlock(-6,25,-4,CONCRETE:7,60,quark:iron_plate,20,STAINED_CLAY:12,15,STAINED_CLAY:15,5,AIR,7,IRON_BARS,12,CONCRETE:7,100)
RandomBlock(-6,25,-3,CONCRETE:7,60,quark:iron_plate,20,STAINED_CLAY:12,15,STAINED_CLAY:15,5,AIR,7,IRON_BARS,12,CONCRETE:7,100)
RandomBlock(-6,25,3,STAINED_GLASS_PANE:0,40,AIR,100)
RandomBlock(-6,25,5,STAINED_GLASS:15,40,AIR,100)
RandomBlock(-6,26,-5,STAINED_GLASS_PANE:15,40,AIR,100)
RandomBlock(-6,26,-4,CONCRETE:7,60,quark:iron_plate,20,STAINED_CLAY:12,15,STAINED_CLAY:15,5,AIR,7,IRON_BARS,12,CONCRETE:7,100)
RandomBlock(-6,26,-3,STAINED_GLASS_PANE:15,40,AIR,100)
RandomBlock(-6,26,3,STAINED_GLASS_PANE:0,40,AIR,100)
RandomBlock(-6,26,5,STAINED_GLASS:15,40,AIR,100)
Block(-6,27,-4,STEP:0)
RandomBlock(-6,27,3,STAINED_GLASS_PANE:0,40,AIR,100)
RandomBlock(-6,27,5,STAINED_GLASS:15,40,AIR,100)
Block(-6,28,-7,CONCRETE:15)
Block(-6,28,-6,CONCRETE:15)
RandomBlock(-6,28,3,STAINED_GLASS_PANE:0,40,AIR,100)
Block(-6,28,5,STEP:8)
Block(-6,29,-7,STEP:8)
Block(-6,29,-6,STEP:8)
Block(-6,29,-5,STEP:8)
Block(-6,29,-4,STEP:8)
Block(-6,29,-3,STEP:8)
Block(-6,29,-2,STEP:8)
Block(-6,29,-1,STEP:8)
Block(-6,29,0,STEP:8)
Block(-6,29,1,STEP:8)
Block(-6,29,2,STEP:8)
Block(-6,29,3,CONCRETE:0)
Block(-6,29,4,CONCRETE:0)
Block(-6,29,5,CONCRETE:0)
Block(-6,29,6,CONCRETE:0)
Block(-6,29,7,STEP:8)
Block(-6,29,8,QUARTZ_STAIRS:4)
RandomBlock(-6,30,5,CONCRETE:7,60,quark:iron_plate,20,STAINED_CLAY:12,15,STAINED_CLAY:15,5,AIR,7,IRON_BARS,12,CONCRETE:7,100)
Block(-6,30,6,STEP:7)
Block(-6,30,7,IRON_FENCE:0)
Block(-6,30,8,COBBLE_WALL:0)
RandomBlock(-6,31,5,STAINED_GLASS_PANE:15,40,AIR,100)
RandomBlock(-6,32,5,STAINED_GLASS_PANE:15,40,AIR,100)
Block(-6,32,6,STEP:8)
Block(-6,33,1,CONCRETE:0)
Block(-6,33,2,STEP:8)
Block(-6,33,3,STEP:8)
Block(-6,33,4,CONCRETE:0)
Block(-6,33,5,CONCRETE:0)
Block(-6,33,6,CONCRETE:0)
Block(-6,33,7,STEP:8)
Block(-6,33,8,QUARTZ_STAIRS:4)
RandomBlock(-6,34,1,STAINED_GLASS_PANE:15,40,AIR,100)
RandomBlock(-6,34,4,CONCRETE:7,60,quark:iron_plate,20,STAINED_CLAY:12,15,STAINED_CLAY:15,5,AIR,7,IRON_BARS,12,CONCRETE:7,100)
Block(-6,34,5,STEP:7)
Block(-6,34,7,IRON_FENCE:0)
Block(-6,34,8,COBBLE_WALL:0)
RandomBlock(-6,35,4,STAINED_GLASS_PANE:15,40,AIR,100)
RandomBlock(-6,36,4,STAINED_GLASS_PANE:15,40,AIR,100)
RandomBlock(-6,37,4,STAINED_GLASS_PANE:15,40,AIR,100)
RandomBlock(-6,38,4,STAINED_GLASS_PANE:15,40,AIR,100)
RandomBlock(-6,39,4,STAINED_GLASS_PANE:15,40,AIR,100)
Block(-6,39,5,COBBLE_WALL:0)
Block(-6,40,2,STEP:15)
Block(-6,40,3,STEP:15)
Block(-6,40,4,DOUBLE_STEP:7)
Block(-6,40,5,CONCRETE:0)
Block(-6,40,6,STEP:8)
RandomBlock(-6,41,0,CONCRETE:7,60,quark:iron_plate,20,STAINED_CLAY:12,15,STAINED_CLAY:15,5,AIR,7,IRON_BARS,12,CONCRETE:7,100)
Block(-6,41,1,STEP:7)
Block(-6,41,2,STEP:7)
Block(-6,41,5,CONCRETE:0)
RandomBlock(-6,42,0,STAINED_GLASS_PANE:15,40,AIR,100)
Block(-6,42,5,COBBLE_WALL:0)
RandomBlock(-6,43,0,STAINED_GLASS_PANE:15,40,AIR,100)
RandomBlock(-6,44,0,STAINED_GLASS_PANE:15,40,AIR,100)
RandomBlock(-6,45,0,STAINED_GLASS_PANE:15,40,AIR,100)
Block(-6,46,0,CONCRETE:0)
RandomBlock(-6,47,-1,CONCRETE:7,60,quark:iron_plate,20,STAINED_CLAY:12,15,STAINED_CLAY:15,5,AIR,7,IRON_BARS,12,CONCRETE:7,100)
RandomBlock(-6,48,-1,CONCRETE:7,60,quark:iron_plate,20,STAINED_CLAY:12,15,STAINED_CLAY:15,5,AIR,7,IRON_BARS,12,CONCRETE:7,100)
RandomBlock(-6,49,-3,CONCRETE:7,60,quark:iron_plate,20,STAINED_CLAY:12,15,STAINED_CLAY:15,5,AIR,7,IRON_BARS,12,CONCRETE:7,100)
RandomBlock(-6,49,-2,CONCRETE:7,60,quark:iron_plate,20,STAINED_CLAY:12,15,STAINED_CLAY:15,5,AIR,7,IRON_BARS,12,CONCRETE:7,100)
Block(-6,50,-5,CONCRETE:0)
Block(-6,50,-4,CONCRETE:0)
RandomBlock(-6,51,-7,CONCRETE:7,60,quark:iron_plate,20,STAINED_CLAY:12,15,STAINED_CLAY:15,5,AIR,7,IRON_BARS,12,CONCRETE:7,100)
RandomBlock(-6,51,-6,CONCRETE:7,60,quark:iron_plate,20,STAINED_CLAY:12,15,STAINED_CLAY:15,5,AIR,7,IRON_BARS,12,CONCRETE:7,100)
RandomBlock(-5,0,-7,CONCRETE:7,60,quark:iron_plate,20,STAINED_CLAY:12,15,STAINED_CLAY:15,5,AIR,7,IRON_BARS,12,CONCRETE:7,100)
RandomBlock(-5,0,-6,CONCRETE:7,60,quark:iron_plate,20,STAINED_CLAY:12,15,STAINED_CLAY:15,5,AIR,7,IRON_BARS,12,CONCRETE:7,100)
RandomBlock(-5,0,-5,CONCRETE:7,60,quark:iron_plate,20,STAINED_CLAY:12,15,STAINED_CLAY:15,5,AIR,7,IRON_BARS,12,CONCRETE:7,100)
RandomBlock(-5,0,-4,CONCRETE:7,60,quark:iron_plate,20,STAINED_CLAY:12,15,STAINED_CLAY:15,5,AIR,7,IRON_BARS,12,CONCRETE:7,100)
RandomBlock(-5,0,-3,CONCRETE:7,60,quark:iron_plate,20,STAINED_CLAY:12,15,STAINED_CLAY:15,5,AIR,7,IRON_BARS,12,CONCRETE:7,100)
RandomBlock(-5,0,-2,CONCRETE:7,60,quark:iron_plate,20,STAINED_CLAY:12,15,STAINED_CLAY:15,5,AIR,7,IRON_BARS,12,CONCRETE:7,100)
RandomBlock(-5,0,-1,CONCRETE:7,60,quark:iron_plate,20,STAINED_CLAY:12,15,STAINED_CLAY:15,5,AIR,7,IRON_BARS,12,CONCRETE:7,100)
RandomBlock(-5,0,0,CONCRETE:7,60,quark:iron_plate,20,STAINED_CLAY:12,15,STAINED_CLAY:15,5,AIR,7,IRON_BARS,12,CONCRETE:7,100)
RandomBlock(-5,0,1,CONCRETE:7,60,quark:iron_plate,20,STAINED_CLAY:12,15,STAINED_CLAY:15,5,AIR,7,IRON_BARS,12,CONCRETE:7,100)
RandomBlock(-5,0,2,CONCRETE:7,60,quark:iron_plate,20,STAINED_CLAY:12,15,STAINED_CLAY:15,5,AIR,7,IRON_BARS,12,CONCRETE:7,100)
RandomBlock(-5,0,3,CONCRETE:7,60,quark:iron_plate,20,STAINED_CLAY:12,15,STAINED_CLAY:15,5,AIR,7,IRON_BARS,12,CONCRETE:7,100)
RandomBlock(-5,0,4,CONCRETE:7,60,quark:iron_plate,20,STAINED_CLAY:12,15,STAINED_CLAY:15,5,AIR,7,IRON_BARS,12,CONCRETE:7,100)
RandomBlock(-5,0,5,CONCRETE:7,60,quark:iron_plate,20,STAINED_CLAY:12,15,STAINED_CLAY:15,5,AIR,7,IRON_BARS,12,CONCRETE:7,100)
RandomBlock(-5,0,6,CONCRETE:7,60,quark:iron_plate,20,STAINED_CLAY:12,15,STAINED_CLAY:15,5,AIR,7,IRON_BARS,12,CONCRETE:7,100)
RandomBlock(-5,0,7,CONCRETE:7,60,quark:iron_plate,20,STAINED_CLAY:12,15,STAINED_CLAY:15,5,AIR,7,IRON_BARS,12,CONCRETE:7,100)
RandomBlock(-5,0,8,CONCRETE:7,60,quark:iron_plate,20,STAINED_CLAY:12,15,STAINED_CLAY:15,5,AIR,7,IRON_BARS,12,CONCRETE:7,100)
Block(-5,1,-7,OBSIDIAN:0)
Block(-5,1,-6,OBSIDIAN:0)
Block(-5,1,-5,OBSIDIAN:0)
Block(-5,1,-4,OBSIDIAN:0)
Block(-5,1,-3,OBSIDIAN:0)
Block(-5,1,-2,OBSIDIAN:0)
Block(-5,1,-1,OBSIDIAN:0)
Block(-5,1,0,OBSIDIAN:0)
Block(-5,1,1,OBSIDIAN:0)
Block(-5,1,2,OBSIDIAN:0)
Block(-5,1,3,OBSIDIAN:0)
Block(-5,1,4,OBSIDIAN:0)
Block(-5,1,5,OBSIDIAN:0)
Block(-5,1,6,OBSIDIAN:0)
Block(-5,1,7,OBSIDIAN:0)
Block(-5,1,8,OBSIDIAN:0)
RandomBlock(-5,2,-7,CONCRETE:7,60,quark:iron_plate,20,STAINED_CLAY:12,15,STAINED_CLAY:15,5,AIR,7,IRON_BARS,12,CONCRETE:7,100)
RandomBlock(-5,2,-6,CONCRETE:7,60,quark:iron_plate,20,STAINED_CLAY:12,15,STAINED_CLAY:15,5,AIR,7,IRON_BARS,12,CONCRETE:7,100)
RandomBlock(-5,2,-5,CONCRETE:7,60,quark:iron_plate,20,STAINED_CLAY:12,15,STAINED_CLAY:15,5,AIR,7,IRON_BARS,12,CONCRETE:7,100)
RandomBlock(-5,2,-4,CONCRETE:7,60,quark:iron_plate,20,STAINED_CLAY:12,15,STAINED_CLAY:15,5,AIR,7,IRON_BARS,12,CONCRETE:7,100)
RandomBlock(-5,2,-3,CONCRETE:7,60,quark:iron_plate,20,STAINED_CLAY:12,15,STAINED_CLAY:15,5,AIR,7,IRON_BARS,12,CONCRETE:7,100)
RandomBlock(-5,2,-2,CONCRETE:7,60,quark:iron_plate,20,STAINED_CLAY:12,15,STAINED_CLAY:15,5,AIR,7,IRON_BARS,12,CONCRETE:7,100)
RandomBlock(-5,2,-1,CONCRETE:7,60,quark:iron_plate,20,STAINED_CLAY:12,15,STAINED_CLAY:15,5,AIR,7,IRON_BARS,12,CONCRETE:7,100)
RandomBlock(-5,2,0,CONCRETE:7,60,quark:iron_plate,20,STAINED_CLAY:12,15,STAINED_CLAY:15,5,AIR,7,IRON_BARS,12,CONCRETE:7,100)
RandomBlock(-5,2,1,CONCRETE:7,60,quark:iron_plate,20,STAINED_CLAY:12,15,STAINED_CLAY:15,5,AIR,7,IRON_BARS,12,CONCRETE:7,100)
RandomBlock(-5,2,2,CONCRETE:7,60,quark:iron_plate,20,STAINED_CLAY:12,15,STAINED_CLAY:15,5,AIR,7,IRON_BARS,12,CONCRETE:7,100)
RandomBlock(-5,2,3,CONCRETE:7,60,quark:iron_plate,20,STAINED_CLAY:12,15,STAINED_CLAY:15,5,AIR,7,IRON_BARS,12,CONCRETE:7,100)
RandomBlock(-5,2,4,CONCRETE:7,60,quark:iron_plate,20,STAINED_CLAY:12,15,STAINED_CLAY:15,5,AIR,7,IRON_BARS,12,CONCRETE:7,100)
RandomBlock(-5,2,5,CONCRETE:7,60,quark:iron_plate,20,STAINED_CLAY:12,15,STAINED_CLAY:15,5,AIR,7,IRON_BARS,12,CONCRETE:7,100)
RandomBlock(-5,2,6,CONCRETE:7,60,quark:iron_plate,20,STAINED_CLAY:12,15,STAINED_CLAY:15,5,AIR,7,IRON_BARS,12,CONCRETE:7,100)
RandomBlock(-5,2,7,CONCRETE:7,60,quark:iron_plate,20,STAINED_CLAY:12,15,STAINED_CLAY:15,5,AIR,7,IRON_BARS,12,CONCRETE:7,100)
RandomBlock(-5,2,8,CONCRETE:7,60,quark:iron_plate,20,STAINED_CLAY:12,15,STAINED_CLAY:15,5,AIR,7,IRON_BARS,12,CONCRETE:7,100)
RandomBlock(-5,3,-7,CONCRETE:7,60,quark:iron_plate,20,STAINED_CLAY:12,15,STAINED_CLAY:15,5,AIR,7,IRON_BARS,12,CONCRETE:7,100)
RandomBlock(-5,3,-6,CONCRETE:7,60,quark:iron_plate,20,STAINED_CLAY:12,15,STAINED_CLAY:15,5,AIR,7,IRON_BARS,12,CONCRETE:7,100)
RandomBlock(-5,3,-5,CONCRETE:7,60,quark:iron_plate,20,STAINED_CLAY:12,15,STAINED_CLAY:15,5,AIR,7,IRON_BARS,12,CONCRETE:7,100)
RandomBlock(-5,3,-4,CONCRETE:7,60,quark:iron_plate,20,STAINED_CLAY:12,15,STAINED_CLAY:15,5,AIR,7,IRON_BARS,12,CONCRETE:7,100)
RandomBlock(-5,3,-3,CONCRETE:7,60,quark:iron_plate,20,STAINED_CLAY:12,15,STAINED_CLAY:15,5,AIR,7,IRON_BARS,12,CONCRETE:7,100)
RandomBlock(-5,3,-2,CONCRETE:7,60,quark:iron_plate,20,STAINED_CLAY:12,15,STAINED_CLAY:15,5,AIR,7,IRON_BARS,12,CONCRETE:7,100)
RandomBlock(-5,3,-1,CONCRETE:7,60,quark:iron_plate,20,STAINED_CLAY:12,15,STAINED_CLAY:15,5,AIR,7,IRON_BARS,12,CONCRETE:7,100)
RandomBlock(-5,3,0,CONCRETE:7,60,quark:iron_plate,20,STAINED_CLAY:12,15,STAINED_CLAY:15,5,AIR,7,IRON_BARS,12,CONCRETE:7,100)
RandomBlock(-5,3,1,CONCRETE:7,60,quark:iron_plate,20,STAINED_CLAY:12,15,STAINED_CLAY:15,5,AIR,7,IRON_BARS,12,CONCRETE:7,100)
RandomBlock(-5,3,2,CONCRETE:7,60,quark:iron_plate,20,STAINED_CLAY:12,15,STAINED_CLAY:15,5,AIR,7,IRON_BARS,12,CONCRETE:7,100)
RandomBlock(-5,3,3,CONCRETE:7,60,quark:iron_plate,20,STAINED_CLAY:12,15,STAINED_CLAY:15,5,AIR,7,IRON_BARS,12,CONCRETE:7,100)
RandomBlock(-5,3,4,CONCRETE:7,60,quark:iron_plate,20,STAINED_CLAY:12,15,STAINED_CLAY:15,5,AIR,7,IRON_BARS,12,CONCRETE:7,100)
RandomBlock(-5,3,5,CONCRETE:7,60,quark:iron_plate,20,STAINED_CLAY:12,15,STAINED_CLAY:15,5,AIR,7,IRON_BARS,12,CONCRETE:7,100)
RandomBlock(-5,3,6,CONCRETE:7,60,quark:iron_plate,20,STAINED_CLAY:12,15,STAINED_CLAY:15,5,AIR,7,IRON_BARS,12,CONCRETE:7,100)
RandomBlock(-5,3,7,CONCRETE:7,60,quark:iron_plate,20,STAINED_CLAY:12,15,STAINED_CLAY:15,5,AIR,7,IRON_BARS,12,CONCRETE:7,100)
RandomBlock(-5,3,8,CONCRETE:7,60,quark:iron_plate,20,STAINED_CLAY:12,15,STAINED_CLAY:15,5,AIR,7,IRON_BARS,12,CONCRETE:7,100)
RandomBlock(-5,4,-7,CONCRETE:7,60,quark:iron_plate,20,STAINED_CLAY:12,15,STAINED_CLAY:15,5,AIR,7,IRON_BARS,12,CONCRETE:7,100)
RandomBlock(-5,4,-6,CONCRETE:7,60,quark:iron_plate,20,STAINED_CLAY:12,15,STAINED_CLAY:15,5,AIR,7,IRON_BARS,12,CONCRETE:7,100)
RandomBlock(-5,4,-5,CONCRETE:7,60,quark:iron_plate,20,STAINED_CLAY:12,15,STAINED_CLAY:15,5,AIR,7,IRON_BARS,12,CONCRETE:7,100)
RandomBlock(-5,4,-4,CONCRETE:7,60,quark:iron_plate,20,STAINED_CLAY:12,15,STAINED_CLAY:15,5,AIR,7,IRON_BARS,12,CONCRETE:7,100)
RandomBlock(-5,4,-3,CONCRETE:7,60,quark:iron_plate,20,STAINED_CLAY:12,15,STAINED_CLAY:15,5,AIR,7,IRON_BARS,12,CONCRETE:7,100)
RandomBlock(-5,4,-2,CONCRETE:7,60,quark:iron_plate,20,STAINED_CLAY:12,15,STAINED_CLAY:15,5,AIR,7,IRON_BARS,12,CONCRETE:7,100)
RandomBlock(-5,4,-1,CONCRETE:7,60,quark:iron_plate,20,STAINED_CLAY:12,15,STAINED_CLAY:15,5,AIR,7,IRON_BARS,12,CONCRETE:7,100)
RandomBlock(-5,4,0,CONCRETE:7,60,quark:iron_plate,20,STAINED_CLAY:12,15,STAINED_CLAY:15,5,AIR,7,IRON_BARS,12,CONCRETE:7,100)
RandomBlock(-5,4,1,CONCRETE:7,60,quark:iron_plate,20,STAINED_CLAY:12,15,STAINED_CLAY:15,5,AIR,7,IRON_BARS,12,CONCRETE:7,100)
RandomBlock(-5,4,2,CONCRETE:7,60,quark:iron_plate,20,STAINED_CLAY:12,15,STAINED_CLAY:15,5,AIR,7,IRON_BARS,12,CONCRETE:7,100)
RandomBlock(-5,4,3,CONCRETE:7,60,quark:iron_plate,20,STAINED_CLAY:12,15,STAINED_CLAY:15,5,AIR,7,IRON_BARS,12,CONCRETE:7,100)
RandomBlock(-5,4,4,CONCRETE:7,60,quark:iron_plate,20,STAINED_CLAY:12,15,STAINED_CLAY:15,5,AIR,7,IRON_BARS,12,CONCRETE:7,100)
RandomBlock(-5,4,5,CONCRETE:7,60,quark:iron_plate,20,STAINED_CLAY:12,15,STAINED_CLAY:15,5,AIR,7,IRON_BARS,12,CONCRETE:7,100)
RandomBlock(-5,4,6,CONCRETE:7,60,quark:iron_plate,20,STAINED_CLAY:12,15,STAINED_CLAY:15,5,AIR,7,IRON_BARS,12,CONCRETE:7,100)
RandomBlock(-5,4,7,CONCRETE:7,60,quark:iron_plate,20,STAINED_CLAY:12,15,STAINED_CLAY:15,5,AIR,7,IRON_BARS,12,CONCRETE:7,100)
RandomBlock(-5,4,8,CONCRETE:7,60,quark:iron_plate,20,STAINED_CLAY:12,15,STAINED_CLAY:15,5,AIR,7,IRON_BARS,12,CONCRETE:7,100)
Block(-5,5,-7,OBSIDIAN:0)
Block(-5,5,-6,OBSIDIAN:0)
Block(-5,5,-5,OBSIDIAN:0)
Block(-5,5,-4,OBSIDIAN:0)
Block(-5,5,-3,OBSIDIAN:0)
Block(-5,5,-2,OBSIDIAN:0)
Block(-5,5,-1,OBSIDIAN:0)
Block(-5,5,0,OBSIDIAN:0)
Block(-5,5,1,OBSIDIAN:0)
Block(-5,5,2,OBSIDIAN:0)
Block(-5,5,3,OBSIDIAN:0)
Block(-5,5,4,SMOOTH_STAIRS:1)
Block(-5,5,5,SMOOTH_STAIRS:1)
Block(-5,5,6,SMOOTH_STAIRS:1)
Block(-5,5,7,SMOOTH_STAIRS:1)
Block(-5,5,8,SMOOTH_STAIRS:1)
Block(-5,6,-7,OBSIDIAN:0)
Block(-5,6,-6,OBSIDIAN:0)
Block(-5,6,-5,OBSIDIAN:0)
Block(-5,6,-4,OBSIDIAN:0)
Block(-5,6,-3,OBSIDIAN:0)
Block(-5,6,-2,OBSIDIAN:0)
Block(-5,6,-1,OBSIDIAN:0)
Block(-5,6,0,OBSIDIAN:0)
Block(-5,6,1,OBSIDIAN:0)
Block(-5,6,2,OBSIDIAN:0)
Block(-5,6,3,OBSIDIAN:0)
Block(-5,6,4,AIR:0)
Block(-5,6,5,AIR:0)
Block(-5,6,6,AIR:0)
Block(-5,6,7,AIR:0)
Block(-5,6,8,AIR:0)
Block(-5,7,-7,OBSIDIAN:0)
Block(-5,7,-6,OBSIDIAN:0)
Block(-5,7,-5,OBSIDIAN:0)
Block(-5,7,-4,OBSIDIAN:0)
Block(-5,7,-3,OBSIDIAN:0)
Block(-5,7,-2,OBSIDIAN:0)
Block(-5,7,-1,OBSIDIAN:0)
Block(-5,7,0,OBSIDIAN:0)
Block(-5,7,1,OBSIDIAN:0)
Block(-5,7,2,OBSIDIAN:0)
Block(-5,7,3,OBSIDIAN:0)
RandomBlock(-5,7,4,CONCRETE:8,60,notreepunching:cobblestone/andesite,15,STONE:5,15,STAINED_CLAY:9,10,IRON_BARS,12,AIR,8,STAINED_CLAY:12,30,CONCRETE:8,100)
RandomBlock(-5,7,5,CONCRETE:8,60,notreepunching:cobblestone/andesite,15,STONE:5,15,STAINED_CLAY:9,10,IRON_BARS,12,AIR,8,STAINED_CLAY:12,30,CONCRETE:8,100)
RandomBlock(-5,7,6,CONCRETE:8,60,notreepunching:cobblestone/andesite,15,STONE:5,15,STAINED_CLAY:9,10,IRON_BARS,12,AIR,8,STAINED_CLAY:12,30,CONCRETE:8,100)
RandomBlock(-5,7,7,CONCRETE:8,60,notreepunching:cobblestone/andesite,15,STONE:5,15,STAINED_CLAY:9,10,IRON_BARS,12,AIR,8,STAINED_CLAY:12,30,CONCRETE:8,100)
RandomBlock(-5,7,8,CONCRETE:8,60,notreepunching:cobblestone/andesite,15,STONE:5,15,STAINED_CLAY:9,10,IRON_BARS,12,AIR,8,STAINED_CLAY:12,30,CONCRETE:8,100)
Block(-5,8,-7,OBSIDIAN:0)
Block(-5,8,-6,OBSIDIAN:0)
Block(-5,8,-5,OBSIDIAN:0)
Block(-5,8,-4,OBSIDIAN:0)
Block(-5,8,-3,OBSIDIAN:0)
