Author: NLBlackEagle
Description: No description given
SettingsMode: WriteDisable
Frequency: 0
SpawnHeight: highestBlock
UseCenterForHighestBlock: true
MinHeight: 0
MaxHeight: 255
InheritBO3: 
InheritBO3Rotation: NORTH
OverrideChildSettings: true
OverrideParentHeight: false
CanOverride: true
BranchFrequency: 0
BranchFrequencyGroup: 
MustBeBelowOther: false
MustBeInside: 
CannotBeInside: 
MustBeInsideWorldBorders: false
CanSpawnOnWater: true
SpawnOnWaterOnly: false
SpawnUnderWater: true
SpawnAtWaterLevel: false
HeightOffset: 0
RemoveAir: false
ReplaceAbove: 
ReplaceBelow: 
ReplaceWithBiomeBlocks: false
ReplaceWithSurfaceBlock: GRASS
ReplaceWithGroundBlock: DIRT
ReplaceWithStoneBlock: eaglemixins:deepslate
SmoothRadius: 0
SmoothHeightOffset: 0
SmoothStartTop: false
SmoothStartWood: false
SmoothingSurfaceBlock: 
SmoothingGroundBlock: 
BO3Group: 
IsSpawnPoint: false
DoReplaceBlocks: false
RandomBlock(-8,0,-7,CONCRETE:7,60,quark:iron_plate,20,STAINED_CLAY:12,15,STAINED_CLAY:15,5,AIR,7,IRON_BARS,12,CONCRETE:7,100)
RandomBlock(-8,0,-6,CONCRETE:7,60,quark:iron_plate,20,STAINED_CLAY:12,15,STAINED_CLAY:15,5,AIR,7,IRON_BARS,12,CONCRETE:7,100)
RandomBlock(-8,0,-5,CONCRETE:7,60,quark:iron_plate,20,STAINED_CLAY:12,15,STAINED_CLAY:15,5,AIR,7,IRON_BARS,12,CONCRETE:7,100)
RandomBlock(-8,0,-4,CONCRETE:7,60,quark:iron_plate,20,STAINED_CLAY:12,15,STAINED_CLAY:15,5,AIR,7,IRON_BARS,12,CONCRETE:7,100)
RandomBlock(-8,0,-3,CONCRETE:7,60,quark:iron_plate,20,STAINED_CLAY:12,15,STAINED_CLAY:15,5,AIR,7,IRON_BARS,12,CONCRETE:7,100)
RandomBlock(-8,0,-2,CONCRETE:7,60,quark:iron_plate,20,STAINED_CLAY:12,15,STAINED_CLAY:15,5,AIR,7,IRON_BARS,12,CONCRETE:7,100)
RandomBlock(-8,0,-1,CONCRETE:7,60,quark:iron_plate,20,STAINED_CLAY:12,15,STAINED_CLAY:15,5,AIR,7,IRON_BARS,12,CONCRETE:7,100)
RandomBlock(-8,0,0,CONCRETE:7,60,quark:iron_plate,20,STAINED_CLAY:12,15,STAINED_CLAY:15,5,AIR,7,IRON_BARS,12,CONCRETE:7,100)
RandomBlock(-8,0,1,CONCRETE:7,60,quark:iron_plate,20,STAINED_CLAY:12,15,STAINED_CLAY:15,5,AIR,7,IRON_BARS,12,CONCRETE:7,100)
RandomBlock(-8,0,2,CONCRETE:7,60,quark:iron_plate,20,STAINED_CLAY:12,15,STAINED_CLAY:15,5,AIR,7,IRON_BARS,12,CONCRETE:7,100)
RandomBlock(-8,0,3,CONCRETE:7,60,quark:iron_plate,20,STAINED_CLAY:12,15,STAINED_CLAY:15,5,AIR,7,IRON_BARS,12,CONCRETE:7,100)
RandomBlock(-8,0,4,CONCRETE:7,60,quark:iron_plate,20,STAINED_CLAY:12,15,STAINED_CLAY:15,5,AIR,7,IRON_BARS,12,CONCRETE:7,100)
RandomBlock(-8,0,5,CONCRETE:7,60,quark:iron_plate,20,STAINED_CLAY:12,15,STAINED_CLAY:15,5,AIR,7,IRON_BARS,12,CONCRETE:7,100)
RandomBlock(-8,0,6,CONCRETE:7,60,quark:iron_plate,20,STAINED_CLAY:12,15,STAINED_CLAY:15,5,AIR,7,IRON_BARS,12,CONCRETE:7,100)
RandomBlock(-8,0,7,CONCRETE:7,60,quark:iron_plate,20,STAINED_CLAY:12,15,STAINED_CLAY:15,5,AIR,7,IRON_BARS,12,CONCRETE:7,100)
RandomBlock(-8,0,8,CONCRETE:7,60,quark:iron_plate,20,STAINED_CLAY:12,15,STAINED_CLAY:15,5,AIR,7,IRON_BARS,12,CONCRETE:7,100)
RandomBlock(-8,1,-7,CONCRETE:7,60,quark:iron_plate,20,STAINED_CLAY:12,15,STAINED_CLAY:15,5,AIR,7,IRON_BARS,12,CONCRETE:7,100)
RandomBlock(-8,1,-6,CONCRETE:7,60,quark:iron_plate,20,STAINED_CLAY:12,15,STAINED_CLAY:15,5,AIR,7,IRON_BARS,12,CONCRETE:7,100)
RandomBlock(-8,1,-5,CONCRETE:7,60,quark:iron_plate,20,STAINED_CLAY:12,15,STAINED_CLAY:15,5,AIR,7,IRON_BARS,12,CONCRETE:7,100)
RandomBlock(-8,1,-4,CONCRETE:7,60,quark:iron_plate,20,STAINED_CLAY:12,15,STAINED_CLAY:15,5,AIR,7,IRON_BARS,12,CONCRETE:7,100)
Block(-8,1,-3,STATIONARY_WATER:0)
Block(-8,1,-2,STATIONARY_WATER:0)
RandomBlock(-8,1,-1,CONCRETE:7,60,quark:iron_plate,20,STAINED_CLAY:12,15,STAINED_CLAY:15,5,AIR,7,IRON_BARS,12,CONCRETE:7,100)
RandomBlock(-8,1,0,CONCRETE:7,60,quark:iron_plate,20,STAINED_CLAY:12,15,STAINED_CLAY:15,5,AIR,7,IRON_BARS,12,CONCRETE:7,100)
RandomBlock(-8,1,1,CONCRETE:7,60,quark:iron_plate,20,STAINED_CLAY:12,15,STAINED_CLAY:15,5,AIR,7,IRON_BARS,12,CONCRETE:7,100)
RandomBlock(-8,1,2,CONCRETE:7,60,quark:iron_plate,20,STAINED_CLAY:12,15,STAINED_CLAY:15,5,AIR,7,IRON_BARS,12,CONCRETE:7,100)
RandomBlock(-8,1,3,CONCRETE:7,60,quark:iron_plate,20,STAINED_CLAY:12,15,STAINED_CLAY:15,5,AIR,7,IRON_BARS,12,CONCRETE:7,100)
RandomBlock(-8,1,4,CONCRETE:7,60,quark:iron_plate,20,STAINED_CLAY:12,15,STAINED_CLAY:15,5,AIR,7,IRON_BARS,12,CONCRETE:7,100)
RandomBlock(-8,1,5,CONCRETE:7,60,quark:iron_plate,20,STAINED_CLAY:12,15,STAINED_CLAY:15,5,AIR,7,IRON_BARS,12,CONCRETE:7,100)
RandomBlock(-8,1,6,CONCRETE:7,60,quark:iron_plate,20,STAINED_CLAY:12,15,STAINED_CLAY:15,5,AIR,7,IRON_BARS,12,CONCRETE:7,100)
RandomBlock(-8,1,7,CONCRETE:7,60,quark:iron_plate,20,STAINED_CLAY:12,15,STAINED_CLAY:15,5,AIR,7,IRON_BARS,12,CONCRETE:7,100)
RandomBlock(-8,1,8,CONCRETE:7,60,quark:iron_plate,20,STAINED_CLAY:12,15,STAINED_CLAY:15,5,AIR,7,IRON_BARS,12,CONCRETE:7,100)
RandomBlock(-8,2,-7,CONCRETE:7,60,quark:iron_plate,20,STAINED_CLAY:12,15,STAINED_CLAY:15,5,AIR,7,IRON_BARS,12,CONCRETE:7,100)
RandomBlock(-8,2,-6,CONCRETE:7,60,quark:iron_plate,20,STAINED_CLAY:12,15,STAINED_CLAY:15,5,AIR,7,IRON_BARS,12,CONCRETE:7,100)
RandomBlock(-8,2,-5,CONCRETE:7,60,quark:iron_plate,20,STAINED_CLAY:12,15,STAINED_CLAY:15,5,AIR,7,IRON_BARS,12,CONCRETE:7,100)
Block(-8,2,-4,SMOOTH_STAIRS:3)
Block(-8,2,-3,AIR:0)
Block(-8,2,-2,AIR:0)
Block(-8,2,-1,SMOOTH_STAIRS:2)
RandomBlock(-8,2,0,CONCRETE:7,60,quark:iron_plate,20,STAINED_CLAY:12,15,STAINED_CLAY:15,5,AIR,7,IRON_BARS,12,CONCRETE:7,100)
RandomBlock(-8,2,1,CONCRETE:7,60,quark:iron_plate,20,STAINED_CLAY:12,15,STAINED_CLAY:15,5,AIR,7,IRON_BARS,12,CONCRETE:7,100)
RandomBlock(-8,2,2,CONCRETE:7,60,quark:iron_plate,20,STAINED_CLAY:12,15,STAINED_CLAY:15,5,AIR,7,IRON_BARS,12,CONCRETE:7,100)
RandomBlock(-8,2,3,CONCRETE:7,60,quark:iron_plate,20,STAINED_CLAY:12,15,STAINED_CLAY:15,5,AIR,7,IRON_BARS,12,CONCRETE:7,100)
RandomBlock(-8,2,4,CONCRETE:7,60,quark:iron_plate,20,STAINED_CLAY:12,15,STAINED_CLAY:15,5,AIR,7,IRON_BARS,12,CONCRETE:7,100)
RandomBlock(-8,2,5,CONCRETE:7,60,quark:iron_plate,20,STAINED_CLAY:12,15,STAINED_CLAY:15,5,AIR,7,IRON_BARS,12,CONCRETE:7,100)
RandomBlock(-8,2,6,CONCRETE:7,60,quark:iron_plate,20,STAINED_CLAY:12,15,STAINED_CLAY:15,5,AIR,7,IRON_BARS,12,CONCRETE:7,100)
RandomBlock(-8,2,7,CONCRETE:7,60,quark:iron_plate,20,STAINED_CLAY:12,15,STAINED_CLAY:15,5,AIR,7,IRON_BARS,12,CONCRETE:7,100)
RandomBlock(-8,2,8,CONCRETE:7,60,quark:iron_plate,20,STAINED_CLAY:12,15,STAINED_CLAY:15,5,AIR,7,IRON_BARS,12,CONCRETE:7,100)
RandomBlock(-8,3,-7,CONCRETE:7,60,quark:iron_plate,20,STAINED_CLAY:12,15,STAINED_CLAY:15,5,AIR,7,IRON_BARS,12,CONCRETE:7,100)
Block(-8,3,-6,AIR:0)
Block(-8,3,-5,AIR:0)
Block(-8,3,-4,AIR:0)
Block(-8,3,-3,AIR:0)
Block(-8,3,-2,AIR:0)
Block(-8,3,-1,AIR:0)
Block(-8,3,0,AIR:0)
Block(-8,3,1,AIR:0)
Block(-8,3,2,AIR:0)
Block(-8,3,3,AIR:0)
Block(-8,3,4,AIR:0)
Block(-8,3,5,AIR:0)
Block(-8,3,6,AIR:0)
Block(-8,3,7,AIR:0)
Block(-8,3,8,AIR:0)
RandomBlock(-8,4,-7,CONCRETE:7,60,quark:iron_plate,20,STAINED_CLAY:12,15,STAINED_CLAY:15,5,AIR,7,IRON_BARS,12,CONCRETE:7,100)
Block(-8,4,-6,AIR:0)
Block(-8,4,-5,AIR:0)
Block(-8,4,-4,AIR:0)
Block(-8,4,-3,AIR:0)
Block(-8,4,-2,AIR:0)
Block(-8,4,-1,AIR:0)
Block(-8,4,0,AIR:0)
Block(-8,4,1,AIR:0)
Block(-8,4,2,AIR:0)
Block(-8,4,3,AIR:0)
Block(-8,4,4,AIR:0)
Block(-8,4,5,AIR:0)
Block(-8,4,6,AIR:0)
Block(-8,4,7,AIR:0)
Block(-8,4,8,AIR:0)
RandomBlock(-8,5,-7,CONCRETE:7,60,quark:iron_plate,20,STAINED_CLAY:12,15,STAINED_CLAY:15,5,AIR,7,IRON_BARS,12,CONCRETE:7,100)
Block(-8,5,-6,CONCRETE:4)
Block(-8,5,-5,CONCRETE:12)
Block(-8,5,-4,AIR:0)
Block(-8,5,-3,AIR:0)
Block(-8,5,-2,AIR:0)
Block(-8,5,-1,AIR:0)
Block(-8,5,0,AIR:0)
Block(-8,5,1,AIR:0)
Block(-8,5,2,AIR:0)
Block(-8,5,3,AIR:0)
Block(-8,5,4,AIR:0)
Block(-8,5,5,AIR:0)
Block(-8,5,6,AIR:0)
Block(-8,5,7,AIR:0)
Block(-8,5,8,AIR:0)
RandomBlock(-8,6,-7,CONCRETE:7,60,quark:iron_plate,20,STAINED_CLAY:12,15,STAINED_CLAY:15,5,AIR,7,IRON_BARS,12,CONCRETE:7,100)
Block(-8,6,-6,AIR:0)
Block(-8,6,-5,AIR:0)
Block(-8,6,-4,AIR:0)
Block(-8,6,-3,AIR:0)
Block(-8,6,-2,AIR:0)
Block(-8,6,-1,AIR:0)
Block(-8,6,0,AIR:0)
Block(-8,6,1,AIR:0)
Block(-8,6,2,AIR:0)
Block(-8,6,3,AIR:0)
Block(-8,6,4,AIR:0)
Block(-8,6,5,AIR:0)
Block(-8,6,6,AIR:0)
Block(-8,6,7,AIR:0)
RandomBlock(-8,6,8,CONCRETE:7,60,quark:iron_plate,20,STAINED_CLAY:12,15,STAINED_CLAY:15,5,AIR,7,IRON_BARS,12,CONCRETE:7,100)
RandomBlock(-8,7,-7,CONCRETE:7,60,quark:iron_plate,20,STAINED_CLAY:12,15,STAINED_CLAY:15,5,AIR,7,IRON_BARS,12,CONCRETE:7,100)
RandomBlock(-8,7,-6,CONCRETE:7,60,quark:iron_plate,20,STAINED_CLAY:12,15,STAINED_CLAY:15,5,AIR,7,IRON_BARS,12,CONCRETE:7,100)
RandomBlock(-8,7,-5,CONCRETE:7,60,quark:iron_plate,20,STAINED_CLAY:12,15,STAINED_CLAY:15,5,AIR,7,IRON_BARS,12,CONCRETE:7,100)
RandomBlock(-8,7,-4,CONCRETE:7,60,quark:iron_plate,20,STAINED_CLAY:12,15,STAINED_CLAY:15,5,AIR,7,IRON_BARS,12,CONCRETE:7,100)
RandomBlock(-8,7,-3,CONCRETE:7,60,quark:iron_plate,20,STAINED_CLAY:12,15,STAINED_CLAY:15,5,AIR,7,IRON_BARS,12,CONCRETE:7,100)
RandomBlock(-8,7,-2,CONCRETE:7,60,quark:iron_plate,20,STAINED_CLAY:12,15,STAINED_CLAY:15,5,AIR,7,IRON_BARS,12,CONCRETE:7,100)
RandomBlock(-8,7,-1,CONCRETE:7,60,quark:iron_plate,20,STAINED_CLAY:12,15,STAINED_CLAY:15,5,AIR,7,IRON_BARS,12,CONCRETE:7,100)
RandomBlock(-8,7,0,CONCRETE:7,60,quark:iron_plate,20,STAINED_CLAY:12,15,STAINED_CLAY:15,5,AIR,7,IRON_BARS,12,CONCRETE:7,100)
RandomBlock(-8,7,1,CONCRETE:7,60,quark:iron_plate,20,STAINED_CLAY:12,15,STAINED_CLAY:15,5,AIR,7,IRON_BARS,12,CONCRETE:7,100)
RandomBlock(-8,7,2,CONCRETE:7,60,quark:iron_plate,20,STAINED_CLAY:12,15,STAINED_CLAY:15,5,AIR,7,IRON_BARS,12,CONCRETE:7,100)
RandomBlock(-8,7,3,CONCRETE:7,60,quark:iron_plate,20,STAINED_CLAY:12,15,STAINED_CLAY:15,5,AIR,7,IRON_BARS,12,CONCRETE:7,100)
RandomBlock(-8,7,4,CONCRETE:7,60,quark:iron_plate,20,STAINED_CLAY:12,15,STAINED_CLAY:15,5,AIR,7,IRON_BARS,12,CONCRETE:7,100)
RandomBlock(-8,7,5,CONCRETE:7,60,quark:iron_plate,20,STAINED_CLAY:12,15,STAINED_CLAY:15,5,AIR,7,IRON_BARS,12,CONCRETE:7,100)
RandomBlock(-8,7,6,CONCRETE:7,60,quark:iron_plate,20,STAINED_CLAY:12,15,STAINED_CLAY:15,5,AIR,7,IRON_BARS,12,CONCRETE:7,100)
RandomBlock(-8,7,7,CONCRETE:7,60,quark:iron_plate,20,STAINED_CLAY:12,15,STAINED_CLAY:15,5,AIR,7,IRON_BARS,12,CONCRETE:7,100)
RandomBlock(-8,7,8,CONCRETE:7,60,quark:iron_plate,20,STAINED_CLAY:12,15,STAINED_CLAY:15,5,AIR,7,IRON_BARS,12,CONCRETE:7,100)
Block(-8,8,-7,AIR:0)
Block(-8,8,-6,IRON_FENCE:0)
Block(-8,8,-5,AIR:0)
Block(-8,8,-4,AIR:0)
RandomBlock(-8,8,-2,CONCRETE:7,60,quark:iron_plate,20,STAINED_CLAY:12,15,STAINED_CLAY:15,5,AIR,7,IRON_BARS,12,CONCRETE:7,100)
RandomBlock(-8,8,-1,CONCRETE:7,60,quark:iron_plate,20,STAINED_CLAY:12,15,STAINED_CLAY:15,5,AIR,7,IRON_BARS,12,CONCRETE:7,100)
RandomBlock(-8,8,0,CONCRETE:7,60,quark:iron_plate,20,STAINED_CLAY:12,15,STAINED_CLAY:15,5,AIR,7,IRON_BARS,12,CONCRETE:7,100)
RandomBlock(-8,8,1,CONCRETE:7,60,quark:iron_plate,20,STAINED_CLAY:12,15,STAINED_CLAY:15,5,AIR,7,IRON_BARS,12,CONCRETE:7,100)
RandomBlock(-8,8,2,CONCRETE:7,60,quark:iron_plate,20,STAINED_CLAY:12,15,STAINED_CLAY:15,5,AIR,7,IRON_BARS,12,CONCRETE:7,100)
RandomBlock(-8,8,3,CONCRETE:7,60,quark:iron_plate,20,STAINED_CLAY:12,15,STAINED_CLAY:15,5,AIR,7,IRON_BARS,12,CONCRETE:7,100)
RandomBlock(-8,8,4,CONCRETE:7,60,quark:iron_plate,20,STAINED_CLAY:12,15,STAINED_CLAY:15,5,AIR,7,IRON_BARS,12,CONCRETE:7,100)
RandomBlock(-8,8,5,CONCRETE:7,60,quark:iron_plate,20,STAINED_CLAY:12,15,STAINED_CLAY:15,5,AIR,7,IRON_BARS,12,CONCRETE:7,100)
RandomBlock(-8,8,6,CONCRETE:7,60,quark:iron_plate,20,STAINED_CLAY:12,15,STAINED_CLAY:15,5,AIR,7,IRON_BARS,12,CONCRETE:7,100)
RandomBlock(-8,8,7,CONCRETE:7,60,quark:iron_plate,20,STAINED_CLAY:12,15,STAINED_CLAY:15,5,AIR,7,IRON_BARS,12,CONCRETE:7,100)
RandomBlock(-8,8,8,CONCRETE:7,60,quark:iron_plate,20,STAINED_CLAY:12,15,STAINED_CLAY:15,5,AIR,7,IRON_BARS,12,CONCRETE:7,100)
Block(-8,9,-7,AIR:0)
Block(-8,9,-6,CONCRETE:14)
Block(-8,9,-5,AIR:0)
Block(-8,9,-4,AIR:0)
Block(-8,9,-3,AIR:0)
RandomBlock(-8,9,-2,CONCRETE:7,60,quark:iron_plate,20,STAINED_CLAY:12,15,STAINED_CLAY:15,5,AIR,7,IRON_BARS,12,CONCRETE:7,100)
RandomBlock(-8,9,-1,CONCRETE:7,60,quark:iron_plate,20,STAINED_CLAY:12,15,STAINED_CLAY:15,5,AIR,7,IRON_BARS,12,CONCRETE:7,100)
RandomBlock(-8,9,0,CONCRETE:7,60,quark:iron_plate,20,STAINED_CLAY:12,15,STAINED_CLAY:15,5,AIR,7,IRON_BARS,12,CONCRETE:7,100)
RandomBlock(-8,9,1,CONCRETE:7,60,quark:iron_plate,20,STAINED_CLAY:12,15,STAINED_CLAY:15,5,AIR,7,IRON_BARS,12,CONCRETE:7,100)
RandomBlock(-8,9,2,CONCRETE:7,60,quark:iron_plate,20,STAINED_CLAY:12,15,STAINED_CLAY:15,5,AIR,7,IRON_BARS,12,CONCRETE:7,100)
RandomBlock(-8,9,3,CONCRETE:7,60,quark:iron_plate,20,STAINED_CLAY:12,15,STAINED_CLAY:15,5,AIR,7,IRON_BARS,12,CONCRETE:7,100)
RandomBlock(-8,9,4,CONCRETE:7,60,quark:iron_plate,20,STAINED_CLAY:12,15,STAINED_CLAY:15,5,AIR,7,IRON_BARS,12,CONCRETE:7,100)
RandomBlock(-8,9,5,CONCRETE:7,60,quark:iron_plate,20,STAINED_CLAY:12,15,STAINED_CLAY:15,5,AIR,7,IRON_BARS,12,CONCRETE:7,100)
RandomBlock(-8,9,6,CONCRETE:7,60,quark:iron_plate,20,STAINED_CLAY:12,15,STAINED_CLAY:15,5,AIR,7,IRON_BARS,12,CONCRETE:7,100)
RandomBlock(-8,9,7,CONCRETE:7,60,quark:iron_plate,20,STAINED_CLAY:12,15,STAINED_CLAY:15,5,AIR,7,IRON_BARS,12,CONCRETE:7,100)
RandomBlock(-8,9,8,CONCRETE:7,60,quark:iron_plate,20,STAINED_CLAY:12,15,STAINED_CLAY:15,5,AIR,7,IRON_BARS,12,CONCRETE:7,100)
Block(-8,10,-7,AIR:0)
Block(-8,10,-6,CONCRETE:14)
Block(-8,10,-5,AIR:0)
Block(-8,10,-4,AIR:0)
Block(-8,10,-3,AIR:0)
RandomBlock(-8,10,-2,CONCRETE:7,60,quark:iron_plate,20,STAINED_CLAY:12,15,STAINED_CLAY:15,5,AIR,7,IRON_BARS,12,CONCRETE:7,100)
RandomBlock(-8,10,-1,CONCRETE:7,60,quark:iron_plate,20,STAINED_CLAY:12,15,STAINED_CLAY:15,5,AIR,7,IRON_BARS,12,CONCRETE:7,100)
RandomBlock(-8,10,0,CONCRETE:7,60,quark:iron_plate,20,STAINED_CLAY:12,15,STAINED_CLAY:15,5,AIR,7,IRON_BARS,12,CONCRETE:7,100)
RandomBlock(-8,10,1,CONCRETE:7,60,quark:iron_plate,20,STAINED_CLAY:12,15,STAINED_CLAY:15,5,AIR,7,IRON_BARS,12,CONCRETE:7,100)
RandomBlock(-8,10,2,CONCRETE:7,60,quark:iron_plate,20,STAINED_CLAY:12,15,STAINED_CLAY:15,5,AIR,7,IRON_BARS,12,CONCRETE:7,100)
RandomBlock(-8,10,3,CONCRETE:7,60,quark:iron_plate,20,STAINED_CLAY:12,15,STAINED_CLAY:15,5,AIR,7,IRON_BARS,12,CONCRETE:7,100)
RandomBlock(-8,10,4,CONCRETE:7,60,quark:iron_plate,20,STAINED_CLAY:12,15,STAINED_CLAY:15,5,AIR,7,IRON_BARS,12,CONCRETE:7,100)
RandomBlock(-8,10,5,CONCRETE:7,60,quark:iron_plate,20,STAINED_CLAY:12,15,STAINED_CLAY:15,5,AIR,7,IRON_BARS,12,CONCRETE:7,100)
RandomBlock(-8,10,6,CONCRETE:7,60,quark:iron_plate,20,STAINED_CLAY:12,15,STAINED_CLAY:15,5,AIR,7,IRON_BARS,12,CONCRETE:7,100)
RandomBlock(-8,10,7,CONCRETE:7,60,quark:iron_plate,20,STAINED_CLAY:12,15,STAINED_CLAY:15,5,AIR,7,IRON_BARS,12,CONCRETE:7,100)
RandomBlock(-8,10,8,CONCRETE:7,60,quark:iron_plate,20,STAINED_CLAY:12,15,STAINED_CLAY:15,5,AIR,7,IRON_BARS,12,CONCRETE:7,100)
Block(-8,11,-7,AIR:0)
Block(-8,11,-6,CONCRETE:14)
Block(-8,11,-5,AIR:0)
Block(-8,11,-4,AIR:0)
Block(-8,11,-3,AIR:0)
Block(-8,11,-2,STEP:7)
Block(-8,11,-1,STEP:7)
Block(-8,11,0,CONCRETE:12)
Block(-8,11,1,STEP:7)
Block(-8,11,2,CONCRETE:4)
Block(-8,11,3,STEP:7)
Block(-8,11,4,STEP:7)
RandomBlock(-8,11,5,CONCRETE:7,60,quark:iron_plate,20,STAINED_CLAY:12,15,STAINED_CLAY:15,5,AIR,7,IRON_BARS,12,CONCRETE:7,100)
RandomBlock(-8,11,6,CONCRETE:7,60,quark:iron_plate,20,STAINED_CLAY:12,15,STAINED_CLAY:15,5,AIR,7,IRON_BARS,12,CONCRETE:7,100)
RandomBlock(-8,11,7,CONCRETE:7,60,quark:iron_plate,20,STAINED_CLAY:12,15,STAINED_CLAY:15,5,AIR,7,IRON_BARS,12,CONCRETE:7,100)
RandomBlock(-8,11,8,CONCRETE:7,60,quark:iron_plate,20,STAINED_CLAY:12,15,STAINED_CLAY:15,5,AIR,7,IRON_BARS,12,CONCRETE:7,100)
Block(-8,12,-7,AIR:0)
Block(-8,12,-6,IRON_FENCE:0)
Block(-8,12,-5,AIR:0)
Block(-8,12,-4,AIR:0)
Block(-8,12,-3,AIR:0)
Block(-8,12,-2,AIR:0)
Block(-8,12,-1,AIR:0)
Block(-8,12,0,AIR:0)
Block(-8,12,1,AIR:0)
Block(-8,12,2,AIR:0)
Block(-8,12,3,AIR:0)
Block(-8,12,4,AIR:0)
RandomBlock(-8,12,5,CONCRETE:7,60,quark:iron_plate,20,STAINED_CLAY:12,15,STAINED_CLAY:15,5,AIR,7,IRON_BARS,12,CONCRETE:7,100)
RandomBlock(-8,12,6,CONCRETE:7,60,quark:iron_plate,20,STAINED_CLAY:12,15,STAINED_CLAY:15,5,AIR,7,IRON_BARS,12,CONCRETE:7,100)
RandomBlock(-8,12,7,CONCRETE:7,60,quark:iron_plate,20,STAINED_CLAY:12,15,STAINED_CLAY:15,5,AIR,7,IRON_BARS,12,CONCRETE:7,100)
RandomBlock(-8,12,8,CONCRETE:7,60,quark:iron_plate,20,STAINED_CLAY:12,15,STAINED_CLAY:15,5,AIR,7,IRON_BARS,12,CONCRETE:7,100)
RandomBlock(-8,13,-7,CONCRETE:8,60,notreepunching:cobblestone/andesite,15,STONE:5,15,STAINED_CLAY:9,10,IRON_BARS,12,AIR,8,STAINED_CLAY:12,30,CONCRETE:8,100)
RandomBlock(-8,13,-6,CONCRETE:8,60,notreepunching:cobblestone/andesite,15,STONE:5,15,STAINED_CLAY:9,10,IRON_BARS,12,AIR,8,STAINED_CLAY:12,30,CONCRETE:8,100)
RandomBlock(-8,13,-5,CONCRETE:8,60,notreepunching:cobblestone/andesite,15,STONE:5,15,STAINED_CLAY:9,10,IRON_BARS,12,AIR,8,STAINED_CLAY:12,30,CONCRETE:8,100)
RandomBlock(-8,13,-4,CONCRETE:8,60,notreepunching:cobblestone/andesite,15,STONE:5,15,STAINED_CLAY:9,10,IRON_BARS,12,AIR,8,STAINED_CLAY:12,30,CONCRETE:8,100)
RandomBlock(-8,13,-3,CONCRETE:8,60,notreepunching:cobblestone/andesite,15,STONE:5,15,STAINED_CLAY:9,10,IRON_BARS,12,AIR,8,STAINED_CLAY:12,30,CONCRETE:8,100)
RandomBlock(-8,13,-2,CONCRETE:8,60,notreepunching:cobblestone/andesite,15,STONE:5,15,STAINED_CLAY:9,10,IRON_BARS,12,AIR,8,STAINED_CLAY:12,30,CONCRETE:8,100)
RandomBlock(-8,13,-1,CONCRETE:8,60,notreepunching:cobblestone/andesite,15,STONE:5,15,STAINED_CLAY:9,10,IRON_BARS,12,AIR,8,STAINED_CLAY:12,30,CONCRETE:8,100)
RandomBlock(-8,13,0,CONCRETE:8,60,notreepunching:cobblestone/andesite,15,STONE:5,15,STAINED_CLAY:9,10,IRON_BARS,12,AIR,8,STAINED_CLAY:12,30,CONCRETE:8,100)
RandomBlock(-8,13,1,CONCRETE:8,60,notreepunching:cobblestone/andesite,15,STONE:5,15,STAINED_CLAY:9,10,IRON_BARS,12,AIR,8,STAINED_CLAY:12,30,CONCRETE:8,100)
RandomBlock(-8,13,2,CONCRETE:8,60,notreepunching:cobblestone/andesite,15,STONE:5,15,STAINED_CLAY:9,10,IRON_BARS,12,AIR,8,STAINED_CLAY:12,30,CONCRETE:8,100)
RandomBlock(-8,13,3,CONCRETE:8,60,notreepunching:cobblestone/andesite,15,STONE:5,15,STAINED_CLAY:9,10,IRON_BARS,12,AIR,8,STAINED_CLAY:12,30,CONCRETE:8,100)
RandomBlock(-8,13,4,CONCRETE:8,60,notreepunching:cobblestone/andesite,15,STONE:5,15,STAINED_CLAY:9,10,IRON_BARS,12,AIR,8,STAINED_CLAY:12,30,CONCRETE:8,100)
RandomBlock(-8,13,5,CONCRETE:8,60,notreepunching:cobblestone/andesite,15,STONE:5,15,STAINED_CLAY:9,10,IRON_BARS,12,AIR,8,STAINED_CLAY:12,30,CONCRETE:8,100)
RandomBlock(-8,13,6,CONCRETE:8,60,notreepunching:cobblestone/andesite,15,STONE:5,15,STAINED_CLAY:9,10,IRON_BARS,12,AIR,8,STAINED_CLAY:12,30,CONCRETE:8,100)
RandomBlock(-8,13,7,CONCRETE:8,60,notreepunching:cobblestone/andesite,15,STONE:5,15,STAINED_CLAY:9,10,IRON_BARS,12,AIR,8,STAINED_CLAY:12,30,CONCRETE:8,100)
RandomBlock(-8,13,8,CONCRETE:8,60,notreepunching:cobblestone/andesite,15,STONE:5,15,STAINED_CLAY:9,10,IRON_BARS,12,AIR,8,STAINED_CLAY:12,30,CONCRETE:8,100)
RandomBlock(-8,14,-7,CONCRETE:8,60,notreepunching:cobblestone/andesite,15,STONE:5,15,STAINED_CLAY:9,10,IRON_BARS,12,AIR,8,STAINED_CLAY:12,30,CONCRETE:8,100)
RandomBlock(-8,14,-6,CONCRETE:8,60,notreepunching:cobblestone/andesite,15,STONE:5,15,STAINED_CLAY:9,10,IRON_BARS,12,AIR,8,STAINED_CLAY:12,30,CONCRETE:8,100)
RandomBlock(-8,14,-5,CONCRETE:8,60,notreepunching:cobblestone/andesite,15,STONE:5,15,STAINED_CLAY:9,10,IRON_BARS,12,AIR,8,STAINED_CLAY:12,30,CONCRETE:8,100)
RandomBlock(-8,14,-4,CONCRETE:8,60,notreepunching:cobblestone/andesite,15,STONE:5,15,STAINED_CLAY:9,10,IRON_BARS,12,AIR,8,STAINED_CLAY:12,30,CONCRETE:8,100)
RandomBlock(-8,14,-3,CONCRETE:8,60,notreepunching:cobblestone/andesite,15,STONE:5,15,STAINED_CLAY:9,10,IRON_BARS,12,AIR,8,STAINED_CLAY:12,30,CONCRETE:8,100)
RandomBlock(-8,14,-2,CONCRETE:8,60,notreepunching:cobblestone/andesite,15,STONE:5,15,STAINED_CLAY:9,10,IRON_BARS,12,AIR,8,STAINED_CLAY:12,30,CONCRETE:8,100)
RandomBlock(-8,14,-1,CONCRETE:8,60,notreepunching:cobblestone/andesite,15,STONE:5,15,STAINED_CLAY:9,10,IRON_BARS,12,AIR,8,STAINED_CLAY:12,30,CONCRETE:8,100)
Block(-8,14,0,AIR:0)
Block(-8,14,1,AIR:0)
Block(-8,14,2,AIR:0)
Block(-8,14,3,QUARTZ_STAIRS:3)
RandomBlock(-8,14,4,CONCRETE:8,60,notreepunching:cobblestone/andesite,15,STONE:5,15,STAINED_CLAY:9,10,IRON_BARS,12,AIR,8,STAINED_CLAY:12,30,CONCRETE:8,100)
RandomBlock(-8,14,5,CONCRETE:8,60,notreepunching:cobblestone/andesite,15,STONE:5,15,STAINED_CLAY:9,10,IRON_BARS,12,AIR,8,STAINED_CLAY:12,30,CONCRETE:8,100)
RandomBlock(-8,14,6,CONCRETE:8,60,notreepunching:cobblestone/andesite,15,STONE:5,15,STAINED_CLAY:9,10,IRON_BARS,12,AIR,8,STAINED_CLAY:12,30,CONCRETE:8,100)
RandomBlock(-8,14,7,CONCRETE:8,60,notreepunching:cobblestone/andesite,15,STONE:5,15,STAINED_CLAY:9,10,IRON_BARS,12,AIR,8,STAINED_CLAY:12,30,CONCRETE:8,100)
Block(-8,14,8,STEP:15)
RandomBlock(-8,15,-7,CONCRETE:7,60,quark:iron_plate,20,STAINED_CLAY:12,15,STAINED_CLAY:15,5,AIR,7,IRON_BARS,12,CONCRETE:7,100)
RandomBlock(-8,15,-6,CONCRETE:7,60,quark:iron_plate,20,STAINED_CLAY:12,15,STAINED_CLAY:15,5,AIR,7,IRON_BARS,12,CONCRETE:7,100)
RandomBlock(-8,15,-5,CONCRETE:7,60,quark:iron_plate,20,STAINED_CLAY:12,15,STAINED_CLAY:15,5,AIR,7,IRON_BARS,12,CONCRETE:7,100)
RandomBlock(-8,15,-4,CONCRETE:7,60,quark:iron_plate,20,STAINED_CLAY:12,15,STAINED_CLAY:15,5,AIR,7,IRON_BARS,12,CONCRETE:7,100)
RandomBlock(-8,15,-3,CONCRETE:7,60,quark:iron_plate,20,STAINED_CLAY:12,15,STAINED_CLAY:15,5,AIR,7,IRON_BARS,12,CONCRETE:7,100)
RandomBlock(-8,15,-2,CONCRETE:7,60,quark:iron_plate,20,STAINED_CLAY:12,15,STAINED_CLAY:15,5,AIR,7,IRON_BARS,12,CONCRETE:7,100)
RandomBlock(-8,15,-1,CONCRETE:7,60,quark:iron_plate,20,STAINED_CLAY:12,15,STAINED_CLAY:15,5,AIR,7,IRON_BARS,12,CONCRETE:7,100)
Block(-8,15,0,AIR:0)
Block(-8,15,1,AIR:0)
Block(-8,15,2,AIR:0)
Block(-8,15,3,AIR:0)
RandomBlock(-8,15,4,CONCRETE:7,60,quark:iron_plate,20,STAINED_CLAY:12,15,STAINED_CLAY:15,5,AIR,7,IRON_BARS,12,CONCRETE:7,100)
RandomBlock(-8,15,5,CONCRETE:7,60,quark:iron_plate,20,STAINED_CLAY:12,15,STAINED_CLAY:15,5,AIR,7,IRON_BARS,12,CONCRETE:7,100)
RandomBlock(-8,15,6,CONCRETE:8,60,notreepunching:cobblestone/andesite,15,STONE:5,15,STAINED_CLAY:9,10,IRON_BARS,12,AIR,8,STAINED_CLAY:12,30,CONCRETE:8,100)
RandomBlock(-8,15,7,CONCRETE:7,60,quark:iron_plate,20,STAINED_CLAY:12,15,STAINED_CLAY:15,5,AIR,7,IRON_BARS,12,CONCRETE:7,100)
RandomBlock(-8,15,8,AIR,90,IRON_TRAPDOOR:9,100)
RandomBlock(-8,16,-7,CONCRETE:7,60,quark:iron_plate,20,STAINED_CLAY:12,15,STAINED_CLAY:15,5,AIR,7,IRON_BARS,12,CONCRETE:7,100)
RandomBlock(-8,16,-6,CONCRETE:7,60,quark:iron_plate,20,STAINED_CLAY:12,15,STAINED_CLAY:15,5,AIR,7,IRON_BARS,12,CONCRETE:7,100)
RandomBlock(-8,16,-5,CONCRETE:7,60,quark:iron_plate,20,STAINED_CLAY:12,15,STAINED_CLAY:15,5,AIR,7,IRON_BARS,12,CONCRETE:7,100)
RandomBlock(-8,16,-4,CONCRETE:7,60,quark:iron_plate,20,STAINED_CLAY:12,15,STAINED_CLAY:15,5,AIR,7,IRON_BARS,12,CONCRETE:7,100)
RandomBlock(-8,16,-3,CONCRETE:7,60,quark:iron_plate,20,STAINED_CLAY:12,15,STAINED_CLAY:15,5,AIR,7,IRON_BARS,12,CONCRETE:7,100)
RandomBlock(-8,16,-2,CONCRETE:7,60,quark:iron_plate,20,STAINED_CLAY:12,15,STAINED_CLAY:15,5,AIR,7,IRON_BARS,12,CONCRETE:7,100)
RandomBlock(-8,16,-1,CONCRETE:7,60,quark:iron_plate,20,STAINED_CLAY:12,15,STAINED_CLAY:15,5,AIR,7,IRON_BARS,12,CONCRETE:7,100)
Block(-8,16,0,STEP:15)
Block(-8,16,1,STEP:15)
Block(-8,16,2,STEP:15)
Block(-8,16,3,STEP:15)
RandomBlock(-8,16,4,CONCRETE:7,60,quark:iron_plate,20,STAINED_CLAY:12,15,STAINED_CLAY:15,5,AIR,7,IRON_BARS,12,CONCRETE:7,100)
RandomBlock(-8,16,5,CONCRETE:7,60,quark:iron_plate,20,STAINED_CLAY:12,15,STAINED_CLAY:15,5,AIR,7,IRON_BARS,12,CONCRETE:7,100)
RandomBlock(-8,16,6,CONCRETE:8,60,notreepunching:cobblestone/andesite,15,STONE:5,15,STAINED_CLAY:9,10,IRON_BARS,12,AIR,8,STAINED_CLAY:12,30,CONCRETE:8,100)
RandomBlock(-8,16,7,CONCRETE:7,60,quark:iron_plate,20,STAINED_CLAY:12,15,STAINED_CLAY:15,5,AIR,7,IRON_BARS,12,CONCRETE:7,100)
Block(-8,16,8,AIR:0)
RandomBlock(-8,17,-7,CONCRETE:7,60,quark:iron_plate,20,STAINED_CLAY:12,15,STAINED_CLAY:15,5,AIR,7,IRON_BARS,12,CONCRETE:7,100)
RandomBlock(-8,17,-6,CONCRETE:7,60,quark:iron_plate,20,STAINED_CLAY:12,15,STAINED_CLAY:15,5,AIR,7,IRON_BARS,12,CONCRETE:7,100)
RandomBlock(-8,17,-5,CONCRETE:7,60,quark:iron_plate,20,STAINED_CLAY:12,15,STAINED_CLAY:15,5,AIR,7,IRON_BARS,12,CONCRETE:7,100)
RandomBlock(-8,17,-4,CONCRETE:7,60,quark:iron_plate,20,STAINED_CLAY:12,15,STAINED_CLAY:15,5,AIR,7,IRON_BARS,12,CONCRETE:7,100)
RandomBlock(-8,17,-3,CONCRETE:7,60,quark:iron_plate,20,STAINED_CLAY:12,15,STAINED_CLAY:15,5,AIR,7,IRON_BARS,12,CONCRETE:7,100)
RandomBlock(-8,17,-2,CONCRETE:7,60,quark:iron_plate,20,STAINED_CLAY:12,15,STAINED_CLAY:15,5,AIR,7,IRON_BARS,12,CONCRETE:7,100)
RandomBlock(-8,17,-1,CONCRETE:7,60,quark:iron_plate,20,STAINED_CLAY:12,15,STAINED_CLAY:15,5,AIR,7,IRON_BARS,12,CONCRETE:7,100)
RandomBlock(-8,17,0,CONCRETE:7,60,quark:iron_plate,20,STAINED_CLAY:12,15,STAINED_CLAY:15,5,AIR,7,IRON_BARS,12,CONCRETE:7,100)
RandomBlock(-8,17,1,CONCRETE:7,60,quark:iron_plate,20,STAINED_CLAY:12,15,STAINED_CLAY:15,5,AIR,7,IRON_BARS,12,CONCRETE:7,100)
RandomBlock(-8,17,2,CONCRETE:7,60,quark:iron_plate,20,STAINED_CLAY:12,15,STAINED_CLAY:15,5,AIR,7,IRON_BARS,12,CONCRETE:7,100)
RandomBlock(-8,17,3,CONCRETE:7,60,quark:iron_plate,20,STAINED_CLAY:12,15,STAINED_CLAY:15,5,AIR,7,IRON_BARS,12,CONCRETE:7,100)
RandomBlock(-8,17,4,CONCRETE:7,60,quark:iron_plate,20,STAINED_CLAY:12,15,STAINED_CLAY:15,5,AIR,7,IRON_BARS,12,CONCRETE:7,100)
RandomBlock(-8,17,5,CONCRETE:7,60,quark:iron_plate,20,STAINED_CLAY:12,15,STAINED_CLAY:15,5,AIR,7,IRON_BARS,12,CONCRETE:7,100)
RandomBlock(-8,17,6,CONCRETE:7,60,quark:iron_plate,20,STAINED_CLAY:12,15,STAINED_CLAY:15,5,AIR,7,IRON_BARS,12,CONCRETE:7,100)
RandomBlock(-8,17,7,CONCRETE:7,60,quark:iron_plate,20,STAINED_CLAY:12,15,STAINED_CLAY:15,5,AIR,7,IRON_BARS,12,CONCRETE:7,100)
RandomBlock(-8,17,8,CONCRETE:7,60,quark:iron_plate,20,STAINED_CLAY:12,15,STAINED_CLAY:15,5,AIR,7,IRON_BARS,12,CONCRETE:7,100)
Block(-8,18,0,AIR)
Block(-8,18,1,AIR)
Block(-8,18,2,AIR)
Block(-8,25,-7,CONCRETE:15)
Block(-8,25,-6,CONCRETE:15)
Block(-8,25,-5,CONCRETE:15)
Block(-8,25,-4,CONCRETE:15)
Block(-8,25,-3,CONCRETE:15)
Block(-8,25,-2,CONCRETE:15)
Block(-8,25,-1,CONCRETE:15)
Block(-8,25,0,CONCRETE:15)
Block(-8,25,1,CONCRETE:15)
Block(-8,25,2,CONCRETE:15)
Block(-8,25,3,CONCRETE:15)
Block(-8,25,4,CONCRETE:15)
Block(-8,25,5,CONCRETE:15)
Block(-8,25,6,CONCRETE:15)
Block(-8,25,7,CONCRETE:15)
Block(-8,25,8,CONCRETE:15)
Block(-8,26,-6,AIR)
Block(-8,26,-4,CONCRETE:0)
Block(-8,26,-3,AIR)
Block(-8,26,-2,AIR)
Block(-8,26,-1,AIR)
Block(-8,26,0,AIR)
Block(-8,26,1,CONCRETE:0)
Block(-8,26,2,AIR)
Block(-8,26,3,AIR)
Block(-8,26,5,AIR)
Block(-8,26,6,CONCRETE:0)
Block(-8,26,8,AIR)
Block(-8,27,-4,CONCRETE:0)
Block(-8,27,1,CONCRETE:0)
Block(-8,27,6,CONCRETE:0)
Block(-8,28,-4,CONCRETE:0)
Block(-8,28,1,CONCRETE:0)
Block(-8,28,6,CONCRETE:0)
Block(-8,29,-7,CONCRETE:15)
Block(-8,29,-6,CONCRETE:15)
Block(-8,29,-5,CONCRETE:15)
Block(-8,29,-4,CONCRETE:15)
Block(-8,29,-3,CONCRETE:15)
Block(-8,29,-2,CONCRETE:15)
Block(-8,29,-1,CONCRETE:15)
Block(-8,29,0,CONCRETE:15)
Block(-8,29,1,CONCRETE:15)
Block(-8,29,2,CONCRETE:15)
Block(-8,29,3,CONCRETE:15)
Block(-8,29,4,CONCRETE:15)
Block(-8,29,5,CONCRETE:15)
Block(-8,29,6,CONCRETE:15)
Block(-8,29,7,CONCRETE:15)
Block(-8,29,8,CONCRETE:15)
Block(-8,30,-2,DOUBLE_STEP:7)
Block(-8,30,-1,AIR)
Block(-8,30,0,AIR)
Block(-8,30,4,AIR)
Block(-8,31,-2,AIR)
Block(-8,31,0,AIR)
Block(-8,31,4,AIR)
RandomBlock(-8,32,4,CONCRETE:7,60,quark:iron_plate,20,STAINED_CLAY:12,15,STAINED_CLAY:15,5,AIR,7,IRON_BARS,12,CONCRETE:7,100)
Block(-8,33,-7,CONCRETE:15)
Block(-8,33,-6,CONCRETE:15)
Block(-8,33,-5,CONCRETE:15)
Block(-8,33,-4,CONCRETE:15)
Block(-8,33,-3,CONCRETE:15)
Block(-8,33,-2,CONCRETE:15)
Block(-8,33,-1,CONCRETE:15)
Block(-8,33,0,CONCRETE:15)
Block(-8,33,1,CONCRETE:15)
Block(-8,33,2,CONCRETE:15)
Block(-8,33,3,CONCRETE:15)
Block(-8,33,4,CONCRETE:15)
Block(-8,33,5,CONCRETE:15)
Block(-8,33,6,CONCRETE:15)
Block(-8,33,7,CONCRETE:15)
Block(-8,33,8,CONCRETE:15)
Block(-8,34,-1,AIR)
Block(-8,34,0,AIR)
Block(-8,34,1,AIR)
Block(-8,34,2,AIR)
Block(-8,34,3,AIR)
Block(-8,37,-7,CONCRETE:15)
Block(-8,37,-6,CONCRETE:15)
Block(-8,37,-5,CONCRETE:15)
Block(-8,37,-4,CONCRETE:15)
Block(-8,37,-3,CONCRETE:15)
Block(-8,37,-2,CONCRETE:15)
Block(-8,37,-1,CONCRETE:15)
Block(-8,37,0,CONCRETE:15)
Block(-8,37,1,CONCRETE:15)
Block(-8,37,2,CONCRETE:15)
Block(-8,37,3,CONCRETE:15)
Block(-8,37,4,CONCRETE:15)
Block(-8,37,5,CONCRETE:15)
Block(-8,37,6,CONCRETE:15)
Block(-8,37,7,CONCRETE:15)
Block(-8,37,8,CONCRETE:15)
Block(-8,38,-1,AIR)
Block(-8,38,0,AIR)
Block(-8,38,1,AIR)
Block(-8,38,2,AIR)
Block(-8,38,3,AIR)
Block(-8,41,-7,CONCRETE:15)
Block(-8,41,-6,CONCRETE:15)
Block(-8,41,-5,CONCRETE:15)
Block(-8,41,-4,CONCRETE:15)
Block(-8,41,-3,CONCRETE:15)
Block(-8,41,-2,CONCRETE:15)
Block(-8,41,-1,CONCRETE:15)
Block(-8,41,0,CONCRETE:15)
Block(-8,41,1,CONCRETE:15)
Block(-8,41,2,CONCRETE:15)
Block(-8,41,3,CONCRETE:15)
Block(-8,41,4,CONCRETE:15)
Block(-8,41,5,CONCRETE:15)
Block(-8,41,6,CONCRETE:15)
Block(-8,41,7,CONCRETE:15)
Block(-8,41,8,CONCRETE:15)
Block(-8,42,-1,AIR)
Block(-8,42,0,AIR)
Block(-8,42,1,AIR)
Block(-8,42,2,AIR)
Block(-8,42,3,AIR)
Block(-8,45,-7,CONCRETE:15)
Block(-8,45,-6,CONCRETE:15)
Block(-8,45,-5,CONCRETE:15)
Block(-8,45,-4,CONCRETE:15)
Block(-8,45,-3,CONCRETE:15)
Block(-8,45,-2,CONCRETE:15)
Block(-8,45,-1,CONCRETE:15)
Block(-8,45,0,CONCRETE:15)
Block(-8,45,1,CONCRETE:15)
Block(-8,45,2,CONCRETE:15)
Block(-8,45,3,CONCRETE:15)
Block(-8,45,4,CONCRETE:15)
Block(-8,45,5,CONCRETE:15)
Block(-8,45,6,CONCRETE:15)
Block(-8,45,7,CONCRETE:15)
Block(-8,45,8,CONCRETE:15)
Block(-8,46,-1,AIR)
Block(-8,46,0,AIR)
Block(-8,46,1,AIR)
Block(-8,46,2,AIR)
Block(-8,46,3,AIR)
Block(-8,49,-7,CONCRETE:15)
Block(-8,49,-6,CONCRETE:15)
Block(-8,49,-5,CONCRETE:15)
Block(-8,49,-4,CONCRETE:15)
Block(-8,49,-3,CONCRETE:15)
Block(-8,49,-2,CONCRETE:15)
Block(-8,49,-1,CONCRETE:15)
Block(-8,49,0,CONCRETE:15)
Block(-8,49,1,CONCRETE:15)
Block(-8,49,2,CONCRETE:15)
Block(-8,49,3,CONCRETE:15)
Block(-8,49,4,CONCRETE:15)
Block(-8,49,5,CONCRETE:15)
Block(-8,49,6,CONCRETE:15)
Block(-8,49,7,CONCRETE:15)
Block(-8,49,8,CONCRETE:15)
Block(-8,50,-2,DOUBLE_STEP:7)
Block(-8,50,-1,AIR)
Block(-8,50,0,AIR)
Block(-8,50,4,AIR)
Block(-8,51,-2,AIR)
Block(-8,51,0,AIR)
Block(-8,51,4,AIR)
RandomBlock(-8,52,4,CONCRETE:7,60,quark:iron_plate,20,STAINED_CLAY:12,15,STAINED_CLAY:15,5,AIR,7,IRON_BARS,12,CONCRETE:7,100)
Block(-8,53,-7,CONCRETE:15)
Block(-8,53,-6,CONCRETE:15)
Block(-8,53,-5,CONCRETE:15)
Block(-8,53,-4,CONCRETE:15)
Block(-8,53,-3,CONCRETE:15)
Block(-8,53,-2,CONCRETE:15)
Block(-8,53,-1,CONCRETE:15)
Block(-8,53,0,CONCRETE:15)
Block(-8,53,1,CONCRETE:15)
Block(-8,53,2,CONCRETE:15)
Block(-8,53,3,CONCRETE:15)
Block(-8,53,4,CONCRETE:15)
Block(-8,53,5,CONCRETE:15)
Block(-8,53,6,CONCRETE:15)
Block(-8,53,7,CONCRETE:15)
Block(-8,53,8,CONCRETE:15)
Block(-8,54,-1,AIR)
Block(-8,54,0,AIR)
Block(-8,54,1,AIR)
Block(-8,54,2,AIR)
Block(-8,54,3,AIR)
Block(-8,57,-7,CONCRETE:15)
Block(-8,57,-6,CONCRETE:15)
Block(-8,57,-5,CONCRETE:15)
Block(-8,57,-4,CONCRETE:15)
Block(-8,57,-3,CONCRETE:15)
Block(-8,57,-2,CONCRETE:15)
Block(-8,57,-1,CONCRETE:15)
Block(-8,57,0,CONCRETE:15)
Block(-8,57,1,CONCRETE:15)
Block(-8,57,2,CONCRETE:15)
Block(-8,57,3,CONCRETE:15)
Block(-8,57,4,CONCRETE:15)
Block(-8,57,5,CONCRETE:15)
Block(-8,57,6,CONCRETE:15)
Block(-8,57,7,CONCRETE:15)
Block(-8,57,8,CONCRETE:15)
Block(-8,58,-1,AIR)
Block(-8,58,0,AIR)
Block(-8,58,1,AIR)
Block(-8,58,2,AIR)
Block(-8,58,3,AIR)
Block(-8,61,-7,CONCRETE:15)
Block(-8,61,-6,CONCRETE:15)
Block(-8,61,-5,CONCRETE:15)
Block(-8,61,-4,CONCRETE:15)
Block(-8,61,-3,CONCRETE:15)
Block(-8,61,-2,CONCRETE:15)
Block(-8,61,-1,CONCRETE:15)
Block(-8,61,0,CONCRETE:15)
Block(-8,61,1,CONCRETE:15)
Block(-8,61,2,CONCRETE:15)
Block(-8,61,3,CONCRETE:15)
Block(-8,61,4,CONCRETE:15)
Block(-8,61,5,CONCRETE:15)
Block(-8,61,6,CONCRETE:15)
Block(-8,61,7,CONCRETE:15)
Block(-8,61,8,CONCRETE:15)
Block(-8,62,-1,AIR)
Block(-8,62,0,AIR)
Block(-8,62,1,AIR)
Block(-8,62,2,AIR)
Block(-8,62,3,AIR)
Block(-8,65,-7,CONCRETE:15)
Block(-8,65,-6,CONCRETE:15)
Block(-8,65,-5,CONCRETE:15)
Block(-8,65,-4,CONCRETE:15)
Block(-8,65,-3,CONCRETE:15)
Block(-8,65,-2,CONCRETE:15)
Block(-8,65,-1,CONCRETE:15)
Block(-8,65,0,CONCRETE:15)
Block(-8,65,1,CONCRETE:15)
Block(-8,65,2,CONCRETE:15)
Block(-8,65,3,CONCRETE:15)
Block(-8,65,4,CONCRETE:15)
Block(-8,65,5,CONCRETE:15)
Block(-8,65,6,CONCRETE:15)
Block(-8,65,7,CONCRETE:15)
Block(-8,65,8,CONCRETE:15)
Block(-8,66,-1,AIR)
Block(-8,66,0,AIR)
Block(-8,66,1,AIR)
Block(-8,66,2,AIR)
Block(-8,66,3,AIR)
Block(-8,69,-7,CONCRETE:15)
Block(-8,69,-6,CONCRETE:15)
Block(-8,69,-5,CONCRETE:15)
Block(-8,69,-4,CONCRETE:15)
Block(-8,69,-3,CONCRETE:15)
Block(-8,69,-2,CONCRETE:15)
Block(-8,69,-1,CONCRETE:15)
Block(-8,69,0,CONCRETE:15)
Block(-8,69,1,CONCRETE:15)
Block(-8,69,2,CONCRETE:15)
Block(-8,69,3,CONCRETE:15)
Block(-8,69,4,CONCRETE:15)
Block(-8,69,5,CONCRETE:15)
Block(-8,69,6,CONCRETE:15)
Block(-8,69,7,CONCRETE:15)
Block(-8,69,8,CONCRETE:15)
Block(-8,70,-2,DOUBLE_STEP:7)
Block(-8,70,-1,AIR)
Block(-8,70,0,AIR)
Block(-8,70,4,AIR)
Block(-8,71,-2,AIR)
Block(-8,71,0,AIR)
Block(-8,71,4,AIR)
RandomBlock(-8,72,4,CONCRETE:7,60,quark:iron_plate,20,STAINED_CLAY:12,15,STAINED_CLAY:15,5,AIR,7,IRON_BARS,12,CONCRETE:7,100)
Block(-8,73,-7,CONCRETE:15)
Block(-8,73,-6,CONCRETE:15)
Block(-8,73,-5,CONCRETE:15)
Block(-8,73,-4,CONCRETE:15)
Block(-8,73,-3,CONCRETE:15)
Block(-8,73,-2,CONCRETE:15)
Block(-8,73,-1,CONCRETE:15)
Block(-8,73,0,CONCRETE:15)
Block(-8,73,1,CONCRETE:15)
Block(-8,73,2,CONCRETE:15)
Block(-8,73,3,CONCRETE:15)
Block(-8,73,4,CONCRETE:15)
Block(-8,73,5,CONCRETE:15)
Block(-8,73,6,CONCRETE:15)
Block(-8,73,7,CONCRETE:15)
Block(-8,73,8,CONCRETE:15)
Block(-8,74,-1,AIR)
Block(-8,74,0,AIR)
Block(-8,74,1,AIR)
Block(-8,74,2,AIR)
Block(-8,74,3,AIR)
Block(-8,77,-7,CONCRETE:15)
Block(-8,77,-6,CONCRETE:15)
Block(-8,77,-5,CONCRETE:15)
Block(-8,77,-4,CONCRETE:15)
Block(-8,77,-3,CONCRETE:15)
Block(-8,77,-2,CONCRETE:15)
Block(-8,77,-1,CONCRETE:15)
Block(-8,77,0,CONCRETE:15)
Block(-8,77,1,CONCRETE:15)
Block(-8,77,2,CONCRETE:15)
Block(-8,77,3,CONCRETE:15)
Block(-8,77,4,CONCRETE:15)
Block(-8,77,5,CONCRETE:15)
Block(-8,77,6,CONCRETE:15)
Block(-8,77,7,CONCRETE:15)
Block(-8,77,8,CONCRETE:15)
Block(-8,78,-1,AIR)
Block(-8,78,0,AIR)
Block(-8,78,1,AIR)
Block(-8,78,2,AIR)
Block(-8,78,3,AIR)
Block(-8,81,-7,CONCRETE:15)
Block(-8,81,-6,CONCRETE:15)
Block(-8,81,-5,CONCRETE:15)
Block(-8,81,-4,CONCRETE:15)
Block(-8,81,-3,CONCRETE:15)
Block(-8,81,-2,CONCRETE:15)
Block(-8,81,-1,CONCRETE:15)
Block(-8,81,0,CONCRETE:15)
Block(-8,81,1,CONCRETE:15)
Block(-8,81,2,CONCRETE:15)
Block(-8,81,3,CONCRETE:15)
Block(-8,81,4,CONCRETE:15)
Block(-8,81,5,CONCRETE:15)
Block(-8,81,6,CONCRETE:15)
Block(-8,81,7,CONCRETE:15)
Block(-8,81,8,CONCRETE:15)
Block(-8,82,-1,AIR)
Block(-8,82,0,AIR)
Block(-8,82,1,AIR)
Block(-8,82,2,AIR)
Block(-8,82,3,AIR)
Block(-8,85,-7,CONCRETE:15)
Block(-8,85,-6,CONCRETE:15)
Block(-8,85,-5,CONCRETE:15)
Block(-8,85,-4,CONCRETE:15)
Block(-8,85,-3,CONCRETE:15)
Block(-8,85,-2,CONCRETE:15)
Block(-8,85,-1,CONCRETE:15)
Block(-8,85,0,CONCRETE:15)
Block(-8,85,1,CONCRETE:15)
Block(-8,85,2,CONCRETE:15)
Block(-8,85,3,CONCRETE:15)
Block(-8,85,4,CONCRETE:15)
Block(-8,85,5,CONCRETE:15)
Block(-8,85,6,CONCRETE:15)
Block(-8,85,7,CONCRETE:15)
Block(-8,85,8,CONCRETE:15)
RandomBlock(-7,0,-7,CONCRETE:7,60,quark:iron_plate,20,STAINED_CLAY:12,15,STAINED_CLAY:15,5,AIR,7,IRON_BARS,12,CONCRETE:7,100)
RandomBlock(-7,0,-6,CONCRETE:7,60,quark:iron_plate,20,STAINED_CLAY:12,15,STAINED_CLAY:15,5,AIR,7,IRON_BARS,12,CONCRETE:7,100)
RandomBlock(-7,0,-5,CONCRETE:7,60,quark:iron_plate,20,STAINED_CLAY:12,15,STAINED_CLAY:15,5,AIR,7,IRON_BARS,12,CONCRETE:7,100)
RandomBlock(-7,0,-4,CONCRETE:7,60,quark:iron_plate,20,STAINED_CLAY:12,15,STAINED_CLAY:15,5,AIR,7,IRON_BARS,12,CONCRETE:7,100)
RandomBlock(-7,0,-3,CONCRETE:7,60,quark:iron_plate,20,STAINED_CLAY:12,15,STAINED_CLAY:15,5,AIR,7,IRON_BARS,12,CONCRETE:7,100)
RandomBlock(-7,0,-2,CONCRETE:7,60,quark:iron_plate,20,STAINED_CLAY:12,15,STAINED_CLAY:15,5,AIR,7,IRON_BARS,12,CONCRETE:7,100)
RandomBlock(-7,0,-1,CONCRETE:7,60,quark:iron_plate,20,STAINED_CLAY:12,15,STAINED_CLAY:15,5,AIR,7,IRON_BARS,12,CONCRETE:7,100)
RandomBlock(-7,0,0,CONCRETE:7,60,quark:iron_plate,20,STAINED_CLAY:12,15,STAINED_CLAY:15,5,AIR,7,IRON_BARS,12,CONCRETE:7,100)
RandomBlock(-7,0,1,CONCRETE:7,60,quark:iron_plate,20,STAINED_CLAY:12,15,STAINED_CLAY:15,5,AIR,7,IRON_BARS,12,CONCRETE:7,100)
RandomBlock(-7,0,2,CONCRETE:7,60,quark:iron_plate,20,STAINED_CLAY:12,15,STAINED_CLAY:15,5,AIR,7,IRON_BARS,12,CONCRETE:7,100)
RandomBlock(-7,0,3,CONCRETE:7,60,quark:iron_plate,20,STAINED_CLAY:12,15,STAINED_CLAY:15,5,AIR,7,IRON_BARS,12,CONCRETE:7,100)
RandomBlock(-7,0,4,CONCRETE:7,60,quark:iron_plate,20,STAINED_CLAY:12,15,STAINED_CLAY:15,5,AIR,7,IRON_BARS,12,CONCRETE:7,100)
RandomBlock(-7,0,5,CONCRETE:7,60,quark:iron_plate,20,STAINED_CLAY:12,15,STAINED_CLAY:15,5,AIR,7,IRON_BARS,12,CONCRETE:7,100)
RandomBlock(-7,0,6,CONCRETE:7,60,quark:iron_plate,20,STAINED_CLAY:12,15,STAINED_CLAY:15,5,AIR,7,IRON_BARS,12,CONCRETE:7,100)
RandomBlock(-7,0,7,CONCRETE:7,60,quark:iron_plate,20,STAINED_CLAY:12,15,STAINED_CLAY:15,5,AIR,7,IRON_BARS,12,CONCRETE:7,100)
RandomBlock(-7,0,8,CONCRETE:7,60,quark:iron_plate,20,STAINED_CLAY:12,15,STAINED_CLAY:15,5,AIR,7,IRON_BARS,12,CONCRETE:7,100)
RandomBlock(-7,1,-7,CONCRETE:7,60,quark:iron_plate,20,STAINED_CLAY:12,15,STAINED_CLAY:15,5,AIR,7,IRON_BARS,12,CONCRETE:7,100)
RandomBlock(-7,1,-6,CONCRETE:7,60,quark:iron_plate,20,STAINED_CLAY:12,15,STAINED_CLAY:15,5,AIR,7,IRON_BARS,12,CONCRETE:7,100)
RandomBlock(-7,1,-5,CONCRETE:7,60,quark:iron_plate,20,STAINED_CLAY:12,15,STAINED_CLAY:15,5,AIR,7,IRON_BARS,12,CONCRETE:7,100)
RandomBlock(-7,1,-4,CONCRETE:7,60,quark:iron_plate,20,STAINED_CLAY:12,15,STAINED_CLAY:15,5,AIR,7,IRON_BARS,12,CONCRETE:7,100)
Block(-7,1,-3,STATIONARY_WATER:0)
Block(-7,1,-2,STATIONARY_WATER:0)
RandomBlock(-7,1,-1,CONCRETE:7,60,quark:iron_plate,20,STAINED_CLAY:12,15,STAINED_CLAY:15,5,AIR,7,IRON_BARS,12,CONCRETE:7,100)
RandomBlock(-7,1,0,CONCRETE:7,60,quark:iron_plate,20,STAINED_CLAY:12,15,STAINED_CLAY:15,5,AIR,7,IRON_BARS,12,CONCRETE:7,100)
RandomBlock(-7,1,1,CONCRETE:7,60,quark:iron_plate,20,STAINED_CLAY:12,15,STAINED_CLAY:15,5,AIR,7,IRON_BARS,12,CONCRETE:7,100)
RandomBlock(-7,1,2,CONCRETE:7,60,quark:iron_plate,20,STAINED_CLAY:12,15,STAINED_CLAY:15,5,AIR,7,IRON_BARS,12,CONCRETE:7,100)
RandomBlock(-7,1,3,CONCRETE:7,60,quark:iron_plate,20,STAINED_CLAY:12,15,STAINED_CLAY:15,5,AIR,7,IRON_BARS,12,CONCRETE:7,100)
RandomBlock(-7,1,4,CONCRETE:7,60,quark:iron_plate,20,STAINED_CLAY:12,15,STAINED_CLAY:15,5,AIR,7,IRON_BARS,12,CONCRETE:7,100)
RandomBlock(-7,1,5,CONCRETE:7,60,quark:iron_plate,20,STAINED_CLAY:12,15,STAINED_CLAY:15,5,AIR,7,IRON_BARS,12,CONCRETE:7,100)
RandomBlock(-7,1,6,CONCRETE:7,60,quark:iron_plate,20,STAINED_CLAY:12,15,STAINED_CLAY:15,5,AIR,7,IRON_BARS,12,CONCRETE:7,100)
RandomBlock(-7,1,7,CONCRETE:7,60,quark:iron_plate,20,STAINED_CLAY:12,15,STAINED_CLAY:15,5,AIR,7,IRON_BARS,12,CONCRETE:7,100)
RandomBlock(-7,1,8,CONCRETE:7,60,quark:iron_plate,20,STAINED_CLAY:12,15,STAINED_CLAY:15,5,AIR,7,IRON_BARS,12,CONCRETE:7,100)
RandomBlock(-7,2,-7,CONCRETE:7,60,quark:iron_plate,20,STAINED_CLAY:12,15,STAINED_CLAY:15,5,AIR,7,IRON_BARS,12,CONCRETE:7,100)
RandomBlock(-7,2,-6,CONCRETE:7,60,quark:iron_plate,20,STAINED_CLAY:12,15,STAINED_CLAY:15,5,AIR,7,IRON_BARS,12,CONCRETE:7,100)
RandomBlock(-7,2,-5,CONCRETE:7,60,quark:iron_plate,20,STAINED_CLAY:12,15,STAINED_CLAY:15,5,AIR,7,IRON_BARS,12,CONCRETE:7,100)
Block(-7,2,-4,SMOOTH_STAIRS:3)
Block(-7,2,-3,AIR:0)
Block(-7,2,-2,AIR:0)
Block(-7,2,-1,SMOOTH_STAIRS:2)
RandomBlock(-7,2,0,CONCRETE:7,60,quark:iron_plate,20,STAINED_CLAY:12,15,STAINED_CLAY:15,5,AIR,7,IRON_BARS,12,CONCRETE:7,100)
RandomBlock(-7,2,1,CONCRETE:7,60,quark:iron_plate,20,STAINED_CLAY:12,15,STAINED_CLAY:15,5,AIR,7,IRON_BARS,12,CONCRETE:7,100)
RandomBlock(-7,2,2,CONCRETE:7,60,quark:iron_plate,20,STAINED_CLAY:12,15,STAINED_CLAY:15,5,AIR,7,IRON_BARS,12,CONCRETE:7,100)
RandomBlock(-7,2,3,CONCRETE:7,60,quark:iron_plate,20,STAINED_CLAY:12,15,STAINED_CLAY:15,5,AIR,7,IRON_BARS,12,CONCRETE:7,100)
RandomBlock(-7,2,4,CONCRETE:7,60,quark:iron_plate,20,STAINED_CLAY:12,15,STAINED_CLAY:15,5,AIR,7,IRON_BARS,12,CONCRETE:7,100)
RandomBlock(-7,2,5,CONCRETE:7,60,quark:iron_plate,20,STAINED_CLAY:12,15,STAINED_CLAY:15,5,AIR,7,IRON_BARS,12,CONCRETE:7,100)
RandomBlock(-7,2,6,CONCRETE:7,60,quark:iron_plate,20,STAINED_CLAY:12,15,STAINED_CLAY:15,5,AIR,7,IRON_BARS,12,CONCRETE:7,100)
RandomBlock(-7,2,7,CONCRETE:7,60,quark:iron_plate,20,STAINED_CLAY:12,15,STAINED_CLAY:15,5,AIR,7,IRON_BARS,12,CONCRETE:7,100)
RandomBlock(-7,2,8,CONCRETE:7,60,quark:iron_plate,20,STAINED_CLAY:12,15,STAINED_CLAY:15,5,AIR,7,IRON_BARS,12,CONCRETE:7,100)
Block(-7,3,-7,AIR:0)
Block(-7,3,-6,AIR:0)
Block(-7,3,-5,AIR:0)
Block(-7,3,-4,AIR:0)
Block(-7,3,-3,AIR:0)
Block(-7,3,-2,AIR:0)
Block(-7,3,-1,AIR:0)
Block(-7,3,0,AIR:0)
RandomBlock(-7,3,1,CONCRETE:7,60,quark:iron_plate,20,STAINED_CLAY:12,15,STAINED_CLAY:15,5,AIR,7,IRON_BARS,12,CONCRETE:7,100)
RandomBlock(-7,3,2,CONCRETE:7,60,quark:iron_plate,20,STAINED_CLAY:12,15,STAINED_CLAY:15,5,AIR,7,IRON_BARS,12,CONCRETE:7,100)
Block(-7,3,3,AIR:0)
Block(-7,3,4,LADDER:2)
RandomBlock(-7,3,5,CONCRETE:7,60,quark:iron_plate,20,STAINED_CLAY:12,15,STAINED_CLAY:15,5,AIR,7,IRON_BARS,12,CONCRETE:7,100)
RandomBlock(-7,3,6,CONCRETE:7,60,quark:iron_plate,20,STAINED_CLAY:12,15,STAINED_CLAY:15,5,AIR,7,IRON_BARS,12,CONCRETE:7,100)
Block(-7,3,7,AIR:0)
RandomBlock(-7,3,8,CONCRETE:7,60,quark:iron_plate,20,STAINED_CLAY:12,15,STAINED_CLAY:15,5,AIR,7,IRON_BARS,12,CONCRETE:7,100)
Block(-7,4,-7,AIR:0)
Block(-7,4,-6,AIR:0)
Block(-7,4,-5,AIR:0)
Block(-7,4,-4,AIR:0)
Block(-7,4,-3,AIR:0)
Block(-7,4,-2,AIR:0)
Block(-7,4,-1,AIR:0)
Block(-7,4,0,AIR:0)
RandomBlock(-7,4,1,CONCRETE:7,60,quark:iron_plate,20,STAINED_CLAY:12,15,STAINED_CLAY:15,5,AIR,7,IRON_BARS,12,CONCRETE:7,100)
RandomBlock(-7,4,2,CONCRETE:7,60,quark:iron_plate,20,STAINED_CLAY:12,15,STAINED_CLAY:15,5,AIR,7,IRON_BARS,12,CONCRETE:7,100)
Block(-7,4,3,AIR:0)
Block(-7,4,4,LADDER:2)
RandomBlock(-7,4,5,CONCRETE:7,60,quark:iron_plate,20,STAINED_CLAY:12,15,STAINED_CLAY:15,5,AIR,7,IRON_BARS,12,CONCRETE:7,100)
RandomBlock(-7,4,6,CONCRETE:7,60,quark:iron_plate,20,STAINED_CLAY:12,15,STAINED_CLAY:15,5,AIR,7,IRON_BARS,12,CONCRETE:7,100)
Block(-7,4,7,AIR:0)
RandomBlock(-7,4,8,CONCRETE:7,60,quark:iron_plate,20,STAINED_CLAY:12,15,STAINED_CLAY:15,5,AIR,7,IRON_BARS,12,CONCRETE:7,100)
Block(-7,5,-7,AIR:0)
Block(-7,5,-6,CONCRETE:4)
Block(-7,5,-5,CONCRETE:12)
Block(-7,5,-4,AIR:0)
Block(-7,5,-3,AIR:0)
Block(-7,5,-2,AIR:0)
Block(-7,5,-1,AIR:0)
Block(-7,5,0,AIR:0)
RandomBlock(-7,5,1,CONCRETE:7,60,quark:iron_plate,20,STAINED_CLAY:12,15,STAINED_CLAY:15,5,AIR,7,IRON_BARS,12,CONCRETE:7,100)
RandomBlock(-7,5,2,CONCRETE:7,60,quark:iron_plate,20,STAINED_CLAY:12,15,STAINED_CLAY:15,5,AIR,7,IRON_BARS,12,CONCRETE:7,100)
Block(-7,5,3,AIR:0)
Block(-7,5,4,LADDER:2)
RandomBlock(-7,5,5,CONCRETE:7,60,quark:iron_plate,20,STAINED_CLAY:12,15,STAINED_CLAY:15,5,AIR,7,IRON_BARS,12,CONCRETE:7,100)
RandomBlock(-7,5,6,CONCRETE:7,60,quark:iron_plate,20,STAINED_CLAY:12,15,STAINED_CLAY:15,5,AIR,7,IRON_BARS,12,CONCRETE:7,100)
Block(-7,5,7,AIR:0)
RandomBlock(-7,5,8,CONCRETE:7,60,quark:iron_plate,20,STAINED_CLAY:12,15,STAINED_CLAY:15,5,AIR,7,IRON_BARS,12,CONCRETE:7,100)
Block(-7,6,-7,AIR:0)
Block(-7,6,-6,AIR:0)
Block(-7,6,-5,AIR:0)
Block(-7,6,-4,AIR:0)
Block(-7,6,-3,AIR:0)
Block(-7,6,-2,AIR:0)
Block(-7,6,-1,AIR:0)
Block(-7,6,0,AIR:0)
RandomBlock(-7,6,1,CONCRETE:7,60,quark:iron_plate,20,STAINED_CLAY:12,15,STAINED_CLAY:15,5,AIR,7,IRON_BARS,12,CONCRETE:7,100)
RandomBlock(-7,6,2,CONCRETE:7,60,quark:iron_plate,20,STAINED_CLAY:12,15,STAINED_CLAY:15,5,AIR,7,IRON_BARS,12,CONCRETE:7,100)
Block(-7,6,3,AIR:0)
Block(-7,6,4,LADDER:2)
RandomBlock(-7,6,5,CONCRETE:7,60,quark:iron_plate,20,STAINED_CLAY:12,15,STAINED_CLAY:15,5,AIR,7,IRON_BARS,12,CONCRETE:7,100)
RandomBlock(-7,6,6,CONCRETE:7,60,quark:iron_plate,20,STAINED_CLAY:12,15,STAINED_CLAY:15,5,AIR,7,IRON_BARS,12,CONCRETE:7,100)
Block(-7,6,7,AIR:0)
RandomBlock(-7,6,8,CONCRETE:7,60,quark:iron_plate,20,STAINED_CLAY:12,15,STAINED_CLAY:15,5,AIR,7,IRON_BARS,12,CONCRETE:7,100)
RandomBlock(-7,7,-7,CONCRETE:7,60,quark:iron_plate,20,STAINED_CLAY:12,15,STAINED_CLAY:15,5,AIR,7,IRON_BARS,12,CONCRETE:7,100)
RandomBlock(-7,7,-6,CONCRETE:7,60,quark:iron_plate,20,STAINED_CLAY:12,15,STAINED_CLAY:15,5,AIR,7,IRON_BARS,12,CONCRETE:7,100)
RandomBlock(-7,7,-5,CONCRETE:7,60,quark:iron_plate,20,STAINED_CLAY:12,15,STAINED_CLAY:15,5,AIR,7,IRON_BARS,12,CONCRETE:7,100)
RandomBlock(-7,7,-4,CONCRETE:7,60,quark:iron_plate,20,STAINED_CLAY:12,15,STAINED_CLAY:15,5,AIR,7,IRON_BARS,12,CONCRETE:7,100)
RandomBlock(-7,7,-3,CONCRETE:7,60,quark:iron_plate,20,STAINED_CLAY:12,15,STAINED_CLAY:15,5,AIR,7,IRON_BARS,12,CONCRETE:7,100)
RandomBlock(-7,7,-2,CONCRETE:7,60,quark:iron_plate,20,STAINED_CLAY:12,15,STAINED_CLAY:15,5,AIR,7,IRON_BARS,12,CONCRETE:7,100)
RandomBlock(-7,7,-1,CONCRETE:7,60,quark:iron_plate,20,STAINED_CLAY:12,15,STAINED_CLAY:15,5,AIR,7,IRON_BARS,12,CONCRETE:7,100)
RandomBlock(-7,7,0,CONCRETE:7,60,quark:iron_plate,20,STAINED_CLAY:12,15,STAINED_CLAY:15,5,AIR,7,IRON_BARS,12,CONCRETE:7,100)
RandomBlock(-7,7,1,CONCRETE:7,60,quark:iron_plate,20,STAINED_CLAY:12,15,STAINED_CLAY:15,5,AIR,7,IRON_BARS,12,CONCRETE:7,100)
RandomBlock(-7,7,2,CONCRETE:7,60,quark:iron_plate,20,STAINED_CLAY:12,15,STAINED_CLAY:15,5,AIR,7,IRON_BARS,12,CONCRETE:7,100)
RandomBlock(-7,7,3,CONCRETE:7,60,quark:iron_plate,20,STAINED_CLAY:12,15,STAINED_CLAY:15,5,AIR,7,IRON_BARS,12,CONCRETE:7,100)
Block(-7,7,4,LADDER:2)
RandomBlock(-7,7,5,CONCRETE:7,60,quark:iron_plate,20,STAINED_CLAY:12,15,STAINED_CLAY:15,5,AIR,7,IRON_BARS,12,CONCRETE:7,100)
RandomBlock(-7,7,6,CONCRETE:7,60,quark:iron_plate,20,STAINED_CLAY:12,15,STAINED_CLAY:15,5,AIR,7,IRON_BARS,12,CONCRETE:7,100)
RandomBlock(-7,7,7,CONCRETE:7,60,quark:iron_plate,20,STAINED_CLAY:12,15,STAINED_CLAY:15,5,AIR,7,IRON_BARS,12,CONCRETE:7,100)
RandomBlock(-7,7,8,CONCRETE:7,60,quark:iron_plate,20,STAINED_CLAY:12,15,STAINED_CLAY:15,5,AIR,7,IRON_BARS,12,CONCRETE:7,100)
Block(-7,8,-7,AIR:0)
Block(-7,8,-6,AIR:0)
Block(-7,8,-5,AIR:0)
Block(-7,8,-4,AIR:0)
Block(-7,8,-3,AIR:0)
Block(-7,8,-2,IRON_FENCE:0)
Block(-7,8,-1,AIR:0)
Block(-7,8,0,AIR:0)
Block(-7,8,1,AIR:0)
Block(-7,8,2,AIR:0)
Block(-7,8,3,AIR:0)
RandomBlock(-7,8,5,CONCRETE:7,60,quark:iron_plate,20,STAINED_CLAY:12,15,STAINED_CLAY:15,5,AIR,7,IRON_BARS,12,CONCRETE:7,100)
RandomBlock(-7,8,6,CONCRETE:7,60,quark:iron_plate,20,STAINED_CLAY:12,15,STAINED_CLAY:15,5,AIR,7,IRON_BARS,12,CONCRETE:7,100)
RandomBlock(-7,8,7,CONCRETE:7,60,quark:iron_plate,20,STAINED_CLAY:12,15,STAINED_CLAY:15,5,AIR,7,IRON_BARS,12,CONCRETE:7,100)
RandomBlock(-7,8,8,CONCRETE:7,60,quark:iron_plate,20,STAINED_CLAY:12,15,STAINED_CLAY:15,5,AIR,7,IRON_BARS,12,CONCRETE:7,100)
Block(-7,9,-7,AIR:0)
Block(-7,9,-6,AIR:0)
Block(-7,9,-5,AIR:0)
Block(-7,9,-4,AIR:0)
Block(-7,9,-3,AIR:0)
Block(-7,9,-2,IRON_FENCE:0)
Block(-7,9,-1,AIR:0)
Block(-7,9,0,AIR:0)
Block(-7,9,1,AIR:0)
Block(-7,9,2,AIR:0)
Block(-7,9,3,AIR:0)
Block(-7,9,4,AIR:0)
RandomBlock(-7,9,5,CONCRETE:7,60,quark:iron_plate,20,STAINED_CLAY:12,15,STAINED_CLAY:15,5,AIR,7,IRON_BARS,12,CONCRETE:7,100)
RandomBlock(-7,9,6,CONCRETE:7,60,quark:iron_plate,20,STAINED_CLAY:12,15,STAINED_CLAY:15,5,AIR,7,IRON_BARS,12,CONCRETE:7,100)
RandomBlock(-7,9,7,CONCRETE:7,60,quark:iron_plate,20,STAINED_CLAY:12,15,STAINED_CLAY:15,5,AIR,7,IRON_BARS,12,CONCRETE:7,100)
RandomBlock(-7,9,8,CONCRETE:7,60,quark:iron_plate,20,STAINED_CLAY:12,15,STAINED_CLAY:15,5,AIR,7,IRON_BARS,12,CONCRETE:7,100)
Block(-7,10,-7,AIR:0)
Block(-7,10,-6,AIR:0)
Block(-7,10,-5,AIR:0)
Block(-7,10,-4,AIR:0)
Block(-7,10,-3,AIR:0)
Block(-7,10,-2,IRON_FENCE:0)
Block(-7,10,-1,AIR:0)
Block(-7,10,0,AIR:0)
Block(-7,10,1,AIR:0)
Block(-7,10,2,AIR:0)
Block(-7,10,3,AIR:0)
Block(-7,10,4,AIR:0)
RandomBlock(-7,10,5,CONCRETE:7,60,quark:iron_plate,20,STAINED_CLAY:12,15,STAINED_CLAY:15,5,AIR,7,IRON_BARS,12,CONCRETE:7,100)
RandomBlock(-7,10,6,CONCRETE:7,60,quark:iron_plate,20,STAINED_CLAY:12,15,STAINED_CLAY:15,5,AIR,7,IRON_BARS,12,CONCRETE:7,100)
RandomBlock(-7,10,7,CONCRETE:7,60,quark:iron_plate,20,STAINED_CLAY:12,15,STAINED_CLAY:15,5,AIR,7,IRON_BARS,12,CONCRETE:7,100)
RandomBlock(-7,10,8,CONCRETE:7,60,quark:iron_plate,20,STAINED_CLAY:12,15,STAINED_CLAY:15,5,AIR,7,IRON_BARS,12,CONCRETE:7,100)
Block(-7,11,-7,AIR:0)
Block(-7,11,-6,CONCRETE:14)
Block(-7,11,-5,AIR:0)
Block(-7,11,-4,AIR:0)
Block(-7,11,-3,AIR:0)
Block(-7,11,-2,AIR:0)
Block(-7,11,-1,AIR:0)
Block(-7,11,0,CONCRETE:12)
Block(-7,11,1,AIR:0)
Block(-7,11,2,CONCRETE:4)
Block(-7,11,3,AIR:0)
Block(-7,11,4,AIR:0)
RandomBlock(-7,11,5,CONCRETE:7,60,quark:iron_plate,20,STAINED_CLAY:12,15,STAINED_CLAY:15,5,AIR,7,IRON_BARS,12,CONCRETE:7,100)
RandomBlock(-7,11,6,CONCRETE:7,60,quark:iron_plate,20,STAINED_CLAY:12,15,STAINED_CLAY:15,5,AIR,7,IRON_BARS,12,CONCRETE:7,100)
RandomBlock(-7,11,7,CONCRETE:7,60,quark:iron_plate,20,STAINED_CLAY:12,15,STAINED_CLAY:15,5,AIR,7,IRON_BARS,12,CONCRETE:7,100)
RandomBlock(-7,11,8,CONCRETE:7,60,quark:iron_plate,20,STAINED_CLAY:12,15,STAINED_CLAY:15,5,AIR,7,IRON_BARS,12,CONCRETE:7,100)
Block(-7,12,-7,AIR:0)
Block(-7,12,-6,AIR:0)
Block(-7,12,-5,AIR:0)
Block(-7,12,-4,AIR:0)
Block(-7,12,-3,AIR:0)
Block(-7,12,-2,AIR:0)
Block(-7,12,-1,AIR:0)
Block(-7,12,0,AIR:0)
Block(-7,12,1,AIR:0)
Block(-7,12,2,AIR:0)
Block(-7,12,3,AIR:0)
Block(-7,12,4,AIR:0)
RandomBlock(-7,12,5,CONCRETE:7,60,quark:iron_plate,20,STAINED_CLAY:12,15,STAINED_CLAY:15,5,AIR,7,IRON_BARS,12,CONCRETE:7,100)
RandomBlock(-7,12,6,CONCRETE:7,60,quark:iron_plate,20,STAINED_CLAY:12,15,STAINED_CLAY:15,5,AIR,7,IRON_BARS,12,CONCRETE:7,100)
RandomBlock(-7,12,7,CONCRETE:7,60,quark:iron_plate,20,STAINED_CLAY:12,15,STAINED_CLAY:15,5,AIR,7,IRON_BARS,12,CONCRETE:7,100)
RandomBlock(-7,12,8,CONCRETE:7,60,quark:iron_plate,20,STAINED_CLAY:12,15,STAINED_CLAY:15,5,AIR,7,IRON_BARS,12,CONCRETE:7,100)
RandomBlock(-7,13,-7,CONCRETE:8,60,notreepunching:cobblestone/andesite,15,STONE:5,15,STAINED_CLAY:9,10,IRON_BARS,12,AIR,8,STAINED_CLAY:12,30,CONCRETE:8,100)
RandomBlock(-7,13,-6,CONCRETE:8,60,notreepunching:cobblestone/andesite,15,STONE:5,15,STAINED_CLAY:9,10,IRON_BARS,12,AIR,8,STAINED_CLAY:12,30,CONCRETE:8,100)
RandomBlock(-7,13,-5,CONCRETE:8,60,notreepunching:cobblestone/andesite,15,STONE:5,15,STAINED_CLAY:9,10,IRON_BARS,12,AIR,8,STAINED_CLAY:12,30,CONCRETE:8,100)
RandomBlock(-7,13,-4,CONCRETE:8,60,notreepunching:cobblestone/andesite,15,STONE:5,15,STAINED_CLAY:9,10,IRON_BARS,12,AIR,8,STAINED_CLAY:12,30,CONCRETE:8,100)
RandomBlock(-7,13,-3,CONCRETE:8,60,notreepunching:cobblestone/andesite,15,STONE:5,15,STAINED_CLAY:9,10,IRON_BARS,12,AIR,8,STAINED_CLAY:12,30,CONCRETE:8,100)
RandomBlock(-7,13,-2,CONCRETE:8,60,notreepunching:cobblestone/andesite,15,STONE:5,15,STAINED_CLAY:9,10,IRON_BARS,12,AIR,8,STAINED_CLAY:12,30,CONCRETE:8,100)
RandomBlock(-7,13,-1,CONCRETE:8,60,notreepunching:cobblestone/andesite,15,STONE:5,15,STAINED_CLAY:9,10,IRON_BARS,12,AIR,8,STAINED_CLAY:12,30,CONCRETE:8,100)
RandomBlock(-7,13,0,CONCRETE:8,60,notreepunching:cobblestone/andesite,15,STONE:5,15,STAINED_CLAY:9,10,IRON_BARS,12,AIR,8,STAINED_CLAY:12,30,CONCRETE:8,100)
RandomBlock(-7,13,1,CONCRETE:8,60,notreepunching:cobblestone/andesite,15,STONE:5,15,STAINED_CLAY:9,10,IRON_BARS,12,AIR,8,STAINED_CLAY:12,30,CONCRETE:8,100)
RandomBlock(-7,13,2,CONCRETE:8,60,notreepunching:cobblestone/andesite,15,STONE:5,15,STAINED_CLAY:9,10,IRON_BARS,12,AIR,8,STAINED_CLAY:12,30,CONCRETE:8,100)
RandomBlock(-7,13,3,CONCRETE:8,60,notreepunching:cobblestone/andesite,15,STONE:5,15,STAINED_CLAY:9,10,IRON_BARS,12,AIR,8,STAINED_CLAY:12,30,CONCRETE:8,100)
RandomBlock(-7,13,4,CONCRETE:8,60,notreepunching:cobblestone/andesite,15,STONE:5,15,STAINED_CLAY:9,10,IRON_BARS,12,AIR,8,STAINED_CLAY:12,30,CONCRETE:8,100)
RandomBlock(-7,13,5,CONCRETE:8,60,notreepunching:cobblestone/andesite,15,STONE:5,15,STAINED_CLAY:9,10,IRON_BARS,12,AIR,8,STAINED_CLAY:12,30,CONCRETE:8,100)
RandomBlock(-7,13,6,CONCRETE:8,60,notreepunching:cobblestone/andesite,15,STONE:5,15,STAINED_CLAY:9,10,IRON_BARS,12,AIR,8,STAINED_CLAY:12,30,CONCRETE:8,100)
RandomBlock(-7,13,7,CONCRETE:8,60,notreepunching:cobblestone/andesite,15,STONE:5,15,STAINED_CLAY:9,10,IRON_BARS,12,AIR,8,STAINED_CLAY:12,30,CONCRETE:8,100)
RandomBlock(-7,13,8,CONCRETE:8,60,notreepunching:cobblestone/andesite,15,STONE:5,15,STAINED_CLAY:9,10,IRON_BARS,12,AIR,8,STAINED_CLAY:12,30,CONCRETE:8,100)
RandomBlock(-7,14,-7,CONCRETE:8,60,notreepunching:cobblestone/andesite,15,STONE:5,15,STAINED_CLAY:9,10,IRON_BARS,12,AIR,8,STAINED_CLAY:12,30,CONCRETE:8,100)
Block(-7,14,-6,STEP:0)
RandomBlock(-7,14,-5,STONE:6,80,STONE:6,90,DROPPER:1,../../../../../Chests/Loot/toilet_loot.nbt,100)
RandomBlock(-7,14,-4,CONCRETE:8,60,notreepunching:cobblestone/andesite,15,STONE:5,15,STAINED_CLAY:9,10,IRON_BARS,12,AIR,8,STAINED_CLAY:12,30,CONCRETE:8,100)
RandomBlock(-7,14,-3,STONE:6,80,STONE:6,90,DROPPER:1,../../../../../Chests/Loot/toilet_loot.nbt,100)
Block(-7,14,-2,STEP:0)
RandomBlock(-7,14,-1,CONCRETE:8,60,notreepunching:cobblestone/andesite,15,STONE:5,15,STAINED_CLAY:9,10,IRON_BARS,12,AIR,8,STAINED_CLAY:12,30,CONCRETE:8,100)
Block(-7,14,0,AIR:0)
Block(-7,14,1,AIR:0)
Block(-7,14,2,AIR:0)
Block(-7,14,3,QUARTZ_STAIRS:3)
RandomBlock(-7,14,4,CONCRETE:8,60,notreepunching:cobblestone/andesite,15,STONE:5,15,STAINED_CLAY:9,10,IRON_BARS,12,AIR,8,STAINED_CLAY:12,30,CONCRETE:8,100)
RandomBlock(-7,14,5,CONCRETE:8,60,notreepunching:cobblestone/andesite,15,STONE:5,15,STAINED_CLAY:9,10,IRON_BARS,12,AIR,8,STAINED_CLAY:12,30,CONCRETE:8,100)
RandomBlock(-7,14,6,CONCRETE:8,60,notreepunching:cobblestone/andesite,15,STONE:5,15,STAINED_CLAY:9,10,IRON_BARS,12,AIR,8,STAINED_CLAY:12,30,CONCRETE:8,100)
RandomBlock(-7,14,7,CONCRETE:8,60,notreepunching:cobblestone/andesite,15,STONE:5,15,STAINED_CLAY:9,10,IRON_BARS,12,AIR,8,STAINED_CLAY:12,30,CONCRETE:8,100)
Block(-7,14,8,STEP:15)
RandomBlock(-7,15,-7,CONCRETE:7,60,quark:iron_plate,20,STAINED_CLAY:12,15,STAINED_CLAY:15,5,AIR,7,IRON_BARS,12,CONCRETE:7,100)
Block(-7,15,-6,AIR:0)
RandomBlock(-7,15,-4,CONCRETE:7,60,quark:iron_plate,20,STAINED_CLAY:12,15,STAINED_CLAY:15,5,AIR,7,IRON_BARS,12,CONCRETE:7,100)
Block(-7,15,-2,AIR:0)
RandomBlock(-7,15,-1,CONCRETE:7,60,quark:iron_plate,20,STAINED_CLAY:12,15,STAINED_CLAY:15,5,AIR,7,IRON_BARS,12,CONCRETE:7,100)
Block(-7,15,0,AIR:0)
Block(-7,15,1,AIR:0)
Block(-7,15,2,AIR:0)
Block(-7,15,3,TRIPWIRE_HOOK:2)
RandomBlock(-7,15,4,CONCRETE:7,60,quark:iron_plate,20,STAINED_CLAY:12,15,STAINED_CLAY:15,5,AIR,7,IRON_BARS,12,CONCRETE:7,100)
RandomBlock(-7,15,5,CONCRETE:7,60,quark:iron_plate,20,STAINED_CLAY:12,15,STAINED_CLAY:15,5,AIR,7,IRON_BARS,12,CONCRETE:7,100)
RandomBlock(-7,15,6,CONCRETE:8,60,notreepunching:cobblestone/andesite,15,STONE:5,15,STAINED_CLAY:9,10,IRON_BARS,12,AIR,8,STAINED_CLAY:12,30,CONCRETE:8,100)
RandomBlock(-7,15,7,CONCRETE:7,60,quark:iron_plate,20,STAINED_CLAY:12,15,STAINED_CLAY:15,5,AIR,7,IRON_BARS,12,CONCRETE:7,100)
RandomBlock(-7,15,8,AIR,90,IRON_TRAPDOOR:9,100)
RandomBlock(-7,16,-7,CONCRETE:7,60,quark:iron_plate,20,STAINED_CLAY:12,15,STAINED_CLAY:15,5,AIR,7,IRON_BARS,12,CONCRETE:7,100)
Block(-7,16,-6,AIR:0)
Block(-7,16,-5,AIR:0)
RandomBlock(-7,16,-4,CONCRETE:7,60,quark:iron_plate,20,STAINED_CLAY:12,15,STAINED_CLAY:15,5,AIR,7,IRON_BARS,12,CONCRETE:7,100)
Block(-7,16,-3,AIR:0)
Block(-7,16,-2,AIR:0)
RandomBlock(-7,16,-1,CONCRETE:7,60,quark:iron_plate,20,STAINED_CLAY:12,15,STAINED_CLAY:15,5,AIR,7,IRON_BARS,12,CONCRETE:7,100)
Block(-7,16,0,AIR:0)
Block(-7,16,1,AIR:0)
Block(-7,16,2,AIR:0)
Block(-7,16,3,AIR:0)
RandomBlock(-7,16,4,CONCRETE:7,60,quark:iron_plate,20,STAINED_CLAY:12,15,STAINED_CLAY:15,5,AIR,7,IRON_BARS,12,CONCRETE:7,100)
RandomBlock(-7,16,5,CONCRETE:7,60,quark:iron_plate,20,STAINED_CLAY:12,15,STAINED_CLAY:15,5,AIR,7,IRON_BARS,12,CONCRETE:7,100)
RandomBlock(-7,16,6,CONCRETE:8,60,notreepunching:cobblestone/andesite,15,STONE:5,15,STAINED_CLAY:9,10,IRON_BARS,12,AIR,8,STAINED_CLAY:12,30,CONCRETE:8,100)
RandomBlock(-7,16,7,CONCRETE:7,60,quark:iron_plate,20,STAINED_CLAY:12,15,STAINED_CLAY:15,5,AIR,7,IRON_BARS,12,CONCRETE:7,100)
Block(-7,16,8,AIR:0)
RandomBlock(-7,17,-7,CONCRETE:7,60,quark:iron_plate,20,STAINED_CLAY:12,15,STAINED_CLAY:15,5,AIR,7,IRON_BARS,12,CONCRETE:7,100)
RandomBlock(-7,17,-6,CONCRETE:7,60,quark:iron_plate,20,STAINED_CLAY:12,15,STAINED_CLAY:15,5,AIR,7,IRON_BARS,12,CONCRETE:7,100)
RandomBlock(-7,17,-5,CONCRETE:7,60,quark:iron_plate,20,STAINED_CLAY:12,15,STAINED_CLAY:15,5,AIR,7,IRON_BARS,12,CONCRETE:7,100)
RandomBlock(-7,17,-4,CONCRETE:7,60,quark:iron_plate,20,STAINED_CLAY:12,15,STAINED_CLAY:15,5,AIR,7,IRON_BARS,12,CONCRETE:7,100)
RandomBlock(-7,17,-3,CONCRETE:7,60,quark:iron_plate,20,STAINED_CLAY:12,15,STAINED_CLAY:15,5,AIR,7,IRON_BARS,12,CONCRETE:7,100)
RandomBlock(-7,17,-2,CONCRETE:7,60,quark:iron_plate,20,STAINED_CLAY:12,15,STAINED_CLAY:15,5,AIR,7,IRON_BARS,12,CONCRETE:7,100)
RandomBlock(-7,17,-1,CONCRETE:7,60,quark:iron_plate,20,STAINED_CLAY:12,15,STAINED_CLAY:15,5,AIR,7,IRON_BARS,12,CONCRETE:7,100)
RandomBlock(-7,17,0,CONCRETE:7,60,quark:iron_plate,20,STAINED_CLAY:12,15,STAINED_CLAY:15,5,AIR,7,IRON_BARS,12,CONCRETE:7,100)
RandomBlock(-7,17,1,CONCRETE:7,60,quark:iron_plate,20,STAINED_CLAY:12,15,STAINED_CLAY:15,5,AIR,7,IRON_BARS,12,CONCRETE:7,100)
RandomBlock(-7,17,2,CONCRETE:7,60,quark:iron_plate,20,STAINED_CLAY:12,15,STAINED_CLAY:15,5,AIR,7,IRON_BARS,12,CONCRETE:7,100)
RandomBlock(-7,17,3,CONCRETE:7,60,quark:iron_plate,20,STAINED_CLAY:12,15,STAINED_CLAY:15,5,AIR,7,IRON_BARS,12,CONCRETE:7,100)
RandomBlock(-7,17,4,CONCRETE:7,60,quark:iron_plate,20,STAINED_CLAY:12,15,STAINED_CLAY:15,5,AIR,7,IRON_BARS,12,CONCRETE:7,100)
RandomBlock(-7,17,5,CONCRETE:7,60,quark:iron_plate,20,STAINED_CLAY:12,15,STAINED_CLAY:15,5,AIR,7,IRON_BARS,12,CONCRETE:7,100)
RandomBlock(-7,17,6,CONCRETE:7,60,quark:iron_plate,20,STAINED_CLAY:12,15,STAINED_CLAY:15,5,AIR,7,IRON_BARS,12,CONCRETE:7,100)
RandomBlock(-7,17,7,CONCRETE:7,60,quark:iron_plate,20,STAINED_CLAY:12,15,STAINED_CLAY:15,5,AIR,7,IRON_BARS,12,CONCRETE:7,100)
RandomBlock(-7,17,8,CONCRETE:7,60,quark:iron_plate,20,STAINED_CLAY:12,15,STAINED_CLAY:15,5,AIR,7,IRON_BARS,12,CONCRETE:7,100)
Block(-7,18,0,AIR)
Block(-7,18,1,AIR)
Block(-7,18,2,AIR)
Block(-7,23,-6,CONCRETE:0)
Block(-7,23,2,CONCRETE:0)
Block(-7,24,-6,CONCRETE:0)
Block(-7,24,-4,minecraft:black_glazed_terracotta)
Block(-7,24,-2,CONCRETE:15)
Block(-7,24,0,CONCRETE:0)
Block(-7,24,2,CONCRETE:0)
Block(-7,24,4,minecraft:black_glazed_terracotta)
Block(-7,24,6,CONCRETE:0)
Block(-7,24,8,CONCRETE:15)
Block(-7,25,-7,CONCRETE:15)
Block(-7,25,-6,CONCRETE:15)
Block(-7,25,-5,CONCRETE:15)
Block(-7,25,-4,CONCRETE:15)
Block(-7,25,-3,CONCRETE:15)
Block(-7,25,-2,CONCRETE:15)
Block(-7,25,-1,CONCRETE:15)
Block(-7,25,0,CONCRETE:15)
Block(-7,25,1,CONCRETE:15)
Block(-7,25,2,CONCRETE:15)
Block(-7,25,3,CONCRETE:15)
Block(-7,25,4,CONCRETE:15)
Block(-7,25,5,CONCRETE:15)
Block(-7,25,6,CONCRETE:15)
Block(-7,25,7,CONCRETE:15)
Block(-7,25,8,CONCRETE:15)
Block(-7,26,-6,AIR)
Block(-7,26,-4,CONCRETE:0)
Block(-7,26,-3,CONCRETE:0)
Block(-7,26,-2,CONCRETE:0)
Block(-7,26,-1,CONCRETE:0)
Block(-7,26,0,CONCRETE:0)
Block(-7,26,1,CONCRETE:0)
Block(-7,26,2,CONCRETE:0)
Block(-7,26,3,CONCRETE:0)
Block(-7,26,4,CONCRETE:0)
Block(-7,26,5,CONCRETE:0)
Block(-7,26,6,CONCRETE:0)
Block(-7,26,8,AIR)
Block(-7,27,-4,CONCRETE:0)
RandomBlock(-7,27,-3,STAINED_GLASS_PANE:15,40,AIR,100)
RandomBlock(-7,27,-2,STAINED_GLASS_PANE:15,40,AIR,100)
RandomBlock(-7,27,-1,STAINED_GLASS_PANE:15,40,AIR,100)
RandomBlock(-7,27,0,STAINED_GLASS_PANE:15,40,AIR,100)
Block(-7,27,1,CONCRETE:0)
RandomBlock(-7,27,2,STAINED_GLASS_PANE:15,40,AIR,100)
RandomBlock(-7,27,3,STAINED_GLASS_PANE:15,40,AIR,100)
RandomBlock(-7,27,4,STAINED_GLASS_PANE:15,40,AIR,100)
RandomBlock(-7,27,5,STAINED_GLASS_PANE:15,40,AIR,100)
Block(-7,27,6,CONCRETE:0)
Block(-7,28,-4,CONCRETE:0)
Block(-7,28,-3,CONCRETE:0)
Block(-7,28,-2,CONCRETE:0)
Block(-7,28,-1,CONCRETE:0)
Block(-7,28,0,CONCRETE:0)
Block(-7,28,1,CONCRETE:0)
Block(-7,28,2,CONCRETE:0)
Block(-7,28,3,CONCRETE:0)
Block(-7,28,4,CONCRETE:0)
Block(-7,28,5,CONCRETE:0)
Block(-7,28,6,CONCRETE:0)
Block(-7,29,-7,CONCRETE:15)
Block(-7,29,-6,CONCRETE:15)
Block(-7,29,-5,CONCRETE:15)
Block(-7,29,-4,CONCRETE:15)
Block(-7,29,-3,CONCRETE:15)
Block(-7,29,-2,CONCRETE:15)
Block(-7,29,-1,CONCRETE:15)
Block(-7,29,0,CONCRETE:15)
Block(-7,29,1,CONCRETE:15)
Block(-7,29,2,CONCRETE:15)
Block(-7,29,3,CONCRETE:15)
Block(-7,29,4,CONCRETE:15)
Block(-7,29,5,CONCRETE:15)
Block(-7,29,6,CONCRETE:15)
Block(-7,29,7,CONCRETE:15)
Block(-7,29,8,CONCRETE:15)
Block(-7,30,-7,AIR)
Block(-7,30,-6,AIR)
Block(-7,30,-2,STEP:15)
RandomBlock(-7,30,4,CONCRETE:7,60,quark:iron_plate,20,STAINED_CLAY:12,15,STAINED_CLAY:15,5,AIR,7,IRON_BARS,12,CONCRETE:7,100)
Block(-7,30,7,AIR)
Block(-7,30,8,AIR)
Block(-7,31,-6,AIR)
RandomBlock(-7,31,4,CONCRETE:7,60,quark:iron_plate,20,STAINED_CLAY:12,15,STAINED_CLAY:15,5,AIR,7,IRON_BARS,12,CONCRETE:7,100)
Block(-7,31,7,AIR)
RandomBlock(-7,32,4,CONCRETE:7,60,quark:iron_plate,20,STAINED_CLAY:12,15,STAINED_CLAY:15,5,AIR,7,IRON_BARS,12,CONCRETE:7,100)
Block(-7,33,-7,CONCRETE:15)
Block(-7,33,-6,CONCRETE:15)
Block(-7,33,-5,CONCRETE:15)
Block(-7,33,-4,CONCRETE:15)
Block(-7,33,-3,CONCRETE:15)
Block(-7,33,-2,CONCRETE:15)
Block(-7,33,-1,CONCRETE:15)
Block(-7,33,0,CONCRETE:15)
Block(-7,33,1,CONCRETE:15)
Block(-7,33,2,CONCRETE:15)
Block(-7,33,3,CONCRETE:15)
Block(-7,33,4,CONCRETE:15)
Block(-7,33,5,CONCRETE:15)
Block(-7,33,6,CONCRETE:15)
Block(-7,33,7,CONCRETE:15)
Block(-7,33,8,CONCRETE:15)
Block(-7,34,-1,AIR)
Block(-7,34,0,AIR)
Block(-7,34,1,AIR)
Block(-7,34,2,AIR)
Block(-7,34,3,AIR)
Block(-7,37,-7,CONCRETE:15)
Block(-7,37,-6,CONCRETE:15)
Block(-7,37,-5,CONCRETE:15)
Block(-7,37,-4,CONCRETE:15)
Block(-7,37,-3,CONCRETE:15)
Block(-7,37,-2,CONCRETE:15)
Block(-7,37,-1,CONCRETE:15)
Block(-7,37,0,CONCRETE:15)
Block(-7,37,1,CONCRETE:15)
Block(-7,37,2,CONCRETE:15)
Block(-7,37,3,CONCRETE:15)
Block(-7,37,4,CONCRETE:15)
Block(-7,37,5,CONCRETE:15)
Block(-7,37,6,CONCRETE:15)
Block(-7,37,7,CONCRETE:15)
Block(-7,37,8,CONCRETE:15)
Block(-7,38,-1,AIR)
Block(-7,38,0,AIR)
Block(-7,38,1,AIR)
Block(-7,38,2,AIR)
Block(-7,38,3,AIR)
Block(-7,41,-7,CONCRETE:15)
Block(-7,41,-6,CONCRETE:15)
Block(-7,41,-5,CONCRETE:15)
Block(-7,41,-4,CONCRETE:15)
Block(-7,41,-3,CONCRETE:15)
Block(-7,41,-2,CONCRETE:15)
Block(-7,41,-1,CONCRETE:15)
Block(-7,41,0,CONCRETE:15)
Block(-7,41,1,CONCRETE:15)
Block(-7,41,2,CONCRETE:15)
Block(-7,41,3,CONCRETE:15)
Block(-7,41,4,CONCRETE:15)
Block(-7,41,5,CONCRETE:15)
Block(-7,41,6,CONCRETE:15)
Block(-7,41,7,CONCRETE:15)
Block(-7,41,8,CONCRETE:15)
Block(-7,42,-1,AIR)
Block(-7,42,0,AIR)
Block(-7,42,1,AIR)
Block(-7,42,2,AIR)
Block(-7,42,3,AIR)
Block(-7,45,-7,CONCRETE:15)
Block(-7,45,-6,CONCRETE:15)
Block(-7,45,-5,CONCRETE:15)
Block(-7,45,-4,CONCRETE:15)
Block(-7,45,-3,CONCRETE:15)
Block(-7,45,-2,CONCRETE:15)
Block(-7,45,-1,CONCRETE:15)
Block(-7,45,0,CONCRETE:15)
Block(-7,45,1,CONCRETE:15)
Block(-7,45,2,CONCRETE:15)
Block(-7,45,3,CONCRETE:15)
Block(-7,45,4,CONCRETE:15)
Block(-7,45,5,CONCRETE:15)
Block(-7,45,6,CONCRETE:15)
Block(-7,45,7,CONCRETE:15)
Block(-7,45,8,CONCRETE:15)
Block(-7,46,-1,AIR)
Block(-7,46,0,AIR)
Block(-7,46,1,AIR)
Block(-7,46,2,AIR)
Block(-7,46,3,AIR)
Block(-7,49,-7,CONCRETE:15)
Block(-7,49,-6,CONCRETE:15)
Block(-7,49,-5,CONCRETE:15)
Block(-7,49,-4,CONCRETE:15)
Block(-7,49,-3,CONCRETE:15)
Block(-7,49,-2,CONCRETE:15)
Block(-7,49,-1,CONCRETE:15)
Block(-7,49,0,CONCRETE:15)
Block(-7,49,1,CONCRETE:15)
Block(-7,49,2,CONCRETE:15)
Block(-7,49,3,CONCRETE:15)
Block(-7,49,4,CONCRETE:15)
Block(-7,49,5,CONCRETE:15)
Block(-7,49,6,CONCRETE:15)
Block(-7,49,7,CONCRETE:15)
Block(-7,49,8,CONCRETE:15)
Block(-7,50,-7,AIR)
Block(-7,50,-6,AIR)
Block(-7,50,-2,STEP:15)
RandomBlock(-7,50,4,CONCRETE:7,60,quark:iron_plate,20,STAINED_CLAY:12,15,STAINED_CLAY:15,5,AIR,7,IRON_BARS,12,CONCRETE:7,100)
Block(-7,50,7,AIR)
Block(-7,50,8,AIR)
Block(-7,51,-6,AIR)
RandomBlock(-7,51,4,CONCRETE:7,60,quark:iron_plate,20,STAINED_CLAY:12,15,STAINED_CLAY:15,5,AIR,7,IRON_BARS,12,CONCRETE:7,100)
Block(-7,51,7,AIR)
RandomBlock(-7,52,4,CONCRETE:7,60,quark:iron_plate,20,STAINED_CLAY:12,15,STAINED_CLAY:15,5,AIR,7,IRON_BARS,12,CONCRETE:7,100)
Block(-7,53,-7,CONCRETE:15)
Block(-7,53,-6,CONCRETE:15)
Block(-7,53,-5,CONCRETE:15)
Block(-7,53,-4,CONCRETE:15)
Block(-7,53,-3,CONCRETE:15)
Block(-7,53,-2,CONCRETE:15)
Block(-7,53,-1,CONCRETE:15)
Block(-7,53,0,CONCRETE:15)
Block(-7,53,1,CONCRETE:15)
Block(-7,53,2,CONCRETE:15)
Block(-7,53,3,CONCRETE:15)
Block(-7,53,4,CONCRETE:15)
Block(-7,53,5,CONCRETE:15)
Block(-7,53,6,CONCRETE:15)
Block(-7,53,7,CONCRETE:15)
Block(-7,53,8,CONCRETE:15)
Block(-7,54,-1,AIR)
Block(-7,54,0,AIR)
Block(-7,54,1,AIR)
Block(-7,54,2,AIR)
Block(-7,54,3,AIR)
Block(-7,57,-7,CONCRETE:15)
Block(-7,57,-6,CONCRETE:15)
Block(-7,57,-5,CONCRETE:15)
Block(-7,57,-4,CONCRETE:15)
Block(-7,57,-3,CONCRETE:15)
Block(-7,57,-2,CONCRETE:15)
Block(-7,57,-1,CONCRETE:15)
Block(-7,57,0,CONCRETE:15)
Block(-7,57,1,CONCRETE:15)
Block(-7,57,2,CONCRETE:15)
Block(-7,57,3,CONCRETE:15)
Block(-7,57,4,CONCRETE:15)
Block(-7,57,5,CONCRETE:15)
Block(-7,57,6,CONCRETE:15)
Block(-7,57,7,CONCRETE:15)
Block(-7,57,8,CONCRETE:15)
Block(-7,58,-1,AIR)
Block(-7,58,0,AIR)
Block(-7,58,1,AIR)
Block(-7,58,2,AIR)
Block(-7,58,3,AIR)
Block(-7,61,-7,CONCRETE:15)
Block(-7,61,-6,CONCRETE:15)
Block(-7,61,-5,CONCRETE:15)
Block(-7,61,-4,CONCRETE:15)
Block(-7,61,-3,CONCRETE:15)
Block(-7,61,-2,CONCRETE:15)
Block(-7,61,-1,CONCRETE:15)
Block(-7,61,0,CONCRETE:15)
Block(-7,61,1,CONCRETE:15)
Block(-7,61,2,CONCRETE:15)
Block(-7,61,3,CONCRETE:15)
Block(-7,61,4,CONCRETE:15)
Block(-7,61,5,CONCRETE:15)
Block(-7,61,6,CONCRETE:15)
Block(-7,61,7,CONCRETE:15)
Block(-7,61,8,CONCRETE:15)
Block(-7,62,-1,AIR)
Block(-7,62,0,AIR)
Block(-7,62,1,AIR)
Block(-7,62,2,AIR)
Block(-7,62,3,AIR)
Block(-7,65,-7,CONCRETE:15)
Block(-7,65,-6,CONCRETE:15)
Block(-7,65,-5,CONCRETE:15)
Block(-7,65,-4,CONCRETE:15)
Block(-7,65,-3,CONCRETE:15)
Block(-7,65,-2,CONCRETE:15)
Block(-7,65,-1,CONCRETE:15)
Block(-7,65,0,CONCRETE:15)
Block(-7,65,1,CONCRETE:15)
Block(-7,65,2,CONCRETE:15)
Block(-7,65,3,CONCRETE:15)
Block(-7,65,4,CONCRETE:15)
Block(-7,65,5,CONCRETE:15)
Block(-7,65,6,CONCRETE:15)
Block(-7,65,7,CONCRETE:15)
Block(-7,65,8,CONCRETE:15)
Block(-7,66,-1,AIR)
Block(-7,66,0,AIR)
Block(-7,66,1,AIR)
Block(-7,66,2,AIR)
Block(-7,66,3,AIR)
Block(-7,69,-7,CONCRETE:15)
Block(-7,69,-6,CONCRETE:15)
Block(-7,69,-5,CONCRETE:15)
Block(-7,69,-4,CONCRETE:15)
Block(-7,69,-3,CONCRETE:15)
Block(-7,69,-2,CONCRETE:15)
Block(-7,69,-1,CONCRETE:15)
Block(-7,69,0,CONCRETE:15)
Block(-7,69,1,CONCRETE:15)
Block(-7,69,2,CONCRETE:15)
Block(-7,69,3,CONCRETE:15)
Block(-7,69,4,CONCRETE:15)
Block(-7,69,5,CONCRETE:15)
Block(-7,69,6,CONCRETE:15)
Block(-7,69,7,CONCRETE:15)
Block(-7,69,8,CONCRETE:15)
Block(-7,70,-7,AIR)
Block(-7,70,-6,AIR)
Block(-7,70,-2,STEP:15)
RandomBlock(-7,70,4,CONCRETE:7,60,quark:iron_plate,20,STAINED_CLAY:12,15,STAINED_CLAY:15,5,AIR,7,IRON_BARS,12,CONCRETE:7,100)
Block(-7,70,7,AIR)
Block(-7,70,8,AIR)
Block(-7,71,-6,AIR)
RandomBlock(-7,71,4,CONCRETE:7,60,quark:iron_plate,20,STAINED_CLAY:12,15,STAINED_CLAY:15,5,AIR,7,IRON_BARS,12,CONCRETE:7,100)
Block(-7,71,7,AIR)
RandomBlock(-7,72,4,CONCRETE:7,60,quark:iron_plate,20,STAINED_CLAY:12,15,STAINED_CLAY:15,5,AIR,7,IRON_BARS,12,CONCRETE:7,100)
Block(-7,73,-7,CONCRETE:15)
Block(-7,73,-6,CONCRETE:15)
Block(-7,73,-5,CONCRETE:15)
Block(-7,73,-4,CONCRETE:15)
Block(-7,73,-3,CONCRETE:15)
Block(-7,73,-2,CONCRETE:15)
Block(-7,73,-1,CONCRETE:15)
Block(-7,73,0,CONCRETE:15)
Block(-7,73,1,CONCRETE:15)
Block(-7,73,2,CONCRETE:15)
Block(-7,73,3,CONCRETE:15)
Block(-7,73,4,CONCRETE:15)
Block(-7,73,5,CONCRETE:15)
Block(-7,73,6,CONCRETE:15)
Block(-7,73,7,CONCRETE:15)
Block(-7,73,8,CONCRETE:15)
Block(-7,74,-1,AIR)
Block(-7,74,0,AIR)
Block(-7,74,1,AIR)
Block(-7,74,2,AIR)
Block(-7,74,3,AIR)
Block(-7,77,-7,CONCRETE:15)
Block(-7,77,-6,CONCRETE:15)
Block(-7,77,-5,CONCRETE:15)
Block(-7,77,-4,CONCRETE:15)
Block(-7,77,-3,CONCRETE:15)
Block(-7,77,-2,CONCRETE:15)
Block(-7,77,-1,CONCRETE:15)
Block(-7,77,0,CONCRETE:15)
Block(-7,77,1,CONCRETE:15)
Block(-7,77,2,CONCRETE:15)
Block(-7,77,3,CONCRETE:15)
Block(-7,77,4,CONCRETE:15)
Block(-7,77,5,CONCRETE:15)
Block(-7,77,6,CONCRETE:15)
Block(-7,77,7,CONCRETE:15)
Block(-7,77,8,CONCRETE:15)
Block(-7,78,-1,AIR)
Block(-7,78,0,AIR)
Block(-7,78,1,AIR)
Block(-7,78,2,AIR)
Block(-7,78,3,AIR)
Block(-7,81,-7,CONCRETE:15)
Block(-7,81,-6,CONCRETE:15)
Block(-7,81,-5,CONCRETE:15)
Block(-7,81,-4,CONCRETE:15)
Block(-7,81,-3,CONCRETE:15)
Block(-7,81,-2,CONCRETE:15)
Block(-7,81,-1,CONCRETE:15)
Block(-7,81,0,CONCRETE:15)
Block(-7,81,1,CONCRETE:15)
Block(-7,81,2,CONCRETE:15)
Block(-7,81,3,CONCRETE:15)
Block(-7,81,4,CONCRETE:15)
Block(-7,81,5,CONCRETE:15)
Block(-7,81,6,CONCRETE:15)
Block(-7,81,7,CONCRETE:15)
Block(-7,81,8,CONCRETE:15)
Block(-7,82,-1,AIR)
Block(-7,82,0,AIR)
Block(-7,82,1,AIR)
Block(-7,82,2,AIR)
Block(-7,82,3,AIR)
Block(-7,85,-7,CONCRETE:15)
Block(-7,85,-6,CONCRETE:15)
Block(-7,85,-5,CONCRETE:15)
Block(-7,85,-4,CONCRETE:15)
Block(-7,85,-3,CONCRETE:15)
Block(-7,85,-2,CONCRETE:15)
Block(-7,85,-1,CONCRETE:15)
Block(-7,85,0,CONCRETE:15)
Block(-7,85,1,CONCRETE:15)
Block(-7,85,2,CONCRETE:15)
Block(-7,85,3,CONCRETE:15)
Block(-7,85,4,CONCRETE:15)
Block(-7,85,5,CONCRETE:15)
Block(-7,85,6,CONCRETE:15)
Block(-7,85,7,CONCRETE:15)
Block(-7,85,8,CONCRETE:15)
RandomBlock(-6,0,-7,CONCRETE:7,60,quark:iron_plate,20,STAINED_CLAY:12,15,STAINED_CLAY:15,5,AIR,7,IRON_BARS,12,CONCRETE:7,100)
RandomBlock(-6,0,-6,CONCRETE:7,60,quark:iron_plate,20,STAINED_CLAY:12,15,STAINED_CLAY:15,5,AIR,7,IRON_BARS,12,CONCRETE:7,100)
RandomBlock(-6,0,-5,CONCRETE:7,60,quark:iron_plate,20,STAINED_CLAY:12,15,STAINED_CLAY:15,5,AIR,7,IRON_BARS,12,CONCRETE:7,100)
RandomBlock(-6,0,-4,CONCRETE:7,60,quark:iron_plate,20,STAINED_CLAY:12,15,STAINED_CLAY:15,5,AIR,7,IRON_BARS,12,CONCRETE:7,100)
RandomBlock(-6,0,-3,CONCRETE:7,60,quark:iron_plate,20,STAINED_CLAY:12,15,STAINED_CLAY:15,5,AIR,7,IRON_BARS,12,CONCRETE:7,100)
RandomBlock(-6,0,-2,CONCRETE:7,60,quark:iron_plate,20,STAINED_CLAY:12,15,STAINED_CLAY:15,5,AIR,7,IRON_BARS,12,CONCRETE:7,100)
RandomBlock(-6,0,-1,CONCRETE:7,60,quark:iron_plate,20,STAINED_CLAY:12,15,STAINED_CLAY:15,5,AIR,7,IRON_BARS,12,CONCRETE:7,100)
RandomBlock(-6,0,0,CONCRETE:7,60,quark:iron_plate,20,STAINED_CLAY:12,15,STAINED_CLAY:15,5,AIR,7,IRON_BARS,12,CONCRETE:7,100)
RandomBlock(-6,0,1,CONCRETE:7,60,quark:iron_plate,20,STAINED_CLAY:12,15,STAINED_CLAY:15,5,AIR,7,IRON_BARS,12,CONCRETE:7,100)
RandomBlock(-6,0,2,CONCRETE:7,60,quark:iron_plate,20,STAINED_CLAY:12,15,STAINED_CLAY:15,5,AIR,7,IRON_BARS,12,CONCRETE:7,100)
RandomBlock(-6,0,3,CONCRETE:7,60,quark:iron_plate,20,STAINED_CLAY:12,15,STAINED_CLAY:15,5,AIR,7,IRON_BARS,12,CONCRETE:7,100)
RandomBlock(-6,0,4,CONCRETE:7,60,quark:iron_plate,20,STAINED_CLAY:12,15,STAINED_CLAY:15,5,AIR,7,IRON_BARS,12,CONCRETE:7,100)
RandomBlock(-6,0,5,CONCRETE:7,60,quark:iron_plate,20,STAINED_CLAY:12,15,STAINED_CLAY:15,5,AIR,7,IRON_BARS,12,CONCRETE:7,100)
RandomBlock(-6,0,6,CONCRETE:7,60,quark:iron_plate,20,STAINED_CLAY:12,15,STAINED_CLAY:15,5,AIR,7,IRON_BARS,12,CONCRETE:7,100)
RandomBlock(-6,0,7,CONCRETE:7,60,quark:iron_plate,20,STAINED_CLAY:12,15,STAINED_CLAY:15,5,AIR,7,IRON_BARS,12,CONCRETE:7,100)
RandomBlock(-6,0,8,CONCRETE:7,60,quark:iron_plate,20,STAINED_CLAY:12,15,STAINED_CLAY:15,5,AIR,7,IRON_BARS,12,CONCRETE:7,100)
RandomBlock(-6,1,-7,CONCRETE:7,60,quark:iron_plate,20,STAINED_CLAY:12,15,STAINED_CLAY:15,5,AIR,7,IRON_BARS,12,CONCRETE:7,100)
RandomBlock(-6,1,-6,CONCRETE:7,60,quark:iron_plate,20,STAINED_CLAY:12,15,STAINED_CLAY:15,5,AIR,7,IRON_BARS,12,CONCRETE:7,100)
RandomBlock(-6,1,-5,CONCRETE:7,60,quark:iron_plate,20,STAINED_CLAY:12,15,STAINED_CLAY:15,5,AIR,7,IRON_BARS,12,CONCRETE:7,100)
RandomBlock(-6,1,-4,CONCRETE:7,60,quark:iron_plate,20,STAINED_CLAY:12,15,STAINED_CLAY:15,5,AIR,7,IRON_BARS,12,CONCRETE:7,100)
Block(-6,1,-3,STATIONARY_WATER:0)
Block(-6,1,-2,STATIONARY_WATER:0)
RandomBlock(-6,1,-1,CONCRETE:7,60,quark:iron_plate,20,STAINED_CLAY:12,15,STAINED_CLAY:15,5,AIR,7,IRON_BARS,12,CONCRETE:7,100)
RandomBlock(-6,1,0,CONCRETE:7,60,quark:iron_plate,20,STAINED_CLAY:12,15,STAINED_CLAY:15,5,AIR,7,IRON_BARS,12,CONCRETE:7,100)
RandomBlock(-6,1,1,CONCRETE:7,60,quark:iron_plate,20,STAINED_CLAY:12,15,STAINED_CLAY:15,5,AIR,7,IRON_BARS,12,CONCRETE:7,100)
RandomBlock(-6,1,2,CONCRETE:7,60,quark:iron_plate,20,STAINED_CLAY:12,15,STAINED_CLAY:15,5,AIR,7,IRON_BARS,12,CONCRETE:7,100)
RandomBlock(-6,1,3,CONCRETE:7,60,quark:iron_plate,20,STAINED_CLAY:12,15,STAINED_CLAY:15,5,AIR,7,IRON_BARS,12,CONCRETE:7,100)
RandomBlock(-6,1,4,CONCRETE:7,60,quark:iron_plate,20,STAINED_CLAY:12,15,STAINED_CLAY:15,5,AIR,7,IRON_BARS,12,CONCRETE:7,100)
RandomBlock(-6,1,5,CONCRETE:7,60,quark:iron_plate,20,STAINED_CLAY:12,15,STAINED_CLAY:15,5,AIR,7,IRON_BARS,12,CONCRETE:7,100)
RandomBlock(-6,1,6,CONCRETE:7,60,quark:iron_plate,20,STAINED_CLAY:12,15,STAINED_CLAY:15,5,AIR,7,IRON_BARS,12,CONCRETE:7,100)
RandomBlock(-6,1,7,CONCRETE:7,60,quark:iron_plate,20,STAINED_CLAY:12,15,STAINED_CLAY:15,5,AIR,7,IRON_BARS,12,CONCRETE:7,100)
RandomBlock(-6,1,8,CONCRETE:7,60,quark:iron_plate,20,STAINED_CLAY:12,15,STAINED_CLAY:15,5,AIR,7,IRON_BARS,12,CONCRETE:7,100)
RandomBlock(-6,2,-7,CONCRETE:7,60,quark:iron_plate,20,STAINED_CLAY:12,15,STAINED_CLAY:15,5,AIR,7,IRON_BARS,12,CONCRETE:7,100)
RandomBlock(-6,2,-6,CONCRETE:7,60,quark:iron_plate,20,STAINED_CLAY:12,15,STAINED_CLAY:15,5,AIR,7,IRON_BARS,12,CONCRETE:7,100)
RandomBlock(-6,2,-5,CONCRETE:7,60,quark:iron_plate,20,STAINED_CLAY:12,15,STAINED_CLAY:15,5,AIR,7,IRON_BARS,12,CONCRETE:7,100)
Block(-6,2,-4,SMOOTH_STAIRS:3)
Block(-6,2,-3,AIR:0)
Block(-6,2,-2,AIR:0)
Block(-6,2,-1,SMOOTH_STAIRS:2)
RandomBlock(-6,2,0,CONCRETE:7,60,quark:iron_plate,20,STAINED_CLAY:12,15,STAINED_CLAY:15,5,AIR,7,IRON_BARS,12,CONCRETE:7,100)
RandomBlock(-6,2,1,CONCRETE:7,60,quark:iron_plate,20,STAINED_CLAY:12,15,STAINED_CLAY:15,5,AIR,7,IRON_BARS,12,CONCRETE:7,100)
RandomBlock(-6,2,2,CONCRETE:7,60,quark:iron_plate,20,STAINED_CLAY:12,15,STAINED_CLAY:15,5,AIR,7,IRON_BARS,12,CONCRETE:7,100)
RandomBlock(-6,2,3,CONCRETE:7,60,quark:iron_plate,20,STAINED_CLAY:12,15,STAINED_CLAY:15,5,AIR,7,IRON_BARS,12,CONCRETE:7,100)
RandomBlock(-6,2,4,CONCRETE:7,60,quark:iron_plate,20,STAINED_CLAY:12,15,STAINED_CLAY:15,5,AIR,7,IRON_BARS,12,CONCRETE:7,100)
RandomBlock(-6,2,5,CONCRETE:7,60,quark:iron_plate,20,STAINED_CLAY:12,15,STAINED_CLAY:15,5,AIR,7,IRON_BARS,12,CONCRETE:7,100)
RandomBlock(-6,2,6,CONCRETE:7,60,quark:iron_plate,20,STAINED_CLAY:12,15,STAINED_CLAY:15,5,AIR,7,IRON_BARS,12,CONCRETE:7,100)
RandomBlock(-6,2,7,CONCRETE:7,60,quark:iron_plate,20,STAINED_CLAY:12,15,STAINED_CLAY:15,5,AIR,7,IRON_BARS,12,CONCRETE:7,100)
RandomBlock(-6,2,8,CONCRETE:7,60,quark:iron_plate,20,STAINED_CLAY:12,15,STAINED_CLAY:15,5,AIR,7,IRON_BARS,12,CONCRETE:7,100)
Block(-6,3,-7,AIR:0)
Block(-6,3,-6,AIR:0)
Block(-6,3,-5,AIR:0)
Block(-6,3,-4,AIR:0)
Block(-6,3,-3,AIR:0)
Block(-6,3,-2,AIR:0)
Block(-6,3,-1,AIR:0)
Block(-6,3,0,AIR:0)
RandomBlock(-6,3,1,CONCRETE:7,60,quark:iron_plate,20,STAINED_CLAY:12,15,STAINED_CLAY:15,5,AIR,7,IRON_BARS,12,CONCRETE:7,100)
RandomBlock(-6,3,2,CONCRETE:7,60,quark:iron_plate,20,STAINED_CLAY:12,15,STAINED_CLAY:15,5,AIR,7,IRON_BARS,12,CONCRETE:7,100)
Block(-6,3,3,AIR:0)
Block(-6,3,4,AIR:0)
RandomBlock(-6,3,5,CONCRETE:7,60,quark:iron_plate,20,STAINED_CLAY:12,15,STAINED_CLAY:15,5,AIR,7,IRON_BARS,12,CONCRETE:7,100)
RandomBlock(-6,3,6,CONCRETE:7,60,quark:iron_plate,20,STAINED_CLAY:12,15,STAINED_CLAY:15,5,AIR,7,IRON_BARS,12,CONCRETE:7,100)
Block(-6,3,7,AIR:0)
RandomBlock(-6,3,8,CONCRETE:7,60,quark:iron_plate,20,STAINED_CLAY:12,15,STAINED_CLAY:15,5,AIR,7,IRON_BARS,12,CONCRETE:7,100)
Block(-6,4,-7,AIR:0)
Block(-6,4,-6,AIR:0)
Block(-6,4,-5,AIR:0)
Block(-6,4,-4,AIR:0)
Block(-6,4,-3,AIR:0)
Block(-6,4,-2,AIR:0)
Block(-6,4,-1,AIR:0)
Block(-6,4,0,AIR:0)
RandomBlock(-6,4,1,CONCRETE:7,60,quark:iron_plate,20,STAINED_CLAY:12,15,STAINED_CLAY:15,5,AIR,7,IRON_BARS,12,CONCRETE:7,100)
RandomBlock(-6,4,2,CONCRETE:7,60,quark:iron_plate,20,STAINED_CLAY:12,15,STAINED_CLAY:15,5,AIR,7,IRON_BARS,12,CONCRETE:7,100)
Block(-6,4,3,AIR:0)
Block(-6,4,4,AIR:0)
RandomBlock(-6,4,5,CONCRETE:7,60,quark:iron_plate,20,STAINED_CLAY:12,15,STAINED_CLAY:15,5,AIR,7,IRON_BARS,12,CONCRETE:7,100)
RandomBlock(-6,4,6,CONCRETE:7,60,quark:iron_plate,20,STAINED_CLAY:12,15,STAINED_CLAY:15,5,AIR,7,IRON_BARS,12,CONCRETE:7,100)
Block(-6,4,7,AIR:0)
RandomBlock(-6,4,8,CONCRETE:7,60,quark:iron_plate,20,STAINED_CLAY:12,15,STAINED_CLAY:15,5,AIR,7,IRON_BARS,12,CONCRETE:7,100)
Block(-6,5,-7,AIR:0)
Block(-6,5,-6,CONCRETE:4)
Block(-6,5,-5,CONCRETE:12)
Block(-6,5,-4,CONCRETE:12)
Block(-6,5,-3,CONCRETE:12)
Block(-6,5,-2,CONCRETE:12)
Block(-6,5,-1,CONCRETE:12)
Block(-6,5,0,CONCRETE:12)
RandomBlock(-6,5,1,CONCRETE:7,60,quark:iron_plate,20,STAINED_CLAY:12,15,STAINED_CLAY:15,5,AIR,7,IRON_BARS,12,CONCRETE:7,100)
RandomBlock(-6,5,2,CONCRETE:7,60,quark:iron_plate,20,STAINED_CLAY:12,15,STAINED_CLAY:15,5,AIR,7,IRON_BARS,12,CONCRETE:7,100)
Block(-6,5,3,AIR:0)
Block(-6,5,4,AIR:0)
RandomBlock(-6,5,5,CONCRETE:7,60,quark:iron_plate,20,STAINED_CLAY:12,15,STAINED_CLAY:15,5,AIR,7,IRON_BARS,12,CONCRETE:7,100)
RandomBlock(-6,5,6,CONCRETE:7,60,quark:iron_plate,20,STAINED_CLAY:12,15,STAINED_CLAY:15,5,AIR,7,IRON_BARS,12,CONCRETE:7,100)
Block(-6,5,7,AIR:0)
RandomBlock(-6,5,8,CONCRETE:7,60,quark:iron_plate,20,STAINED_CLAY:12,15,STAINED_CLAY:15,5,AIR,7,IRON_BARS,12,CONCRETE:7,100)
Block(-6,6,-7,AIR:0)
Block(-6,6,-6,IRON_FENCE:0)
Block(-6,6,-5,AIR:0)
Block(-6,6,-4,AIR:0)
Block(-6,6,-3,AIR:0)
Block(-6,6,-2,IRON_FENCE:0)
Block(-6,6,-1,AIR:0)
Block(-6,6,0,CONCRETE:12)
RandomBlock(-6,6,1,CONCRETE:7,60,quark:iron_plate,20,STAINED_CLAY:12,15,STAINED_CLAY:15,5,AIR,7,IRON_BARS,12,CONCRETE:7,100)
RandomBlock(-6,6,2,CONCRETE:7,60,quark:iron_plate,20,STAINED_CLAY:12,15,STAINED_CLAY:15,5,AIR,7,IRON_BARS,12,CONCRETE:7,100)
Block(-6,6,3,AIR:0)
Block(-6,6,4,AIR:0)
RandomBlock(-6,6,5,CONCRETE:7,60,quark:iron_plate,20,STAINED_CLAY:12,15,STAINED_CLAY:15,5,AIR,7,IRON_BARS,12,CONCRETE:7,100)
RandomBlock(-6,6,6,CONCRETE:7,60,quark:iron_plate,20,STAINED_CLAY:12,15,STAINED_CLAY:15,5,AIR,7,IRON_BARS,12,CONCRETE:7,100)
Block(-6,6,7,AIR:0)
RandomBlock(-6,6,8,CONCRETE:7,60,quark:iron_plate,20,STAINED_CLAY:12,15,STAINED_CLAY:15,5,AIR,7,IRON_BARS,12,CONCRETE:7,100)
RandomBlock(-6,7,-7,CONCRETE:7,60,quark:iron_plate,20,STAINED_CLAY:12,15,STAINED_CLAY:15,5,AIR,7,IRON_BARS,12,CONCRETE:7,100)
RandomBlock(-6,7,-6,CONCRETE:7,60,quark:iron_plate,20,STAINED_CLAY:12,15,STAINED_CLAY:15,5,AIR,7,IRON_BARS,12,CONCRETE:7,100)
RandomBlock(-6,7,-5,CONCRETE:7,60,quark:iron_plate,20,STAINED_CLAY:12,15,STAINED_CLAY:15,5,AIR,7,IRON_BARS,12,CONCRETE:7,100)
RandomBlock(-6,7,-4,CONCRETE:7,60,quark:iron_plate,20,STAINED_CLAY:12,15,STAINED_CLAY:15,5,AIR,7,IRON_BARS,12,CONCRETE:7,100)
RandomBlock(-6,7,-3,CONCRETE:7,60,quark:iron_plate,20,STAINED_CLAY:12,15,STAINED_CLAY:15,5,AIR,7,IRON_BARS,12,CONCRETE:7,100)
RandomBlock(-6,7,-2,CONCRETE:7,60,quark:iron_plate,20,STAINED_CLAY:12,15,STAINED_CLAY:15,5,AIR,7,IRON_BARS,12,CONCRETE:7,100)
RandomBlock(-6,7,-1,CONCRETE:7,60,quark:iron_plate,20,STAINED_CLAY:12,15,STAINED_CLAY:15,5,AIR,7,IRON_BARS,12,CONCRETE:7,100)
Block(-6,7,0,CONCRETE:12)
RandomBlock(-6,7,1,CONCRETE:7,60,quark:iron_plate,20,STAINED_CLAY:12,15,STAINED_CLAY:15,5,AIR,7,IRON_BARS,12,CONCRETE:7,100)
RandomBlock(-6,7,2,CONCRETE:7,60,quark:iron_plate,20,STAINED_CLAY:12,15,STAINED_CLAY:15,5,AIR,7,IRON_BARS,12,CONCRETE:7,100)
RandomBlock(-6,7,3,CONCRETE:7,60,quark:iron_plate,20,STAINED_CLAY:12,15,STAINED_CLAY:15,5,AIR,7,IRON_BARS,12,CONCRETE:7,100)
RandomBlock(-6,7,4,CONCRETE:7,60,quark:iron_plate,20,STAINED_CLAY:12,15,STAINED_CLAY:15,5,AIR,7,IRON_BARS,12,CONCRETE:7,100)
RandomBlock(-6,7,5,CONCRETE:7,60,quark:iron_plate,20,STAINED_CLAY:12,15,STAINED_CLAY:15,5,AIR,7,IRON_BARS,12,CONCRETE:7,100)
RandomBlock(-6,7,6,CONCRETE:7,60,quark:iron_plate,20,STAINED_CLAY:12,15,STAINED_CLAY:15,5,AIR,7,IRON_BARS,12,CONCRETE:7,100)
RandomBlock(-6,7,7,CONCRETE:7,60,quark:iron_plate,20,STAINED_CLAY:12,15,STAINED_CLAY:15,5,AIR,7,IRON_BARS,12,CONCRETE:7,100)
RandomBlock(-6,7,8,CONCRETE:7,60,quark:iron_plate,20,STAINED_CLAY:12,15,STAINED_CLAY:15,5,AIR,7,IRON_BARS,12,CONCRETE:7,100)
Block(-6,8,-7,IRON_FENCE:0)
Block(-6,8,-6,IRON_FENCE:0)
RandomBlock(-6,8,-5,CONCRETE:7,60,quark:iron_plate,20,STAINED_CLAY:12,15,STAINED_CLAY:15,5,AIR,7,IRON_BARS,12,CONCRETE:7,100)
Block(-6,8,-4,IRON_DOOR_BLOCK:1)
RandomBlock(-6,8,-3,CONCRETE:7,60,quark:iron_plate,20,STAINED_CLAY:12,15,STAINED_CLAY:15,5,AIR,7,IRON_BARS,12,CONCRETE:7,100)
RandomBlock(-6,8,-2,CONCRETE:7,60,quark:iron_plate,20,STAINED_CLAY:12,15,STAINED_CLAY:15,5,AIR,7,IRON_BARS,12,CONCRETE:7,100)
Block(-6,8,-1,AIR:0)
Block(-6,8,0,CONCRETE:12)
Block(-6,8,1,AIR:0)
Block(-6,8,2,AIR:0)
Block(-6,8,3,AIR:0)
Block(-6,8,4,AIR:0)
Block(-6,8,5,AIR:0)
Block(-6,8,6,AIR:0)
RandomBlock(-6,8,7,CONCRETE:7,60,quark:iron_plate,20,STAINED_CLAY:12,15,STAINED_CLAY:15,5,AIR,7,IRON_BARS,12,CONCRETE:7,100)
RandomBlock(-6,8,8,CONCRETE:7,60,quark:iron_plate,20,STAINED_CLAY:12,15,STAINED_CLAY:15,5,AIR,7,IRON_BARS,12,CONCRETE:7,100)
Block(-6,9,-7,IRON_FENCE:0)
Block(-6,9,-6,IRON_FENCE:0)
RandomBlock(-6,9,-5,CONCRETE:7,60,quark:iron_plate,20,STAINED_CLAY:12,15,STAINED_CLAY:15,5,AIR,7,IRON_BARS,12,CONCRETE:7,100)
Block(-6,9,-4,IRON_DOOR_BLOCK:11)
RandomBlock(-6,9,-3,CONCRETE:7,60,quark:iron_plate,20,STAINED_CLAY:12,15,STAINED_CLAY:15,5,AIR,7,IRON_BARS,12,CONCRETE:7,100)
RandomBlock(-6,9,-2,CONCRETE:7,60,quark:iron_plate,20,STAINED_CLAY:12,15,STAINED_CLAY:15,5,AIR,7,IRON_BARS,12,CONCRETE:7,100)
Block(-6,9,-1,AIR:0)
Block(-6,9,0,CONCRETE:12)
Block(-6,9,1,AIR:0)
Block(-6,9,2,AIR:0)
Block(-6,9,3,AIR:0)
Block(-6,9,4,AIR:0)
Block(-6,9,5,AIR:0)
Block(-6,9,6,AIR:0)
RandomBlock(-6,9,7,CONCRETE:7,60,quark:iron_plate,20,STAINED_CLAY:12,15,STAINED_CLAY:15,5,AIR,7,IRON_BARS,12,CONCRETE:7,100)
RandomBlock(-6,9,8,CONCRETE:7,60,quark:iron_plate,20,STAINED_CLAY:12,15,STAINED_CLAY:15,5,AIR,7,IRON_BARS,12,CONCRETE:7,100)
Block(-6,10,-7,IRON_FENCE:0)
Block(-6,10,-6,IRON_FENCE:0)
RandomBlock(-6,10,-5,CONCRETE:7,60,quark:iron_plate,20,STAINED_CLAY:12,15,STAINED_CLAY:15,5,AIR,7,IRON_BARS,12,CONCRETE:7,100)
RandomBlock(-6,10,-4,CONCRETE:7,60,quark:iron_plate,20,STAINED_CLAY:12,15,STAINED_CLAY:15,5,AIR,7,IRON_BARS,12,CONCRETE:7,100)
RandomBlock(-6,10,-3,CONCRETE:7,60,quark:iron_plate,20,STAINED_CLAY:12,15,STAINED_CLAY:15,5,AIR,7,IRON_BARS,12,CONCRETE:7,100)
RandomBlock(-6,10,-2,CONCRETE:7,60,quark:iron_plate,20,STAINED_CLAY:12,15,STAINED_CLAY:15,5,AIR,7,IRON_BARS,12,CONCRETE:7,100)
Block(-6,10,-1,AIR:0)
Block(-6,10,0,CONCRETE:12)
Block(-6,10,1,AIR:0)
Block(-6,10,2,AIR:0)
Block(-6,10,3,AIR:0)
Block(-6,10,4,AIR:0)
Block(-6,10,5,AIR:0)
Block(-6,10,6,AIR:0)
RandomBlock(-6,10,7,CONCRETE:7,60,quark:iron_plate,20,STAINED_CLAY:12,15,STAINED_CLAY:15,5,AIR,7,IRON_BARS,12,CONCRETE:7,100)
RandomBlock(-6,10,8,CONCRETE:7,60,quark:iron_plate,20,STAINED_CLAY:12,15,STAINED_CLAY:15,5,AIR,7,IRON_BARS,12,CONCRETE:7,100)
Block(-6,11,-7,AIR:0)
Block(-6,11,-6,CONCRETE:14)
RandomBlock(-6,11,-5,CONCRETE:7,60,quark:iron_plate,20,STAINED_CLAY:12,15,STAINED_CLAY:15,5,AIR,7,IRON_BARS,12,CONCRETE:7,100)
Block(-6,11,-4,AIR:0)
RandomBlock(-6,11,-3,CONCRETE:7,60,quark:iron_plate,20,STAINED_CLAY:12,15,STAINED_CLAY:15,5,AIR,7,IRON_BARS,12,CONCRETE:7,100)
RandomBlock(-6,11,-2,CONCRETE:7,60,quark:iron_plate,20,STAINED_CLAY:12,15,STAINED_CLAY:15,5,AIR,7,IRON_BARS,12,CONCRETE:7,100)
Block(-6,11,-1,AIR:0)
Block(-6,11,0,CONCRETE:12)
Block(-6,11,1,AIR:0)
Block(-6,11,2,CONCRETE:4)
Block(-6,11,3,AIR:0)
Block(-6,11,4,AIR:0)
Block(-6,11,5,AIR:0)
Block(-6,11,6,AIR:0)
RandomBlock(-6,11,7,CONCRETE:7,60,quark:iron_plate,20,STAINED_CLAY:12,15,STAINED_CLAY:15,5,AIR,7,IRON_BARS,12,CONCRETE:7,100)
RandomBlock(-6,11,8,CONCRETE:7,60,quark:iron_plate,20,STAINED_CLAY:12,15,STAINED_CLAY:15,5,AIR,7,IRON_BARS,12,CONCRETE:7,100)
Block(-6,12,-7,AIR:0)
Block(-6,12,-6,AIR:0)
RandomBlock(-6,12,-5,CONCRETE:7,60,quark:iron_plate,20,STAINED_CLAY:12,15,STAINED_CLAY:15,5,AIR,7,IRON_BARS,12,CONCRETE:7,100)
Block(-6,12,-4,AIR:0)
RandomBlock(-6,12,-3,CONCRETE:7,60,quark:iron_plate,20,STAINED_CLAY:12,15,STAINED_CLAY:15,5,AIR,7,IRON_BARS,12,CONCRETE:7,100)
RandomBlock(-6,12,-2,CONCRETE:7,60,quark:iron_plate,20,STAINED_CLAY:12,15,STAINED_CLAY:15,5,AIR,7,IRON_BARS,12,CONCRETE:7,100)
Block(-6,12,-1,AIR:0)
Block(-6,12,0,IRON_FENCE:0)
Block(-6,12,1,AIR:0)
Block(-6,12,2,IRON_FENCE:0)
Block(-6,12,3,AIR:0)
Block(-6,12,4,AIR:0)
Block(-6,12,5,AIR:0)
Block(-6,12,6,AIR:0)
RandomBlock(-6,12,7,CONCRETE:7,60,quark:iron_plate,20,STAINED_CLAY:12,15,STAINED_CLAY:15,5,AIR,7,IRON_BARS,12,CONCRETE:7,100)
RandomBlock(-6,12,8,CONCRETE:7,60,quark:iron_plate,20,STAINED_CLAY:12,15,STAINED_CLAY:15,5,AIR,7,IRON_BARS,12,CONCRETE:7,100)
RandomBlock(-6,13,-7,CONCRETE:8,60,notreepunching:cobblestone/andesite,15,STONE:5,15,STAINED_CLAY:9,10,IRON_BARS,12,AIR,8,STAINED_CLAY:12,30,CONCRETE:8,100)
RandomBlock(-6,13,-6,CONCRETE:8,60,notreepunching:cobblestone/andesite,15,STONE:5,15,STAINED_CLAY:9,10,IRON_BARS,12,AIR,8,STAINED_CLAY:12,30,CONCRETE:8,100)
RandomBlock(-6,13,-5,CONCRETE:8,60,notreepunching:cobblestone/andesite,15,STONE:5,15,STAINED_CLAY:9,10,IRON_BARS,12,AIR,8,STAINED_CLAY:12,30,CONCRETE:8,100)
RandomBlock(-6,13,-4,CONCRETE:8,60,notreepunching:cobblestone/andesite,15,STONE:5,15,STAINED_CLAY:9,10,IRON_BARS,12,AIR,8,STAINED_CLAY:12,30,CONCRETE:8,100)
RandomBlock(-6,13,-3,CONCRETE:8,60,notreepunching:cobblestone/andesite,15,STONE:5,15,STAINED_CLAY:9,10,IRON_BARS,12,AIR,8,STAINED_CLAY:12,30,CONCRETE:8,100)
RandomBlock(-6,13,-2,CONCRETE:8,60,notreepunching:cobblestone/andesite,15,STONE:5,15,STAINED_CLAY:9,10,IRON_BARS,12,AIR,8,STAINED_CLAY:12,30,CONCRETE:8,100)
RandomBlock(-6,13,-1,CONCRETE:8,60,notreepunching:cobblestone/andesite,15,STONE:5,15,STAINED_CLAY:9,10,IRON_BARS,12,AIR,8,STAINED_CLAY:12,30,CONCRETE:8,100)
RandomBlock(-6,13,0,CONCRETE:8,60,notreepunching:cobblestone/andesite,15,STONE:5,15,STAINED_CLAY:9,10,IRON_BARS,12,AIR,8,STAINED_CLAY:12,30,CONCRETE:8,100)
RandomBlock(-6,13,1,CONCRETE:8,60,notreepunching:cobblestone/andesite,15,STONE:5,15,STAINED_CLAY:9,10,IRON_BARS,12,AIR,8,STAINED_CLAY:12,30,CONCRETE:8,100)
RandomBlock(-6,13,2,CONCRETE:8,60,notreepunching:cobblestone/andesite,15,STONE:5,15,STAINED_CLAY:9,10,IRON_BARS,12,AIR,8,STAINED_CLAY:12,30,CONCRETE:8,100)
RandomBlock(-6,13,3,CONCRETE:8,60,notreepunching:cobblestone/andesite,15,STONE:5,15,STAINED_CLAY:9,10,IRON_BARS,12,AIR,8,STAINED_CLAY:12,30,CONCRETE:8,100)
RandomBlock(-6,13,4,CONCRETE:8,60,notreepunching:cobblestone/andesite,15,STONE:5,15,STAINED_CLAY:9,10,IRON_BARS,12,AIR,8,STAINED_CLAY:12,30,CONCRETE:8,100)
RandomBlock(-6,13,5,CONCRETE:8,60,notreepunching:cobblestone/andesite,15,STONE:5,15,STAINED_CLAY:9,10,IRON_BARS,12,AIR,8,STAINED_CLAY:12,30,CONCRETE:8,100)
RandomBlock(-6,13,6,CONCRETE:8,60,notreepunching:cobblestone/andesite,15,STONE:5,15,STAINED_CLAY:9,10,IRON_BARS,12,AIR,8,STAINED_CLAY:12,30,CONCRETE:8,100)
RandomBlock(-6,13,7,CONCRETE:8,60,notreepunching:cobblestone/andesite,15,STONE:5,15,STAINED_CLAY:9,10,IRON_BARS,12,AIR,8,STAINED_CLAY:12,30,CONCRETE:8,100)
RandomBlock(-6,13,8,CONCRETE:8,60,notreepunching:cobblestone/andesite,15,STONE:5,15,STAINED_CLAY:9,10,IRON_BARS,12,AIR,8,STAINED_CLAY:12,30,CONCRETE:8,100)
Block(-6,14,-7,AIR)
Block(-6,14,-6,AIR:0)
RandomBlock(-6,14,-5,STONE:6,85,CAULDRON:3,100)
RandomBlock(-6,14,-4,CONCRETE:8,60,notreepunching:cobblestone/andesite,15,STONE:5,15,STAINED_CLAY:9,10,IRON_BARS,12,AIR,8,STAINED_CLAY:12,30,CONCRETE:8,100)
Block(-6,14,-3,AIR:0)
Block(-6,14,-2,AIR:0)
Block(-6,14,-1,AIR)
Block(-6,14,0,AIR:0)
Block(-6,14,1,AIR:0)
Block(-6,14,2,AIR:0)
Block(-6,14,3,QUARTZ_STAIRS:3)
RandomBlock(-6,14,4,CONCRETE:8,60,notreepunching:cobblestone/andesite,15,STONE:5,15,STAINED_CLAY:9,10,IRON_BARS,12,AIR,8,STAINED_CLAY:12,30,CONCRETE:8,100)
RandomBlock(-6,14,5,CONCRETE:8,60,notreepunching:cobblestone/andesite,15,STONE:5,15,STAINED_CLAY:9,10,IRON_BARS,12,AIR,8,STAINED_CLAY:12,30,CONCRETE:8,100)
RandomBlock(-6,14,6,CONCRETE:8,60,notreepunching:cobblestone/andesite,15,STONE:5,15,STAINED_CLAY:9,10,IRON_BARS,12,AIR,8,STAINED_CLAY:12,30,CONCRETE:8,100)
RandomBlock(-6,14,7,CONCRETE:8,60,notreepunching:cobblestone/andesite,15,STONE:5,15,STAINED_CLAY:9,10,IRON_BARS,12,AIR,8,STAINED_CLAY:12,30,CONCRETE:8,100)
Block(-6,14,8,QUARTZ_STAIRS:4)
Block(-6,15,-7,AIR)
Block(-6,15,-6,AIR:0)
Block(-6,15,-5,TRIPWIRE_HOOK:2)
RandomBlock(-6,15,-4,CONCRETE:7,60,quark:iron_plate,20,STAINED_CLAY:12,15,STAINED_CLAY:15,5,AIR,7,IRON_BARS,12,CONCRETE:7,100)
Block(-6,15,-3,AIR:0)
Block(-6,15,-2,AIR:0)
Block(-6,15,-1,AIR)
Block(-6,15,0,AIR:0)
Block(-6,15,1,AIR:0)
Block(-6,15,2,AIR:0)
Block(-6,15,3,AIR:0)
RandomBlock(-6,15,4,CONCRETE:7,60,quark:iron_plate,20,STAINED_CLAY:12,15,STAINED_CLAY:15,5,AIR,7,IRON_BARS,12,CONCRETE:7,100)
RandomBlock(-6,15,5,CONCRETE:7,60,quark:iron_plate,20,STAINED_CLAY:12,15,STAINED_CLAY:15,5,AIR,7,IRON_BARS,12,CONCRETE:7,100)
RandomBlock(-6,15,6,CONCRETE:8,60,notreepunching:cobblestone/andesite,15,STONE:5,15,STAINED_CLAY:9,10,IRON_BARS,12,AIR,8,STAINED_CLAY:12,30,CONCRETE:8,100)
RandomBlock(-6,15,7,CONCRETE:7,60,quark:iron_plate,20,STAINED_CLAY:12,15,STAINED_CLAY:15,5,AIR,7,IRON_BARS,12,CONCRETE:7,100)
RandomBlock(-6,15,8,AIR,90,IRON_TRAPDOOR:9,100)
Block(-6,16,-6,AIR:0)
Block(-6,16,-5,AIR:0)
RandomBlock(-6,16,-4,CONCRETE:7,60,quark:iron_plate,20,STAINED_CLAY:12,15,STAINED_CLAY:15,5,AIR,7,IRON_BARS,12,CONCRETE:7,100)
Block(-6,16,-3,AIR:0)
Block(-6,16,-2,AIR:0)
Block(-6,16,0,AIR:0)
Block(-6,16,1,AIR:0)
Block(-6,16,2,AIR:0)
Block(-6,16,3,AIR:0)
RandomBlock(-6,16,4,CONCRETE:7,60,quark:iron_plate,20,STAINED_CLAY:12,15,STAINED_CLAY:15,5,AIR,7,IRON_BARS,12,CONCRETE:7,100)
RandomBlock(-6,16,5,CONCRETE:7,60,quark:iron_plate,20,STAINED_CLAY:12,15,STAINED_CLAY:15,5,AIR,7,IRON_BARS,12,CONCRETE:7,100)
RandomBlock(-6,16,6,CONCRETE:8,60,notreepunching:cobblestone/andesite,15,STONE:5,15,STAINED_CLAY:9,10,IRON_BARS,12,AIR,8,STAINED_CLAY:12,30,CONCRETE:8,100)
RandomBlock(-6,16,7,CONCRETE:7,60,quark:iron_plate,20,STAINED_CLAY:12,15,STAINED_CLAY:15,5,AIR,7,IRON_BARS,12,CONCRETE:7,100)
Block(-6,16,8,AIR:0)
RandomBlock(-6,17,-7,CONCRETE:7,60,quark:iron_plate,20,STAINED_CLAY:12,15,STAINED_CLAY:15,5,AIR,7,IRON_BARS,12,CONCRETE:7,100)
RandomBlock(-6,17,-6,CONCRETE:7,60,quark:iron_plate,20,STAINED_CLAY:12,15,STAINED_CLAY:15,5,AIR,7,IRON_BARS,12,CONCRETE:7,100)
RandomBlock(-6,17,-5,CONCRETE:7,60,quark:iron_plate,20,STAINED_CLAY:12,15,STAINED_CLAY:15,5,AIR,7,IRON_BARS,12,CONCRETE:7,100)
RandomBlock(-6,17,-4,CONCRETE:7,60,quark:iron_plate,20,STAINED_CLAY:12,15,STAINED_CLAY:15,5,AIR,7,IRON_BARS,12,CONCRETE:7,100)
RandomBlock(-6,17,-3,CONCRETE:7,60,quark:iron_plate,20,STAINED_CLAY:12,15,STAINED_CLAY:15,5,AIR,7,IRON_BARS,12,CONCRETE:7,100)
RandomBlock(-6,17,-2,CONCRETE:7,60,quark:iron_plate,20,STAINED_CLAY:12,15,STAINED_CLAY:15,5,AIR,7,IRON_BARS,12,CONCRETE:7,100)
RandomBlock(-6,17,-1,CONCRETE:7,60,quark:iron_plate,20,STAINED_CLAY:12,15,STAINED_CLAY:15,5,AIR,7,IRON_BARS,12,CONCRETE:7,100)
RandomBlock(-6,17,0,CONCRETE:7,60,quark:iron_plate,20,STAINED_CLAY:12,15,STAINED_CLAY:15,5,AIR,7,IRON_BARS,12,CONCRETE:7,100)
RandomBlock(-6,17,1,CONCRETE:7,60,quark:iron_plate,20,STAINED_CLAY:12,15,STAINED_CLAY:15,5,AIR,7,IRON_BARS,12,CONCRETE:7,100)
RandomBlock(-6,17,2,CONCRETE:7,60,quark:iron_plate,20,STAINED_CLAY:12,15,STAINED_CLAY:15,5,AIR,7,IRON_BARS,12,CONCRETE:7,100)
RandomBlock(-6,17,3,CONCRETE:7,60,quark:iron_plate,20,STAINED_CLAY:12,15,STAINED_CLAY:15,5,AIR,7,IRON_BARS,12,CONCRETE:7,100)
RandomBlock(-6,17,4,CONCRETE:7,60,quark:iron_plate,20,STAINED_CLAY:12,15,STAINED_CLAY:15,5,AIR,7,IRON_BARS,12,CONCRETE:7,100)
RandomBlock(-6,17,5,CONCRETE:7,60,quark:iron_plate,20,STAINED_CLAY:12,15,STAINED_CLAY:15,5,AIR,7,IRON_BARS,12,CONCRETE:7,100)
RandomBlock(-6,17,6,CONCRETE:7,60,quark:iron_plate,20,STAINED_CLAY:12,15,STAINED_CLAY:15,5,AIR,7,IRON_BARS,12,CONCRETE:7,100)
RandomBlock(-6,17,7,CONCRETE:7,60,quark:iron_plate,20,STAINED_CLAY:12,15,STAINED_CLAY:15,5,AIR,7,IRON_BARS,12,CONCRETE:7,100)
RandomBlock(-6,17,8,CONCRETE:7,60,quark:iron_plate,20,STAINED_CLAY:12,15,STAINED_CLAY:15,5,AIR,7,IRON_BARS,12,CONCRETE:7,100)
Block(-6,18,0,AIR)
Block(-6,18,1,AIR)
Block(-6,18,2,AIR)
Block(-6,25,-7,CONCRETE:15)
Block(-6,25,-6,CONCRETE:15)
Block(-6,25,-5,CONCRETE:15)
Block(-6,25,-4,CONCRETE:15)
Block(-6,25,-3,CONCRETE:15)
Block(-6,25,-2,CONCRETE:15)
Block(-6,25,-1,CONCRETE:15)
Block(-6,25,0,CONCRETE:15)
Block(-6,25,1,CONCRETE:15)
Block(-6,25,2,CONCRETE:15)
Block(-6,25,3,CONCRETE:15)
Block(-6,25,4,CONCRETE:15)
Block(-6,25,5,CONCRETE:15)
Block(-6,25,6,CONCRETE:15)
Block(-6,25,7,CONCRETE:15)
Block(-6,25,8,CONCRETE:15)
Block(-6,26,-6,AIR)
Block(-6,26,8,AIR)
Block(-6,29,-7,CONCRETE:15)
Block(-6,29,-6,CONCRETE:15)
Block(-6,29,-5,CONCRETE:15)
Block(-6,29,-4,CONCRETE:15)
Block(-6,29,-3,CONCRETE:15)
Block(-6,29,-2,CONCRETE:15)
Block(-6,29,-1,CONCRETE:15)
Block(-6,29,0,CONCRETE:15)
Block(-6,29,1,CONCRETE:15)
Block(-6,29,2,CONCRETE:15)
Block(-6,29,3,CONCRETE:15)
Block(-6,29,4,CONCRETE:15)
Block(-6,29,5,CONCRETE:15)
Block(-6,29,6,CONCRETE:15)
Block(-6,29,7,CONCRETE:15)
Block(-6,29,8,CONCRETE:15)
Block(-6,30,-5,AIR)
Block(-6,30,-4,AIR)
Block(-6,30,-3,DOUBLE_STEP:7)
Block(-6,30,-2,DOUBLE_STEP:7)
Block(-6,30,1,QUARTZ_STAIRS:4)
Block(-6,30,2,QUARTZ_STAIRS:4)
RandomBlock(-6,30,4,CONCRETE:7,60,quark:iron_plate,20,STAINED_CLAY:12,15,STAINED_CLAY:15,5,AIR,7,IRON_BARS,12,CONCRETE:7,100)
Block(-6,30,5,AIR)
Block(-6,31,-5,AIR)
Block(-6,31,-3,AIR)
RandomBlock(-6,31,1,AIR,75,FLOWER_POT:0,../AllScraperData/skyscraper_3x3_03/351-flower_potC16R16.nbt,100)
RandomBlock(-6,31,4,STAINED_GLASS_PANE:10,40,AIR,100)
RandomBlock(-6,32,4,CONCRETE:7,60,quark:iron_plate,20,STAINED_CLAY:12,15,STAINED_CLAY:15,5,AIR,7,IRON_BARS,12,CONCRETE:7,100)
Block(-6,33,-7,CONCRETE:15)
Block(-6,33,-6,CONCRETE:15)
Block(-6,33,-5,CONCRETE:15)
Block(-6,33,-4,CONCRETE:15)
Block(-6,33,-3,CONCRETE:15)
Block(-6,33,-2,CONCRETE:15)
Block(-6,33,-1,CONCRETE:15)
Block(-6,33,0,CONCRETE:15)
Block(-6,33,1,CONCRETE:15)
Block(-6,33,2,CONCRETE:15)
Block(-6,33,3,CONCRETE:15)
Block(-6,33,4,CONCRETE:15)
Block(-6,33,5,CONCRETE:15)
Block(-6,33,6,CONCRETE:15)
Block(-6,33,7,CONCRETE:15)
Block(-6,33,8,CONCRETE:15)
Block(-6,34,-1,AIR)
Block(-6,34,0,AIR)
Block(-6,34,1,AIR)
Block(-6,34,2,AIR)
Block(-6,34,3,AIR)
Block(-6,37,-7,CONCRETE:15)
Block(-6,37,-6,CONCRETE:15)
Block(-6,37,-5,CONCRETE:15)
Block(-6,37,-4,CONCRETE:15)
Block(-6,37,-3,CONCRETE:15)
Block(-6,37,-2,CONCRETE:15)
Block(-6,37,-1,CONCRETE:15)
Block(-6,37,0,CONCRETE:15)
Block(-6,37,1,CONCRETE:15)
Block(-6,37,2,CONCRETE:15)
Block(-6,37,3,CONCRETE:15)
Block(-6,37,4,CONCRETE:15)
Block(-6,37,5,CONCRETE:15)
Block(-6,37,6,CONCRETE:15)
Block(-6,37,7,CONCRETE:15)
Block(-6,37,8,CONCRETE:15)
Block(-6,38,-1,AIR)
Block(-6,38,0,AIR)
Block(-6,38,1,AIR)
Block(-6,38,2,AIR)
Block(-6,38,3,AIR)
Block(-6,41,-7,CONCRETE:15)
Block(-6,41,-6,CONCRETE:15)
Block(-6,41,-5,CONCRETE:15)
Block(-6,41,-4,CONCRETE:15)
Block(-6,41,-3,CONCRETE:15)
Block(-6,41,-2,CONCRETE:15)
Block(-6,41,-1,CONCRETE:15)
Block(-6,41,0,CONCRETE:15)
Block(-6,41,1,CONCRETE:15)
Block(-6,41,2,CONCRETE:15)
Block(-6,41,3,CONCRETE:15)
Block(-6,41,4,CONCRETE:15)
Block(-6,41,5,CONCRETE:15)
Block(-6,41,6,CONCRETE:15)
Block(-6,41,7,CONCRETE:15)
Block(-6,41,8,CONCRETE:15)
Block(-6,42,-1,AIR)
Block(-6,42,0,AIR)
Block(-6,42,1,AIR)
Block(-6,42,2,AIR)
Block(-6,42,3,AIR)
Block(-6,45,-7,CONCRETE:15)
Block(-6,45,-6,CONCRETE:15)
Block(-6,45,-5,CONCRETE:15)
Block(-6,45,-4,CONCRETE:15)
Block(-6,45,-3,CONCRETE:15)
Block(-6,45,-2,CONCRETE:15)
Block(-6,45,-1,CONCRETE:15)
Block(-6,45,0,CONCRETE:15)
Block(-6,45,1,CONCRETE:15)
Block(-6,45,2,CONCRETE:15)
Block(-6,45,3,CONCRETE:15)
Block(-6,45,4,CONCRETE:15)
Block(-6,45,5,CONCRETE:15)
Block(-6,45,6,CONCRETE:15)
Block(-6,45,7,CONCRETE:15)
Block(-6,45,8,CONCRETE:15)
Block(-6,46,-1,AIR)
Block(-6,46,0,AIR)
Block(-6,46,1,AIR)
Block(-6,46,2,AIR)
Block(-6,46,3,AIR)
Block(-6,49,-7,CONCRETE:15)
Block(-6,49,-6,CONCRETE:15)
Block(-6,49,-5,CONCRETE:15)
Block(-6,49,-4,CONCRETE:15)
Block(-6,49,-3,CONCRETE:15)
Block(-6,49,-2,CONCRETE:15)
Block(-6,49,-1,CONCRETE:15)
Block(-6,49,0,CONCRETE:15)
Block(-6,49,1,CONCRETE:15)
Block(-6,49,2,CONCRETE:15)
Block(-6,49,3,CONCRETE:15)
Block(-6,49,4,CONCRETE:15)
Block(-6,49,5,CONCRETE:15)
Block(-6,49,6,CONCRETE:15)
Block(-6,49,7,CONCRETE:15)
Block(-6,49,8,CONCRETE:15)
Block(-6,50,-5,AIR)
Block(-6,50,-4,AIR)
Block(-6,50,-3,DOUBLE_STEP:7)
Block(-6,50,-2,DOUBLE_STEP:7)
Block(-6,50,1,QUARTZ_STAIRS:4)
Block(-6,50,2,QUARTZ_STAIRS:4)
RandomBlock(-6,50,4,CONCRETE:7,60,quark:iron_plate,20,STAINED_CLAY:12,15,STAINED_CLAY:15,5,AIR,7,IRON_BARS,12,CONCRETE:7,100)
Block(-6,50,5,AIR)
Block(-6,51,-5,AIR)
Block(-6,51,-3,AIR)
RandomBlock(-6,51,1,AIR,75,FLOWER_POT:0,../AllScraperData/skyscraper_3x3_03/361-flower_potC16R16.nbt,100)
RandomBlock(-6,51,4,STAINED_GLASS_PANE:10,40,AIR,100)
RandomBlock(-6,52,4,CONCRETE:7,60,quark:iron_plate,20,STAINED_CLAY:12,15,STAINED_CLAY:15,5,AIR,7,IRON_BARS,12,CONCRETE:7,100)
Block(-6,53,-7,CONCRETE:15)
Block(-6,53,-6,CONCRETE:15)
Block(-6,53,-5,CONCRETE:15)
Block(-6,53,-4,CONCRETE:15)
Block(-6,53,-3,CONCRETE:15)
Block(-6,53,-2,CONCRETE:15)
Block(-6,53,-1,CONCRETE:15)
Block(-6,53,0,CONCRETE:15)
Block(-6,53,1,CONCRETE:15)
Block(-6,53,2,CONCRETE:15)
Block(-6,53,3,CONCRETE:15)
Block(-6,53,4,CONCRETE:15)
Block(-6,53,5,CONCRETE:15)
Block(-6,53,6,CONCRETE:15)
Block(-6,53,7,CONCRETE:15)
Block(-6,53,8,CONCRETE:15)
Block(-6,54,-1,AIR)
Block(-6,54,0,AIR)
Block(-6,54,1,AIR)
Block(-6,54,2,AIR)
Block(-6,54,3,AIR)
Block(-6,57,-7,CONCRETE:15)
Block(-6,57,-6,CONCRETE:15)
Block(-6,57,-5,CONCRETE:15)
Block(-6,57,-4,CONCRETE:15)
Block(-6,57,-3,CONCRETE:15)
Block(-6,57,-2,CONCRETE:15)
Block(-6,57,-1,CONCRETE:15)
Block(-6,57,0,CONCRETE:15)
Block(-6,57,1,CONCRETE:15)
Block(-6,57,2,CONCRETE:15)
Block(-6,57,3,CONCRETE:15)
Block(-6,57,4,CONCRETE:15)
Block(-6,57,5,CONCRETE:15)
Block(-6,57,6,CONCRETE:15)
Block(-6,57,7,CONCRETE:15)
Block(-6,57,8,CONCRETE:15)
Block(-6,58,-1,AIR)
Block(-6,58,0,AIR)
Block(-6,58,1,AIR)
Block(-6,58,2,AIR)
Block(-6,58,3,AIR)
Block(-6,61,-7,CONCRETE:15)
Block(-6,61,-6,CONCRETE:15)
Block(-6,61,-5,CONCRETE:15)
Block(-6,61,-4,CONCRETE:15)
Block(-6,61,-3,CONCRETE:15)
Block(-6,61,-2,CONCRETE:15)
Block(-6,61,-1,CONCRETE:15)
Block(-6,61,0,CONCRETE:15)
Block(-6,61,1,CONCRETE:15)
Block(-6,61,2,CONCRETE:15)
Block(-6,61,3,CONCRETE:15)
Block(-6,61,4,CONCRETE:15)
Block(-6,61,5,CONCRETE:15)
Block(-6,61,6,CONCRETE:15)
Block(-6,61,7,CONCRETE:15)
Block(-6,61,8,CONCRETE:15)
Block(-6,62,-1,AIR)
Block(-6,62,0,AIR)
Block(-6,62,1,AIR)
Block(-6,62,2,AIR)
Block(-6,62,3,AIR)
Block(-6,65,-7,CONCRETE:15)
Block(-6,65,-6,CONCRETE:15)
Block(-6,65,-5,CONCRETE:15)
Block(-6,65,-4,CONCRETE:15)
Block(-6,65,-3,CONCRETE:15)
Block(-6,65,-2,CONCRETE:15)
Block(-6,65,-1,CONCRETE:15)
Block(-6,65,0,CONCRETE:15)
Block(-6,65,1,CONCRETE:15)
Block(-6,65,2,CONCRETE:15)
Block(-6,65,3,CONCRETE:15)
Block(-6,65,4,CONCRETE:15)
Block(-6,65,5,CONCRETE:15)
Block(-6,65,6,CONCRETE:15)
Block(-6,65,7,CONCRETE:15)
Block(-6,65,8,CONCRETE:15)
Block(-6,66,-1,AIR)
Block(-6,66,0,AIR)
Block(-6,66,1,AIR)
Block(-6,66,2,AIR)
Block(-6,66,3,AIR)
Block(-6,69,-7,CONCRETE:15)
Block(-6,69,-6,CONCRETE:15)
Block(-6,69,-5,CONCRETE:15)
Block(-6,69,-4,CONCRETE:15)
Block(-6,69,-3,CONCRETE:15)
Block(-6,69,-2,CONCRETE:15)
Block(-6,69,-1,CONCRETE:15)
Block(-6,69,0,CONCRETE:15)
Block(-6,69,1,CONCRETE:15)
Block(-6,69,2,CONCRETE:15)
Block(-6,69,3,CONCRETE:15)
Block(-6,69,4,CONCRETE:15)
Block(-6,69,5,CONCRETE:15)
Block(-6,69,6,CONCRETE:15)
Block(-6,69,7,CONCRETE:15)
Block(-6,69,8,CONCRETE:15)
Block(-6,70,-5,AIR)
Block(-6,70,-4,AIR)
Block(-6,70,-3,DOUBLE_STEP:7)
Block(-6,70,-2,DOUBLE_STEP:7)
Block(-6,70,1,QUARTZ_STAIRS:4)
Block(-6,70,2,QUARTZ_STAIRS:4)
RandomBlock(-6,70,4,CONCRETE:7,60,quark:iron_plate,20,STAINED_CLAY:12,15,STAINED_CLAY:15,5,AIR,7,IRON_BARS,12,CONCRETE:7,100)
Block(-6,70,5,AIR)
Block(-6,71,-5,AIR)
Block(-6,71,-3,AIR)
RandomBlock(-6,71,1,AIR,75,FLOWER_POT:0,../AllScraperData/skyscraper_3x3_03/371-flower_potC16R16.nbt,100)
RandomBlock(-6,71,4,STAINED_GLASS_PANE:10,40,AIR,100)
RandomBlock(-6,72,4,CONCRETE:7,60,quark:iron_plate,20,STAINED_CLAY:12,15,STAINED_CLAY:15,5,AIR,7,IRON_BARS,12,CONCRETE:7,100)
Block(-6,73,-7,CONCRETE:15)
Block(-6,73,-6,CONCRETE:15)
Block(-6,73,-5,CONCRETE:15)
Block(-6,73,-4,CONCRETE:15)
Block(-6,73,-3,CONCRETE:15)
Block(-6,73,-2,CONCRETE:15)
Block(-6,73,-1,CONCRETE:15)
Block(-6,73,0,CONCRETE:15)
Block(-6,73,1,CONCRETE:15)
Block(-6,73,2,CONCRETE:15)
Block(-6,73,3,CONCRETE:15)
