Author: NLBlackEagle
Description: No description given
SettingsMode: WriteDisable
Frequency: 0
SpawnHeight: highestBlock
UseCenterForHighestBlock: true
MinHeight: 0
MaxHeight: 255
InheritBO3: 
InheritBO3Rotation: NORTH
OverrideChildSettings: true
OverrideParentHeight: false
CanOverride: true
BranchFrequency: 0
BranchFrequencyGroup: 
MustBeBelowOther: false
MustBeInside: 
CannotBeInside: 
ReplacesBO3: L4-M-CrossC0R0, L4-M-CrossC0R1, L4-M-CrossC0R2, L4-M-CrossC0R3, L4-M-CrossC1R0, L4-M-CrossC1R1, L4-M-CrossC1R2, L4-M-CrossC1R3, L4-M-CrossC2R0, L4-M-CrossC2R1, L4-M-CrossC2R2, L4-M-CrossC2R3, L4-M-CrossC3R0, L4-M-CrossC3R1, L4-M-CrossC3R2, L4-M-CrossC3R3, L4-M-Straigth-START_01-C0R0, L4-M-Straigth-START_01-C0R1, L4-M-Straigth-START_01-C1R0, L4-M-Straigth-START_01-C1R1, L4-M-Straigth-START_01-C2R0, L4-M-Straigth-START_01-C2R1, L4-M-Straigth-START_01-C3R0, L4-M-Straigth-START_01-C3R1, L4-M-Straigth-3CC0R0, L4-M-Straigth-3CC0R1, L4-M-Straigth-3CC0R2, L4-M-Straigth-3CC1R0, L4-M-Straigth-3CC1R1, L4-M-Straigth-3CC1R2, L4-M-Straigth-3CC2R0, L4-M-Straigth-3CC2R1, L4-M-Straigth-3CC2R2, L4-M-Straigth-3CC3R0, L4-M-Straigth-3CC3R1, L4-M-Straigth-3CC3R2, L4-M-Cross, ruinscraper_2x2_01, ruinscraper_2x2_02, ruinscraper_2x2_03, ruinscraper_2x2_04, ruinscraper_2x2_05, ruinscraper_3x3_01, ruinscraper_3x3_02, ruinscraper_3x3_03, L3-M-Straigth-2CC0R0, L3-M-Straigth-2CC0R1, L3-M-Straigth-2CC1R0, L3-M-Straigth-2CC1R1, L3-M-Straigth-2CC2R0, L3-M-Straigth-2CC2R1, L3-M-Straigth-2CC3R0, L3-M-Straigth-2CC3R1, L3-M-Straigth-3CC0R0, L3-M-Straigth-3CC0R1, L3-M-Straigth-3CC0R2, L3-M-Straigth-3CC1R0, L3-M-Straigth-3CC1R1, L3-M-Straigth-3CC1R2, L3-M-Straigth-3CC2R0, L3-M-Straigth-3CC2R1, L3-M-Straigth-3CC2R2, L3-M-Straigth-3CC3R0, L3-M-Straigth-3CC3R1, L3-M-Straigth-3CC3R2L4-M-CrossC0R0, L4-M-CrossC0R1, L4-M-CrossC0R2, L4-M-CrossC0R3, L4-M-CrossC1R0, L4-M-CrossC1R1, L4-M-CrossC1R2, L4-M-CrossC1R3, L4-M-CrossC2R0, L4-M-CrossC2R1, L4-M-CrossC2R2, L4-M-CrossC2R3, L4-M-CrossC3R0, L4-M-CrossC3R1, L4-M-CrossC3R2, L4-M-CrossC3R3, L4-M-Straigth-START_01-C0R0, L4-M-Straigth-START_01-C0R1, L4-M-Straigth-START_01-C1R0, L4-M-Straigth-START_01-C1R1, L4-M-Straigth-START_01-C2R0, L4-M-Straigth-START_01-C2R1, L4-M-Straigth-START_01-C3R0, L4-M-Straigth-START_01-C3R1, L4-M-Straigth-3CC0R0, L4-M-Straigth-3CC0R1, L4-M-Straigth-3CC0R2, L4-M-Straigth-3CC1R0, L4-M-Straigth-3CC1R1, L4-M-Straigth-3CC1R2, L4-M-Straigth-3CC2R0, L4-M-Straigth-3CC2R1, L4-M-Straigth-3CC2R2, L4-M-Straigth-3CC3R0, L4-M-Straigth-3CC3R1, L4-M-Straigth-3CC3R2, L4-M-Cross, ruinscraper_2x2_01, ruinscraper_2x2_02, ruinscraper_2x2_03, ruinscraper_2x2_04, ruinscraper_2x2_05, ruinscraper_3x3_01, ruinscraper_3x3_02, ruinscraper_3x3_03
MustBeInsideWorldBorders: false
CanSpawnOnWater: true
SpawnOnWaterOnly: false
SpawnUnderWater: false
SpawnAtWaterLevel: false
HeightOffset: 0
RemoveAir: false
ReplaceAbove: 
ReplaceBelow: 
ReplaceWithBiomeBlocks: false
ReplaceWithSurfaceBlock: GRASS
ReplaceWithGroundBlock: DIRT
ReplaceWithStoneBlock: eaglemixins:deepslate
SmoothRadius: 0
SmoothHeightOffset: 0
SmoothStartTop: false
SmoothStartWood: false
SmoothingSurfaceBlock: 
SmoothingGroundBlock: 
BO3Group: 
IsSpawnPoint: false
DoReplaceBlocks: false
RandomBlock(-8,0,-7,CONCRETE:7,60,quark:iron_plate,20,STAINED_CLAY:12,15,STAINED_CLAY:15,5,AIR,7,IRON_BARS,12,CONCRETE:7,100)
RandomBlock(-8,0,-6,CONCRETE:7,60,quark:iron_plate,20,STAINED_CLAY:12,15,STAINED_CLAY:15,5,AIR,7,IRON_BARS,12,CONCRETE:7,100)
RandomBlock(-8,0,-5,CONCRETE:7,60,quark:iron_plate,20,STAINED_CLAY:12,15,STAINED_CLAY:15,5,AIR,7,IRON_BARS,12,CONCRETE:7,100)
RandomBlock(-8,0,-4,CONCRETE:7,60,quark:iron_plate,20,STAINED_CLAY:12,15,STAINED_CLAY:15,5,AIR,7,IRON_BARS,12,CONCRETE:7,100)
RandomBlock(-8,0,-3,CONCRETE:7,60,quark:iron_plate,20,STAINED_CLAY:12,15,STAINED_CLAY:15,5,AIR,7,IRON_BARS,12,CONCRETE:7,100)
RandomBlock(-8,0,-2,CONCRETE:7,60,quark:iron_plate,20,STAINED_CLAY:12,15,STAINED_CLAY:15,5,AIR,7,IRON_BARS,12,CONCRETE:7,100)
RandomBlock(-8,0,-1,CONCRETE:7,60,quark:iron_plate,20,STAINED_CLAY:12,15,STAINED_CLAY:15,5,AIR,7,IRON_BARS,12,CONCRETE:7,100)
RandomBlock(-8,0,0,CONCRETE:7,60,quark:iron_plate,20,STAINED_CLAY:12,15,STAINED_CLAY:15,5,AIR,7,IRON_BARS,12,CONCRETE:7,100)
RandomBlock(-8,0,1,CONCRETE:7,60,quark:iron_plate,20,STAINED_CLAY:12,15,STAINED_CLAY:15,5,AIR,7,IRON_BARS,12,CONCRETE:7,100)
RandomBlock(-8,0,2,CONCRETE:7,60,quark:iron_plate,20,STAINED_CLAY:12,15,STAINED_CLAY:15,5,AIR,7,IRON_BARS,12,CONCRETE:7,100)
RandomBlock(-8,0,3,CONCRETE:7,60,quark:iron_plate,20,STAINED_CLAY:12,15,STAINED_CLAY:15,5,AIR,7,IRON_BARS,12,CONCRETE:7,100)
RandomBlock(-8,0,4,CONCRETE:7,60,quark:iron_plate,20,STAINED_CLAY:12,15,STAINED_CLAY:15,5,AIR,7,IRON_BARS,12,CONCRETE:7,100)
RandomBlock(-8,0,5,CONCRETE:7,60,quark:iron_plate,20,STAINED_CLAY:12,15,STAINED_CLAY:15,5,AIR,7,IRON_BARS,12,CONCRETE:7,100)
RandomBlock(-8,0,6,CONCRETE:7,60,quark:iron_plate,20,STAINED_CLAY:12,15,STAINED_CLAY:15,5,AIR,7,IRON_BARS,12,CONCRETE:7,100)
RandomBlock(-8,0,7,CONCRETE:7,60,quark:iron_plate,20,STAINED_CLAY:12,15,STAINED_CLAY:15,5,AIR,7,IRON_BARS,12,CONCRETE:7,100)
RandomBlock(-8,0,8,CONCRETE:7,60,quark:iron_plate,20,STAINED_CLAY:12,15,STAINED_CLAY:15,5,AIR,7,IRON_BARS,12,CONCRETE:7,100)
Block(-8,1,-7,OBSIDIAN:0)
Block(-8,1,-6,OBSIDIAN:0)
Block(-8,1,-5,OBSIDIAN:0)
Block(-8,1,-4,OBSIDIAN:0)
Block(-8,1,-3,OBSIDIAN:0)
Block(-8,1,-2,OBSIDIAN:0)
Block(-8,1,-1,OBSIDIAN:0)
Block(-8,1,0,OBSIDIAN:0)
Block(-8,1,1,OBSIDIAN:0)
Block(-8,1,2,OBSIDIAN:0)
Block(-8,1,3,OBSIDIAN:0)
Block(-8,1,4,OBSIDIAN:0)
Block(-8,1,5,OBSIDIAN:0)
Block(-8,1,6,OBSIDIAN:0)
Block(-8,1,7,OBSIDIAN:0)
Block(-8,1,8,OBSIDIAN:0)
RandomBlock(-8,2,-7,CONCRETE:7,60,quark:iron_plate,20,STAINED_CLAY:12,15,STAINED_CLAY:15,5,AIR,7,IRON_BARS,12,CONCRETE:7,100)
RandomBlock(-8,2,-6,CONCRETE:7,60,quark:iron_plate,20,STAINED_CLAY:12,15,STAINED_CLAY:15,5,AIR,7,IRON_BARS,12,CONCRETE:7,100)
RandomBlock(-8,2,-5,CONCRETE:7,60,quark:iron_plate,20,STAINED_CLAY:12,15,STAINED_CLAY:15,5,AIR,7,IRON_BARS,12,CONCRETE:7,100)
RandomBlock(-8,2,-4,CONCRETE:7,60,quark:iron_plate,20,STAINED_CLAY:12,15,STAINED_CLAY:15,5,AIR,7,IRON_BARS,12,CONCRETE:7,100)
RandomBlock(-8,2,-3,CONCRETE:7,60,quark:iron_plate,20,STAINED_CLAY:12,15,STAINED_CLAY:15,5,AIR,7,IRON_BARS,12,CONCRETE:7,100)
RandomBlock(-8,2,-2,CONCRETE:7,60,quark:iron_plate,20,STAINED_CLAY:12,15,STAINED_CLAY:15,5,AIR,7,IRON_BARS,12,CONCRETE:7,100)
RandomBlock(-8,2,-1,CONCRETE:7,60,quark:iron_plate,20,STAINED_CLAY:12,15,STAINED_CLAY:15,5,AIR,7,IRON_BARS,12,CONCRETE:7,100)
RandomBlock(-8,2,0,CONCRETE:7,60,quark:iron_plate,20,STAINED_CLAY:12,15,STAINED_CLAY:15,5,AIR,7,IRON_BARS,12,CONCRETE:7,100)
RandomBlock(-8,2,1,CONCRETE:7,60,quark:iron_plate,20,STAINED_CLAY:12,15,STAINED_CLAY:15,5,AIR,7,IRON_BARS,12,CONCRETE:7,100)
RandomBlock(-8,2,2,CONCRETE:7,60,quark:iron_plate,20,STAINED_CLAY:12,15,STAINED_CLAY:15,5,AIR,7,IRON_BARS,12,CONCRETE:7,100)
RandomBlock(-8,2,3,CONCRETE:7,60,quark:iron_plate,20,STAINED_CLAY:12,15,STAINED_CLAY:15,5,AIR,7,IRON_BARS,12,CONCRETE:7,100)
RandomBlock(-8,2,4,CONCRETE:7,60,quark:iron_plate,20,STAINED_CLAY:12,15,STAINED_CLAY:15,5,AIR,7,IRON_BARS,12,CONCRETE:7,100)
RandomBlock(-8,2,5,CONCRETE:7,60,quark:iron_plate,20,STAINED_CLAY:12,15,STAINED_CLAY:15,5,AIR,7,IRON_BARS,12,CONCRETE:7,100)
RandomBlock(-8,2,6,CONCRETE:7,60,quark:iron_plate,20,STAINED_CLAY:12,15,STAINED_CLAY:15,5,AIR,7,IRON_BARS,12,CONCRETE:7,100)
RandomBlock(-8,2,7,CONCRETE:7,60,quark:iron_plate,20,STAINED_CLAY:12,15,STAINED_CLAY:15,5,AIR,7,IRON_BARS,12,CONCRETE:7,100)
RandomBlock(-8,2,8,CONCRETE:7,60,quark:iron_plate,20,STAINED_CLAY:12,15,STAINED_CLAY:15,5,AIR,7,IRON_BARS,12,CONCRETE:7,100)
RandomBlock(-8,3,-7,CONCRETE:7,60,quark:iron_plate,20,STAINED_CLAY:12,15,STAINED_CLAY:15,5,AIR,7,IRON_BARS,12,CONCRETE:7,100)
RandomBlock(-8,3,-6,CONCRETE:7,60,quark:iron_plate,20,STAINED_CLAY:12,15,STAINED_CLAY:15,5,AIR,7,IRON_BARS,12,CONCRETE:7,100)
RandomBlock(-8,3,-5,CONCRETE:7,60,quark:iron_plate,20,STAINED_CLAY:12,15,STAINED_CLAY:15,5,AIR,7,IRON_BARS,12,CONCRETE:7,100)
RandomBlock(-8,3,-4,CONCRETE:7,60,quark:iron_plate,20,STAINED_CLAY:12,15,STAINED_CLAY:15,5,AIR,7,IRON_BARS,12,CONCRETE:7,100)
RandomBlock(-8,3,-3,CONCRETE:7,60,quark:iron_plate,20,STAINED_CLAY:12,15,STAINED_CLAY:15,5,AIR,7,IRON_BARS,12,CONCRETE:7,100)
RandomBlock(-8,3,-2,CONCRETE:7,60,quark:iron_plate,20,STAINED_CLAY:12,15,STAINED_CLAY:15,5,AIR,7,IRON_BARS,12,CONCRETE:7,100)
RandomBlock(-8,3,-1,CONCRETE:7,60,quark:iron_plate,20,STAINED_CLAY:12,15,STAINED_CLAY:15,5,AIR,7,IRON_BARS,12,CONCRETE:7,100)
RandomBlock(-8,3,0,CONCRETE:7,60,quark:iron_plate,20,STAINED_CLAY:12,15,STAINED_CLAY:15,5,AIR,7,IRON_BARS,12,CONCRETE:7,100)
RandomBlock(-8,3,1,CONCRETE:7,60,quark:iron_plate,20,STAINED_CLAY:12,15,STAINED_CLAY:15,5,AIR,7,IRON_BARS,12,CONCRETE:7,100)
RandomBlock(-8,3,2,CONCRETE:7,60,quark:iron_plate,20,STAINED_CLAY:12,15,STAINED_CLAY:15,5,AIR,7,IRON_BARS,12,CONCRETE:7,100)
RandomBlock(-8,3,3,CONCRETE:7,60,quark:iron_plate,20,STAINED_CLAY:12,15,STAINED_CLAY:15,5,AIR,7,IRON_BARS,12,CONCRETE:7,100)
RandomBlock(-8,3,4,CONCRETE:7,60,quark:iron_plate,20,STAINED_CLAY:12,15,STAINED_CLAY:15,5,AIR,7,IRON_BARS,12,CONCRETE:7,100)
RandomBlock(-8,3,5,CONCRETE:7,60,quark:iron_plate,20,STAINED_CLAY:12,15,STAINED_CLAY:15,5,AIR,7,IRON_BARS,12,CONCRETE:7,100)
RandomBlock(-8,3,6,CONCRETE:7,60,quark:iron_plate,20,STAINED_CLAY:12,15,STAINED_CLAY:15,5,AIR,7,IRON_BARS,12,CONCRETE:7,100)
RandomBlock(-8,3,7,CONCRETE:7,60,quark:iron_plate,20,STAINED_CLAY:12,15,STAINED_CLAY:15,5,AIR,7,IRON_BARS,12,CONCRETE:7,100)
RandomBlock(-8,3,8,CONCRETE:7,60,quark:iron_plate,20,STAINED_CLAY:12,15,STAINED_CLAY:15,5,AIR,7,IRON_BARS,12,CONCRETE:7,100)
RandomBlock(-8,4,-7,CONCRETE:7,60,quark:iron_plate,20,STAINED_CLAY:12,15,STAINED_CLAY:15,5,AIR,7,IRON_BARS,12,CONCRETE:7,100)
RandomBlock(-8,4,-6,CONCRETE:7,60,quark:iron_plate,20,STAINED_CLAY:12,15,STAINED_CLAY:15,5,AIR,7,IRON_BARS,12,CONCRETE:7,100)
RandomBlock(-8,4,-5,CONCRETE:7,60,quark:iron_plate,20,STAINED_CLAY:12,15,STAINED_CLAY:15,5,AIR,7,IRON_BARS,12,CONCRETE:7,100)
RandomBlock(-8,4,-4,CONCRETE:7,60,quark:iron_plate,20,STAINED_CLAY:12,15,STAINED_CLAY:15,5,AIR,7,IRON_BARS,12,CONCRETE:7,100)
RandomBlock(-8,4,-3,CONCRETE:7,60,quark:iron_plate,20,STAINED_CLAY:12,15,STAINED_CLAY:15,5,AIR,7,IRON_BARS,12,CONCRETE:7,100)
RandomBlock(-8,4,-2,CONCRETE:7,60,quark:iron_plate,20,STAINED_CLAY:12,15,STAINED_CLAY:15,5,AIR,7,IRON_BARS,12,CONCRETE:7,100)
RandomBlock(-8,4,-1,CONCRETE:7,60,quark:iron_plate,20,STAINED_CLAY:12,15,STAINED_CLAY:15,5,AIR,7,IRON_BARS,12,CONCRETE:7,100)
RandomBlock(-8,4,0,CONCRETE:7,60,quark:iron_plate,20,STAINED_CLAY:12,15,STAINED_CLAY:15,5,AIR,7,IRON_BARS,12,CONCRETE:7,100)
RandomBlock(-8,4,1,CONCRETE:7,60,quark:iron_plate,20,STAINED_CLAY:12,15,STAINED_CLAY:15,5,AIR,7,IRON_BARS,12,CONCRETE:7,100)
RandomBlock(-8,4,2,CONCRETE:7,60,quark:iron_plate,20,STAINED_CLAY:12,15,STAINED_CLAY:15,5,AIR,7,IRON_BARS,12,CONCRETE:7,100)
RandomBlock(-8,4,3,CONCRETE:7,60,quark:iron_plate,20,STAINED_CLAY:12,15,STAINED_CLAY:15,5,AIR,7,IRON_BARS,12,CONCRETE:7,100)
RandomBlock(-8,4,4,CONCRETE:7,60,quark:iron_plate,20,STAINED_CLAY:12,15,STAINED_CLAY:15,5,AIR,7,IRON_BARS,12,CONCRETE:7,100)
RandomBlock(-8,4,5,CONCRETE:7,60,quark:iron_plate,20,STAINED_CLAY:12,15,STAINED_CLAY:15,5,AIR,7,IRON_BARS,12,CONCRETE:7,100)
RandomBlock(-8,4,6,CONCRETE:7,60,quark:iron_plate,20,STAINED_CLAY:12,15,STAINED_CLAY:15,5,AIR,7,IRON_BARS,12,CONCRETE:7,100)
RandomBlock(-8,4,7,CONCRETE:7,60,quark:iron_plate,20,STAINED_CLAY:12,15,STAINED_CLAY:15,5,AIR,7,IRON_BARS,12,CONCRETE:7,100)
RandomBlock(-8,4,8,CONCRETE:7,60,quark:iron_plate,20,STAINED_CLAY:12,15,STAINED_CLAY:15,5,AIR,7,IRON_BARS,12,CONCRETE:7,100)
Block(-8,5,-7,AIR:0)
Block(-8,5,-6,AIR:0)
Block(-8,5,-5,AIR:0)
Block(-8,5,-4,AIR:0)
Block(-8,5,-3,AIR:0)
Block(-8,5,-2,OBSIDIAN:0)
Block(-8,5,-1,IRON_FENCE:0)
Block(-8,5,0,AIR:0)
Block(-8,5,1,AIR:0)
Block(-8,5,2,AIR:0)
Block(-8,5,3,AIR:0)
Block(-8,5,4,AIR:0)
Block(-8,5,5,IRON_FENCE:0)
Block(-8,5,6,OBSIDIAN:0)
RandomBlock(-8,5,7,AIR,90,IRON_TRAPDOOR:9,100)
Block(-8,5,8,AIR:0)
Block(-8,6,-7,AIR:0)
Block(-8,6,-6,AIR:0)
Block(-8,6,-5,AIR:0)
Block(-8,6,-4,AIR:0)
Block(-8,6,-3,AIR:0)
Block(-8,6,-2,OBSIDIAN:0)
Block(-8,6,-1,IRON_FENCE:0)
Block(-8,6,0,AIR:0)
Block(-8,6,1,AIR:0)
Block(-8,6,2,AIR:0)
Block(-8,6,3,AIR:0)
Block(-8,6,4,AIR:0)
Block(-8,6,5,IRON_FENCE:0)
Block(-8,6,6,OBSIDIAN:0)
Block(-8,6,8,AIR:0)
Block(-8,7,-7,AIR:0)
Block(-8,7,-6,AIR:0)
Block(-8,7,-5,AIR:0)
Block(-8,7,-4,AIR:0)
Block(-8,7,-3,AIR:0)
Block(-8,7,-2,OBSIDIAN:0)
Block(-8,7,-1,IRON_FENCE:0)
Block(-8,7,0,AIR:0)
Block(-8,7,1,AIR:0)
Block(-8,7,2,AIR:0)
Block(-8,7,3,AIR:0)
Block(-8,7,4,AIR:0)
Block(-8,7,5,IRON_FENCE:0)
Block(-8,7,6,OBSIDIAN:0)
RandomBlock(-8,7,7,AIR,90,IRON_TRAPDOOR:1,100)
Block(-8,7,8,AIR:0)
RandomBlock(-8,8,-7,AIR,90,IRON_TRAPDOOR:10,100)
RandomBlock(-8,8,-6,AIR,90,IRON_TRAPDOOR:10,100)
RandomBlock(-8,8,-5,CONCRETE:7,60,quark:iron_plate,20,STAINED_CLAY:12,15,STAINED_CLAY:15,5,AIR,7,IRON_BARS,12,CONCRETE:7,100)
RandomBlock(-8,8,-4,AIR,90,IRON_TRAPDOOR:10,100)
RandomBlock(-8,8,-3,AIR,90,IRON_TRAPDOOR:10,100)
RandomBlock(-8,8,-2,CONCRETE:7,60,quark:iron_plate,20,STAINED_CLAY:12,15,STAINED_CLAY:15,5,AIR,7,IRON_BARS,12,CONCRETE:7,100)
RandomBlock(-8,8,-1,CONCRETE:7,60,quark:iron_plate,20,STAINED_CLAY:12,15,STAINED_CLAY:15,5,AIR,7,IRON_BARS,12,CONCRETE:7,100)
RandomBlock(-8,8,0,AIR,90,IRON_TRAPDOOR:9,100)
Block(-8,8,1,AIR:0)
Block(-8,8,2,AIR:0)
Block(-8,8,3,AIR:0)
Block(-8,8,4,AIR:0)
RandomBlock(-8,8,5,CONCRETE:7,60,quark:iron_plate,20,STAINED_CLAY:12,15,STAINED_CLAY:15,5,AIR,7,IRON_BARS,12,CONCRETE:7,100)
RandomBlock(-8,8,6,CONCRETE:7,60,quark:iron_plate,20,STAINED_CLAY:12,15,STAINED_CLAY:15,5,AIR,7,IRON_BARS,12,CONCRETE:7,100)
RandomBlock(-8,8,7,AIR,90,IRON_TRAPDOOR:1,100)
Block(-8,8,8,AIR:0)
Block(-8,9,-7,AIR:0)
Block(-8,9,-6,AIR:0)
Block(-8,9,-5,AIR:0)
Block(-8,9,-4,AIR:0)
Block(-8,9,-3,AIR:0)
Block(-8,9,-2,OBSIDIAN:0)
Block(-8,9,-1,IRON_FENCE:0)
Block(-8,9,0,CONCRETE:14)
Block(-8,9,1,AIR:0)
Block(-8,9,2,AIR:0)
Block(-8,9,3,AIR:0)
Block(-8,9,4,AIR:0)
Block(-8,9,5,IRON_FENCE:0)
Block(-8,9,6,OBSIDIAN:0)
Block(-8,9,7,AIR:0)
Block(-8,9,8,AIR:0)
Block(-8,10,-7,AIR:0)
Block(-8,10,-6,AIR:0)
Block(-8,10,-5,AIR:0)
Block(-8,10,-4,AIR:0)
Block(-8,10,-3,AIR:0)
Block(-8,10,-2,OBSIDIAN:0)
Block(-8,10,-1,IRON_FENCE:0)
RandomBlock(-8,10,0,AIR,90,IRON_TRAPDOOR:10,100)
Block(-8,10,1,AIR:0)
Block(-8,10,2,AIR:0)
Block(-8,10,3,AIR:0)
Block(-8,10,4,AIR:0)
Block(-8,10,5,IRON_FENCE:0)
Block(-8,10,6,OBSIDIAN:0)
Block(-8,10,7,AIR:0)
Block(-8,10,8,AIR:0)
Block(-8,11,-7,AIR:0)
Block(-8,11,-6,AIR:0)
Block(-8,11,-5,AIR:0)
Block(-8,11,-4,AIR:0)
Block(-8,11,-3,AIR:0)
Block(-8,11,-2,OBSIDIAN:0)
Block(-8,11,-1,IRON_FENCE:0)
Block(-8,11,0,CONCRETE:4)
Block(-8,11,1,AIR:0)
Block(-8,11,2,STEP:13)
Block(-8,11,3,AIR:0)
Block(-8,11,4,AIR:0)
Block(-8,11,5,IRON_FENCE:0)
Block(-8,11,6,OBSIDIAN:0)
Block(-8,11,7,AIR:0)
Block(-8,11,8,AIR:0)
RandomBlock(-8,12,-7,AIR,90,IRON_TRAPDOOR:9,100)
RandomBlock(-8,12,-6,AIR,90,IRON_TRAPDOOR:8,100)
RandomBlock(-8,12,-5,CONCRETE:7,60,quark:iron_plate,20,STAINED_CLAY:12,15,STAINED_CLAY:15,5,AIR,7,IRON_BARS,12,CONCRETE:7,100)
RandomBlock(-8,12,-4,AIR,90,IRON_TRAPDOOR:9,100)
RandomBlock(-8,12,-3,AIR,90,IRON_TRAPDOOR:8,100)
RandomBlock(-8,12,-2,CONCRETE:7,60,quark:iron_plate,20,STAINED_CLAY:12,15,STAINED_CLAY:15,5,AIR,7,IRON_BARS,12,CONCRETE:7,100)
RandomBlock(-8,12,-1,CONCRETE:7,60,quark:iron_plate,20,STAINED_CLAY:12,15,STAINED_CLAY:15,5,AIR,7,IRON_BARS,12,CONCRETE:7,100)
Block(-8,12,0,STEP:8)
Block(-8,12,1,STEP:8)
Block(-8,12,2,STEP:8)
Block(-8,12,3,STEP:8)
Block(-8,12,4,STEP:8)
RandomBlock(-8,12,5,CONCRETE:7,60,quark:iron_plate,20,STAINED_CLAY:12,15,STAINED_CLAY:15,5,AIR,7,IRON_BARS,12,CONCRETE:7,100)
RandomBlock(-8,12,6,CONCRETE:7,60,quark:iron_plate,20,STAINED_CLAY:12,15,STAINED_CLAY:15,5,AIR,7,IRON_BARS,12,CONCRETE:7,100)
RandomBlock(-8,12,7,AIR,90,IRON_TRAPDOOR:9,100)
RandomBlock(-8,12,8,AIR,90,IRON_TRAPDOOR:8,100)
Block(-8,13,-7,AIR:0)
Block(-8,13,-6,AIR:0)
Block(-8,13,-5,AIR:0)
Block(-8,13,-4,AIR:0)
Block(-8,13,-3,AIR:0)
Block(-8,13,-2,OBSIDIAN:0)
Block(-8,13,-1,IRON_FENCE:0)
Block(-8,13,0,CONCRETE:4)
Block(-8,13,1,CONCRETE:14)
Block(-8,13,2,AIR:0)
Block(-8,13,3,AIR:0)
Block(-8,13,4,AIR:0)
Block(-8,13,5,IRON_FENCE:0)
Block(-8,13,6,CONCRETE:12)
Block(-8,13,7,AIR:0)
Block(-8,13,8,AIR:0)
Block(-8,14,-7,STEP:8)
Block(-8,14,-6,STEP:8)
RandomBlock(-8,14,-5,CONCRETE:7,60,quark:iron_plate,20,STAINED_CLAY:12,15,STAINED_CLAY:15,5,AIR,7,IRON_BARS,12,CONCRETE:7,100)
Block(-8,14,-4,STEP:8)
Block(-8,14,-3,STEP:8)
Block(-8,14,-2,OBSIDIAN:0)
Block(-8,14,-1,IRON_FENCE:0)
Block(-8,14,0,CONCRETE:14)
Block(-8,14,1,CONCRETE:4)
Block(-8,14,2,AIR:0)
Block(-8,14,3,AIR:0)
Block(-8,14,4,AIR:0)
Block(-8,14,5,IRON_FENCE:0)
Block(-8,14,6,OBSIDIAN:0)
Block(-8,14,7,STEP:8)
Block(-8,14,8,STEP:8)
RandomBlock(-8,15,-7,CONCRETE:7,60,quark:iron_plate,20,STAINED_CLAY:12,15,STAINED_CLAY:15,5,AIR,7,IRON_BARS,12,CONCRETE:7,100)
RandomBlock(-8,15,-6,CONCRETE:7,60,quark:iron_plate,20,STAINED_CLAY:12,15,STAINED_CLAY:15,5,AIR,7,IRON_BARS,12,CONCRETE:7,100)
RandomBlock(-8,15,-5,CONCRETE:7,60,quark:iron_plate,20,STAINED_CLAY:12,15,STAINED_CLAY:15,5,AIR,7,IRON_BARS,12,CONCRETE:7,100)
RandomBlock(-8,15,-4,CONCRETE:7,60,quark:iron_plate,20,STAINED_CLAY:12,15,STAINED_CLAY:15,5,AIR,7,IRON_BARS,12,CONCRETE:7,100)
RandomBlock(-8,15,-3,CONCRETE:7,60,quark:iron_plate,20,STAINED_CLAY:12,15,STAINED_CLAY:15,5,AIR,7,IRON_BARS,12,CONCRETE:7,100)
RandomBlock(-8,15,-2,CONCRETE:7,60,quark:iron_plate,20,STAINED_CLAY:12,15,STAINED_CLAY:15,5,AIR,7,IRON_BARS,12,CONCRETE:7,100)
RandomBlock(-8,15,-1,CONCRETE:7,60,quark:iron_plate,20,STAINED_CLAY:12,15,STAINED_CLAY:15,5,AIR,7,IRON_BARS,12,CONCRETE:7,100)
RandomBlock(-8,15,0,CONCRETE:7,60,quark:iron_plate,20,STAINED_CLAY:12,15,STAINED_CLAY:15,5,AIR,7,IRON_BARS,12,CONCRETE:7,100)
RandomBlock(-8,15,1,CONCRETE:7,60,quark:iron_plate,20,STAINED_CLAY:12,15,STAINED_CLAY:15,5,AIR,7,IRON_BARS,12,CONCRETE:7,100)
RandomBlock(-8,15,2,CONCRETE:7,60,quark:iron_plate,20,STAINED_CLAY:12,15,STAINED_CLAY:15,5,AIR,7,IRON_BARS,12,CONCRETE:7,100)
RandomBlock(-8,15,3,CONCRETE:7,60,quark:iron_plate,20,STAINED_CLAY:12,15,STAINED_CLAY:15,5,AIR,7,IRON_BARS,12,CONCRETE:7,100)
RandomBlock(-8,15,4,CONCRETE:7,60,quark:iron_plate,20,STAINED_CLAY:12,15,STAINED_CLAY:15,5,AIR,7,IRON_BARS,12,CONCRETE:7,100)
RandomBlock(-8,15,5,CONCRETE:7,60,quark:iron_plate,20,STAINED_CLAY:12,15,STAINED_CLAY:15,5,AIR,7,IRON_BARS,12,CONCRETE:7,100)
RandomBlock(-8,15,6,CONCRETE:7,60,quark:iron_plate,20,STAINED_CLAY:12,15,STAINED_CLAY:15,5,AIR,7,IRON_BARS,12,CONCRETE:7,100)
RandomBlock(-8,15,7,CONCRETE:7,60,quark:iron_plate,20,STAINED_CLAY:12,15,STAINED_CLAY:15,5,AIR,7,IRON_BARS,12,CONCRETE:7,100)
RandomBlock(-8,15,8,CONCRETE:7,60,quark:iron_plate,20,STAINED_CLAY:12,15,STAINED_CLAY:15,5,AIR,7,IRON_BARS,12,CONCRETE:7,100)
Block(-8,16,-7,OBSIDIAN:0)
Block(-8,16,-6,OBSIDIAN:0)
Block(-8,16,-5,OBSIDIAN:0)
Block(-8,16,-4,OBSIDIAN:0)
Block(-8,16,-3,OBSIDIAN:0)
Block(-8,16,-2,OBSIDIAN:0)
Block(-8,16,-1,OBSIDIAN:0)
Block(-8,16,0,OBSIDIAN:0)
Block(-8,16,1,OBSIDIAN:0)
Block(-8,16,2,OBSIDIAN:0)
Block(-8,16,3,OBSIDIAN:0)
Block(-8,16,4,OBSIDIAN:0)
Block(-8,16,5,OBSIDIAN:0)
Block(-8,16,6,OBSIDIAN:0)
Block(-8,16,7,OBSIDIAN:0)
Block(-8,16,8,OBSIDIAN:0)
RandomBlock(-8,17,-7,CONCRETE:7,60,quark:iron_plate,20,STAINED_CLAY:12,15,STAINED_CLAY:15,5,AIR,7,IRON_BARS,12,CONCRETE:7,100)
RandomBlock(-8,17,-6,CONCRETE:7,60,quark:iron_plate,20,STAINED_CLAY:12,15,STAINED_CLAY:15,5,AIR,7,IRON_BARS,12,CONCRETE:7,100)
RandomBlock(-8,17,-5,CONCRETE:7,60,quark:iron_plate,20,STAINED_CLAY:12,15,STAINED_CLAY:15,5,AIR,7,IRON_BARS,12,CONCRETE:7,100)
RandomBlock(-8,17,-4,CONCRETE:7,60,quark:iron_plate,20,STAINED_CLAY:12,15,STAINED_CLAY:15,5,AIR,7,IRON_BARS,12,CONCRETE:7,100)
RandomBlock(-8,17,-3,CONCRETE:7,60,quark:iron_plate,20,STAINED_CLAY:12,15,STAINED_CLAY:15,5,AIR,7,IRON_BARS,12,CONCRETE:7,100)
RandomBlock(-8,17,-2,CONCRETE:7,60,quark:iron_plate,20,STAINED_CLAY:12,15,STAINED_CLAY:15,5,AIR,7,IRON_BARS,12,CONCRETE:7,100)
RandomBlock(-8,17,-1,CONCRETE:7,60,quark:iron_plate,20,STAINED_CLAY:12,15,STAINED_CLAY:15,5,AIR,7,IRON_BARS,12,CONCRETE:7,100)
RandomBlock(-8,17,0,CONCRETE:7,60,quark:iron_plate,20,STAINED_CLAY:12,15,STAINED_CLAY:15,5,AIR,7,IRON_BARS,12,CONCRETE:7,100)
RandomBlock(-8,17,1,CONCRETE:7,60,quark:iron_plate,20,STAINED_CLAY:12,15,STAINED_CLAY:15,5,AIR,7,IRON_BARS,12,CONCRETE:7,100)
RandomBlock(-8,17,2,CONCRETE:7,60,quark:iron_plate,20,STAINED_CLAY:12,15,STAINED_CLAY:15,5,AIR,7,IRON_BARS,12,CONCRETE:7,100)
RandomBlock(-8,17,3,CONCRETE:7,60,quark:iron_plate,20,STAINED_CLAY:12,15,STAINED_CLAY:15,5,AIR,7,IRON_BARS,12,CONCRETE:7,100)
RandomBlock(-8,17,4,CONCRETE:7,60,quark:iron_plate,20,STAINED_CLAY:12,15,STAINED_CLAY:15,5,AIR,7,IRON_BARS,12,CONCRETE:7,100)
RandomBlock(-8,17,5,CONCRETE:7,60,quark:iron_plate,20,STAINED_CLAY:12,15,STAINED_CLAY:15,5,AIR,7,IRON_BARS,12,CONCRETE:7,100)
RandomBlock(-8,17,6,CONCRETE:7,60,quark:iron_plate,20,STAINED_CLAY:12,15,STAINED_CLAY:15,5,AIR,7,IRON_BARS,12,CONCRETE:7,100)
RandomBlock(-8,17,7,CONCRETE:7,60,quark:iron_plate,20,STAINED_CLAY:12,15,STAINED_CLAY:15,5,AIR,7,IRON_BARS,12,CONCRETE:7,100)
RandomBlock(-8,17,8,CONCRETE:7,60,quark:iron_plate,20,STAINED_CLAY:12,15,STAINED_CLAY:15,5,AIR,7,IRON_BARS,12,CONCRETE:7,100)
Block(-8,18,-7,OBSIDIAN:0)
Block(-8,18,-6,OBSIDIAN:0)
Block(-8,18,-5,OBSIDIAN:0)
Block(-8,18,-4,OBSIDIAN:0)
Block(-8,18,-3,OBSIDIAN:0)
Block(-8,18,-2,OBSIDIAN:0)
Block(-8,18,-1,OBSIDIAN:0)
Block(-8,18,0,OBSIDIAN:0)
Block(-8,18,1,OBSIDIAN:0)
Block(-8,18,2,OBSIDIAN:0)
Block(-8,18,3,OBSIDIAN:0)
Block(-8,18,4,OBSIDIAN:0)
Block(-8,18,5,OBSIDIAN:0)
Block(-8,18,6,OBSIDIAN:0)
Block(-8,18,7,OBSIDIAN:0)
Block(-8,18,8,CONCRETE:0)
Block(-8,19,-7,OBSIDIAN:0)
Block(-8,19,-6,OBSIDIAN:0)
Block(-8,19,-5,OBSIDIAN:0)
Block(-8,19,-4,OBSIDIAN:0)
Block(-8,19,-3,OBSIDIAN:0)
Block(-8,19,-2,OBSIDIAN:0)
Block(-8,19,-1,OBSIDIAN:0)
Block(-8,19,0,OBSIDIAN:0)
Block(-8,19,1,OBSIDIAN:0)
Block(-8,19,2,OBSIDIAN:0)
Block(-8,19,3,OBSIDIAN:0)
Block(-8,19,4,OBSIDIAN:0)
Block(-8,19,5,OBSIDIAN:0)
Block(-8,19,6,OBSIDIAN:0)
Block(-8,19,7,OBSIDIAN:0)
Block(-8,19,8,CONCRETE:0)
Block(-8,20,-7,OBSIDIAN:0)
Block(-8,20,-6,OBSIDIAN:0)
Block(-8,20,-5,OBSIDIAN:0)
Block(-8,20,-4,OBSIDIAN:0)
Block(-8,20,-3,OBSIDIAN:0)
Block(-8,20,-2,OBSIDIAN:0)
Block(-8,20,-1,OBSIDIAN:0)
Block(-8,20,0,OBSIDIAN:0)
Block(-8,20,1,OBSIDIAN:0)
Block(-8,20,2,OBSIDIAN:0)
Block(-8,20,3,OBSIDIAN:0)
Block(-8,20,4,OBSIDIAN:0)
Block(-8,20,5,OBSIDIAN:0)
Block(-8,20,6,OBSIDIAN:0)
Block(-8,20,7,OBSIDIAN:0)
Block(-8,20,8,CONCRETE:0)
Block(-8,21,-7,OBSIDIAN:0)
Block(-8,21,-6,OBSIDIAN:0)
Block(-8,21,-5,OBSIDIAN:0)
Block(-8,21,-4,OBSIDIAN:0)
Block(-8,21,-3,OBSIDIAN:0)
Block(-8,21,-2,OBSIDIAN:0)
Block(-8,21,-1,OBSIDIAN:0)
Block(-8,21,0,OBSIDIAN:0)
Block(-8,21,1,OBSIDIAN:0)
Block(-8,21,2,OBSIDIAN:0)
Block(-8,21,3,OBSIDIAN:0)
Block(-8,21,4,OBSIDIAN:0)
Block(-8,21,5,OBSIDIAN:0)
Block(-8,21,6,OBSIDIAN:0)
Block(-8,21,7,OBSIDIAN:0)
Block(-8,21,8,CONCRETE:0)
Block(-8,22,-7,OBSIDIAN:0)
Block(-8,22,-6,OBSIDIAN:0)
Block(-8,22,-5,OBSIDIAN:0)
Block(-8,22,-4,OBSIDIAN:0)
Block(-8,22,-3,OBSIDIAN:0)
Block(-8,22,-2,OBSIDIAN:0)
Block(-8,22,-1,OBSIDIAN:0)
Block(-8,22,0,OBSIDIAN:0)
Block(-8,22,1,OBSIDIAN:0)
Block(-8,22,2,OBSIDIAN:0)
Block(-8,22,3,OBSIDIAN:0)
Block(-8,22,4,OBSIDIAN:0)
Block(-8,22,5,OBSIDIAN:0)
Block(-8,22,6,OBSIDIAN:0)
Block(-8,22,7,OBSIDIAN:0)
Block(-8,22,8,CONCRETE:0)
Block(-8,23,-7,CONCRETE:0)
Block(-8,23,-6,CONCRETE:0)
Block(-8,23,-5,CONCRETE:0)
Block(-8,23,-4,CONCRETE:0)
Block(-8,23,-3,CONCRETE:0)
Block(-8,23,-2,CONCRETE:0)
Block(-8,23,-1,CONCRETE:0)
Block(-8,23,0,CONCRETE:0)
Block(-8,23,1,CONCRETE:0)
Block(-8,23,2,CONCRETE:0)
Block(-8,23,3,CONCRETE:0)
Block(-8,23,4,CONCRETE:0)
Block(-8,23,5,CONCRETE:0)
Block(-8,23,6,CONCRETE:0)
Block(-8,23,7,CONCRETE:0)
Block(-8,23,8,CONCRETE:0)
RandomBlock(-7,0,-7,CONCRETE:7,60,quark:iron_plate,20,STAINED_CLAY:12,15,STAINED_CLAY:15,5,AIR,7,IRON_BARS,12,CONCRETE:7,100)
RandomBlock(-7,0,-6,CONCRETE:7,60,quark:iron_plate,20,STAINED_CLAY:12,15,STAINED_CLAY:15,5,AIR,7,IRON_BARS,12,CONCRETE:7,100)
RandomBlock(-7,0,-5,CONCRETE:7,60,quark:iron_plate,20,STAINED_CLAY:12,15,STAINED_CLAY:15,5,AIR,7,IRON_BARS,12,CONCRETE:7,100)
RandomBlock(-7,0,-4,CONCRETE:7,60,quark:iron_plate,20,STAINED_CLAY:12,15,STAINED_CLAY:15,5,AIR,7,IRON_BARS,12,CONCRETE:7,100)
RandomBlock(-7,0,-3,CONCRETE:7,60,quark:iron_plate,20,STAINED_CLAY:12,15,STAINED_CLAY:15,5,AIR,7,IRON_BARS,12,CONCRETE:7,100)
RandomBlock(-7,0,-2,CONCRETE:7,60,quark:iron_plate,20,STAINED_CLAY:12,15,STAINED_CLAY:15,5,AIR,7,IRON_BARS,12,CONCRETE:7,100)
RandomBlock(-7,0,-1,CONCRETE:7,60,quark:iron_plate,20,STAINED_CLAY:12,15,STAINED_CLAY:15,5,AIR,7,IRON_BARS,12,CONCRETE:7,100)
RandomBlock(-7,0,0,CONCRETE:7,60,quark:iron_plate,20,STAINED_CLAY:12,15,STAINED_CLAY:15,5,AIR,7,IRON_BARS,12,CONCRETE:7,100)
RandomBlock(-7,0,1,CONCRETE:7,60,quark:iron_plate,20,STAINED_CLAY:12,15,STAINED_CLAY:15,5,AIR,7,IRON_BARS,12,CONCRETE:7,100)
RandomBlock(-7,0,2,CONCRETE:7,60,quark:iron_plate,20,STAINED_CLAY:12,15,STAINED_CLAY:15,5,AIR,7,IRON_BARS,12,CONCRETE:7,100)
RandomBlock(-7,0,3,CONCRETE:7,60,quark:iron_plate,20,STAINED_CLAY:12,15,STAINED_CLAY:15,5,AIR,7,IRON_BARS,12,CONCRETE:7,100)
RandomBlock(-7,0,4,CONCRETE:7,60,quark:iron_plate,20,STAINED_CLAY:12,15,STAINED_CLAY:15,5,AIR,7,IRON_BARS,12,CONCRETE:7,100)
RandomBlock(-7,0,5,CONCRETE:7,60,quark:iron_plate,20,STAINED_CLAY:12,15,STAINED_CLAY:15,5,AIR,7,IRON_BARS,12,CONCRETE:7,100)
RandomBlock(-7,0,6,CONCRETE:7,60,quark:iron_plate,20,STAINED_CLAY:12,15,STAINED_CLAY:15,5,AIR,7,IRON_BARS,12,CONCRETE:7,100)
RandomBlock(-7,0,7,CONCRETE:7,60,quark:iron_plate,20,STAINED_CLAY:12,15,STAINED_CLAY:15,5,AIR,7,IRON_BARS,12,CONCRETE:7,100)
RandomBlock(-7,0,8,CONCRETE:7,60,quark:iron_plate,20,STAINED_CLAY:12,15,STAINED_CLAY:15,5,AIR,7,IRON_BARS,12,CONCRETE:7,100)
Block(-7,1,-7,OBSIDIAN:0)
Block(-7,1,-6,OBSIDIAN:0)
Block(-7,1,-5,OBSIDIAN:0)
Block(-7,1,-4,OBSIDIAN:0)
Block(-7,1,-3,OBSIDIAN:0)
Block(-7,1,-2,OBSIDIAN:0)
Block(-7,1,-1,OBSIDIAN:0)
Block(-7,1,0,OBSIDIAN:0)
Block(-7,1,1,OBSIDIAN:0)
Block(-7,1,2,OBSIDIAN:0)
Block(-7,1,3,OBSIDIAN:0)
Block(-7,1,4,OBSIDIAN:0)
Block(-7,1,5,OBSIDIAN:0)
Block(-7,1,6,OBSIDIAN:0)
Block(-7,1,7,OBSIDIAN:0)
Block(-7,1,8,OBSIDIAN:0)
RandomBlock(-7,2,-7,CONCRETE:7,60,quark:iron_plate,20,STAINED_CLAY:12,15,STAINED_CLAY:15,5,AIR,7,IRON_BARS,12,CONCRETE:7,100)
RandomBlock(-7,2,-6,CONCRETE:7,60,quark:iron_plate,20,STAINED_CLAY:12,15,STAINED_CLAY:15,5,AIR,7,IRON_BARS,12,CONCRETE:7,100)
RandomBlock(-7,2,-5,CONCRETE:7,60,quark:iron_plate,20,STAINED_CLAY:12,15,STAINED_CLAY:15,5,AIR,7,IRON_BARS,12,CONCRETE:7,100)
RandomBlock(-7,2,-4,CONCRETE:7,60,quark:iron_plate,20,STAINED_CLAY:12,15,STAINED_CLAY:15,5,AIR,7,IRON_BARS,12,CONCRETE:7,100)
RandomBlock(-7,2,-3,CONCRETE:7,60,quark:iron_plate,20,STAINED_CLAY:12,15,STAINED_CLAY:15,5,AIR,7,IRON_BARS,12,CONCRETE:7,100)
RandomBlock(-7,2,-2,CONCRETE:7,60,quark:iron_plate,20,STAINED_CLAY:12,15,STAINED_CLAY:15,5,AIR,7,IRON_BARS,12,CONCRETE:7,100)
RandomBlock(-7,2,-1,CONCRETE:7,60,quark:iron_plate,20,STAINED_CLAY:12,15,STAINED_CLAY:15,5,AIR,7,IRON_BARS,12,CONCRETE:7,100)
RandomBlock(-7,2,0,CONCRETE:7,60,quark:iron_plate,20,STAINED_CLAY:12,15,STAINED_CLAY:15,5,AIR,7,IRON_BARS,12,CONCRETE:7,100)
RandomBlock(-7,2,1,CONCRETE:7,60,quark:iron_plate,20,STAINED_CLAY:12,15,STAINED_CLAY:15,5,AIR,7,IRON_BARS,12,CONCRETE:7,100)
RandomBlock(-7,2,2,CONCRETE:7,60,quark:iron_plate,20,STAINED_CLAY:12,15,STAINED_CLAY:15,5,AIR,7,IRON_BARS,12,CONCRETE:7,100)
RandomBlock(-7,2,3,CONCRETE:7,60,quark:iron_plate,20,STAINED_CLAY:12,15,STAINED_CLAY:15,5,AIR,7,IRON_BARS,12,CONCRETE:7,100)
RandomBlock(-7,2,4,CONCRETE:7,60,quark:iron_plate,20,STAINED_CLAY:12,15,STAINED_CLAY:15,5,AIR,7,IRON_BARS,12,CONCRETE:7,100)
RandomBlock(-7,2,5,CONCRETE:7,60,quark:iron_plate,20,STAINED_CLAY:12,15,STAINED_CLAY:15,5,AIR,7,IRON_BARS,12,CONCRETE:7,100)
RandomBlock(-7,2,6,CONCRETE:7,60,quark:iron_plate,20,STAINED_CLAY:12,15,STAINED_CLAY:15,5,AIR,7,IRON_BARS,12,CONCRETE:7,100)
RandomBlock(-7,2,7,CONCRETE:7,60,quark:iron_plate,20,STAINED_CLAY:12,15,STAINED_CLAY:15,5,AIR,7,IRON_BARS,12,CONCRETE:7,100)
RandomBlock(-7,2,8,CONCRETE:7,60,quark:iron_plate,20,STAINED_CLAY:12,15,STAINED_CLAY:15,5,AIR,7,IRON_BARS,12,CONCRETE:7,100)
RandomBlock(-7,3,-7,CONCRETE:7,60,quark:iron_plate,20,STAINED_CLAY:12,15,STAINED_CLAY:15,5,AIR,7,IRON_BARS,12,CONCRETE:7,100)
RandomBlock(-7,3,-6,CONCRETE:7,60,quark:iron_plate,20,STAINED_CLAY:12,15,STAINED_CLAY:15,5,AIR,7,IRON_BARS,12,CONCRETE:7,100)
RandomBlock(-7,3,-5,CONCRETE:7,60,quark:iron_plate,20,STAINED_CLAY:12,15,STAINED_CLAY:15,5,AIR,7,IRON_BARS,12,CONCRETE:7,100)
RandomBlock(-7,3,-4,CONCRETE:7,60,quark:iron_plate,20,STAINED_CLAY:12,15,STAINED_CLAY:15,5,AIR,7,IRON_BARS,12,CONCRETE:7,100)
RandomBlock(-7,3,-3,CONCRETE:7,60,quark:iron_plate,20,STAINED_CLAY:12,15,STAINED_CLAY:15,5,AIR,7,IRON_BARS,12,CONCRETE:7,100)
RandomBlock(-7,3,-2,CONCRETE:7,60,quark:iron_plate,20,STAINED_CLAY:12,15,STAINED_CLAY:15,5,AIR,7,IRON_BARS,12,CONCRETE:7,100)
RandomBlock(-7,3,-1,CONCRETE:7,60,quark:iron_plate,20,STAINED_CLAY:12,15,STAINED_CLAY:15,5,AIR,7,IRON_BARS,12,CONCRETE:7,100)
RandomBlock(-7,3,0,CONCRETE:7,60,quark:iron_plate,20,STAINED_CLAY:12,15,STAINED_CLAY:15,5,AIR,7,IRON_BARS,12,CONCRETE:7,100)
RandomBlock(-7,3,1,CONCRETE:7,60,quark:iron_plate,20,STAINED_CLAY:12,15,STAINED_CLAY:15,5,AIR,7,IRON_BARS,12,CONCRETE:7,100)
RandomBlock(-7,3,2,CONCRETE:7,60,quark:iron_plate,20,STAINED_CLAY:12,15,STAINED_CLAY:15,5,AIR,7,IRON_BARS,12,CONCRETE:7,100)
RandomBlock(-7,3,3,CONCRETE:7,60,quark:iron_plate,20,STAINED_CLAY:12,15,STAINED_CLAY:15,5,AIR,7,IRON_BARS,12,CONCRETE:7,100)
RandomBlock(-7,3,4,CONCRETE:7,60,quark:iron_plate,20,STAINED_CLAY:12,15,STAINED_CLAY:15,5,AIR,7,IRON_BARS,12,CONCRETE:7,100)
RandomBlock(-7,3,5,CONCRETE:7,60,quark:iron_plate,20,STAINED_CLAY:12,15,STAINED_CLAY:15,5,AIR,7,IRON_BARS,12,CONCRETE:7,100)
RandomBlock(-7,3,6,CONCRETE:7,60,quark:iron_plate,20,STAINED_CLAY:12,15,STAINED_CLAY:15,5,AIR,7,IRON_BARS,12,CONCRETE:7,100)
RandomBlock(-7,3,7,CONCRETE:7,60,quark:iron_plate,20,STAINED_CLAY:12,15,STAINED_CLAY:15,5,AIR,7,IRON_BARS,12,CONCRETE:7,100)
RandomBlock(-7,3,8,CONCRETE:7,60,quark:iron_plate,20,STAINED_CLAY:12,15,STAINED_CLAY:15,5,AIR,7,IRON_BARS,12,CONCRETE:7,100)
RandomBlock(-7,4,-7,CONCRETE:7,60,quark:iron_plate,20,STAINED_CLAY:12,15,STAINED_CLAY:15,5,AIR,7,IRON_BARS,12,CONCRETE:7,100)
RandomBlock(-7,4,-6,CONCRETE:7,60,quark:iron_plate,20,STAINED_CLAY:12,15,STAINED_CLAY:15,5,AIR,7,IRON_BARS,12,CONCRETE:7,100)
RandomBlock(-7,4,-5,CONCRETE:7,60,quark:iron_plate,20,STAINED_CLAY:12,15,STAINED_CLAY:15,5,AIR,7,IRON_BARS,12,CONCRETE:7,100)
RandomBlock(-7,4,-4,CONCRETE:7,60,quark:iron_plate,20,STAINED_CLAY:12,15,STAINED_CLAY:15,5,AIR,7,IRON_BARS,12,CONCRETE:7,100)
RandomBlock(-7,4,-3,CONCRETE:7,60,quark:iron_plate,20,STAINED_CLAY:12,15,STAINED_CLAY:15,5,AIR,7,IRON_BARS,12,CONCRETE:7,100)
RandomBlock(-7,4,-2,CONCRETE:7,60,quark:iron_plate,20,STAINED_CLAY:12,15,STAINED_CLAY:15,5,AIR,7,IRON_BARS,12,CONCRETE:7,100)
RandomBlock(-7,4,-1,CONCRETE:7,60,quark:iron_plate,20,STAINED_CLAY:12,15,STAINED_CLAY:15,5,AIR,7,IRON_BARS,12,CONCRETE:7,100)
RandomBlock(-7,4,0,CONCRETE:7,60,quark:iron_plate,20,STAINED_CLAY:12,15,STAINED_CLAY:15,5,AIR,7,IRON_BARS,12,CONCRETE:7,100)
RandomBlock(-7,4,1,CONCRETE:7,60,quark:iron_plate,20,STAINED_CLAY:12,15,STAINED_CLAY:15,5,AIR,7,IRON_BARS,12,CONCRETE:7,100)
RandomBlock(-7,4,2,CONCRETE:7,60,quark:iron_plate,20,STAINED_CLAY:12,15,STAINED_CLAY:15,5,AIR,7,IRON_BARS,12,CONCRETE:7,100)
RandomBlock(-7,4,3,CONCRETE:7,60,quark:iron_plate,20,STAINED_CLAY:12,15,STAINED_CLAY:15,5,AIR,7,IRON_BARS,12,CONCRETE:7,100)
RandomBlock(-7,4,4,CONCRETE:7,60,quark:iron_plate,20,STAINED_CLAY:12,15,STAINED_CLAY:15,5,AIR,7,IRON_BARS,12,CONCRETE:7,100)
RandomBlock(-7,4,5,CONCRETE:7,60,quark:iron_plate,20,STAINED_CLAY:12,15,STAINED_CLAY:15,5,AIR,7,IRON_BARS,12,CONCRETE:7,100)
RandomBlock(-7,4,6,CONCRETE:7,60,quark:iron_plate,20,STAINED_CLAY:12,15,STAINED_CLAY:15,5,AIR,7,IRON_BARS,12,CONCRETE:7,100)
RandomBlock(-7,4,7,CONCRETE:7,60,quark:iron_plate,20,STAINED_CLAY:12,15,STAINED_CLAY:15,5,AIR,7,IRON_BARS,12,CONCRETE:7,100)
RandomBlock(-7,4,8,CONCRETE:7,60,quark:iron_plate,20,STAINED_CLAY:12,15,STAINED_CLAY:15,5,AIR,7,IRON_BARS,12,CONCRETE:7,100)
Block(-7,5,-7,AIR:0)
Block(-7,5,-6,AIR:0)
Block(-7,5,-5,AIR:0)
Block(-7,5,-4,AIR:0)
Block(-7,5,-3,AIR:0)
Block(-7,5,-2,OBSIDIAN:0)
Block(-7,5,-1,IRON_FENCE:0)
Block(-7,5,0,AIR:0)
Block(-7,5,1,AIR:0)
Block(-7,5,2,AIR:0)
Block(-7,5,3,AIR:0)
Block(-7,5,4,AIR:0)
Block(-7,5,5,IRON_FENCE:0)
Block(-7,5,6,OBSIDIAN:0)
RandomBlock(-7,5,7,AIR,90,IRON_TRAPDOOR:9,100)
Block(-7,5,8,AIR:0)
Block(-7,6,-7,AIR:0)
Block(-7,6,-6,AIR:0)
Block(-7,6,-5,AIR:0)
Block(-7,6,-4,AIR:0)
Block(-7,6,-3,AIR:0)
Block(-7,6,-2,OBSIDIAN:0)
Block(-7,6,-1,IRON_FENCE:0)
Block(-7,6,0,AIR:0)
Block(-7,6,1,AIR:0)
Block(-7,6,2,AIR:0)
Block(-7,6,3,AIR:0)
Block(-7,6,4,AIR:0)
Block(-7,6,5,IRON_FENCE:0)
Block(-7,6,6,OBSIDIAN:0)
RandomBlock(-7,6,7,AIR,90,IRON_TRAPDOOR:9,100)
Block(-7,6,8,AIR:0)
Block(-7,7,-7,AIR:0)
Block(-7,7,-6,AIR:0)
Block(-7,7,-5,AIR:0)
Block(-7,7,-4,AIR:0)
Block(-7,7,-3,AIR:0)
Block(-7,7,-2,OBSIDIAN:0)
Block(-7,7,-1,IRON_FENCE:0)
Block(-7,7,0,AIR:0)
Block(-7,7,1,AIR:0)
Block(-7,7,2,AIR:0)
Block(-7,7,3,AIR:0)
Block(-7,7,4,AIR:0)
Block(-7,7,5,IRON_FENCE:0)
Block(-7,7,6,OBSIDIAN:0)
Block(-7,7,8,AIR:0)
RandomBlock(-7,8,-7,AIR,90,IRON_TRAPDOOR:10,100)
RandomBlock(-7,8,-6,AIR,90,IRON_TRAPDOOR:10,100)
RandomBlock(-7,8,-5,CONCRETE:7,60,quark:iron_plate,20,STAINED_CLAY:12,15,STAINED_CLAY:15,5,AIR,7,IRON_BARS,12,CONCRETE:7,100)
RandomBlock(-7,8,-4,AIR,90,IRON_TRAPDOOR:10,100)
RandomBlock(-7,8,-3,AIR,90,IRON_TRAPDOOR:10,100)
RandomBlock(-7,8,-2,CONCRETE:7,60,quark:iron_plate,20,STAINED_CLAY:12,15,STAINED_CLAY:15,5,AIR,7,IRON_BARS,12,CONCRETE:7,100)
RandomBlock(-7,8,-1,CONCRETE:7,60,quark:iron_plate,20,STAINED_CLAY:12,15,STAINED_CLAY:15,5,AIR,7,IRON_BARS,12,CONCRETE:7,100)
RandomBlock(-7,8,0,AIR,90,IRON_TRAPDOOR:9,100)
Block(-7,8,1,AIR:0)
Block(-7,8,2,AIR:0)
Block(-7,8,3,AIR:0)
Block(-7,8,4,AIR:0)
RandomBlock(-7,8,5,CONCRETE:7,60,quark:iron_plate,20,STAINED_CLAY:12,15,STAINED_CLAY:15,5,AIR,7,IRON_BARS,12,CONCRETE:7,100)
RandomBlock(-7,8,6,CONCRETE:7,60,quark:iron_plate,20,STAINED_CLAY:12,15,STAINED_CLAY:15,5,AIR,7,IRON_BARS,12,CONCRETE:7,100)
RandomBlock(-7,8,7,AIR,90,IRON_TRAPDOOR:1,100)
Block(-7,8,8,AIR:0)
Block(-7,9,-7,AIR)
Block(-7,9,-6,AIR:0)
Block(-7,9,-5,AIR:0)
Block(-7,9,-4,AIR:0)
Block(-7,9,-3,AIR:0)
Block(-7,9,-2,OBSIDIAN:0)
Block(-7,9,-1,IRON_FENCE:0)
Block(-7,9,0,CONCRETE:14)
Block(-7,9,1,AIR:0)
Block(-7,9,2,AIR:0)
Block(-7,9,3,AIR:0)
Block(-7,9,4,AIR:0)
Block(-7,9,5,IRON_FENCE:0)
Block(-7,9,6,OBSIDIAN:0)
Block(-7,9,7,AIR:0)
Block(-7,9,8,AIR:0)
Block(-7,10,-7,AIR:0)
Block(-7,10,-6,AIR:0)
Block(-7,10,-5,AIR:0)
Block(-7,10,-4,AIR:0)
Block(-7,10,-3,AIR:0)
Block(-7,10,-2,OBSIDIAN:0)
Block(-7,10,-1,IRON_FENCE:0)
RandomBlock(-7,10,0,AIR,90,IRON_TRAPDOOR:9,100)
Block(-7,10,1,AIR:0)
Block(-7,10,2,AIR:0)
Block(-7,10,3,AIR:0)
Block(-7,10,4,AIR:0)
Block(-7,10,5,IRON_FENCE:0)
Block(-7,10,6,OBSIDIAN:0)
Block(-7,10,7,AIR:0)
Block(-7,10,8,AIR:0)
Block(-7,11,-7,AIR:0)
Block(-7,11,-6,AIR:0)
Block(-7,11,-5,AIR:0)
Block(-7,11,-4,AIR:0)
Block(-7,11,-3,AIR:0)
Block(-7,11,-2,OBSIDIAN:0)
Block(-7,11,-1,IRON_FENCE:0)
Block(-7,11,0,CONCRETE:4)
Block(-7,11,1,AIR:0)
Block(-7,11,2,STEP:13)
Block(-7,11,3,AIR:0)
Block(-7,11,4,AIR:0)
Block(-7,11,5,IRON_FENCE:0)
Block(-7,11,6,OBSIDIAN:0)
Block(-7,11,7,AIR:0)
Block(-7,11,8,AIR:0)
RandomBlock(-7,12,-7,AIR,90,IRON_TRAPDOOR:9,100)
RandomBlock(-7,12,-6,AIR,90,IRON_TRAPDOOR:8,100)
RandomBlock(-7,12,-5,CONCRETE:7,60,quark:iron_plate,20,STAINED_CLAY:12,15,STAINED_CLAY:15,5,AIR,7,IRON_BARS,12,CONCRETE:7,100)
RandomBlock(-7,12,-4,AIR,90,IRON_TRAPDOOR:9,100)
RandomBlock(-7,12,-3,AIR,90,IRON_TRAPDOOR:8,100)
RandomBlock(-7,12,-2,CONCRETE:7,60,quark:iron_plate,20,STAINED_CLAY:12,15,STAINED_CLAY:15,5,AIR,7,IRON_BARS,12,CONCRETE:7,100)
RandomBlock(-7,12,-1,CONCRETE:7,60,quark:iron_plate,20,STAINED_CLAY:12,15,STAINED_CLAY:15,5,AIR,7,IRON_BARS,12,CONCRETE:7,100)
Block(-7,12,0,STEP:8)
Block(-7,12,1,STEP:8)
Block(-7,12,2,STEP:8)
Block(-7,12,3,STEP:8)
Block(-7,12,4,STEP:8)
RandomBlock(-7,12,5,CONCRETE:7,60,quark:iron_plate,20,STAINED_CLAY:12,15,STAINED_CLAY:15,5,AIR,7,IRON_BARS,12,CONCRETE:7,100)
RandomBlock(-7,12,6,CONCRETE:7,60,quark:iron_plate,20,STAINED_CLAY:12,15,STAINED_CLAY:15,5,AIR,7,IRON_BARS,12,CONCRETE:7,100)
RandomBlock(-7,12,7,AIR,90,IRON_TRAPDOOR:9,100)
RandomBlock(-7,12,8,AIR,90,IRON_TRAPDOOR:8,100)
Block(-7,13,-7,AIR:0)
Block(-7,13,-6,AIR:0)
Block(-7,13,-5,AIR:0)
Block(-7,13,-4,AIR:0)
Block(-7,13,-3,AIR:0)
Block(-7,13,-2,OBSIDIAN:0)
Block(-7,13,-1,IRON_FENCE:0)
Block(-7,13,0,CONCRETE:4)
Block(-7,13,1,CONCRETE:14)
Block(-7,13,2,AIR:0)
Block(-7,13,3,AIR:0)
Block(-7,13,4,AIR:0)
Block(-7,13,5,IRON_FENCE:0)
Block(-7,13,6,CONCRETE:12)
Block(-7,13,7,AIR:0)
Block(-7,13,8,AIR:0)
Block(-7,14,-7,STEP:8)
Block(-7,14,-6,STEP:8)
RandomBlock(-7,14,-5,CONCRETE:7,60,quark:iron_plate,20,STAINED_CLAY:12,15,STAINED_CLAY:15,5,AIR,7,IRON_BARS,12,CONCRETE:7,100)
Block(-7,14,-4,STEP:8)
Block(-7,14,-3,STEP:8)
Block(-7,14,-2,OBSIDIAN:0)
Block(-7,14,-1,IRON_FENCE:0)
Block(-7,14,0,CONCRETE:14)
Block(-7,14,1,CONCRETE:4)
Block(-7,14,2,AIR:0)
Block(-7,14,3,AIR:0)
Block(-7,14,4,AIR:0)
Block(-7,14,5,IRON_FENCE:0)
Block(-7,14,6,OBSIDIAN:0)
Block(-7,14,7,STEP:8)
Block(-7,14,8,STEP:8)
RandomBlock(-7,15,-7,CONCRETE:7,60,quark:iron_plate,20,STAINED_CLAY:12,15,STAINED_CLAY:15,5,AIR,7,IRON_BARS,12,CONCRETE:7,100)
RandomBlock(-7,15,-6,CONCRETE:7,60,quark:iron_plate,20,STAINED_CLAY:12,15,STAINED_CLAY:15,5,AIR,7,IRON_BARS,12,CONCRETE:7,100)
RandomBlock(-7,15,-5,CONCRETE:7,60,quark:iron_plate,20,STAINED_CLAY:12,15,STAINED_CLAY:15,5,AIR,7,IRON_BARS,12,CONCRETE:7,100)
RandomBlock(-7,15,-4,CONCRETE:7,60,quark:iron_plate,20,STAINED_CLAY:12,15,STAINED_CLAY:15,5,AIR,7,IRON_BARS,12,CONCRETE:7,100)
RandomBlock(-7,15,-3,CONCRETE:7,60,quark:iron_plate,20,STAINED_CLAY:12,15,STAINED_CLAY:15,5,AIR,7,IRON_BARS,12,CONCRETE:7,100)
RandomBlock(-7,15,-2,CONCRETE:7,60,quark:iron_plate,20,STAINED_CLAY:12,15,STAINED_CLAY:15,5,AIR,7,IRON_BARS,12,CONCRETE:7,100)
RandomBlock(-7,15,-1,CONCRETE:7,60,quark:iron_plate,20,STAINED_CLAY:12,15,STAINED_CLAY:15,5,AIR,7,IRON_BARS,12,CONCRETE:7,100)
RandomBlock(-7,15,0,CONCRETE:7,60,quark:iron_plate,20,STAINED_CLAY:12,15,STAINED_CLAY:15,5,AIR,7,IRON_BARS,12,CONCRETE:7,100)
RandomBlock(-7,15,1,CONCRETE:7,60,quark:iron_plate,20,STAINED_CLAY:12,15,STAINED_CLAY:15,5,AIR,7,IRON_BARS,12,CONCRETE:7,100)
RandomBlock(-7,15,2,CONCRETE:7,60,quark:iron_plate,20,STAINED_CLAY:12,15,STAINED_CLAY:15,5,AIR,7,IRON_BARS,12,CONCRETE:7,100)
RandomBlock(-7,15,3,CONCRETE:7,60,quark:iron_plate,20,STAINED_CLAY:12,15,STAINED_CLAY:15,5,AIR,7,IRON_BARS,12,CONCRETE:7,100)
RandomBlock(-7,15,4,CONCRETE:7,60,quark:iron_plate,20,STAINED_CLAY:12,15,STAINED_CLAY:15,5,AIR,7,IRON_BARS,12,CONCRETE:7,100)
RandomBlock(-7,15,5,CONCRETE:7,60,quark:iron_plate,20,STAINED_CLAY:12,15,STAINED_CLAY:15,5,AIR,7,IRON_BARS,12,CONCRETE:7,100)
RandomBlock(-7,15,6,CONCRETE:7,60,quark:iron_plate,20,STAINED_CLAY:12,15,STAINED_CLAY:15,5,AIR,7,IRON_BARS,12,CONCRETE:7,100)
RandomBlock(-7,15,7,CONCRETE:7,60,quark:iron_plate,20,STAINED_CLAY:12,15,STAINED_CLAY:15,5,AIR,7,IRON_BARS,12,CONCRETE:7,100)
RandomBlock(-7,15,8,CONCRETE:7,60,quark:iron_plate,20,STAINED_CLAY:12,15,STAINED_CLAY:15,5,AIR,7,IRON_BARS,12,CONCRETE:7,100)
Block(-7,16,-7,OBSIDIAN:0)
Block(-7,16,-6,OBSIDIAN:0)
Block(-7,16,-5,OBSIDIAN:0)
Block(-7,16,-4,OBSIDIAN:0)
Block(-7,16,-3,OBSIDIAN:0)
Block(-7,16,-2,OBSIDIAN:0)
Block(-7,16,-1,OBSIDIAN:0)
Block(-7,16,0,OBSIDIAN:0)
Block(-7,16,1,OBSIDIAN:0)
Block(-7,16,2,OBSIDIAN:0)
Block(-7,16,3,OBSIDIAN:0)
Block(-7,16,4,OBSIDIAN:0)
Block(-7,16,5,OBSIDIAN:0)
Block(-7,16,6,OBSIDIAN:0)
Block(-7,16,7,OBSIDIAN:0)
Block(-7,16,8,OBSIDIAN:0)
RandomBlock(-7,17,-7,CONCRETE:7,60,quark:iron_plate,20,STAINED_CLAY:12,15,STAINED_CLAY:15,5,AIR,7,IRON_BARS,12,CONCRETE:7,100)
RandomBlock(-7,17,-6,CONCRETE:7,60,quark:iron_plate,20,STAINED_CLAY:12,15,STAINED_CLAY:15,5,AIR,7,IRON_BARS,12,CONCRETE:7,100)
RandomBlock(-7,17,-5,CONCRETE:7,60,quark:iron_plate,20,STAINED_CLAY:12,15,STAINED_CLAY:15,5,AIR,7,IRON_BARS,12,CONCRETE:7,100)
RandomBlock(-7,17,-4,CONCRETE:7,60,quark:iron_plate,20,STAINED_CLAY:12,15,STAINED_CLAY:15,5,AIR,7,IRON_BARS,12,CONCRETE:7,100)
RandomBlock(-7,17,-3,CONCRETE:7,60,quark:iron_plate,20,STAINED_CLAY:12,15,STAINED_CLAY:15,5,AIR,7,IRON_BARS,12,CONCRETE:7,100)
RandomBlock(-7,17,-2,CONCRETE:7,60,quark:iron_plate,20,STAINED_CLAY:12,15,STAINED_CLAY:15,5,AIR,7,IRON_BARS,12,CONCRETE:7,100)
RandomBlock(-7,17,-1,CONCRETE:7,60,quark:iron_plate,20,STAINED_CLAY:12,15,STAINED_CLAY:15,5,AIR,7,IRON_BARS,12,CONCRETE:7,100)
RandomBlock(-7,17,0,CONCRETE:7,60,quark:iron_plate,20,STAINED_CLAY:12,15,STAINED_CLAY:15,5,AIR,7,IRON_BARS,12,CONCRETE:7,100)
RandomBlock(-7,17,1,CONCRETE:7,60,quark:iron_plate,20,STAINED_CLAY:12,15,STAINED_CLAY:15,5,AIR,7,IRON_BARS,12,CONCRETE:7,100)
RandomBlock(-7,17,2,CONCRETE:7,60,quark:iron_plate,20,STAINED_CLAY:12,15,STAINED_CLAY:15,5,AIR,7,IRON_BARS,12,CONCRETE:7,100)
RandomBlock(-7,17,3,CONCRETE:7,60,quark:iron_plate,20,STAINED_CLAY:12,15,STAINED_CLAY:15,5,AIR,7,IRON_BARS,12,CONCRETE:7,100)
RandomBlock(-7,17,4,CONCRETE:7,60,quark:iron_plate,20,STAINED_CLAY:12,15,STAINED_CLAY:15,5,AIR,7,IRON_BARS,12,CONCRETE:7,100)
RandomBlock(-7,17,5,CONCRETE:7,60,quark:iron_plate,20,STAINED_CLAY:12,15,STAINED_CLAY:15,5,AIR,7,IRON_BARS,12,CONCRETE:7,100)
RandomBlock(-7,17,6,CONCRETE:7,60,quark:iron_plate,20,STAINED_CLAY:12,15,STAINED_CLAY:15,5,AIR,7,IRON_BARS,12,CONCRETE:7,100)
RandomBlock(-7,17,7,CONCRETE:7,60,quark:iron_plate,20,STAINED_CLAY:12,15,STAINED_CLAY:15,5,AIR,7,IRON_BARS,12,CONCRETE:7,100)
RandomBlock(-7,17,8,CONCRETE:7,60,quark:iron_plate,20,STAINED_CLAY:12,15,STAINED_CLAY:15,5,AIR,7,IRON_BARS,12,CONCRETE:7,100)
Block(-7,18,-7,OBSIDIAN:0)
Block(-7,18,-6,OBSIDIAN:0)
Block(-7,18,-5,OBSIDIAN:0)
Block(-7,18,-4,OBSIDIAN:0)
Block(-7,18,-3,OBSIDIAN:0)
Block(-7,18,-2,OBSIDIAN:0)
Block(-7,18,-1,OBSIDIAN:0)
Block(-7,18,0,OBSIDIAN:0)
Block(-7,18,1,OBSIDIAN:0)
Block(-7,18,2,OBSIDIAN:0)
Block(-7,18,3,OBSIDIAN:0)
Block(-7,18,4,OBSIDIAN:0)
Block(-7,18,5,OBSIDIAN:0)
Block(-7,18,6,OBSIDIAN:0)
Block(-7,18,7,OBSIDIAN:0)
Block(-7,18,8,CONCRETE:0)
Block(-7,19,-7,OBSIDIAN:0)
Block(-7,19,-6,OBSIDIAN:0)
Block(-7,19,-5,OBSIDIAN:0)
Block(-7,19,-4,OBSIDIAN:0)
Block(-7,19,-3,OBSIDIAN:0)
Block(-7,19,-2,OBSIDIAN:0)
Block(-7,19,-1,OBSIDIAN:0)
Block(-7,19,0,OBSIDIAN:0)
Block(-7,19,1,OBSIDIAN:0)
Block(-7,19,2,OBSIDIAN:0)
Block(-7,19,3,OBSIDIAN:0)
Block(-7,19,4,OBSIDIAN:0)
Block(-7,19,5,OBSIDIAN:0)
Block(-7,19,6,OBSIDIAN:0)
Block(-7,19,7,OBSIDIAN:0)
Block(-7,19,8,CONCRETE:0)
Block(-7,20,-7,OBSIDIAN:0)
Block(-7,20,-6,OBSIDIAN:0)
Block(-7,20,-5,OBSIDIAN:0)
Block(-7,20,-4,OBSIDIAN:0)
Block(-7,20,-3,OBSIDIAN:0)
Block(-7,20,-2,OBSIDIAN:0)
Block(-7,20,-1,OBSIDIAN:0)
Block(-7,20,0,OBSIDIAN:0)
Block(-7,20,1,OBSIDIAN:0)
Block(-7,20,2,OBSIDIAN:0)
Block(-7,20,3,OBSIDIAN:0)
Block(-7,20,4,OBSIDIAN:0)
Block(-7,20,5,OBSIDIAN:0)
Block(-7,20,6,OBSIDIAN:0)
Block(-7,20,7,OBSIDIAN:0)
Block(-7,20,8,CONCRETE:0)
Block(-7,21,-7,OBSIDIAN:0)
Block(-7,21,-6,OBSIDIAN:0)
Block(-7,21,-5,OBSIDIAN:0)
Block(-7,21,-4,OBSIDIAN:0)
Block(-7,21,-3,OBSIDIAN:0)
Block(-7,21,-2,OBSIDIAN:0)
Block(-7,21,-1,OBSIDIAN:0)
Block(-7,21,0,OBSIDIAN:0)
Block(-7,21,1,OBSIDIAN:0)
Block(-7,21,2,OBSIDIAN:0)
Block(-7,21,3,OBSIDIAN:0)
Block(-7,21,4,OBSIDIAN:0)
Block(-7,21,5,OBSIDIAN:0)
Block(-7,21,6,OBSIDIAN:0)
Block(-7,21,7,OBSIDIAN:0)
Block(-7,21,8,CONCRETE:0)
Block(-7,22,-7,OBSIDIAN:0)
Block(-7,22,-6,OBSIDIAN:0)
Block(-7,22,-5,OBSIDIAN:0)
Block(-7,22,-4,OBSIDIAN:0)
Block(-7,22,-3,OBSIDIAN:0)
Block(-7,22,-2,OBSIDIAN:0)
Block(-7,22,-1,OBSIDIAN:0)
Block(-7,22,0,OBSIDIAN:0)
Block(-7,22,1,OBSIDIAN:0)
Block(-7,22,2,OBSIDIAN:0)
Block(-7,22,3,OBSIDIAN:0)
Block(-7,22,4,OBSIDIAN:0)
Block(-7,22,5,OBSIDIAN:0)
Block(-7,22,6,OBSIDIAN:0)
Block(-7,22,7,OBSIDIAN:0)
Block(-7,22,8,CONCRETE:0)
Block(-7,23,-7,CONCRETE:0)
Block(-7,23,-6,CONCRETE:0)
Block(-7,23,-5,CONCRETE:0)
Block(-7,23,-4,CONCRETE:0)
Block(-7,23,-3,CONCRETE:0)
Block(-7,23,-2,CONCRETE:0)
Block(-7,23,-1,CONCRETE:0)
Block(-7,23,0,CONCRETE:0)
Block(-7,23,1,CONCRETE:0)
Block(-7,23,2,CONCRETE:0)
Block(-7,23,3,CONCRETE:0)
Block(-7,23,4,CONCRETE:0)
Block(-7,23,5,CONCRETE:0)
Block(-7,23,6,CONCRETE:0)
Block(-7,23,7,CONCRETE:0)
Block(-7,23,8,CONCRETE:0)
RandomBlock(-6,0,-7,CONCRETE:7,60,quark:iron_plate,20,STAINED_CLAY:12,15,STAINED_CLAY:15,5,AIR,7,IRON_BARS,12,CONCRETE:7,100)
RandomBlock(-6,0,-6,CONCRETE:7,60,quark:iron_plate,20,STAINED_CLAY:12,15,STAINED_CLAY:15,5,AIR,7,IRON_BARS,12,CONCRETE:7,100)
RandomBlock(-6,0,-5,CONCRETE:7,60,quark:iron_plate,20,STAINED_CLAY:12,15,STAINED_CLAY:15,5,AIR,7,IRON_BARS,12,CONCRETE:7,100)
RandomBlock(-6,0,-4,CONCRETE:7,60,quark:iron_plate,20,STAINED_CLAY:12,15,STAINED_CLAY:15,5,AIR,7,IRON_BARS,12,CONCRETE:7,100)
RandomBlock(-6,0,-3,CONCRETE:7,60,quark:iron_plate,20,STAINED_CLAY:12,15,STAINED_CLAY:15,5,AIR,7,IRON_BARS,12,CONCRETE:7,100)
RandomBlock(-6,0,-2,CONCRETE:7,60,quark:iron_plate,20,STAINED_CLAY:12,15,STAINED_CLAY:15,5,AIR,7,IRON_BARS,12,CONCRETE:7,100)
RandomBlock(-6,0,-1,CONCRETE:7,60,quark:iron_plate,20,STAINED_CLAY:12,15,STAINED_CLAY:15,5,AIR,7,IRON_BARS,12,CONCRETE:7,100)
RandomBlock(-6,0,0,CONCRETE:7,60,quark:iron_plate,20,STAINED_CLAY:12,15,STAINED_CLAY:15,5,AIR,7,IRON_BARS,12,CONCRETE:7,100)
RandomBlock(-6,0,1,CONCRETE:7,60,quark:iron_plate,20,STAINED_CLAY:12,15,STAINED_CLAY:15,5,AIR,7,IRON_BARS,12,CONCRETE:7,100)
RandomBlock(-6,0,2,CONCRETE:7,60,quark:iron_plate,20,STAINED_CLAY:12,15,STAINED_CLAY:15,5,AIR,7,IRON_BARS,12,CONCRETE:7,100)
RandomBlock(-6,0,3,CONCRETE:7,60,quark:iron_plate,20,STAINED_CLAY:12,15,STAINED_CLAY:15,5,AIR,7,IRON_BARS,12,CONCRETE:7,100)
RandomBlock(-6,0,4,CONCRETE:7,60,quark:iron_plate,20,STAINED_CLAY:12,15,STAINED_CLAY:15,5,AIR,7,IRON_BARS,12,CONCRETE:7,100)
RandomBlock(-6,0,5,CONCRETE:7,60,quark:iron_plate,20,STAINED_CLAY:12,15,STAINED_CLAY:15,5,AIR,7,IRON_BARS,12,CONCRETE:7,100)
RandomBlock(-6,0,6,CONCRETE:7,60,quark:iron_plate,20,STAINED_CLAY:12,15,STAINED_CLAY:15,5,AIR,7,IRON_BARS,12,CONCRETE:7,100)
RandomBlock(-6,0,7,CONCRETE:7,60,quark:iron_plate,20,STAINED_CLAY:12,15,STAINED_CLAY:15,5,AIR,7,IRON_BARS,12,CONCRETE:7,100)
RandomBlock(-6,0,8,CONCRETE:7,60,quark:iron_plate,20,STAINED_CLAY:12,15,STAINED_CLAY:15,5,AIR,7,IRON_BARS,12,CONCRETE:7,100)
Block(-6,1,-7,OBSIDIAN:0)
Block(-6,1,-6,OBSIDIAN:0)
Block(-6,1,-5,OBSIDIAN:0)
Block(-6,1,-4,OBSIDIAN:0)
Block(-6,1,-3,OBSIDIAN:0)
Block(-6,1,-2,OBSIDIAN:0)
Block(-6,1,-1,OBSIDIAN:0)
Block(-6,1,0,OBSIDIAN:0)
Block(-6,1,1,OBSIDIAN:0)
Block(-6,1,2,OBSIDIAN:0)
Block(-6,1,3,OBSIDIAN:0)
Block(-6,1,4,OBSIDIAN:0)
Block(-6,1,5,OBSIDIAN:0)
Block(-6,1,6,OBSIDIAN:0)
Block(-6,1,7,OBSIDIAN:0)
Block(-6,1,8,OBSIDIAN:0)
RandomBlock(-6,2,-7,CONCRETE:7,60,quark:iron_plate,20,STAINED_CLAY:12,15,STAINED_CLAY:15,5,AIR,7,IRON_BARS,12,CONCRETE:7,100)
RandomBlock(-6,2,-6,CONCRETE:7,60,quark:iron_plate,20,STAINED_CLAY:12,15,STAINED_CLAY:15,5,AIR,7,IRON_BARS,12,CONCRETE:7,100)
RandomBlock(-6,2,-5,CONCRETE:7,60,quark:iron_plate,20,STAINED_CLAY:12,15,STAINED_CLAY:15,5,AIR,7,IRON_BARS,12,CONCRETE:7,100)
RandomBlock(-6,2,-4,CONCRETE:7,60,quark:iron_plate,20,STAINED_CLAY:12,15,STAINED_CLAY:15,5,AIR,7,IRON_BARS,12,CONCRETE:7,100)
RandomBlock(-6,2,-3,CONCRETE:7,60,quark:iron_plate,20,STAINED_CLAY:12,15,STAINED_CLAY:15,5,AIR,7,IRON_BARS,12,CONCRETE:7,100)
RandomBlock(-6,2,-2,CONCRETE:7,60,quark:iron_plate,20,STAINED_CLAY:12,15,STAINED_CLAY:15,5,AIR,7,IRON_BARS,12,CONCRETE:7,100)
RandomBlock(-6,2,-1,CONCRETE:7,60,quark:iron_plate,20,STAINED_CLAY:12,15,STAINED_CLAY:15,5,AIR,7,IRON_BARS,12,CONCRETE:7,100)
RandomBlock(-6,2,0,CONCRETE:7,60,quark:iron_plate,20,STAINED_CLAY:12,15,STAINED_CLAY:15,5,AIR,7,IRON_BARS,12,CONCRETE:7,100)
RandomBlock(-6,2,1,CONCRETE:7,60,quark:iron_plate,20,STAINED_CLAY:12,15,STAINED_CLAY:15,5,AIR,7,IRON_BARS,12,CONCRETE:7,100)
RandomBlock(-6,2,2,CONCRETE:7,60,quark:iron_plate,20,STAINED_CLAY:12,15,STAINED_CLAY:15,5,AIR,7,IRON_BARS,12,CONCRETE:7,100)
RandomBlock(-6,2,3,CONCRETE:7,60,quark:iron_plate,20,STAINED_CLAY:12,15,STAINED_CLAY:15,5,AIR,7,IRON_BARS,12,CONCRETE:7,100)
RandomBlock(-6,2,4,CONCRETE:7,60,quark:iron_plate,20,STAINED_CLAY:12,15,STAINED_CLAY:15,5,AIR,7,IRON_BARS,12,CONCRETE:7,100)
RandomBlock(-6,2,5,CONCRETE:7,60,quark:iron_plate,20,STAINED_CLAY:12,15,STAINED_CLAY:15,5,AIR,7,IRON_BARS,12,CONCRETE:7,100)
RandomBlock(-6,2,6,CONCRETE:7,60,quark:iron_plate,20,STAINED_CLAY:12,15,STAINED_CLAY:15,5,AIR,7,IRON_BARS,12,CONCRETE:7,100)
RandomBlock(-6,2,7,CONCRETE:7,60,quark:iron_plate,20,STAINED_CLAY:12,15,STAINED_CLAY:15,5,AIR,7,IRON_BARS,12,CONCRETE:7,100)
RandomBlock(-6,2,8,CONCRETE:7,60,quark:iron_plate,20,STAINED_CLAY:12,15,STAINED_CLAY:15,5,AIR,7,IRON_BARS,12,CONCRETE:7,100)
RandomBlock(-6,3,-7,CONCRETE:7,60,quark:iron_plate,20,STAINED_CLAY:12,15,STAINED_CLAY:15,5,AIR,7,IRON_BARS,12,CONCRETE:7,100)
RandomBlock(-6,3,-6,CONCRETE:7,60,quark:iron_plate,20,STAINED_CLAY:12,15,STAINED_CLAY:15,5,AIR,7,IRON_BARS,12,CONCRETE:7,100)
RandomBlock(-6,3,-5,CONCRETE:7,60,quark:iron_plate,20,STAINED_CLAY:12,15,STAINED_CLAY:15,5,AIR,7,IRON_BARS,12,CONCRETE:7,100)
RandomBlock(-6,3,-4,CONCRETE:7,60,quark:iron_plate,20,STAINED_CLAY:12,15,STAINED_CLAY:15,5,AIR,7,IRON_BARS,12,CONCRETE:7,100)
RandomBlock(-6,3,-3,CONCRETE:7,60,quark:iron_plate,20,STAINED_CLAY:12,15,STAINED_CLAY:15,5,AIR,7,IRON_BARS,12,CONCRETE:7,100)
RandomBlock(-6,3,-2,CONCRETE:7,60,quark:iron_plate,20,STAINED_CLAY:12,15,STAINED_CLAY:15,5,AIR,7,IRON_BARS,12,CONCRETE:7,100)
RandomBlock(-6,3,-1,CONCRETE:7,60,quark:iron_plate,20,STAINED_CLAY:12,15,STAINED_CLAY:15,5,AIR,7,IRON_BARS,12,CONCRETE:7,100)
Block(-6,3,0,CONCRETE:0)
RandomBlock(-6,3,1,CONCRETE:7,60,quark:iron_plate,20,STAINED_CLAY:12,15,STAINED_CLAY:15,5,AIR,7,IRON_BARS,12,CONCRETE:7,100)
RandomBlock(-6,3,2,CONCRETE:7,60,quark:iron_plate,20,STAINED_CLAY:12,15,STAINED_CLAY:15,5,AIR,7,IRON_BARS,12,CONCRETE:7,100)
RandomBlock(-6,3,3,CONCRETE:7,60,quark:iron_plate,20,STAINED_CLAY:12,15,STAINED_CLAY:15,5,AIR,7,IRON_BARS,12,CONCRETE:7,100)
Block(-6,3,4,CONCRETE:0)
RandomBlock(-6,3,5,CONCRETE:7,60,quark:iron_plate,20,STAINED_CLAY:12,15,STAINED_CLAY:15,5,AIR,7,IRON_BARS,12,CONCRETE:7,100)
RandomBlock(-6,3,6,CONCRETE:7,60,quark:iron_plate,20,STAINED_CLAY:12,15,STAINED_CLAY:15,5,AIR,7,IRON_BARS,12,CONCRETE:7,100)
RandomBlock(-6,3,7,CONCRETE:7,60,quark:iron_plate,20,STAINED_CLAY:12,15,STAINED_CLAY:15,5,AIR,7,IRON_BARS,12,CONCRETE:7,100)
RandomBlock(-6,3,8,CONCRETE:7,60,quark:iron_plate,20,STAINED_CLAY:12,15,STAINED_CLAY:15,5,AIR,7,IRON_BARS,12,CONCRETE:7,100)
RandomBlock(-6,4,-7,CONCRETE:7,60,quark:iron_plate,20,STAINED_CLAY:12,15,STAINED_CLAY:15,5,AIR,7,IRON_BARS,12,CONCRETE:7,100)
RandomBlock(-6,4,-6,CONCRETE:7,60,quark:iron_plate,20,STAINED_CLAY:12,15,STAINED_CLAY:15,5,AIR,7,IRON_BARS,12,CONCRETE:7,100)
Block(-6,4,-5,SMOOTH_STAIRS:1)
RandomBlock(-6,4,-4,CONCRETE:7,60,quark:iron_plate,20,STAINED_CLAY:12,15,STAINED_CLAY:15,5,AIR,7,IRON_BARS,12,CONCRETE:7,100)
RandomBlock(-6,4,-3,CONCRETE:7,60,quark:iron_plate,20,STAINED_CLAY:12,15,STAINED_CLAY:15,5,AIR,7,IRON_BARS,12,CONCRETE:7,100)
RandomBlock(-6,4,-2,CONCRETE:7,60,quark:iron_plate,20,STAINED_CLAY:12,15,STAINED_CLAY:15,5,AIR,7,IRON_BARS,12,CONCRETE:7,100)
RandomBlock(-6,4,-1,CONCRETE:7,60,quark:iron_plate,20,STAINED_CLAY:12,15,STAINED_CLAY:15,5,AIR,7,IRON_BARS,12,CONCRETE:7,100)
RandomBlock(-6,4,0,AIR,90,IRON_TRAPDOOR:9,100)
RandomBlock(-6,4,1,CONCRETE:7,60,quark:iron_plate,20,STAINED_CLAY:12,15,STAINED_CLAY:15,5,AIR,7,IRON_BARS,12,CONCRETE:7,100)
RandomBlock(-6,4,2,CONCRETE:7,60,quark:iron_plate,20,STAINED_CLAY:12,15,STAINED_CLAY:15,5,AIR,7,IRON_BARS,12,CONCRETE:7,100)
RandomBlock(-6,4,3,CONCRETE:7,60,quark:iron_plate,20,STAINED_CLAY:12,15,STAINED_CLAY:15,5,AIR,7,IRON_BARS,12,CONCRETE:7,100)
RandomBlock(-6,4,4,AIR,90,IRON_TRAPDOOR:8,100)
RandomBlock(-6,4,5,CONCRETE:7,60,quark:iron_plate,20,STAINED_CLAY:12,15,STAINED_CLAY:15,5,AIR,7,IRON_BARS,12,CONCRETE:7,100)
RandomBlock(-6,4,6,CONCRETE:7,60,quark:iron_plate,20,STAINED_CLAY:12,15,STAINED_CLAY:15,5,AIR,7,IRON_BARS,12,CONCRETE:7,100)
RandomBlock(-6,4,7,CONCRETE:7,60,quark:iron_plate,20,STAINED_CLAY:12,15,STAINED_CLAY:15,5,AIR,7,IRON_BARS,12,CONCRETE:7,100)
RandomBlock(-6,4,8,CONCRETE:7,60,quark:iron_plate,20,STAINED_CLAY:12,15,STAINED_CLAY:15,5,AIR,7,IRON_BARS,12,CONCRETE:7,100)
Block(-6,5,-7,STEP:8)
Block(-6,5,-5,AIR:0)
Block(-6,5,-4,AIR:0)
Block(-6,5,-3,AIR:0)
RandomBlock(-6,5,-2,CONCRETE:7,60,quark:iron_plate,20,STAINED_CLAY:12,15,STAINED_CLAY:15,5,AIR,7,IRON_BARS,12,CONCRETE:7,100)
RandomBlock(-6,5,-1,CONCRETE:7,60,quark:iron_plate,20,STAINED_CLAY:12,15,STAINED_CLAY:15,5,AIR,7,IRON_BARS,12,CONCRETE:7,100)
Block(-6,5,0,AIR:0)
Block(-6,5,1,AIR:0)
Block(-6,5,2,AIR:0)
Block(-6,5,3,AIR:0)
Block(-6,5,4,AIR:0)
RandomBlock(-6,5,5,CONCRETE:7,60,quark:iron_plate,20,STAINED_CLAY:12,15,STAINED_CLAY:15,5,AIR,7,IRON_BARS,12,CONCRETE:7,100)
RandomBlock(-6,5,6,CONCRETE:7,60,quark:iron_plate,20,STAINED_CLAY:12,15,STAINED_CLAY:15,5,AIR,7,IRON_BARS,12,CONCRETE:7,100)
RandomBlock(-6,5,7,CONCRETE:8,60,notreepunching:cobblestone/andesite,15,STONE:5,15,STAINED_CLAY:9,10,IRON_BARS,12,AIR,8,STAINED_CLAY:12,30,CONCRETE:8,100)
Block(-6,5,8,AIR:0)
Block(-6,6,-7,AIR:0)
Block(-6,6,-5,AIR:0)
Block(-6,6,-4,AIR:0)
Block(-6,6,-3,AIR:0)
RandomBlock(-6,6,-2,CONCRETE:7,60,quark:iron_plate,20,STAINED_CLAY:12,15,STAINED_CLAY:15,5,AIR,7,IRON_BARS,12,CONCRETE:7,100)
RandomBlock(-6,6,-1,CONCRETE:7,60,quark:iron_plate,20,STAINED_CLAY:12,15,STAINED_CLAY:15,5,AIR,7,IRON_BARS,12,CONCRETE:7,100)
Block(-6,6,0,AIR:0)
Block(-6,6,1,AIR:0)
Block(-6,6,2,AIR:0)
Block(-6,6,3,AIR:0)
Block(-6,6,4,AIR:0)
RandomBlock(-6,6,5,CONCRETE:7,60,quark:iron_plate,20,STAINED_CLAY:12,15,STAINED_CLAY:15,5,AIR,7,IRON_BARS,12,CONCRETE:7,100)
RandomBlock(-6,6,6,CONCRETE:7,60,quark:iron_plate,20,STAINED_CLAY:12,15,STAINED_CLAY:15,5,AIR,7,IRON_BARS,12,CONCRETE:7,100)
RandomBlock(-6,6,7,CONCRETE:8,60,notreepunching:cobblestone/andesite,15,STONE:5,15,STAINED_CLAY:9,10,IRON_BARS,12,AIR,8,STAINED_CLAY:12,30,CONCRETE:8,100)
Block(-6,6,8,AIR:0)
Block(-6,7,-7,STEP:0)
Block(-6,7,-5,AIR:0)
Block(-6,7,-4,AIR:0)
Block(-6,7,-3,AIR:0)
RandomBlock(-6,7,-2,CONCRETE:7,60,quark:iron_plate,20,STAINED_CLAY:12,15,STAINED_CLAY:15,5,AIR,7,IRON_BARS,12,CONCRETE:7,100)
RandomBlock(-6,7,-1,CONCRETE:7,60,quark:iron_plate,20,STAINED_CLAY:12,15,STAINED_CLAY:15,5,AIR,7,IRON_BARS,12,CONCRETE:7,100)
Block(-6,7,0,AIR:0)
Block(-6,7,1,AIR:0)
Block(-6,7,2,AIR:0)
Block(-6,7,3,AIR:0)
Block(-6,7,4,AIR:0)
RandomBlock(-6,7,5,CONCRETE:7,60,quark:iron_plate,20,STAINED_CLAY:12,15,STAINED_CLAY:15,5,AIR,7,IRON_BARS,12,CONCRETE:7,100)
RandomBlock(-6,7,6,CONCRETE:7,60,quark:iron_plate,20,STAINED_CLAY:12,15,STAINED_CLAY:15,5,AIR,7,IRON_BARS,12,CONCRETE:7,100)
RandomBlock(-6,7,7,CONCRETE:8,60,notreepunching:cobblestone/andesite,15,STONE:5,15,STAINED_CLAY:9,10,IRON_BARS,12,AIR,8,STAINED_CLAY:12,30,CONCRETE:8,100)
Block(-6,7,8,AIR:0)
RandomBlock(-6,8,-7,CONCRETE:7,60,quark:iron_plate,20,STAINED_CLAY:12,15,STAINED_CLAY:15,5,AIR,7,IRON_BARS,12,CONCRETE:7,100)
RandomBlock(-6,8,-6,CONCRETE:7,60,quark:iron_plate,20,STAINED_CLAY:12,15,STAINED_CLAY:15,5,AIR,7,IRON_BARS,12,CONCRETE:7,100)
RandomBlock(-6,8,-5,CONCRETE:7,60,quark:iron_plate,20,STAINED_CLAY:12,15,STAINED_CLAY:15,5,AIR,7,IRON_BARS,12,CONCRETE:7,100)
RandomBlock(-6,8,-4,CONCRETE:7,60,quark:iron_plate,20,STAINED_CLAY:12,15,STAINED_CLAY:15,5,AIR,7,IRON_BARS,12,CONCRETE:7,100)
RandomBlock(-6,8,-3,CONCRETE:7,60,quark:iron_plate,20,STAINED_CLAY:12,15,STAINED_CLAY:15,5,AIR,7,IRON_BARS,12,CONCRETE:7,100)
RandomBlock(-6,8,-2,CONCRETE:7,60,quark:iron_plate,20,STAINED_CLAY:12,15,STAINED_CLAY:15,5,AIR,7,IRON_BARS,12,CONCRETE:7,100)
RandomBlock(-6,8,-1,CONCRETE:7,60,quark:iron_plate,20,STAINED_CLAY:12,15,STAINED_CLAY:15,5,AIR,7,IRON_BARS,12,CONCRETE:7,100)
RandomBlock(-6,8,0,CONCRETE:7,60,quark:iron_plate,20,STAINED_CLAY:12,15,STAINED_CLAY:15,5,AIR,7,IRON_BARS,12,CONCRETE:7,100)
RandomBlock(-6,8,1,CONCRETE:7,60,quark:iron_plate,20,STAINED_CLAY:12,15,STAINED_CLAY:15,5,AIR,7,IRON_BARS,12,CONCRETE:7,100)
RandomBlock(-6,8,2,CONCRETE:7,60,quark:iron_plate,20,STAINED_CLAY:12,15,STAINED_CLAY:15,5,AIR,7,IRON_BARS,12,CONCRETE:7,100)
RandomBlock(-6,8,3,CONCRETE:7,60,quark:iron_plate,20,STAINED_CLAY:12,15,STAINED_CLAY:15,5,AIR,7,IRON_BARS,12,CONCRETE:7,100)
RandomBlock(-6,8,4,CONCRETE:7,60,quark:iron_plate,20,STAINED_CLAY:12,15,STAINED_CLAY:15,5,AIR,7,IRON_BARS,12,CONCRETE:7,100)
RandomBlock(-6,8,5,CONCRETE:7,60,quark:iron_plate,20,STAINED_CLAY:12,15,STAINED_CLAY:15,5,AIR,7,IRON_BARS,12,CONCRETE:7,100)
RandomBlock(-6,8,6,CONCRETE:7,60,quark:iron_plate,20,STAINED_CLAY:12,15,STAINED_CLAY:15,5,AIR,7,IRON_BARS,12,CONCRETE:7,100)
RandomBlock(-6,8,7,CONCRETE:8,60,notreepunching:cobblestone/andesite,15,STONE:5,15,STAINED_CLAY:9,10,IRON_BARS,12,AIR,8,STAINED_CLAY:12,30,CONCRETE:8,100)
Block(-6,8,8,AIR:0)
Block(-6,9,-7,STEP:8)
Block(-6,9,-6,STEP:8)
RandomBlock(-6,9,-5,CONCRETE:7,60,quark:iron_plate,20,STAINED_CLAY:12,15,STAINED_CLAY:15,5,AIR,7,IRON_BARS,12,CONCRETE:7,100)
Block(-6,9,-4,AIR)
Block(-6,9,-3,AIR:0)
RandomBlock(-6,9,-2,CONCRETE:7,60,quark:iron_plate,20,STAINED_CLAY:12,15,STAINED_CLAY:15,5,AIR,7,IRON_BARS,12,CONCRETE:7,100)
RandomBlock(-6,9,-1,CONCRETE:7,60,quark:iron_plate,20,STAINED_CLAY:12,15,STAINED_CLAY:15,5,AIR,7,IRON_BARS,12,CONCRETE:7,100)
Block(-6,9,0,CONCRETE:14)
Block(-6,9,1,AIR:0)
Block(-6,9,2,AIR:0)
Block(-6,9,3,AIR:0)
Block(-6,9,4,AIR:0)
RandomBlock(-6,9,5,CONCRETE:7,60,quark:iron_plate,20,STAINED_CLAY:12,15,STAINED_CLAY:15,5,AIR,7,IRON_BARS,12,CONCRETE:7,100)
RandomBlock(-6,9,6,CONCRETE:7,60,quark:iron_plate,20,STAINED_CLAY:12,15,STAINED_CLAY:15,5,AIR,7,IRON_BARS,12,CONCRETE:7,100)
Block(-6,9,7,AIR:0)
Block(-6,9,8,AIR:0)
Block(-6,10,-7,AIR:0)
Block(-6,10,-6,IRON_FENCE:0)
RandomBlock(-6,10,-5,CONCRETE:7,60,quark:iron_plate,20,STAINED_CLAY:12,15,STAINED_CLAY:15,5,AIR,7,IRON_BARS,12,CONCRETE:7,100)
Block(-6,10,-4,AIR:0)
Block(-6,10,-3,AIR:0)
RandomBlock(-6,10,-2,CONCRETE:7,60,quark:iron_plate,20,STAINED_CLAY:12,15,STAINED_CLAY:15,5,AIR,7,IRON_BARS,12,CONCRETE:7,100)
RandomBlock(-6,10,-1,CONCRETE:7,60,quark:iron_plate,20,STAINED_CLAY:12,15,STAINED_CLAY:15,5,AIR,7,IRON_BARS,12,CONCRETE:7,100)
RandomBlock(-6,10,0,AIR,90,IRON_TRAPDOOR:9,100)
Block(-6,10,1,AIR:0)
Block(-6,10,2,AIR:0)
Block(-6,10,3,AIR:0)
Block(-6,10,4,AIR:0)
RandomBlock(-6,10,5,CONCRETE:7,60,quark:iron_plate,20,STAINED_CLAY:12,15,STAINED_CLAY:15,5,AIR,7,IRON_BARS,12,CONCRETE:7,100)
RandomBlock(-6,10,6,CONCRETE:7,60,quark:iron_plate,20,STAINED_CLAY:12,15,STAINED_CLAY:15,5,AIR,7,IRON_BARS,12,CONCRETE:7,100)
Block(-6,10,7,AIR:0)
Block(-6,10,8,AIR:0)
Block(-6,11,-7,IRON_FENCE:0)
Block(-6,11,-6,IRON_FENCE:0)
RandomBlock(-6,11,-5,CONCRETE:7,60,quark:iron_plate,20,STAINED_CLAY:12,15,STAINED_CLAY:15,5,AIR,7,IRON_BARS,12,CONCRETE:7,100)
Block(-6,11,-4,AIR:0)
Block(-6,11,-3,AIR:0)
RandomBlock(-6,11,-2,CONCRETE:7,60,quark:iron_plate,20,STAINED_CLAY:12,15,STAINED_CLAY:15,5,AIR,7,IRON_BARS,12,CONCRETE:7,100)
RandomBlock(-6,11,-1,CONCRETE:7,60,quark:iron_plate,20,STAINED_CLAY:12,15,STAINED_CLAY:15,5,AIR,7,IRON_BARS,12,CONCRETE:7,100)
Block(-6,11,0,CONCRETE:4)
Block(-6,11,1,AIR:0)
Block(-6,11,2,STEP:13)
Block(-6,11,3,AIR:0)
Block(-6,11,4,AIR:0)
RandomBlock(-6,11,5,CONCRETE:7,60,quark:iron_plate,20,STAINED_CLAY:12,15,STAINED_CLAY:15,5,AIR,7,IRON_BARS,12,CONCRETE:7,100)
RandomBlock(-6,11,6,CONCRETE:7,60,quark:iron_plate,20,STAINED_CLAY:12,15,STAINED_CLAY:15,5,AIR,7,IRON_BARS,12,CONCRETE:7,100)
Block(-6,11,7,AIR:0)
Block(-6,11,8,AIR:0)
RandomBlock(-6,12,-7,CONCRETE:7,60,quark:iron_plate,20,STAINED_CLAY:12,15,STAINED_CLAY:15,5,AIR,7,IRON_BARS,12,CONCRETE:7,100)
RandomBlock(-6,12,-6,CONCRETE:7,60,quark:iron_plate,20,STAINED_CLAY:12,15,STAINED_CLAY:15,5,AIR,7,IRON_BARS,12,CONCRETE:7,100)
RandomBlock(-6,12,-5,CONCRETE:7,60,quark:iron_plate,20,STAINED_CLAY:12,15,STAINED_CLAY:15,5,AIR,7,IRON_BARS,12,CONCRETE:7,100)
RandomBlock(-6,12,-4,CONCRETE:7,60,quark:iron_plate,20,STAINED_CLAY:12,15,STAINED_CLAY:15,5,AIR,7,IRON_BARS,12,CONCRETE:7,100)
RandomBlock(-6,12,-3,CONCRETE:7,60,quark:iron_plate,20,STAINED_CLAY:12,15,STAINED_CLAY:15,5,AIR,7,IRON_BARS,12,CONCRETE:7,100)
RandomBlock(-6,12,-2,CONCRETE:7,60,quark:iron_plate,20,STAINED_CLAY:12,15,STAINED_CLAY:15,5,AIR,7,IRON_BARS,12,CONCRETE:7,100)
RandomBlock(-6,12,-1,CONCRETE:7,60,quark:iron_plate,20,STAINED_CLAY:12,15,STAINED_CLAY:15,5,AIR,7,IRON_BARS,12,CONCRETE:7,100)
RandomBlock(-6,12,0,CONCRETE:7,60,quark:iron_plate,20,STAINED_CLAY:12,15,STAINED_CLAY:15,5,AIR,7,IRON_BARS,12,CONCRETE:7,100)
RandomBlock(-6,12,1,CONCRETE:7,60,quark:iron_plate,20,STAINED_CLAY:12,15,STAINED_CLAY:15,5,AIR,7,IRON_BARS,12,CONCRETE:7,100)
RandomBlock(-6,12,2,CONCRETE:7,60,quark:iron_plate,20,STAINED_CLAY:12,15,STAINED_CLAY:15,5,AIR,7,IRON_BARS,12,CONCRETE:7,100)
RandomBlock(-6,12,3,CONCRETE:7,60,quark:iron_plate,20,STAINED_CLAY:12,15,STAINED_CLAY:15,5,AIR,7,IRON_BARS,12,CONCRETE:7,100)
RandomBlock(-6,12,4,CONCRETE:7,60,quark:iron_plate,20,STAINED_CLAY:12,15,STAINED_CLAY:15,5,AIR,7,IRON_BARS,12,CONCRETE:7,100)
RandomBlock(-6,12,5,CONCRETE:7,60,quark:iron_plate,20,STAINED_CLAY:12,15,STAINED_CLAY:15,5,AIR,7,IRON_BARS,12,CONCRETE:7,100)
RandomBlock(-6,12,6,CONCRETE:7,60,quark:iron_plate,20,STAINED_CLAY:12,15,STAINED_CLAY:15,5,AIR,7,IRON_BARS,12,CONCRETE:7,100)
RandomBlock(-6,12,7,CONCRETE:7,60,quark:iron_plate,20,STAINED_CLAY:12,15,STAINED_CLAY:15,5,AIR,7,IRON_BARS,12,CONCRETE:7,100)
RandomBlock(-6,12,8,CONCRETE:7,60,quark:iron_plate,20,STAINED_CLAY:12,15,STAINED_CLAY:15,5,AIR,7,IRON_BARS,12,CONCRETE:7,100)
Block(-6,13,-7,AIR:0)
Block(-6,13,-6,AIR:0)
Block(-6,13,-5,AIR:0)
Block(-6,13,-4,AIR:0)
Block(-6,13,-3,AIR:0)
RandomBlock(-6,13,-2,CONCRETE:7,60,quark:iron_plate,20,STAINED_CLAY:12,15,STAINED_CLAY:15,5,AIR,7,IRON_BARS,12,CONCRETE:7,100)
RandomBlock(-6,13,-1,CONCRETE:7,60,quark:iron_plate,20,STAINED_CLAY:12,15,STAINED_CLAY:15,5,AIR,7,IRON_BARS,12,CONCRETE:7,100)
Block(-6,13,0,CONCRETE:4)
Block(-6,13,1,CONCRETE:14)
Block(-6,13,2,AIR:0)
Block(-6,13,3,AIR:0)
Block(-6,13,4,AIR:0)
RandomBlock(-6,13,5,CONCRETE:7,60,quark:iron_plate,20,STAINED_CLAY:12,15,STAINED_CLAY:15,5,AIR,7,IRON_BARS,12,CONCRETE:7,100)
Block(-6,13,6,CONCRETE:12)
Block(-6,13,7,AIR:0)
Block(-6,13,8,AIR:0)
RandomBlock(-6,14,-7,CONCRETE:7,60,quark:iron_plate,20,STAINED_CLAY:12,15,STAINED_CLAY:15,5,AIR,7,IRON_BARS,12,CONCRETE:7,100)
RandomBlock(-6,14,-6,CONCRETE:7,60,quark:iron_plate,20,STAINED_CLAY:12,15,STAINED_CLAY:15,5,AIR,7,IRON_BARS,12,CONCRETE:7,100)
RandomBlock(-6,14,-5,CONCRETE:7,60,quark:iron_plate,20,STAINED_CLAY:12,15,STAINED_CLAY:15,5,AIR,7,IRON_BARS,12,CONCRETE:7,100)
RandomBlock(-6,14,-4,CONCRETE:7,60,quark:iron_plate,20,STAINED_CLAY:12,15,STAINED_CLAY:15,5,AIR,7,IRON_BARS,12,CONCRETE:7,100)
RandomBlock(-6,14,-3,CONCRETE:7,60,quark:iron_plate,20,STAINED_CLAY:12,15,STAINED_CLAY:15,5,AIR,7,IRON_BARS,12,CONCRETE:7,100)
RandomBlock(-6,14,-2,CONCRETE:7,60,quark:iron_plate,20,STAINED_CLAY:12,15,STAINED_CLAY:15,5,AIR,7,IRON_BARS,12,CONCRETE:7,100)
RandomBlock(-6,14,-1,CONCRETE:7,60,quark:iron_plate,20,STAINED_CLAY:12,15,STAINED_CLAY:15,5,AIR,7,IRON_BARS,12,CONCRETE:7,100)
Block(-6,14,0,CONCRETE:14)
Block(-6,14,1,CONCRETE:4)
Block(-6,14,2,AIR:0)
Block(-6,14,3,AIR:0)
Block(-6,14,4,AIR:0)
RandomBlock(-6,14,5,CONCRETE:7,60,quark:iron_plate,20,STAINED_CLAY:12,15,STAINED_CLAY:15,5,AIR,7,IRON_BARS,12,CONCRETE:7,100)
RandomBlock(-6,14,6,CONCRETE:7,60,quark:iron_plate,20,STAINED_CLAY:12,15,STAINED_CLAY:15,5,AIR,7,IRON_BARS,12,CONCRETE:7,100)
RandomBlock(-6,14,7,CONCRETE:7,60,quark:iron_plate,20,STAINED_CLAY:12,15,STAINED_CLAY:15,5,AIR,7,IRON_BARS,12,CONCRETE:7,100)
RandomBlock(-6,14,8,CONCRETE:7,60,quark:iron_plate,20,STAINED_CLAY:12,15,STAINED_CLAY:15,5,AIR,7,IRON_BARS,12,CONCRETE:7,100)
RandomBlock(-6,15,-7,CONCRETE:7,60,quark:iron_plate,20,STAINED_CLAY:12,15,STAINED_CLAY:15,5,AIR,7,IRON_BARS,12,CONCRETE:7,100)
RandomBlock(-6,15,-6,CONCRETE:7,60,quark:iron_plate,20,STAINED_CLAY:12,15,STAINED_CLAY:15,5,AIR,7,IRON_BARS,12,CONCRETE:7,100)
RandomBlock(-6,15,-5,CONCRETE:7,60,quark:iron_plate,20,STAINED_CLAY:12,15,STAINED_CLAY:15,5,AIR,7,IRON_BARS,12,CONCRETE:7,100)
RandomBlock(-6,15,-4,CONCRETE:7,60,quark:iron_plate,20,STAINED_CLAY:12,15,STAINED_CLAY:15,5,AIR,7,IRON_BARS,12,CONCRETE:7,100)
RandomBlock(-6,15,-3,CONCRETE:7,60,quark:iron_plate,20,STAINED_CLAY:12,15,STAINED_CLAY:15,5,AIR,7,IRON_BARS,12,CONCRETE:7,100)
RandomBlock(-6,15,-2,CONCRETE:7,60,quark:iron_plate,20,STAINED_CLAY:12,15,STAINED_CLAY:15,5,AIR,7,IRON_BARS,12,CONCRETE:7,100)
RandomBlock(-6,15,-1,CONCRETE:7,60,quark:iron_plate,20,STAINED_CLAY:12,15,STAINED_CLAY:15,5,AIR,7,IRON_BARS,12,CONCRETE:7,100)
RandomBlock(-6,15,0,CONCRETE:7,60,quark:iron_plate,20,STAINED_CLAY:12,15,STAINED_CLAY:15,5,AIR,7,IRON_BARS,12,CONCRETE:7,100)
RandomBlock(-6,15,1,CONCRETE:7,60,quark:iron_plate,20,STAINED_CLAY:12,15,STAINED_CLAY:15,5,AIR,7,IRON_BARS,12,CONCRETE:7,100)
RandomBlock(-6,15,2,CONCRETE:7,60,quark:iron_plate,20,STAINED_CLAY:12,15,STAINED_CLAY:15,5,AIR,7,IRON_BARS,12,CONCRETE:7,100)
RandomBlock(-6,15,3,CONCRETE:7,60,quark:iron_plate,20,STAINED_CLAY:12,15,STAINED_CLAY:15,5,AIR,7,IRON_BARS,12,CONCRETE:7,100)
RandomBlock(-6,15,4,CONCRETE:7,60,quark:iron_plate,20,STAINED_CLAY:12,15,STAINED_CLAY:15,5,AIR,7,IRON_BARS,12,CONCRETE:7,100)
RandomBlock(-6,15,5,CONCRETE:7,60,quark:iron_plate,20,STAINED_CLAY:12,15,STAINED_CLAY:15,5,AIR,7,IRON_BARS,12,CONCRETE:7,100)
RandomBlock(-6,15,6,CONCRETE:7,60,quark:iron_plate,20,STAINED_CLAY:12,15,STAINED_CLAY:15,5,AIR,7,IRON_BARS,12,CONCRETE:7,100)
RandomBlock(-6,15,7,CONCRETE:7,60,quark:iron_plate,20,STAINED_CLAY:12,15,STAINED_CLAY:15,5,AIR,7,IRON_BARS,12,CONCRETE:7,100)
RandomBlock(-6,15,8,CONCRETE:7,60,quark:iron_plate,20,STAINED_CLAY:12,15,STAINED_CLAY:15,5,AIR,7,IRON_BARS,12,CONCRETE:7,100)
Block(-6,16,-7,OBSIDIAN:0)
Block(-6,16,-6,OBSIDIAN:0)
Block(-6,16,-5,OBSIDIAN:0)
Block(-6,16,-4,OBSIDIAN:0)
Block(-6,16,-3,OBSIDIAN:0)
Block(-6,16,-2,OBSIDIAN:0)
Block(-6,16,-1,OBSIDIAN:0)
Block(-6,16,0,OBSIDIAN:0)
Block(-6,16,1,OBSIDIAN:0)
Block(-6,16,2,OBSIDIAN:0)
Block(-6,16,3,OBSIDIAN:0)
Block(-6,16,4,OBSIDIAN:0)
Block(-6,16,5,OBSIDIAN:0)
Block(-6,16,6,OBSIDIAN:0)
Block(-6,16,7,OBSIDIAN:0)
Block(-6,16,8,OBSIDIAN:0)
RandomBlock(-6,17,-7,CONCRETE:7,60,quark:iron_plate,20,STAINED_CLAY:12,15,STAINED_CLAY:15,5,AIR,7,IRON_BARS,12,CONCRETE:7,100)
RandomBlock(-6,17,-6,CONCRETE:7,60,quark:iron_plate,20,STAINED_CLAY:12,15,STAINED_CLAY:15,5,AIR,7,IRON_BARS,12,CONCRETE:7,100)
RandomBlock(-6,17,-5,CONCRETE:7,60,quark:iron_plate,20,STAINED_CLAY:12,15,STAINED_CLAY:15,5,AIR,7,IRON_BARS,12,CONCRETE:7,100)
RandomBlock(-6,17,-4,CONCRETE:7,60,quark:iron_plate,20,STAINED_CLAY:12,15,STAINED_CLAY:15,5,AIR,7,IRON_BARS,12,CONCRETE:7,100)
RandomBlock(-6,17,-3,CONCRETE:7,60,quark:iron_plate,20,STAINED_CLAY:12,15,STAINED_CLAY:15,5,AIR,7,IRON_BARS,12,CONCRETE:7,100)
RandomBlock(-6,17,-2,CONCRETE:7,60,quark:iron_plate,20,STAINED_CLAY:12,15,STAINED_CLAY:15,5,AIR,7,IRON_BARS,12,CONCRETE:7,100)
RandomBlock(-6,17,-1,CONCRETE:7,60,quark:iron_plate,20,STAINED_CLAY:12,15,STAINED_CLAY:15,5,AIR,7,IRON_BARS,12,CONCRETE:7,100)
RandomBlock(-6,17,0,CONCRETE:7,60,quark:iron_plate,20,STAINED_CLAY:12,15,STAINED_CLAY:15,5,AIR,7,IRON_BARS,12,CONCRETE:7,100)
RandomBlock(-6,17,1,CONCRETE:7,60,quark:iron_plate,20,STAINED_CLAY:12,15,STAINED_CLAY:15,5,AIR,7,IRON_BARS,12,CONCRETE:7,100)
RandomBlock(-6,17,2,CONCRETE:7,60,quark:iron_plate,20,STAINED_CLAY:12,15,STAINED_CLAY:15,5,AIR,7,IRON_BARS,12,CONCRETE:7,100)
RandomBlock(-6,17,3,CONCRETE:7,60,quark:iron_plate,20,STAINED_CLAY:12,15,STAINED_CLAY:15,5,AIR,7,IRON_BARS,12,CONCRETE:7,100)
RandomBlock(-6,17,4,CONCRETE:7,60,quark:iron_plate,20,STAINED_CLAY:12,15,STAINED_CLAY:15,5,AIR,7,IRON_BARS,12,CONCRETE:7,100)
RandomBlock(-6,17,5,CONCRETE:7,60,quark:iron_plate,20,STAINED_CLAY:12,15,STAINED_CLAY:15,5,AIR,7,IRON_BARS,12,CONCRETE:7,100)
RandomBlock(-6,17,6,CONCRETE:7,60,quark:iron_plate,20,STAINED_CLAY:12,15,STAINED_CLAY:15,5,AIR,7,IRON_BARS,12,CONCRETE:7,100)
RandomBlock(-6,17,7,CONCRETE:7,60,quark:iron_plate,20,STAINED_CLAY:12,15,STAINED_CLAY:15,5,AIR,7,IRON_BARS,12,CONCRETE:7,100)
RandomBlock(-6,17,8,CONCRETE:7,60,quark:iron_plate,20,STAINED_CLAY:12,15,STAINED_CLAY:15,5,AIR,7,IRON_BARS,12,CONCRETE:7,100)
Block(-6,18,-7,OBSIDIAN:0)
Block(-6,18,-6,OBSIDIAN:0)
Block(-6,18,-5,OBSIDIAN:0)
Block(-6,18,-4,OBSIDIAN:0)
Block(-6,18,-3,OBSIDIAN:0)
Block(-6,18,-2,OBSIDIAN:0)
Block(-6,18,-1,OBSIDIAN:0)
Block(-6,18,0,OBSIDIAN:0)
Block(-6,18,1,OBSIDIAN:0)
Block(-6,18,2,OBSIDIAN:0)
Block(-6,18,3,OBSIDIAN:0)
Block(-6,18,4,OBSIDIAN:0)
Block(-6,18,5,OBSIDIAN:0)
Block(-6,18,6,OBSIDIAN:0)
Block(-6,18,7,OBSIDIAN:0)
Block(-6,18,8,CONCRETE:0)
Block(-6,19,-7,OBSIDIAN:0)
Block(-6,19,-6,OBSIDIAN:0)
Block(-6,19,-5,OBSIDIAN:0)
Block(-6,19,-4,OBSIDIAN:0)
Block(-6,19,-3,OBSIDIAN:0)
Block(-6,19,-2,OBSIDIAN:0)
Block(-6,19,-1,OBSIDIAN:0)
Block(-6,19,0,OBSIDIAN:0)
Block(-6,19,1,OBSIDIAN:0)
Block(-6,19,2,OBSIDIAN:0)
Block(-6,19,3,OBSIDIAN:0)
Block(-6,19,4,OBSIDIAN:0)
Block(-6,19,5,OBSIDIAN:0)
Block(-6,19,6,OBSIDIAN:0)
Block(-6,19,7,OBSIDIAN:0)
Block(-6,19,8,CONCRETE:0)
Block(-6,20,-7,OBSIDIAN:0)
Block(-6,20,-6,OBSIDIAN:0)
Block(-6,20,-5,OBSIDIAN:0)
Block(-6,20,-4,OBSIDIAN:0)
Block(-6,20,-3,OBSIDIAN:0)
Block(-6,20,-2,OBSIDIAN:0)
Block(-6,20,-1,OBSIDIAN:0)
Block(-6,20,0,OBSIDIAN:0)
Block(-6,20,1,OBSIDIAN:0)
Block(-6,20,2,OBSIDIAN:0)
Block(-6,20,3,OBSIDIAN:0)
Block(-6,20,4,OBSIDIAN:0)
Block(-6,20,5,OBSIDIAN:0)
Block(-6,20,6,OBSIDIAN:0)
Block(-6,20,7,OBSIDIAN:0)
Block(-6,20,8,CONCRETE:0)
Block(-6,21,-7,OBSIDIAN:0)
Block(-6,21,-6,OBSIDIAN:0)
Block(-6,21,-5,OBSIDIAN:0)
Block(-6,21,-4,OBSIDIAN:0)
Block(-6,21,-3,OBSIDIAN:0)
Block(-6,21,-2,OBSIDIAN:0)
Block(-6,21,-1,OBSIDIAN:0)
Block(-6,21,0,OBSIDIAN:0)
Block(-6,21,1,OBSIDIAN:0)
Block(-6,21,2,OBSIDIAN:0)
Block(-6,21,3,OBSIDIAN:0)
Block(-6,21,4,OBSIDIAN:0)
Block(-6,21,5,OBSIDIAN:0)
Block(-6,21,6,OBSIDIAN:0)
Block(-6,21,7,OBSIDIAN:0)
Block(-6,21,8,CONCRETE:0)
Block(-6,22,-7,OBSIDIAN:0)
Block(-6,22,-6,OBSIDIAN:0)
Block(-6,22,-5,OBSIDIAN:0)
Block(-6,22,-4,OBSIDIAN:0)
Block(-6,22,-3,OBSIDIAN:0)
Block(-6,22,-2,OBSIDIAN:0)
Block(-6,22,-1,OBSIDIAN:0)
Block(-6,22,0,OBSIDIAN:0)
Block(-6,22,1,OBSIDIAN:0)
Block(-6,22,2,OBSIDIAN:0)
Block(-6,22,3,OBSIDIAN:0)
Block(-6,22,4,OBSIDIAN:0)
Block(-6,22,5,OBSIDIAN:0)
Block(-6,22,6,OBSIDIAN:0)
Block(-6,22,7,OBSIDIAN:0)
Block(-6,22,8,CONCRETE:0)
Block(-6,23,-7,CONCRETE:0)
Block(-6,23,-6,CONCRETE:0)
Block(-6,23,-5,CONCRETE:0)
Block(-6,23,-4,CONCRETE:0)
Block(-6,23,-3,CONCRETE:0)
Block(-6,23,-2,CONCRETE:0)
Block(-6,23,-1,CONCRETE:0)
Block(-6,23,0,CONCRETE:0)
Block(-6,23,1,CONCRETE:0)
Block(-6,23,2,CONCRETE:0)
Block(-6,23,3,CONCRETE:0)
Block(-6,23,4,CONCRETE:0)
Block(-6,23,5,CONCRETE:0)
Block(-6,23,6,CONCRETE:0)
Block(-6,23,7,CONCRETE:0)
Block(-6,23,8,CONCRETE:0)
Block(-6,29,-7,STEP:8)
Block(-6,29,-6,QUARTZ_STAIRS:4)
Block(-6,29,-5,STEP:8)
Block(-6,29,-4,QUARTZ_STAIRS:4)
Block(-6,29,-3,STEP:8)
Block(-6,29,-2,QUARTZ_STAIRS:4)
Block(-6,29,-1,STEP:8)
Block(-6,29,0,QUARTZ_STAIRS:4)
Block(-6,30,-7,IRON_FENCE:0)
Block(-6,30,-6,COBBLE_WALL:0)
Block(-6,30,-5,IRON_FENCE:0)
Block(-6,30,-4,COBBLE_WALL:0)
Block(-6,30,-3,IRON_FENCE:0)
Block(-6,30,-2,COBBLE_WALL:0)
Block(-6,30,-1,IRON_FENCE:0)
Block(-6,30,0,COBBLE_WALL:0)
Block(-6,33,-7,STEP:8)
Block(-6,33,-6,QUARTZ_STAIRS:4)
Block(-6,33,-5,STEP:8)
Block(-6,33,-4,QUARTZ_STAIRS:4)
Block(-6,33,-3,STEP:8)
Block(-6,33,-2,QUARTZ_STAIRS:4)
Block(-6,33,-1,STEP:8)
Block(-6,33,0,QUARTZ_STAIRS:4)
Block(-6,34,-7,IRON_FENCE:0)
Block(-6,34,-6,COBBLE_WALL:0)
Block(-6,34,-5,IRON_FENCE:0)
Block(-6,34,-4,COBBLE_WALL:0)
Block(-6,34,-3,IRON_FENCE:0)
Block(-6,34,-2,COBBLE_WALL:0)
Block(-6,34,-1,IRON_FENCE:0)
Block(-6,34,0,COBBLE_WALL:0)
RandomBlock(-5,0,-7,CONCRETE:7,60,quark:iron_plate,20,STAINED_CLAY:12,15,STAINED_CLAY:15,5,AIR,7,IRON_BARS,12,CONCRETE:7,100)
RandomBlock(-5,0,-6,CONCRETE:7,60,quark:iron_plate,20,STAINED_CLAY:12,15,STAINED_CLAY:15,5,AIR,7,IRON_BARS,12,CONCRETE:7,100)
RandomBlock(-5,0,-5,CONCRETE:7,60,quark:iron_plate,20,STAINED_CLAY:12,15,STAINED_CLAY:15,5,AIR,7,IRON_BARS,12,CONCRETE:7,100)
RandomBlock(-5,0,-4,CONCRETE:7,60,quark:iron_plate,20,STAINED_CLAY:12,15,STAINED_CLAY:15,5,AIR,7,IRON_BARS,12,CONCRETE:7,100)
RandomBlock(-5,0,-3,CONCRETE:7,60,quark:iron_plate,20,STAINED_CLAY:12,15,STAINED_CLAY:15,5,AIR,7,IRON_BARS,12,CONCRETE:7,100)
RandomBlock(-5,0,-2,CONCRETE:7,60,quark:iron_plate,20,STAINED_CLAY:12,15,STAINED_CLAY:15,5,AIR,7,IRON_BARS,12,CONCRETE:7,100)
RandomBlock(-5,0,-1,CONCRETE:7,60,quark:iron_plate,20,STAINED_CLAY:12,15,STAINED_CLAY:15,5,AIR,7,IRON_BARS,12,CONCRETE:7,100)
RandomBlock(-5,0,0,CONCRETE:7,60,quark:iron_plate,20,STAINED_CLAY:12,15,STAINED_CLAY:15,5,AIR,7,IRON_BARS,12,CONCRETE:7,100)
RandomBlock(-5,0,1,CONCRETE:7,60,quark:iron_plate,20,STAINED_CLAY:12,15,STAINED_CLAY:15,5,AIR,7,IRON_BARS,12,CONCRETE:7,100)
RandomBlock(-5,0,2,CONCRETE:7,60,quark:iron_plate,20,STAINED_CLAY:12,15,STAINED_CLAY:15,5,AIR,7,IRON_BARS,12,CONCRETE:7,100)
RandomBlock(-5,0,3,CONCRETE:7,60,quark:iron_plate,20,STAINED_CLAY:12,15,STAINED_CLAY:15,5,AIR,7,IRON_BARS,12,CONCRETE:7,100)
RandomBlock(-5,0,4,CONCRETE:7,60,quark:iron_plate,20,STAINED_CLAY:12,15,STAINED_CLAY:15,5,AIR,7,IRON_BARS,12,CONCRETE:7,100)
RandomBlock(-5,0,5,CONCRETE:7,60,quark:iron_plate,20,STAINED_CLAY:12,15,STAINED_CLAY:15,5,AIR,7,IRON_BARS,12,CONCRETE:7,100)
RandomBlock(-5,0,6,CONCRETE:7,60,quark:iron_plate,20,STAINED_CLAY:12,15,STAINED_CLAY:15,5,AIR,7,IRON_BARS,12,CONCRETE:7,100)
RandomBlock(-5,0,7,CONCRETE:7,60,quark:iron_plate,20,STAINED_CLAY:12,15,STAINED_CLAY:15,5,AIR,7,IRON_BARS,12,CONCRETE:7,100)
RandomBlock(-5,0,8,CONCRETE:7,60,quark:iron_plate,20,STAINED_CLAY:12,15,STAINED_CLAY:15,5,AIR,7,IRON_BARS,12,CONCRETE:7,100)
Block(-5,1,-7,OBSIDIAN:0)
Block(-5,1,-6,OBSIDIAN:0)
Block(-5,1,-5,OBSIDIAN:0)
Block(-5,1,-4,OBSIDIAN:0)
Block(-5,1,-3,OBSIDIAN:0)
Block(-5,1,-2,OBSIDIAN:0)
Block(-5,1,-1,OBSIDIAN:0)
Block(-5,1,0,OBSIDIAN:0)
Block(-5,1,1,OBSIDIAN:0)
Block(-5,1,2,OBSIDIAN:0)
Block(-5,1,3,OBSIDIAN:0)
Block(-5,1,4,OBSIDIAN:0)
Block(-5,1,5,OBSIDIAN:0)
Block(-5,1,6,OBSIDIAN:0)
Block(-5,1,7,OBSIDIAN:0)
Block(-5,1,8,OBSIDIAN:0)
RandomBlock(-5,2,-7,CONCRETE:7,60,quark:iron_plate,20,STAINED_CLAY:12,15,STAINED_CLAY:15,5,AIR,7,IRON_BARS,12,CONCRETE:7,100)
RandomBlock(-5,2,-6,CONCRETE:7,60,quark:iron_plate,20,STAINED_CLAY:12,15,STAINED_CLAY:15,5,AIR,7,IRON_BARS,12,CONCRETE:7,100)
RandomBlock(-5,2,-5,CONCRETE:7,60,quark:iron_plate,20,STAINED_CLAY:12,15,STAINED_CLAY:15,5,AIR,7,IRON_BARS,12,CONCRETE:7,100)
RandomBlock(-5,2,-4,CONCRETE:7,60,quark:iron_plate,20,STAINED_CLAY:12,15,STAINED_CLAY:15,5,AIR,7,IRON_BARS,12,CONCRETE:7,100)
RandomBlock(-5,2,-3,CONCRETE:7,60,quark:iron_plate,20,STAINED_CLAY:12,15,STAINED_CLAY:15,5,AIR,7,IRON_BARS,12,CONCRETE:7,100)
RandomBlock(-5,2,-2,CONCRETE:7,60,quark:iron_plate,20,STAINED_CLAY:12,15,STAINED_CLAY:15,5,AIR,7,IRON_BARS,12,CONCRETE:7,100)
RandomBlock(-5,2,-1,CONCRETE:7,60,quark:iron_plate,20,STAINED_CLAY:12,15,STAINED_CLAY:15,5,AIR,7,IRON_BARS,12,CONCRETE:7,100)
RandomBlock(-5,2,0,CONCRETE:7,60,quark:iron_plate,20,STAINED_CLAY:12,15,STAINED_CLAY:15,5,AIR,7,IRON_BARS,12,CONCRETE:7,100)
RandomBlock(-5,2,1,CONCRETE:7,60,quark:iron_plate,20,STAINED_CLAY:12,15,STAINED_CLAY:15,5,AIR,7,IRON_BARS,12,CONCRETE:7,100)
RandomBlock(-5,2,2,CONCRETE:7,60,quark:iron_plate,20,STAINED_CLAY:12,15,STAINED_CLAY:15,5,AIR,7,IRON_BARS,12,CONCRETE:7,100)
RandomBlock(-5,2,3,CONCRETE:7,60,quark:iron_plate,20,STAINED_CLAY:12,15,STAINED_CLAY:15,5,AIR,7,IRON_BARS,12,CONCRETE:7,100)
RandomBlock(-5,2,4,CONCRETE:7,60,quark:iron_plate,20,STAINED_CLAY:12,15,STAINED_CLAY:15,5,AIR,7,IRON_BARS,12,CONCRETE:7,100)
RandomBlock(-5,2,5,CONCRETE:7,60,quark:iron_plate,20,STAINED_CLAY:12,15,STAINED_CLAY:15,5,AIR,7,IRON_BARS,12,CONCRETE:7,100)
RandomBlock(-5,2,6,CONCRETE:7,60,quark:iron_plate,20,STAINED_CLAY:12,15,STAINED_CLAY:15,5,AIR,7,IRON_BARS,12,CONCRETE:7,100)
RandomBlock(-5,2,7,CONCRETE:7,60,quark:iron_plate,20,STAINED_CLAY:12,15,STAINED_CLAY:15,5,AIR,7,IRON_BARS,12,CONCRETE:7,100)
RandomBlock(-5,2,8,CONCRETE:7,60,quark:iron_plate,20,STAINED_CLAY:12,15,STAINED_CLAY:15,5,AIR,7,IRON_BARS,12,CONCRETE:7,100)
RandomBlock(-5,3,-7,CONCRETE:7,60,quark:iron_plate,20,STAINED_CLAY:12,15,STAINED_CLAY:15,5,AIR,7,IRON_BARS,12,CONCRETE:7,100)
RandomBlock(-5,3,-6,CONCRETE:7,60,quark:iron_plate,20,STAINED_CLAY:12,15,STAINED_CLAY:15,5,AIR,7,IRON_BARS,12,CONCRETE:7,100)
RandomBlock(-5,3,-5,CONCRETE:7,60,quark:iron_plate,20,STAINED_CLAY:12,15,STAINED_CLAY:15,5,AIR,7,IRON_BARS,12,CONCRETE:7,100)
RandomBlock(-5,3,-4,CONCRETE:7,60,quark:iron_plate,20,STAINED_CLAY:12,15,STAINED_CLAY:15,5,AIR,7,IRON_BARS,12,CONCRETE:7,100)
RandomBlock(-5,3,-3,CONCRETE:7,60,quark:iron_plate,20,STAINED_CLAY:12,15,STAINED_CLAY:15,5,AIR,7,IRON_BARS,12,CONCRETE:7,100)
RandomBlock(-5,3,-2,CONCRETE:7,60,quark:iron_plate,20,STAINED_CLAY:12,15,STAINED_CLAY:15,5,AIR,7,IRON_BARS,12,CONCRETE:7,100)
RandomBlock(-5,3,-1,CONCRETE:7,60,quark:iron_plate,20,STAINED_CLAY:12,15,STAINED_CLAY:15,5,AIR,7,IRON_BARS,12,CONCRETE:7,100)
RandomBlock(-5,3,0,CONCRETE:7,60,quark:iron_plate,20,STAINED_CLAY:12,15,STAINED_CLAY:15,5,AIR,7,IRON_BARS,12,CONCRETE:7,100)
RandomBlock(-5,3,1,CONCRETE:7,60,quark:iron_plate,20,STAINED_CLAY:12,15,STAINED_CLAY:15,5,AIR,7,IRON_BARS,12,CONCRETE:7,100)
RandomBlock(-5,3,2,CONCRETE:7,60,quark:iron_plate,20,STAINED_CLAY:12,15,STAINED_CLAY:15,5,AIR,7,IRON_BARS,12,CONCRETE:7,100)
RandomBlock(-5,3,3,CONCRETE:7,60,quark:iron_plate,20,STAINED_CLAY:12,15,STAINED_CLAY:15,5,AIR,7,IRON_BARS,12,CONCRETE:7,100)
RandomBlock(-5,3,4,CONCRETE:7,60,quark:iron_plate,20,STAINED_CLAY:12,15,STAINED_CLAY:15,5,AIR,7,IRON_BARS,12,CONCRETE:7,100)
RandomBlock(-5,3,5,CONCRETE:7,60,quark:iron_plate,20,STAINED_CLAY:12,15,STAINED_CLAY:15,5,AIR,7,IRON_BARS,12,CONCRETE:7,100)
RandomBlock(-5,3,6,CONCRETE:7,60,quark:iron_plate,20,STAINED_CLAY:12,15,STAINED_CLAY:15,5,AIR,7,IRON_BARS,12,CONCRETE:7,100)
RandomBlock(-5,3,7,CONCRETE:7,60,quark:iron_plate,20,STAINED_CLAY:12,15,STAINED_CLAY:15,5,AIR,7,IRON_BARS,12,CONCRETE:7,100)
RandomBlock(-5,3,8,CONCRETE:7,60,quark:iron_plate,20,STAINED_CLAY:12,15,STAINED_CLAY:15,5,AIR,7,IRON_BARS,12,CONCRETE:7,100)
RandomBlock(-5,4,-7,CONCRETE:7,60,quark:iron_plate,20,STAINED_CLAY:12,15,STAINED_CLAY:15,5,AIR,7,IRON_BARS,12,CONCRETE:7,100)
RandomBlock(-5,4,-6,CONCRETE:8,60,notreepunching:cobblestone/andesite,15,STONE:5,15,STAINED_CLAY:9,10,IRON_BARS,12,AIR,8,STAINED_CLAY:12,30,CONCRETE:8,100)
Block(-5,4,-5,AIR:0)
RandomBlock(-5,4,-4,CONCRETE:7,60,quark:iron_plate,20,STAINED_CLAY:12,15,STAINED_CLAY:15,5,AIR,7,IRON_BARS,12,CONCRETE:7,100)
RandomBlock(-5,4,-3,CONCRETE:7,60,quark:iron_plate,20,STAINED_CLAY:12,15,STAINED_CLAY:15,5,AIR,7,IRON_BARS,12,CONCRETE:7,100)
RandomBlock(-5,4,-2,CONCRETE:7,60,quark:iron_plate,20,STAINED_CLAY:12,15,STAINED_CLAY:15,5,AIR,7,IRON_BARS,12,CONCRETE:7,100)
RandomBlock(-5,4,-1,CONCRETE:7,60,quark:iron_plate,20,STAINED_CLAY:12,15,STAINED_CLAY:15,5,AIR,7,IRON_BARS,12,CONCRETE:7,100)
RandomBlock(-5,4,0,CONCRETE:7,60,quark:iron_plate,20,STAINED_CLAY:12,15,STAINED_CLAY:15,5,AIR,7,IRON_BARS,12,CONCRETE:7,100)
RandomBlock(-5,4,1,CONCRETE:7,60,quark:iron_plate,20,STAINED_CLAY:12,15,STAINED_CLAY:15,5,AIR,7,IRON_BARS,12,CONCRETE:7,100)
RandomBlock(-5,4,2,CONCRETE:7,60,quark:iron_plate,20,STAINED_CLAY:12,15,STAINED_CLAY:15,5,AIR,7,IRON_BARS,12,CONCRETE:7,100)
RandomBlock(-5,4,3,CONCRETE:7,60,quark:iron_plate,20,STAINED_CLAY:12,15,STAINED_CLAY:15,5,AIR,7,IRON_BARS,12,CONCRETE:7,100)
RandomBlock(-5,4,4,CONCRETE:7,60,quark:iron_plate,20,STAINED_CLAY:12,15,STAINED_CLAY:15,5,AIR,7,IRON_BARS,12,CONCRETE:7,100)
RandomBlock(-5,4,5,CONCRETE:7,60,quark:iron_plate,20,STAINED_CLAY:12,15,STAINED_CLAY:15,5,AIR,7,IRON_BARS,12,CONCRETE:7,100)
RandomBlock(-5,4,6,CONCRETE:7,60,quark:iron_plate,20,STAINED_CLAY:12,15,STAINED_CLAY:15,5,AIR,7,IRON_BARS,12,CONCRETE:7,100)
RandomBlock(-5,4,7,CONCRETE:7,60,quark:iron_plate,20,STAINED_CLAY:12,15,STAINED_CLAY:15,5,AIR,7,IRON_BARS,12,CONCRETE:7,100)
RandomBlock(-5,4,8,CONCRETE:7,60,quark:iron_plate,20,STAINED_CLAY:12,15,STAINED_CLAY:15,5,AIR,7,IRON_BARS,12,CONCRETE:7,100)
Block(-5,5,-7,SMOOTH_STAIRS:1)
RandomBlock(-5,5,-6,CONCRETE:8,60,notreepunching:cobblestone/andesite,15,STONE:5,15,STAINED_CLAY:9,10,IRON_BARS,12,AIR,8,STAINED_CLAY:12,30,CONCRETE:8,100)
Block(-5,5,-5,AIR:0)
Block(-5,5,-4,AIR:0)
Block(-5,5,-3,AIR:0)
Block(-5,5,-2,OBSIDIAN:0)
Block(-5,5,-1,IRON_FENCE:0)
Block(-5,5,0,AIR:0)
Block(-5,5,1,AIR:0)
Block(-5,5,2,AIR:0)
Block(-5,5,3,AIR:0)
Block(-5,5,4,AIR:0)
Block(-5,5,5,IRON_FENCE:0)
Block(-5,5,6,OBSIDIAN:0)
Block(-5,5,8,AIR:0)
Block(-5,6,-7,AIR:0)
RandomBlock(-5,6,-6,CONCRETE:8,60,notreepunching:cobblestone/andesite,15,STONE:5,15,STAINED_CLAY:9,10,IRON_BARS,12,AIR,8,STAINED_CLAY:12,30,CONCRETE:8,100)
Block(-5,6,-5,AIR:0)
Block(-5,6,-4,AIR:0)
Block(-5,6,-3,AIR:0)
Block(-5,6,-2,OBSIDIAN:0)
Block(-5,6,-1,IRON_FENCE:0)
Block(-5,6,0,AIR:0)
Block(-5,6,1,AIR:0)
Block(-5,6,2,AIR:0)
Block(-5,6,3,AIR:0)
Block(-5,6,4,AIR:0)
Block(-5,6,5,IRON_FENCE:0)
Block(-5,6,6,OBSIDIAN:0)
RandomBlock(-5,6,7,AIR,90,IRON_TRAPDOOR:1,100)
Block(-5,6,8,AIR:0)
RandomBlock(-5,7,-7,CONCRETE:8,60,notreepunching:cobblestone/andesite,15,STONE:5,15,STAINED_CLAY:9,10,IRON_BARS,12,AIR,8,STAINED_CLAY:12,30,CONCRETE:8,100)
RandomBlock(-5,7,-6,CONCRETE:8,60,notreepunching:cobblestone/andesite,15,STONE:5,15,STAINED_CLAY:9,10,IRON_BARS,12,AIR,8,STAINED_CLAY:12,30,CONCRETE:8,100)
Block(-5,7,-5,AIR:0)
Block(-5,7,-4,AIR:0)
Block(-5,7,-3,AIR:0)
Block(-5,7,-2,OBSIDIAN:0)
Block(-5,7,-1,IRON_FENCE:0)
Block(-5,7,0,AIR:0)
Block(-5,7,1,AIR:0)
Block(-5,7,2,AIR:0)
Block(-5,7,3,AIR:0)
Block(-5,7,4,AIR:0)
Block(-5,7,5,IRON_FENCE:0)
Block(-5,7,6,OBSIDIAN:0)
RandomBlock(-5,7,7,AIR,90,IRON_TRAPDOOR:1,100)
Block(-5,7,8,AIR:0)
RandomBlock(-5,8,-7,CONCRETE:8,60,notreepunching:cobblestone/andesite,15,STONE:5,15,STAINED_CLAY:9,10,IRON_BARS,12,AIR,8,STAINED_CLAY:12,30,CONCRETE:8,100)
RandomBlock(-5,8,-6,CONCRETE:8,60,notreepunching:cobblestone/andesite,15,STONE:5,15,STAINED_CLAY:9,10,IRON_BARS,12,AIR,8,STAINED_CLAY:12,30,CONCRETE:8,100)
RandomBlock(-5,8,-5,CONCRETE:7,60,quark:iron_plate,20,STAINED_CLAY:12,15,STAINED_CLAY:15,5,AIR,7,IRON_BARS,12,CONCRETE:7,100)
RandomBlock(-5,8,-4,AIR,90,IRON_TRAPDOOR:10,100)
RandomBlock(-5,8,-3,AIR,90,IRON_TRAPDOOR:10,100)
RandomBlock(-5,8,-2,CONCRETE:7,60,quark:iron_plate,20,STAINED_CLAY:12,15,STAINED_CLAY:15,5,AIR,7,IRON_BARS,12,CONCRETE:7,100)
RandomBlock(-5,8,-1,CONCRETE:7,60,quark:iron_plate,20,STAINED_CLAY:12,15,STAINED_CLAY:15,5,AIR,7,IRON_BARS,12,CONCRETE:7,100)
RandomBlock(-5,8,0,AIR,90,IRON_TRAPDOOR:9,100)
Block(-5,8,1,AIR:0)
Block(-5,8,2,AIR:0)
Block(-5,8,3,AIR:0)
Block(-5,8,4,AIR:0)
RandomBlock(-5,8,5,CONCRETE:7,60,quark:iron_plate,20,STAINED_CLAY:12,15,STAINED_CLAY:15,5,AIR,7,IRON_BARS,12,CONCRETE:7,100)
RandomBlock(-5,8,6,CONCRETE:7,60,quark:iron_plate,20,STAINED_CLAY:12,15,STAINED_CLAY:15,5,AIR,7,IRON_BARS,12,CONCRETE:7,100)
RandomBlock(-5,8,7,AIR,90,IRON_TRAPDOOR:1,100)
Block(-5,8,8,AIR:0)
Block(-5,9,-7,SMOOTH_STAIRS:1)
Block(-5,9,-6,SMOOTH_STAIRS:1)
Block(-5,9,-5,STEP:8)
RandomBlock(-5,9,-4,STONE:6,85,CAULDRON:0,100)
Block(-5,9,-3,AIR:0)
Block(-5,9,-2,OBSIDIAN:0)
Block(-5,9,-1,IRON_FENCE:0)
Block(-5,9,0,CONCRETE:14)
Block(-5,9,1,AIR:0)
Block(-5,9,2,AIR:0)
Block(-5,9,3,AIR:0)
Block(-5,9,4,AIR:0)
Block(-5,9,5,IRON_FENCE:0)
Block(-5,9,6,OBSIDIAN:0)
Block(-5,9,7,AIR:0)
Block(-5,9,8,AIR:0)
Block(-5,10,-7,AIR:0)
Block(-5,10,-6,AIR:0)
Block(-5,10,-5,IRON_FENCE:0)
RandomBlock(-5,10,-4,AIR,90,IRON_TRAPDOOR:2,100)
Block(-5,10,-3,AIR:0)
Block(-5,10,-2,OBSIDIAN:0)
Block(-5,10,-1,IRON_FENCE:0)
RandomBlock(-5,10,0,AIR,90,IRON_TRAPDOOR:11,100)
Block(-5,10,1,AIR:0)
Block(-5,10,2,AIR:0)
Block(-5,10,3,AIR:0)
Block(-5,10,4,AIR:0)
Block(-5,10,5,IRON_FENCE:0)
Block(-5,10,6,OBSIDIAN:0)
Block(-5,10,7,AIR:0)
Block(-5,10,8,AIR:0)
Block(-5,11,-7,AIR:0)
Block(-5,11,-6,AIR:0)
Block(-5,11,-5,IRON_FENCE:0)
Block(-5,11,-4,AIR:0)
Block(-5,11,-3,AIR:0)
Block(-5,11,-2,OBSIDIAN:0)
Block(-5,11,-1,IRON_FENCE:0)
Block(-5,11,0,CONCRETE:4)
Block(-5,11,1,AIR:0)
Block(-5,11,2,STEP:13)
Block(-5,11,3,AIR:0)
Block(-5,11,4,AIR:0)
Block(-5,11,5,IRON_FENCE:0)
Block(-5,11,6,OBSIDIAN:0)
Block(-5,11,7,AIR:0)
Block(-5,11,8,AIR:0)
RandomBlock(-5,12,-7,AIR,90,IRON_TRAPDOOR:9,100)
RandomBlock(-5,12,-6,AIR,90,IRON_TRAPDOOR:9,100)
RandomBlock(-5,12,-5,CONCRETE:7,60,quark:iron_plate,20,STAINED_CLAY:12,15,STAINED_CLAY:15,5,AIR,7,IRON_BARS,12,CONCRETE:7,100)
RandomBlock(-5,12,-4,AIR,90,IRON_TRAPDOOR:11,100)
RandomBlock(-5,12,-3,AIR,90,IRON_TRAPDOOR:11,100)
RandomBlock(-5,12,-2,CONCRETE:7,60,quark:iron_plate,20,STAINED_CLAY:12,15,STAINED_CLAY:15,5,AIR,7,IRON_BARS,12,CONCRETE:7,100)
RandomBlock(-5,12,-1,CONCRETE:7,60,quark:iron_plate,20,STAINED_CLAY:12,15,STAINED_CLAY:15,5,AIR,7,IRON_BARS,12,CONCRETE:7,100)
Block(-5,12,0,STEP:8)
Block(-5,12,1,STEP:8)
Block(-5,12,2,STEP:8)
Block(-5,12,3,STEP:8)
Block(-5,12,4,STEP:8)
RandomBlock(-5,12,5,CONCRETE:7,60,quark:iron_plate,20,STAINED_CLAY:12,15,STAINED_CLAY:15,5,AIR,7,IRON_BARS,12,CONCRETE:7,100)
RandomBlock(-5,12,6,CONCRETE:7,60,quark:iron_plate,20,STAINED_CLAY:12,15,STAINED_CLAY:15,5,AIR,7,IRON_BARS,12,CONCRETE:7,100)
RandomBlock(-5,12,7,AIR,90,IRON_TRAPDOOR:9,100)
RandomBlock(-5,12,8,AIR,90,IRON_TRAPDOOR:11,100)
Block(-5,13,-7,AIR:0)
Block(-5,13,-6,AIR:0)
Block(-5,13,-5,AIR:0)
Block(-5,13,-4,AIR:0)
Block(-5,13,-3,AIR:0)
Block(-5,13,-2,OBSIDIAN:0)
Block(-5,13,-1,IRON_FENCE:0)
Block(-5,13,0,CONCRETE:4)
Block(-5,13,1,CONCRETE:14)
Block(-5,13,2,AIR:0)
Block(-5,13,3,AIR:0)
Block(-5,13,4,AIR:0)
Block(-5,13,5,IRON_FENCE:0)
Block(-5,13,6,CONCRETE:12)
Block(-5,13,7,AIR:0)
Block(-5,13,8,AIR:0)
Block(-5,14,-7,STEP:8)
Block(-5,14,-6,STEP:8)
RandomBlock(-5,14,-5,CONCRETE:7,60,quark:iron_plate,20,STAINED_CLAY:12,15,STAINED_CLAY:15,5,AIR,7,IRON_BARS,12,CONCRETE:7,100)
Block(-5,14,-4,STEP:8)
Block(-5,14,-3,STEP:8)
Block(-5,14,-2,OBSIDIAN:0)
Block(-5,14,-1,IRON_FENCE:0)
Block(-5,14,0,CONCRETE:14)
Block(-5,14,1,CONCRETE:4)
Block(-5,14,2,AIR:0)
Block(-5,14,3,AIR:0)
Block(-5,14,4,AIR:0)
Block(-5,14,5,IRON_FENCE:0)
Block(-5,14,6,OBSIDIAN:0)
Block(-5,14,7,STEP:8)
Block(-5,14,8,STEP:8)
RandomBlock(-5,15,-7,CONCRETE:7,60,quark:iron_plate,20,STAINED_CLAY:12,15,STAINED_CLAY:15,5,AIR,7,IRON_BARS,12,CONCRETE:7,100)
RandomBlock(-5,15,-6,CONCRETE:7,60,quark:iron_plate,20,STAINED_CLAY:12,15,STAINED_CLAY:15,5,AIR,7,IRON_BARS,12,CONCRETE:7,100)
RandomBlock(-5,15,-5,CONCRETE:7,60,quark:iron_plate,20,STAINED_CLAY:12,15,STAINED_CLAY:15,5,AIR,7,IRON_BARS,12,CONCRETE:7,100)
RandomBlock(-5,15,-4,CONCRETE:7,60,quark:iron_plate,20,STAINED_CLAY:12,15,STAINED_CLAY:15,5,AIR,7,IRON_BARS,12,CONCRETE:7,100)
RandomBlock(-5,15,-3,CONCRETE:7,60,quark:iron_plate,20,STAINED_CLAY:12,15,STAINED_CLAY:15,5,AIR,7,IRON_BARS,12,CONCRETE:7,100)
RandomBlock(-5,15,-2,CONCRETE:7,60,quark:iron_plate,20,STAINED_CLAY:12,15,STAINED_CLAY:15,5,AIR,7,IRON_BARS,12,CONCRETE:7,100)
RandomBlock(-5,15,-1,CONCRETE:7,60,quark:iron_plate,20,STAINED_CLAY:12,15,STAINED_CLAY:15,5,AIR,7,IRON_BARS,12,CONCRETE:7,100)
RandomBlock(-5,15,0,CONCRETE:7,60,quark:iron_plate,20,STAINED_CLAY:12,15,STAINED_CLAY:15,5,AIR,7,IRON_BARS,12,CONCRETE:7,100)
RandomBlock(-5,15,1,CONCRETE:7,60,quark:iron_plate,20,STAINED_CLAY:12,15,STAINED_CLAY:15,5,AIR,7,IRON_BARS,12,CONCRETE:7,100)
RandomBlock(-5,15,2,CONCRETE:7,60,quark:iron_plate,20,STAINED_CLAY:12,15,STAINED_CLAY:15,5,AIR,7,IRON_BARS,12,CONCRETE:7,100)
RandomBlock(-5,15,3,CONCRETE:7,60,quark:iron_plate,20,STAINED_CLAY:12,15,STAINED_CLAY:15,5,AIR,7,IRON_BARS,12,CONCRETE:7,100)
RandomBlock(-5,15,4,CONCRETE:7,60,quark:iron_plate,20,STAINED_CLAY:12,15,STAINED_CLAY:15,5,AIR,7,IRON_BARS,12,CONCRETE:7,100)
RandomBlock(-5,15,5,CONCRETE:7,60,quark:iron_plate,20,STAINED_CLAY:12,15,STAINED_CLAY:15,5,AIR,7,IRON_BARS,12,CONCRETE:7,100)
RandomBlock(-5,15,6,CONCRETE:7,60,quark:iron_plate,20,STAINED_CLAY:12,15,STAINED_CLAY:15,5,AIR,7,IRON_BARS,12,CONCRETE:7,100)
RandomBlock(-5,15,7,CONCRETE:7,60,quark:iron_plate,20,STAINED_CLAY:12,15,STAINED_CLAY:15,5,AIR,7,IRON_BARS,12,CONCRETE:7,100)
RandomBlock(-5,15,8,CONCRETE:7,60,quark:iron_plate,20,STAINED_CLAY:12,15,STAINED_CLAY:15,5,AIR,7,IRON_BARS,12,CONCRETE:7,100)
Block(-5,16,-7,OBSIDIAN:0)
Block(-5,16,-6,OBSIDIAN:0)
Block(-5,16,-5,OBSIDIAN:0)
Block(-5,16,-4,OBSIDIAN:0)
Block(-5,16,-3,OBSIDIAN:0)
Block(-5,16,-2,OBSIDIAN:0)
Block(-5,16,-1,OBSIDIAN:0)
Block(-5,16,0,OBSIDIAN:0)
Block(-5,16,1,OBSIDIAN:0)
Block(-5,16,2,OBSIDIAN:0)
Block(-5,16,3,OBSIDIAN:0)
Block(-5,16,4,OBSIDIAN:0)
Block(-5,16,5,OBSIDIAN:0)
Block(-5,16,6,OBSIDIAN:0)
Block(-5,16,7,OBSIDIAN:0)
Block(-5,16,8,OBSIDIAN:0)
RandomBlock(-5,17,-7,CONCRETE:7,60,quark:iron_plate,20,STAINED_CLAY:12,15,STAINED_CLAY:15,5,AIR,7,IRON_BARS,12,CONCRETE:7,100)
RandomBlock(-5,17,-6,CONCRETE:7,60,quark:iron_plate,20,STAINED_CLAY:12,15,STAINED_CLAY:15,5,AIR,7,IRON_BARS,12,CONCRETE:7,100)
RandomBlock(-5,17,-5,CONCRETE:7,60,quark:iron_plate,20,STAINED_CLAY:12,15,STAINED_CLAY:15,5,AIR,7,IRON_BARS,12,CONCRETE:7,100)
RandomBlock(-5,17,-4,CONCRETE:7,60,quark:iron_plate,20,STAINED_CLAY:12,15,STAINED_CLAY:15,5,AIR,7,IRON_BARS,12,CONCRETE:7,100)
RandomBlock(-5,17,-3,CONCRETE:7,60,quark:iron_plate,20,STAINED_CLAY:12,15,STAINED_CLAY:15,5,AIR,7,IRON_BARS,12,CONCRETE:7,100)
RandomBlock(-5,17,-2,CONCRETE:7,60,quark:iron_plate,20,STAINED_CLAY:12,15,STAINED_CLAY:15,5,AIR,7,IRON_BARS,12,CONCRETE:7,100)
RandomBlock(-5,17,-1,CONCRETE:7,60,quark:iron_plate,20,STAINED_CLAY:12,15,STAINED_CLAY:15,5,AIR,7,IRON_BARS,12,CONCRETE:7,100)
RandomBlock(-5,17,0,CONCRETE:7,60,quark:iron_plate,20,STAINED_CLAY:12,15,STAINED_CLAY:15,5,AIR,7,IRON_BARS,12,CONCRETE:7,100)
RandomBlock(-5,17,1,CONCRETE:7,60,quark:iron_plate,20,STAINED_CLAY:12,15,STAINED_CLAY:15,5,AIR,7,IRON_BARS,12,CONCRETE:7,100)
RandomBlock(-5,17,2,CONCRETE:7,60,quark:iron_plate,20,STAINED_CLAY:12,15,STAINED_CLAY:15,5,AIR,7,IRON_BARS,12,CONCRETE:7,100)
RandomBlock(-5,17,3,CONCRETE:7,60,quark:iron_plate,20,STAINED_CLAY:12,15,STAINED_CLAY:15,5,AIR,7,IRON_BARS,12,CONCRETE:7,100)
RandomBlock(-5,17,4,CONCRETE:7,60,quark:iron_plate,20,STAINED_CLAY:12,15,STAINED_CLAY:15,5,AIR,7,IRON_BARS,12,CONCRETE:7,100)
RandomBlock(-5,17,5,CONCRETE:7,60,quark:iron_plate,20,STAINED_CLAY:12,15,STAINED_CLAY:15,5,AIR,7,IRON_BARS,12,CONCRETE:7,100)
RandomBlock(-5,17,6,CONCRETE:7,60,quark:iron_plate,20,STAINED_CLAY:12,15,STAINED_CLAY:15,5,AIR,7,IRON_BARS,12,CONCRETE:7,100)
RandomBlock(-5,17,7,CONCRETE:7,60,quark:iron_plate,20,STAINED_CLAY:12,15,STAINED_CLAY:15,5,AIR,7,IRON_BARS,12,CONCRETE:7,100)
RandomBlock(-5,17,8,CONCRETE:7,60,quark:iron_plate,20,STAINED_CLAY:12,15,STAINED_CLAY:15,5,AIR,7,IRON_BARS,12,CONCRETE:7,100)
Block(-5,18,-7,OBSIDIAN:0)
Block(-5,18,-6,OBSIDIAN:0)
Block(-5,18,-5,OBSIDIAN:0)
Block(-5,18,-4,OBSIDIAN:0)
Block(-5,18,-3,OBSIDIAN:0)
Block(-5,18,-2,OBSIDIAN:0)
Block(-5,18,-1,OBSIDIAN:0)
Block(-5,18,0,OBSIDIAN:0)
Block(-5,18,1,OBSIDIAN:0)
Block(-5,18,2,OBSIDIAN:0)
Block(-5,18,3,OBSIDIAN:0)
Block(-5,18,4,OBSIDIAN:0)
Block(-5,18,5,OBSIDIAN:0)
Block(-5,18,6,OBSIDIAN:0)
Block(-5,18,7,OBSIDIAN:0)
Block(-5,18,8,CONCRETE:0)
Block(-5,19,-7,OBSIDIAN:0)
Block(-5,19,-6,OBSIDIAN:0)
Block(-5,19,-5,OBSIDIAN:0)
Block(-5,19,-4,OBSIDIAN:0)
Block(-5,19,-3,OBSIDIAN:0)
Block(-5,19,-2,OBSIDIAN:0)
Block(-5,19,-1,OBSIDIAN:0)
Block(-5,19,0,OBSIDIAN:0)
Block(-5,19,1,OBSIDIAN:0)
Block(-5,19,2,OBSIDIAN:0)
Block(-5,19,3,OBSIDIAN:0)
Block(-5,19,4,OBSIDIAN:0)
Block(-5,19,5,OBSIDIAN:0)
Block(-5,19,6,OBSIDIAN:0)
Block(-5,19,7,OBSIDIAN:0)
Block(-5,19,8,CONCRETE:0)
Block(-5,20,-7,OBSIDIAN:0)
Block(-5,20,-6,OBSIDIAN:0)
Block(-5,20,-5,OBSIDIAN:0)
Block(-5,20,-4,OBSIDIAN:0)
Block(-5,20,-3,OBSIDIAN:0)
Block(-5,20,-2,OBSIDIAN:0)
Block(-5,20,-1,OBSIDIAN:0)
Block(-5,20,0,OBSIDIAN:0)
Block(-5,20,1,OBSIDIAN:0)
Block(-5,20,2,OBSIDIAN:0)
Block(-5,20,3,OBSIDIAN:0)
Block(-5,20,4,OBSIDIAN:0)
Block(-5,20,5,OBSIDIAN:0)
Block(-5,20,6,OBSIDIAN:0)
Block(-5,20,7,OBSIDIAN:0)
Block(-5,20,8,CONCRETE:0)
Block(-5,21,-7,OBSIDIAN:0)
Block(-5,21,-6,OBSIDIAN:0)
Block(-5,21,-5,OBSIDIAN:0)
Block(-5,21,-4,OBSIDIAN:0)
Block(-5,21,-3,OBSIDIAN:0)
Block(-5,21,-2,OBSIDIAN:0)
Block(-5,21,-1,OBSIDIAN:0)
Block(-5,21,0,OBSIDIAN:0)
Block(-5,21,1,OBSIDIAN:0)
Block(-5,21,2,OBSIDIAN:0)
Block(-5,21,3,OBSIDIAN:0)
Block(-5,21,4,OBSIDIAN:0)
Block(-5,21,5,OBSIDIAN:0)
Block(-5,21,6,OBSIDIAN:0)
Block(-5,21,7,OBSIDIAN:0)
Block(-5,21,8,CONCRETE:0)
Block(-5,22,-7,OBSIDIAN:0)
Block(-5,22,-6,OBSIDIAN:0)
Block(-5,22,-5,OBSIDIAN:0)
Block(-5,22,-4,OBSIDIAN:0)
Block(-5,22,-3,OBSIDIAN:0)
Block(-5,22,-2,OBSIDIAN:0)
Block(-5,22,-1,OBSIDIAN:0)
Block(-5,22,0,OBSIDIAN:0)
Block(-5,22,1,OBSIDIAN:0)
Block(-5,22,2,OBSIDIAN:0)
Block(-5,22,3,OBSIDIAN:0)
Block(-5,22,4,OBSIDIAN:0)
Block(-5,22,5,OBSIDIAN:0)
Block(-5,22,6,OBSIDIAN:0)
Block(-5,22,7,OBSIDIAN:0)
Block(-5,22,8,CONCRETE:0)
Block(-5,23,-7,OBSIDIAN:0)
Block(-5,23,-6,OBSIDIAN:0)
Block(-5,23,-5,OBSIDIAN:0)
Block(-5,23,-4,OBSIDIAN:0)
Block(-5,23,-3,OBSIDIAN:0)
Block(-5,23,-2,OBSIDIAN:0)
Block(-5,23,-1,OBSIDIAN:0)
Block(-5,23,0,OBSIDIAN:0)
Block(-5,23,1,OBSIDIAN:0)
Block(-5,23,2,CONCRETE:0)
Block(-5,23,3,CONCRETE:0)
Block(-5,23,4,CONCRETE:0)
Block(-5,23,5,CONCRETE:0)
Block(-5,23,6,CONCRETE:0)
Block(-5,23,7,CONCRETE:0)
Block(-5,23,8,CONCRETE:0)
Block(-5,24,-7,STEP:0)
Block(-5,24,-6,QUARTZ_STAIRS:0)
Block(-5,24,-5,STEP:0)
Block(-5,24,-4,QUARTZ_STAIRS:0)
Block(-5,24,-3,STEP:0)
Block(-5,24,-2,QUARTZ_STAIRS:0)
Block(-5,24,-1,STEP:0)
Block(-5,24,0,CONCRETE:0)
Block(-5,24,1,QUARTZ_STAIRS:0)
Block(-5,25,0,QUARTZ_STAIRS:0)
Block(-5,27,0,QUARTZ_STAIRS:4)
Block(-5,28,-6,QUARTZ_STAIRS:4)
Block(-5,28,-4,QUARTZ_STAIRS:4)
Block(-5,28,-2,QUARTZ_STAIRS:4)
Block(-5,28,0,CONCRETE:0)
Block(-5,29,-7,CONCRETE:0)
Block(-5,29,-6,CONCRETE:0)
Block(-5,29,-5,CONCRETE:0)
Block(-5,29,-4,CONCRETE:0)
Block(-5,29,-3,CONCRETE:0)
Block(-5,29,-2,CONCRETE:0)
Block(-5,29,-1,CONCRETE:0)
Block(-5,29,0,CONCRETE:0)
Block(-5,29,1,QUARTZ_STAIRS:7)
Block(-5,30,-7,STEP:7)
Block(-5,30,-6,CONCRETE:0)
Block(-5,30,-5,STEP:7)
Block(-5,30,-4,CONCRETE:0)
Block(-5,30,-3,STEP:7)
Block(-5,30,-2,CONCRETE:0)
Block(-5,30,-1,STEP:7)
Block(-5,30,0,CONCRETE:0)
Block(-5,30,1,COBBLE_WALL:0)
Block(-5,31,-6,CONCRETE:0)
Block(-5,31,-4,CONCRETE:0)
Block(-5,31,-2,CONCRETE:0)
Block(-5,31,0,CONCRETE:0)
Block(-5,32,-7,STEP:8)
Block(-5,32,-6,CONCRETE:0)
Block(-5,32,-5,STEP:8)
Block(-5,32,-4,CONCRETE:0)
Block(-5,32,-3,STEP:8)
Block(-5,32,-2,CONCRETE:0)
Block(-5,32,-1,STEP:8)
Block(-5,32,0,CONCRETE:0)
Block(-5,33,-7,CONCRETE:0)
Block(-5,33,-6,CONCRETE:0)
Block(-5,33,-5,CONCRETE:0)
Block(-5,33,-4,CONCRETE:0)
Block(-5,33,-3,CONCRETE:0)
Block(-5,33,-2,CONCRETE:0)
Block(-5,33,-1,CONCRETE:0)
Block(-5,33,0,CONCRETE:0)
Block(-5,33,1,QUARTZ_STAIRS:7)
Block(-5,34,1,COBBLE_WALL:0)
RandomBlock(-4,0,-7,CONCRETE:7,60,quark:iron_plate,20,STAINED_CLAY:12,15,STAINED_CLAY:15,5,AIR,7,IRON_BARS,12,CONCRETE:7,100)
RandomBlock(-4,0,-6,CONCRETE:7,60,quark:iron_plate,20,STAINED_CLAY:12,15,STAINED_CLAY:15,5,AIR,7,IRON_BARS,12,CONCRETE:7,100)
RandomBlock(-4,0,-5,CONCRETE:7,60,quark:iron_plate,20,STAINED_CLAY:12,15,STAINED_CLAY:15,5,AIR,7,IRON_BARS,12,CONCRETE:7,100)
RandomBlock(-4,0,-4,CONCRETE:7,60,quark:iron_plate,20,STAINED_CLAY:12,15,STAINED_CLAY:15,5,AIR,7,IRON_BARS,12,CONCRETE:7,100)
RandomBlock(-4,0,-3,CONCRETE:7,60,quark:iron_plate,20,STAINED_CLAY:12,15,STAINED_CLAY:15,5,AIR,7,IRON_BARS,12,CONCRETE:7,100)
RandomBlock(-4,0,-2,CONCRETE:7,60,quark:iron_plate,20,STAINED_CLAY:12,15,STAINED_CLAY:15,5,AIR,7,IRON_BARS,12,CONCRETE:7,100)
RandomBlock(-4,0,-1,CONCRETE:7,60,quark:iron_plate,20,STAINED_CLAY:12,15,STAINED_CLAY:15,5,AIR,7,IRON_BARS,12,CONCRETE:7,100)
RandomBlock(-4,0,0,CONCRETE:7,60,quark:iron_plate,20,STAINED_CLAY:12,15,STAINED_CLAY:15,5,AIR,7,IRON_BARS,12,CONCRETE:7,100)
RandomBlock(-4,0,1,CONCRETE:7,60,quark:iron_plate,20,STAINED_CLAY:12,15,STAINED_CLAY:15,5,AIR,7,IRON_BARS,12,CONCRETE:7,100)
RandomBlock(-4,0,2,CONCRETE:7,60,quark:iron_plate,20,STAINED_CLAY:12,15,STAINED_CLAY:15,5,AIR,7,IRON_BARS,12,CONCRETE:7,100)
RandomBlock(-4,0,3,CONCRETE:7,60,quark:iron_plate,20,STAINED_CLAY:12,15,STAINED_CLAY:15,5,AIR,7,IRON_BARS,12,CONCRETE:7,100)
RandomBlock(-4,0,4,CONCRETE:7,60,quark:iron_plate,20,STAINED_CLAY:12,15,STAINED_CLAY:15,5,AIR,7,IRON_BARS,12,CONCRETE:7,100)
RandomBlock(-4,0,5,CONCRETE:7,60,quark:iron_plate,20,STAINED_CLAY:12,15,STAINED_CLAY:15,5,AIR,7,IRON_BARS,12,CONCRETE:7,100)
RandomBlock(-4,0,6,CONCRETE:7,60,quark:iron_plate,20,STAINED_CLAY:12,15,STAINED_CLAY:15,5,AIR,7,IRON_BARS,12,CONCRETE:7,100)
RandomBlock(-4,0,7,CONCRETE:7,60,quark:iron_plate,20,STAINED_CLAY:12,15,STAINED_CLAY:15,5,AIR,7,IRON_BARS,12,CONCRETE:7,100)
RandomBlock(-4,0,8,CONCRETE:7,60,quark:iron_plate,20,STAINED_CLAY:12,15,STAINED_CLAY:15,5,AIR,7,IRON_BARS,12,CONCRETE:7,100)
Block(-4,1,-7,OBSIDIAN:0)
Block(-4,1,-6,OBSIDIAN:0)
Block(-4,1,-5,OBSIDIAN:0)
Block(-4,1,-4,OBSIDIAN:0)
Block(-4,1,-3,OBSIDIAN:0)
Block(-4,1,-2,OBSIDIAN:0)
Block(-4,1,-1,OBSIDIAN:0)
Block(-4,1,0,OBSIDIAN:0)
Block(-4,1,1,OBSIDIAN:0)
Block(-4,1,2,OBSIDIAN:0)
Block(-4,1,3,OBSIDIAN:0)
Block(-4,1,4,OBSIDIAN:0)
Block(-4,1,5,OBSIDIAN:0)
Block(-4,1,6,OBSIDIAN:0)
Block(-4,1,7,OBSIDIAN:0)
Block(-4,1,8,OBSIDIAN:0)
RandomBlock(-4,2,-7,CONCRETE:7,60,quark:iron_plate,20,STAINED_CLAY:12,15,STAINED_CLAY:15,5,AIR,7,IRON_BARS,12,CONCRETE:7,100)
RandomBlock(-4,2,-6,CONCRETE:7,60,quark:iron_plate,20,STAINED_CLAY:12,15,STAINED_CLAY:15,5,AIR,7,IRON_BARS,12,CONCRETE:7,100)
RandomBlock(-4,2,-5,CONCRETE:7,60,quark:iron_plate,20,STAINED_CLAY:12,15,STAINED_CLAY:15,5,AIR,7,IRON_BARS,12,CONCRETE:7,100)
RandomBlock(-4,2,-4,CONCRETE:7,60,quark:iron_plate,20,STAINED_CLAY:12,15,STAINED_CLAY:15,5,AIR,7,IRON_BARS,12,CONCRETE:7,100)
RandomBlock(-4,2,-3,CONCRETE:7,60,quark:iron_plate,20,STAINED_CLAY:12,15,STAINED_CLAY:15,5,AIR,7,IRON_BARS,12,CONCRETE:7,100)
RandomBlock(-4,2,-2,CONCRETE:7,60,quark:iron_plate,20,STAINED_CLAY:12,15,STAINED_CLAY:15,5,AIR,7,IRON_BARS,12,CONCRETE:7,100)
RandomBlock(-4,2,-1,CONCRETE:7,60,quark:iron_plate,20,STAINED_CLAY:12,15,STAINED_CLAY:15,5,AIR,7,IRON_BARS,12,CONCRETE:7,100)
RandomBlock(-4,2,0,CONCRETE:7,60,quark:iron_plate,20,STAINED_CLAY:12,15,STAINED_CLAY:15,5,AIR,7,IRON_BARS,12,CONCRETE:7,100)
RandomBlock(-4,2,1,CONCRETE:7,60,quark:iron_plate,20,STAINED_CLAY:12,15,STAINED_CLAY:15,5,AIR,7,IRON_BARS,12,CONCRETE:7,100)
RandomBlock(-4,2,2,CONCRETE:7,60,quark:iron_plate,20,STAINED_CLAY:12,15,STAINED_CLAY:15,5,AIR,7,IRON_BARS,12,CONCRETE:7,100)
RandomBlock(-4,2,3,CONCRETE:7,60,quark:iron_plate,20,STAINED_CLAY:12,15,STAINED_CLAY:15,5,AIR,7,IRON_BARS,12,CONCRETE:7,100)
RandomBlock(-4,2,4,CONCRETE:7,60,quark:iron_plate,20,STAINED_CLAY:12,15,STAINED_CLAY:15,5,AIR,7,IRON_BARS,12,CONCRETE:7,100)
RandomBlock(-4,2,5,CONCRETE:7,60,quark:iron_plate,20,STAINED_CLAY:12,15,STAINED_CLAY:15,5,AIR,7,IRON_BARS,12,CONCRETE:7,100)
RandomBlock(-4,2,6,CONCRETE:7,60,quark:iron_plate,20,STAINED_CLAY:12,15,STAINED_CLAY:15,5,AIR,7,IRON_BARS,12,CONCRETE:7,100)
RandomBlock(-4,2,7,CONCRETE:7,60,quark:iron_plate,20,STAINED_CLAY:12,15,STAINED_CLAY:15,5,AIR,7,IRON_BARS,12,CONCRETE:7,100)
RandomBlock(-4,2,8,CONCRETE:7,60,quark:iron_plate,20,STAINED_CLAY:12,15,STAINED_CLAY:15,5,AIR,7,IRON_BARS,12,CONCRETE:7,100)
RandomBlock(-4,3,-7,CONCRETE:7,60,quark:iron_plate,20,STAINED_CLAY:12,15,STAINED_CLAY:15,5,AIR,7,IRON_BARS,12,CONCRETE:7,100)
RandomBlock(-4,3,-6,CONCRETE:7,60,quark:iron_plate,20,STAINED_CLAY:12,15,STAINED_CLAY:15,5,AIR,7,IRON_BARS,12,CONCRETE:7,100)
RandomBlock(-4,3,-5,CONCRETE:7,60,quark:iron_plate,20,STAINED_CLAY:12,15,STAINED_CLAY:15,5,AIR,7,IRON_BARS,12,CONCRETE:7,100)
RandomBlock(-4,3,-4,CONCRETE:7,60,quark:iron_plate,20,STAINED_CLAY:12,15,STAINED_CLAY:15,5,AIR,7,IRON_BARS,12,CONCRETE:7,100)
RandomBlock(-4,3,-3,CONCRETE:7,60,quark:iron_plate,20,STAINED_CLAY:12,15,STAINED_CLAY:15,5,AIR,7,IRON_BARS,12,CONCRETE:7,100)
RandomBlock(-4,3,-2,CONCRETE:7,60,quark:iron_plate,20,STAINED_CLAY:12,15,STAINED_CLAY:15,5,AIR,7,IRON_BARS,12,CONCRETE:7,100)
RandomBlock(-4,3,-1,CONCRETE:7,60,quark:iron_plate,20,STAINED_CLAY:12,15,STAINED_CLAY:15,5,AIR,7,IRON_BARS,12,CONCRETE:7,100)
RandomBlock(-4,3,0,CONCRETE:7,60,quark:iron_plate,20,STAINED_CLAY:12,15,STAINED_CLAY:15,5,AIR,7,IRON_BARS,12,CONCRETE:7,100)
