Author: NLBlackHeavenNL
Description: No description given
Version: 3
SettingsMode: WriteWithoutComments
Tree: true
Frequency: 1
Rarity: 100.0
RotateRandomly: false
SpawnHeight: randomY
SpawnHeightOffset: -1
SpawnHeightVariance: 0
MinHeight: 63
MaxHeight: 80
ExtrudeMode: None
ExtrudeThroughBlocks: AIR
MaxBranchDepth: 10
ExcludedBiomes: All
SourceBlocks: AIR,GRASS,DIRT,biomesoplenty:grass,biomesoplenty:dirt,SAND
MaxPercentageOutsideSourceBlock: 0
OutsideSourceBlock: placeAnyway
DoReplaceBlocks: true
IsOTGPlus: false
Block(-2,8,1,dynamictreesbop:deadbranch)
Block(-2,10,0,dynamictreesbop:deadbranch)
Block(-2,10,1,dynamictreesbop:deadbranch:1)
Block(-2,11,1,dynamictreesbop:deadbranch)
Block(-1,5,1,dynamictreesbop:deadbranch:3)
Block(-1,6,1,dynamictreesbop:deadbranch:3)
Block(-1,7,1,dynamictreesbop:deadbranch:3)
Block(-1,8,1,dynamictreesbop:deadbranch:2)
Block(-1,9,0,dynamictreesbop:deadbranch)
Block(-1,9,1,dynamictreesbop:deadbranch:2)
Block(-1,10,1,dynamictreesbop:deadbranch:2)
Block(-1,10,2,dynamictreesbop:deadbranch:1)
Block(-1,10,3,dynamictreesbop:deadbranch)
Block(-1,11,2,dynamictreesbop:deadbranch)
Block(0,0,1,dynamictrees:rootydirt:0)
Block(0,1,1,dynamictreesbop:deadbranch:7)
Block(0,2,1,dynamictreesbop:deadbranch:7)
Block(0,3,1,dynamictreesbop:deadbranch:7)
Block(0,4,1,dynamictreesbop:deadbranch:7)
Block(0,5,1,dynamictreesbop:deadbranch:7)
Block(1,5,1,dynamictreesbop:deadbranch:4)
Block(1,6,1,dynamictreesbop:deadbranch:4)
Block(1,7,1,dynamictreesbop:deadbranch:3)
Block(1,8,1,dynamictreesbop:deadbranch:3)
Block(1,9,1,dynamictreesbop:deadbranch:3)
Block(1,10,0,dynamictreesbop:deadbranch:1)
Block(1,10,1,dynamictreesbop:deadbranch:2)
Block(1,10,2,dynamictreesbop:deadbranch:1)
Block(1,11,0,dynamictreesbop:deadbranch)
Block(1,11,2,dynamictreesbop:deadbranch)
Block(2,9,1,dynamictreesbop:deadbranch:1)
Block(2,9,2,dynamictreesbop:deadbranch)
Block(2,10,0,dynamictreesbop:deadbranch)
BlockCheck(0,-1,1,GRASS,DIRT,SAND,biomesoplenty:grass,biomesoplenty:dirt)
